[2024-01-07T17:53:41.624+0000] {taskinstance.py:1159} INFO - Dependencies all met for dep_context=non-requeueable deps ti=<TaskInstance: ingest_from_postgres_to_GCS_bucket.country_load_dataset_to_bq scheduled__2024-01-05T00:00:00+00:00 [queued]>
[2024-01-07T17:53:41.637+0000] {taskinstance.py:1159} INFO - Dependencies all met for dep_context=requeueable deps ti=<TaskInstance: ingest_from_postgres_to_GCS_bucket.country_load_dataset_to_bq scheduled__2024-01-05T00:00:00+00:00 [queued]>
[2024-01-07T17:53:41.637+0000] {taskinstance.py:1361} INFO - Starting attempt 2 of 3
[2024-01-07T17:53:41.701+0000] {taskinstance.py:1382} INFO - Executing <Task(GCSToBigQueryOperator): country_load_dataset_to_bq> on 2024-01-05 00:00:00+00:00
[2024-01-07T17:53:41.711+0000] {standard_task_runner.py:57} INFO - Started process 7280 to run task
[2024-01-07T17:53:41.716+0000] {standard_task_runner.py:84} INFO - Running: ['***', 'tasks', 'run', 'ingest_from_postgres_to_GCS_bucket', 'country_load_dataset_to_bq', 'scheduled__2024-01-05T00:00:00+00:00', '--job-id', '388', '--raw', '--subdir', 'DAGS_FOLDER/postgres_to_gcs_staging.py', '--cfg-path', '/tmp/tmp21j1qi77']
[2024-01-07T17:53:41.719+0000] {standard_task_runner.py:85} INFO - Job 388: Subtask country_load_dataset_to_bq
[2024-01-07T17:53:41.887+0000] {task_command.py:416} INFO - Running <TaskInstance: ingest_from_postgres_to_GCS_bucket.country_load_dataset_to_bq scheduled__2024-01-05T00:00:00+00:00 [running]> on host 5d007c0b4985
[2024-01-07T17:53:42.155+0000] {taskinstance.py:1662} INFO - Exporting env vars: AIRFLOW_CTX_DAG_EMAIL='franklinmutwiri41@gmail.com' AIRFLOW_CTX_DAG_OWNER='***' AIRFLOW_CTX_DAG_ID='ingest_from_postgres_to_GCS_bucket' AIRFLOW_CTX_TASK_ID='country_load_dataset_to_bq' AIRFLOW_CTX_EXECUTION_DATE='2024-01-05T00:00:00+00:00' AIRFLOW_CTX_TRY_NUMBER='2' AIRFLOW_CTX_DAG_RUN_ID='scheduled__2024-01-05T00:00:00+00:00'
[2024-01-07T17:53:42.184+0000] {connection.py:232} WARNING - Connection schemes (type: google_cloud_platform) shall not contain '_' according to RFC3986.
[2024-01-07T17:53:42.192+0000] {base.py:73} INFO - Using connection ID 'google_cloud_default' for task execution.
[2024-01-07T17:53:42.193+0000] {gcs_to_bigquery.py:376} INFO - Using existing BigQuery table for storing data...
[2024-01-07T17:53:42.269+0000] {gcs_to_bigquery.py:380} INFO - Executing: {'load': {'autodetect': True, 'createDisposition': 'CREATE_NEVER', 'destinationTable': {'projectId': 'data-warehousing-proj', 'datasetId': 'staging_school', 'tableId': 'STG_country'}, 'sourceFormat': 'CSV', 'sourceUris': ['gs://school_data_lake_data-warehousing-proj/country-{ds_nodash}.parquet'], 'writeDisposition': 'WRITE_TRUNCATE', 'ignoreUnknownValues': False, 'skipLeadingRows': 1, 'fieldDelimiter': ',', 'quote': None, 'allowQuotedNewlines': 'true', 'encoding': 'UTF-8'}}
[2024-01-07T17:53:42.271+0000] {bigquery.py:1596} INFO - Inserting job ***_ingest_from_postgres_to_GCS_bucket_country_load_dataset_to_bq_2024_01_05T00_00_00_00_00_ceffb68178639c3a5c22575cb98f7b0d
[2024-01-07T17:53:44.625+0000] {taskinstance.py:1937} ERROR - Task failed with exception
Traceback (most recent call last):
  File "/home/airflow/.local/lib/python3.8/site-packages/airflow/providers/google/cloud/transfers/gcs_to_bigquery.py", line 439, in execute
    job.result(timeout=self.result_timeout, retry=self.result_retry)
  File "/home/airflow/.local/lib/python3.8/site-packages/google/cloud/bigquery/job/base.py", line 922, in result
    return super(_AsyncJob, self).result(timeout=timeout, **kwargs)
  File "/home/airflow/.local/lib/python3.8/site-packages/google/api_core/future/polling.py", line 261, in result
    raise self._exception
google.api_core.exceptions.NotFound: 404 Not found: Table data-warehousing-proj:staging_school.STG_country was not found in location europe-west6
[2024-01-07T17:53:44.656+0000] {taskinstance.py:1400} INFO - Marking task as UP_FOR_RETRY. dag_id=ingest_from_postgres_to_GCS_bucket, task_id=country_load_dataset_to_bq, execution_date=20240105T000000, start_date=20240107T175341, end_date=20240107T175344
[2024-01-07T17:53:44.734+0000] {logging_mixin.py:151} WARNING - /home/***/.local/lib/python3.8/site-packages/***/utils/email.py:154 RemovedInAirflow3Warning: Fetching SMTP credentials from configuration variables will be deprecated in a future release. Please set credentials using a connection instead.
[2024-01-07T17:53:44.735+0000] {configuration.py:1068} WARNING - section/key [smtp/smtp_user] not found in config
[2024-01-07T17:53:44.735+0000] {email.py:270} INFO - Email alerting: attempt 1
[2024-01-07T17:53:44.771+0000] {configuration.py:1068} WARNING - section/key [smtp/smtp_user] not found in config
[2024-01-07T17:53:44.772+0000] {email.py:270} INFO - Email alerting: attempt 1
[2024-01-07T17:53:44.772+0000] {taskinstance.py:2007} ERROR - Failed to send email to: ['franklinmutwiri41@gmail.com']
Traceback (most recent call last):
  File "/home/airflow/.local/lib/python3.8/site-packages/airflow/models/taskinstance.py", line 1518, in _run_raw_task
    self._execute_task_with_callbacks(context, test_mode, session=session)
  File "/home/airflow/.local/lib/python3.8/site-packages/airflow/models/taskinstance.py", line 1681, in _execute_task_with_callbacks
    result = self._execute_task(context, task_orig)
  File "/home/airflow/.local/lib/python3.8/site-packages/airflow/models/taskinstance.py", line 1744, in _execute_task
    result = execute_callable(context=context, **execute_callable_kwargs)
  File "/home/airflow/.local/lib/python3.8/site-packages/airflow/providers/google/cloud/transfers/gcs_to_bigquery.py", line 439, in execute
    job.result(timeout=self.result_timeout, retry=self.result_retry)
  File "/home/airflow/.local/lib/python3.8/site-packages/google/cloud/bigquery/job/base.py", line 922, in result
    return super(_AsyncJob, self).result(timeout=timeout, **kwargs)
  File "/home/airflow/.local/lib/python3.8/site-packages/google/api_core/future/polling.py", line 261, in result
    raise self._exception
google.api_core.exceptions.NotFound: 404 Not found: Table data-warehousing-proj:staging_school.STG_country was not found in location europe-west6

During handling of the above exception, another exception occurred:

Traceback (most recent call last):
  File "/home/airflow/.local/lib/python3.8/site-packages/airflow/models/taskinstance.py", line 2420, in email_alert
    send_email(task.email, subject, html_content)
  File "/home/airflow/.local/lib/python3.8/site-packages/airflow/utils/email.py", line 80, in send_email
    return backend(
  File "/home/airflow/.local/lib/python3.8/site-packages/airflow/utils/email.py", line 154, in send_email_smtp
    send_mime_email(e_from=mail_from, e_to=recipients, mime_msg=msg, conn_id=conn_id, dryrun=dryrun)
  File "/home/airflow/.local/lib/python3.8/site-packages/airflow/utils/email.py", line 272, in send_mime_email
    smtp_conn = _get_smtp_connection(smtp_host, smtp_port, smtp_timeout, smtp_ssl)
  File "/home/airflow/.local/lib/python3.8/site-packages/airflow/utils/email.py", line 316, in _get_smtp_connection
    return smtplib.SMTP(host=host, port=port, timeout=timeout)
  File "/usr/local/lib/python3.8/smtplib.py", line 255, in __init__
    (code, msg) = self.connect(host, port)
  File "/usr/local/lib/python3.8/smtplib.py", line 339, in connect
    self.sock = self._get_socket(host, port, self.timeout)
  File "/usr/local/lib/python3.8/smtplib.py", line 310, in _get_socket
    return socket.create_connection((host, port), timeout,
  File "/usr/local/lib/python3.8/socket.py", line 808, in create_connection
    raise err
  File "/usr/local/lib/python3.8/socket.py", line 796, in create_connection
    sock.connect(sa)
OSError: [Errno 99] Cannot assign requested address

During handling of the above exception, another exception occurred:

Traceback (most recent call last):
  File "/home/airflow/.local/lib/python3.8/site-packages/airflow/models/taskinstance.py", line 2005, in handle_failure
    self.email_alert(error, task)
  File "/home/airflow/.local/lib/python3.8/site-packages/airflow/models/taskinstance.py", line 2422, in email_alert
    send_email(task.email, subject, html_content_err)
  File "/home/airflow/.local/lib/python3.8/site-packages/airflow/utils/email.py", line 80, in send_email
    return backend(
  File "/home/airflow/.local/lib/python3.8/site-packages/airflow/utils/email.py", line 154, in send_email_smtp
    send_mime_email(e_from=mail_from, e_to=recipients, mime_msg=msg, conn_id=conn_id, dryrun=dryrun)
  File "/home/airflow/.local/lib/python3.8/site-packages/airflow/utils/email.py", line 272, in send_mime_email
    smtp_conn = _get_smtp_connection(smtp_host, smtp_port, smtp_timeout, smtp_ssl)
  File "/home/airflow/.local/lib/python3.8/site-packages/airflow/utils/email.py", line 316, in _get_smtp_connection
    return smtplib.SMTP(host=host, port=port, timeout=timeout)
  File "/usr/local/lib/python3.8/smtplib.py", line 255, in __init__
    (code, msg) = self.connect(host, port)
  File "/usr/local/lib/python3.8/smtplib.py", line 339, in connect
    self.sock = self._get_socket(host, port, self.timeout)
  File "/usr/local/lib/python3.8/smtplib.py", line 310, in _get_socket
    return socket.create_connection((host, port), timeout,
  File "/usr/local/lib/python3.8/socket.py", line 808, in create_connection
    raise err
  File "/usr/local/lib/python3.8/socket.py", line 796, in create_connection
    sock.connect(sa)
OSError: [Errno 99] Cannot assign requested address
[2024-01-07T17:53:45.643+0000] {standard_task_runner.py:104} ERROR - Failed to execute job 388 for task country_load_dataset_to_bq (404 Not found: Table data-warehousing-proj:staging_school.STG_country was not found in location europe-west6; 7280)
[2024-01-07T17:53:45.676+0000] {local_task_job_runner.py:228} INFO - Task exited with return code 1
[2024-01-07T17:53:45.757+0000] {taskinstance.py:2778} INFO - 0 downstream tasks scheduled from follow-on schedule check
[2024-01-07T18:02:13.152+0000] {taskinstance.py:1159} INFO - Dependencies all met for dep_context=non-requeueable deps ti=<TaskInstance: ingest_from_postgres_to_GCS_bucket.country_load_dataset_to_bq scheduled__2024-01-05T00:00:00+00:00 [queued]>
[2024-01-07T18:02:13.167+0000] {taskinstance.py:1159} INFO - Dependencies all met for dep_context=requeueable deps ti=<TaskInstance: ingest_from_postgres_to_GCS_bucket.country_load_dataset_to_bq scheduled__2024-01-05T00:00:00+00:00 [queued]>
[2024-01-07T18:02:13.167+0000] {taskinstance.py:1361} INFO - Starting attempt 2 of 3
[2024-01-07T18:02:13.190+0000] {taskinstance.py:1382} INFO - Executing <Task(GCSToBigQueryOperator): country_load_dataset_to_bq> on 2024-01-05 00:00:00+00:00
[2024-01-07T18:02:13.198+0000] {standard_task_runner.py:57} INFO - Started process 7536 to run task
[2024-01-07T18:02:13.202+0000] {standard_task_runner.py:84} INFO - Running: ['***', 'tasks', 'run', 'ingest_from_postgres_to_GCS_bucket', 'country_load_dataset_to_bq', 'scheduled__2024-01-05T00:00:00+00:00', '--job-id', '404', '--raw', '--subdir', 'DAGS_FOLDER/postgres_to_gcs_staging.py', '--cfg-path', '/tmp/tmp4yx8v39e']
[2024-01-07T18:02:13.205+0000] {standard_task_runner.py:85} INFO - Job 404: Subtask country_load_dataset_to_bq
[2024-01-07T18:02:13.295+0000] {task_command.py:416} INFO - Running <TaskInstance: ingest_from_postgres_to_GCS_bucket.country_load_dataset_to_bq scheduled__2024-01-05T00:00:00+00:00 [running]> on host 5d007c0b4985
[2024-01-07T18:02:13.409+0000] {taskinstance.py:1662} INFO - Exporting env vars: AIRFLOW_CTX_DAG_EMAIL='franklinmutwiri41@gmail.com' AIRFLOW_CTX_DAG_OWNER='***' AIRFLOW_CTX_DAG_ID='ingest_from_postgres_to_GCS_bucket' AIRFLOW_CTX_TASK_ID='country_load_dataset_to_bq' AIRFLOW_CTX_EXECUTION_DATE='2024-01-05T00:00:00+00:00' AIRFLOW_CTX_TRY_NUMBER='2' AIRFLOW_CTX_DAG_RUN_ID='scheduled__2024-01-05T00:00:00+00:00'
[2024-01-07T18:02:13.424+0000] {connection.py:232} WARNING - Connection schemes (type: google_cloud_platform) shall not contain '_' according to RFC3986.
[2024-01-07T18:02:13.428+0000] {base.py:73} INFO - Using connection ID 'google_cloud_default' for task execution.
[2024-01-07T18:02:13.429+0000] {gcs_to_bigquery.py:376} INFO - Using existing BigQuery table for storing data...
[2024-01-07T18:02:13.475+0000] {gcs_to_bigquery.py:380} INFO - Executing: {'load': {'autodetect': True, 'createDisposition': 'CREATE_NEVER', 'destinationTable': {'projectId': 'data-warehousing-proj', 'datasetId': 'staging_school', 'tableId': 'STG_COUNTRY'}, 'sourceFormat': 'CSV', 'sourceUris': ['gs://school_data_lake_data-warehousing-proj/country-{ds_nodash}.parquet'], 'writeDisposition': 'WRITE_TRUNCATE', 'ignoreUnknownValues': False, 'skipLeadingRows': 1, 'fieldDelimiter': ',', 'quote': None, 'allowQuotedNewlines': 'true', 'encoding': 'UTF-8'}}
[2024-01-07T18:02:13.476+0000] {bigquery.py:1596} INFO - Inserting job ***_ingest_from_postgres_to_GCS_bucket_country_load_dataset_to_bq_2024_01_05T00_00_00_00_00_99c945b6f43cc496fe7e30557ffbcb7f
[2024-01-07T18:02:15.760+0000] {taskinstance.py:1937} ERROR - Task failed with exception
Traceback (most recent call last):
  File "/home/airflow/.local/lib/python3.8/site-packages/airflow/providers/google/cloud/transfers/gcs_to_bigquery.py", line 439, in execute
    job.result(timeout=self.result_timeout, retry=self.result_retry)
  File "/home/airflow/.local/lib/python3.8/site-packages/google/cloud/bigquery/job/base.py", line 922, in result
    return super(_AsyncJob, self).result(timeout=timeout, **kwargs)
  File "/home/airflow/.local/lib/python3.8/site-packages/google/api_core/future/polling.py", line 261, in result
    raise self._exception
google.api_core.exceptions.NotFound: 404 Not found: URI gs://school_data_lake_data-warehousing-proj/country-{ds_nodash}.parquet
[2024-01-07T18:02:15.780+0000] {taskinstance.py:1400} INFO - Marking task as UP_FOR_RETRY. dag_id=ingest_from_postgres_to_GCS_bucket, task_id=country_load_dataset_to_bq, execution_date=20240105T000000, start_date=20240107T180213, end_date=20240107T180215
[2024-01-07T18:02:15.802+0000] {logging_mixin.py:151} WARNING - /home/***/.local/lib/python3.8/site-packages/***/utils/email.py:154 RemovedInAirflow3Warning: Fetching SMTP credentials from configuration variables will be deprecated in a future release. Please set credentials using a connection instead.
[2024-01-07T18:02:15.803+0000] {configuration.py:1068} WARNING - section/key [smtp/smtp_user] not found in config
[2024-01-07T18:02:15.803+0000] {email.py:270} INFO - Email alerting: attempt 1
[2024-01-07T18:02:15.817+0000] {configuration.py:1068} WARNING - section/key [smtp/smtp_user] not found in config
[2024-01-07T18:02:15.817+0000] {email.py:270} INFO - Email alerting: attempt 1
[2024-01-07T18:02:15.818+0000] {taskinstance.py:2007} ERROR - Failed to send email to: ['franklinmutwiri41@gmail.com']
Traceback (most recent call last):
  File "/home/airflow/.local/lib/python3.8/site-packages/airflow/models/taskinstance.py", line 1518, in _run_raw_task
    self._execute_task_with_callbacks(context, test_mode, session=session)
  File "/home/airflow/.local/lib/python3.8/site-packages/airflow/models/taskinstance.py", line 1681, in _execute_task_with_callbacks
    result = self._execute_task(context, task_orig)
  File "/home/airflow/.local/lib/python3.8/site-packages/airflow/models/taskinstance.py", line 1744, in _execute_task
    result = execute_callable(context=context, **execute_callable_kwargs)
  File "/home/airflow/.local/lib/python3.8/site-packages/airflow/providers/google/cloud/transfers/gcs_to_bigquery.py", line 439, in execute
    job.result(timeout=self.result_timeout, retry=self.result_retry)
  File "/home/airflow/.local/lib/python3.8/site-packages/google/cloud/bigquery/job/base.py", line 922, in result
    return super(_AsyncJob, self).result(timeout=timeout, **kwargs)
  File "/home/airflow/.local/lib/python3.8/site-packages/google/api_core/future/polling.py", line 261, in result
    raise self._exception
google.api_core.exceptions.NotFound: 404 Not found: URI gs://school_data_lake_data-warehousing-proj/country-{ds_nodash}.parquet

During handling of the above exception, another exception occurred:

Traceback (most recent call last):
  File "/home/airflow/.local/lib/python3.8/site-packages/airflow/models/taskinstance.py", line 2420, in email_alert
    send_email(task.email, subject, html_content)
  File "/home/airflow/.local/lib/python3.8/site-packages/airflow/utils/email.py", line 80, in send_email
    return backend(
  File "/home/airflow/.local/lib/python3.8/site-packages/airflow/utils/email.py", line 154, in send_email_smtp
    send_mime_email(e_from=mail_from, e_to=recipients, mime_msg=msg, conn_id=conn_id, dryrun=dryrun)
  File "/home/airflow/.local/lib/python3.8/site-packages/airflow/utils/email.py", line 272, in send_mime_email
    smtp_conn = _get_smtp_connection(smtp_host, smtp_port, smtp_timeout, smtp_ssl)
  File "/home/airflow/.local/lib/python3.8/site-packages/airflow/utils/email.py", line 316, in _get_smtp_connection
    return smtplib.SMTP(host=host, port=port, timeout=timeout)
  File "/usr/local/lib/python3.8/smtplib.py", line 255, in __init__
    (code, msg) = self.connect(host, port)
  File "/usr/local/lib/python3.8/smtplib.py", line 339, in connect
    self.sock = self._get_socket(host, port, self.timeout)
  File "/usr/local/lib/python3.8/smtplib.py", line 310, in _get_socket
    return socket.create_connection((host, port), timeout,
  File "/usr/local/lib/python3.8/socket.py", line 808, in create_connection
    raise err
  File "/usr/local/lib/python3.8/socket.py", line 796, in create_connection
    sock.connect(sa)
OSError: [Errno 99] Cannot assign requested address

During handling of the above exception, another exception occurred:

Traceback (most recent call last):
  File "/home/airflow/.local/lib/python3.8/site-packages/airflow/models/taskinstance.py", line 2005, in handle_failure
    self.email_alert(error, task)
  File "/home/airflow/.local/lib/python3.8/site-packages/airflow/models/taskinstance.py", line 2422, in email_alert
    send_email(task.email, subject, html_content_err)
  File "/home/airflow/.local/lib/python3.8/site-packages/airflow/utils/email.py", line 80, in send_email
    return backend(
  File "/home/airflow/.local/lib/python3.8/site-packages/airflow/utils/email.py", line 154, in send_email_smtp
    send_mime_email(e_from=mail_from, e_to=recipients, mime_msg=msg, conn_id=conn_id, dryrun=dryrun)
  File "/home/airflow/.local/lib/python3.8/site-packages/airflow/utils/email.py", line 272, in send_mime_email
    smtp_conn = _get_smtp_connection(smtp_host, smtp_port, smtp_timeout, smtp_ssl)
  File "/home/airflow/.local/lib/python3.8/site-packages/airflow/utils/email.py", line 316, in _get_smtp_connection
    return smtplib.SMTP(host=host, port=port, timeout=timeout)
  File "/usr/local/lib/python3.8/smtplib.py", line 255, in __init__
    (code, msg) = self.connect(host, port)
  File "/usr/local/lib/python3.8/smtplib.py", line 339, in connect
    self.sock = self._get_socket(host, port, self.timeout)
  File "/usr/local/lib/python3.8/smtplib.py", line 310, in _get_socket
    return socket.create_connection((host, port), timeout,
  File "/usr/local/lib/python3.8/socket.py", line 808, in create_connection
    raise err
  File "/usr/local/lib/python3.8/socket.py", line 796, in create_connection
    sock.connect(sa)
OSError: [Errno 99] Cannot assign requested address
[2024-01-07T18:02:15.859+0000] {standard_task_runner.py:104} ERROR - Failed to execute job 404 for task country_load_dataset_to_bq (404 Not found: URI gs://school_data_lake_data-warehousing-proj/country-{ds_nodash}.parquet; 7536)
[2024-01-07T18:02:15.871+0000] {local_task_job_runner.py:228} INFO - Task exited with return code 1
[2024-01-07T18:02:15.893+0000] {taskinstance.py:2778} INFO - 0 downstream tasks scheduled from follow-on schedule check
[2024-01-07T19:14:29.719+0000] {taskinstance.py:1159} INFO - Dependencies all met for dep_context=non-requeueable deps ti=<TaskInstance: ingest_from_postgres_to_GCS_bucket.country_load_dataset_to_bq scheduled__2024-01-05T00:00:00+00:00 [queued]>
[2024-01-07T19:14:29.747+0000] {taskinstance.py:1159} INFO - Dependencies all met for dep_context=requeueable deps ti=<TaskInstance: ingest_from_postgres_to_GCS_bucket.country_load_dataset_to_bq scheduled__2024-01-05T00:00:00+00:00 [queued]>
[2024-01-07T19:14:29.747+0000] {taskinstance.py:1361} INFO - Starting attempt 2 of 3
[2024-01-07T19:14:29.777+0000] {taskinstance.py:1382} INFO - Executing <Task(GCSToBigQueryOperator): country_load_dataset_to_bq> on 2024-01-05 00:00:00+00:00
[2024-01-07T19:14:29.784+0000] {standard_task_runner.py:57} INFO - Started process 9475 to run task
[2024-01-07T19:14:29.789+0000] {standard_task_runner.py:84} INFO - Running: ['***', 'tasks', 'run', 'ingest_from_postgres_to_GCS_bucket', 'country_load_dataset_to_bq', 'scheduled__2024-01-05T00:00:00+00:00', '--job-id', '429', '--raw', '--subdir', 'DAGS_FOLDER/postgres_to_gcs_staging.py', '--cfg-path', '/tmp/tmppdd4zfk4']
[2024-01-07T19:14:29.793+0000] {standard_task_runner.py:85} INFO - Job 429: Subtask country_load_dataset_to_bq
[2024-01-07T19:14:29.924+0000] {task_command.py:416} INFO - Running <TaskInstance: ingest_from_postgres_to_GCS_bucket.country_load_dataset_to_bq scheduled__2024-01-05T00:00:00+00:00 [running]> on host 5d007c0b4985
[2024-01-07T19:14:30.054+0000] {taskinstance.py:1662} INFO - Exporting env vars: AIRFLOW_CTX_DAG_EMAIL='franklinmutwiri41@gmail.com' AIRFLOW_CTX_DAG_OWNER='***' AIRFLOW_CTX_DAG_ID='ingest_from_postgres_to_GCS_bucket' AIRFLOW_CTX_TASK_ID='country_load_dataset_to_bq' AIRFLOW_CTX_EXECUTION_DATE='2024-01-05T00:00:00+00:00' AIRFLOW_CTX_TRY_NUMBER='2' AIRFLOW_CTX_DAG_RUN_ID='scheduled__2024-01-05T00:00:00+00:00'
[2024-01-07T19:14:30.078+0000] {connection.py:232} WARNING - Connection schemes (type: google_cloud_platform) shall not contain '_' according to RFC3986.
[2024-01-07T19:14:30.084+0000] {base.py:73} INFO - Using connection ID 'google_cloud_default' for task execution.
[2024-01-07T19:14:30.085+0000] {gcs_to_bigquery.py:376} INFO - Using existing BigQuery table for storing data...
[2024-01-07T19:14:30.146+0000] {gcs_to_bigquery.py:380} INFO - Executing: {'load': {'autodetect': True, 'createDisposition': 'CREATE_NEVER', 'destinationTable': {'projectId': 'data-warehousing-proj', 'datasetId': 'staging_school', 'tableId': 'STG_COUNTRY'}, 'sourceFormat': 'CSV', 'sourceUris': ['gs://school_data_lake_data-warehousing-proj/country-20240105.parquet'], 'writeDisposition': 'WRITE_TRUNCATE', 'ignoreUnknownValues': False, 'skipLeadingRows': 1, 'fieldDelimiter': ',', 'quote': None, 'allowQuotedNewlines': 'true', 'encoding': 'UTF-8'}}
[2024-01-07T19:14:30.148+0000] {bigquery.py:1596} INFO - Inserting job ***_ingest_from_postgres_to_GCS_bucket_country_load_dataset_to_bq_2024_01_05T00_00_00_00_00_eca42a4f0fdb4fa1e46dcb60e1800af2
[2024-01-07T19:14:32.329+0000] {taskinstance.py:1937} ERROR - Task failed with exception
Traceback (most recent call last):
  File "/home/airflow/.local/lib/python3.8/site-packages/airflow/providers/google/cloud/transfers/gcs_to_bigquery.py", line 439, in execute
    job.result(timeout=self.result_timeout, retry=self.result_retry)
  File "/home/airflow/.local/lib/python3.8/site-packages/google/cloud/bigquery/job/base.py", line 922, in result
    return super(_AsyncJob, self).result(timeout=timeout, **kwargs)
  File "/home/airflow/.local/lib/python3.8/site-packages/google/api_core/future/polling.py", line 261, in result
    raise self._exception
google.api_core.exceptions.NotFound: 404 Not found: URI gs://school_data_lake_data-warehousing-proj/country-20240105.parquet
[2024-01-07T19:14:32.346+0000] {taskinstance.py:1400} INFO - Marking task as UP_FOR_RETRY. dag_id=ingest_from_postgres_to_GCS_bucket, task_id=country_load_dataset_to_bq, execution_date=20240105T000000, start_date=20240107T191429, end_date=20240107T191432
[2024-01-07T19:14:32.366+0000] {logging_mixin.py:151} WARNING - /home/***/.local/lib/python3.8/site-packages/***/utils/email.py:154 RemovedInAirflow3Warning: Fetching SMTP credentials from configuration variables will be deprecated in a future release. Please set credentials using a connection instead.
[2024-01-07T19:14:32.366+0000] {configuration.py:1068} WARNING - section/key [smtp/smtp_user] not found in config
[2024-01-07T19:14:32.367+0000] {email.py:270} INFO - Email alerting: attempt 1
[2024-01-07T19:14:32.382+0000] {configuration.py:1068} WARNING - section/key [smtp/smtp_user] not found in config
[2024-01-07T19:14:32.382+0000] {email.py:270} INFO - Email alerting: attempt 1
[2024-01-07T19:14:32.383+0000] {taskinstance.py:2007} ERROR - Failed to send email to: ['franklinmutwiri41@gmail.com']
Traceback (most recent call last):
  File "/home/airflow/.local/lib/python3.8/site-packages/airflow/models/taskinstance.py", line 1518, in _run_raw_task
    self._execute_task_with_callbacks(context, test_mode, session=session)
  File "/home/airflow/.local/lib/python3.8/site-packages/airflow/models/taskinstance.py", line 1681, in _execute_task_with_callbacks
    result = self._execute_task(context, task_orig)
  File "/home/airflow/.local/lib/python3.8/site-packages/airflow/models/taskinstance.py", line 1744, in _execute_task
    result = execute_callable(context=context, **execute_callable_kwargs)
  File "/home/airflow/.local/lib/python3.8/site-packages/airflow/providers/google/cloud/transfers/gcs_to_bigquery.py", line 439, in execute
    job.result(timeout=self.result_timeout, retry=self.result_retry)
  File "/home/airflow/.local/lib/python3.8/site-packages/google/cloud/bigquery/job/base.py", line 922, in result
    return super(_AsyncJob, self).result(timeout=timeout, **kwargs)
  File "/home/airflow/.local/lib/python3.8/site-packages/google/api_core/future/polling.py", line 261, in result
    raise self._exception
google.api_core.exceptions.NotFound: 404 Not found: URI gs://school_data_lake_data-warehousing-proj/country-20240105.parquet

During handling of the above exception, another exception occurred:

Traceback (most recent call last):
  File "/home/airflow/.local/lib/python3.8/site-packages/airflow/models/taskinstance.py", line 2420, in email_alert
    send_email(task.email, subject, html_content)
  File "/home/airflow/.local/lib/python3.8/site-packages/airflow/utils/email.py", line 80, in send_email
    return backend(
  File "/home/airflow/.local/lib/python3.8/site-packages/airflow/utils/email.py", line 154, in send_email_smtp
    send_mime_email(e_from=mail_from, e_to=recipients, mime_msg=msg, conn_id=conn_id, dryrun=dryrun)
  File "/home/airflow/.local/lib/python3.8/site-packages/airflow/utils/email.py", line 272, in send_mime_email
    smtp_conn = _get_smtp_connection(smtp_host, smtp_port, smtp_timeout, smtp_ssl)
  File "/home/airflow/.local/lib/python3.8/site-packages/airflow/utils/email.py", line 316, in _get_smtp_connection
    return smtplib.SMTP(host=host, port=port, timeout=timeout)
  File "/usr/local/lib/python3.8/smtplib.py", line 255, in __init__
    (code, msg) = self.connect(host, port)
  File "/usr/local/lib/python3.8/smtplib.py", line 339, in connect
    self.sock = self._get_socket(host, port, self.timeout)
  File "/usr/local/lib/python3.8/smtplib.py", line 310, in _get_socket
    return socket.create_connection((host, port), timeout,
  File "/usr/local/lib/python3.8/socket.py", line 808, in create_connection
    raise err
  File "/usr/local/lib/python3.8/socket.py", line 796, in create_connection
    sock.connect(sa)
OSError: [Errno 99] Cannot assign requested address

During handling of the above exception, another exception occurred:

Traceback (most recent call last):
  File "/home/airflow/.local/lib/python3.8/site-packages/airflow/models/taskinstance.py", line 2005, in handle_failure
    self.email_alert(error, task)
  File "/home/airflow/.local/lib/python3.8/site-packages/airflow/models/taskinstance.py", line 2422, in email_alert
    send_email(task.email, subject, html_content_err)
  File "/home/airflow/.local/lib/python3.8/site-packages/airflow/utils/email.py", line 80, in send_email
    return backend(
  File "/home/airflow/.local/lib/python3.8/site-packages/airflow/utils/email.py", line 154, in send_email_smtp
    send_mime_email(e_from=mail_from, e_to=recipients, mime_msg=msg, conn_id=conn_id, dryrun=dryrun)
  File "/home/airflow/.local/lib/python3.8/site-packages/airflow/utils/email.py", line 272, in send_mime_email
    smtp_conn = _get_smtp_connection(smtp_host, smtp_port, smtp_timeout, smtp_ssl)
  File "/home/airflow/.local/lib/python3.8/site-packages/airflow/utils/email.py", line 316, in _get_smtp_connection
    return smtplib.SMTP(host=host, port=port, timeout=timeout)
  File "/usr/local/lib/python3.8/smtplib.py", line 255, in __init__
    (code, msg) = self.connect(host, port)
  File "/usr/local/lib/python3.8/smtplib.py", line 339, in connect
    self.sock = self._get_socket(host, port, self.timeout)
  File "/usr/local/lib/python3.8/smtplib.py", line 310, in _get_socket
    return socket.create_connection((host, port), timeout,
  File "/usr/local/lib/python3.8/socket.py", line 808, in create_connection
    raise err
  File "/usr/local/lib/python3.8/socket.py", line 796, in create_connection
    sock.connect(sa)
OSError: [Errno 99] Cannot assign requested address
[2024-01-07T19:14:32.411+0000] {standard_task_runner.py:104} ERROR - Failed to execute job 429 for task country_load_dataset_to_bq (404 Not found: URI gs://school_data_lake_data-warehousing-proj/country-20240105.parquet; 9475)
[2024-01-07T19:14:32.454+0000] {local_task_job_runner.py:228} INFO - Task exited with return code 1
[2024-01-07T19:14:32.477+0000] {taskinstance.py:2778} INFO - 0 downstream tasks scheduled from follow-on schedule check
[2024-01-07T19:31:06.312+0000] {taskinstance.py:1159} INFO - Dependencies all met for dep_context=non-requeueable deps ti=<TaskInstance: ingest_from_postgres_to_GCS_bucket.country_load_dataset_to_bq scheduled__2024-01-05T00:00:00+00:00 [queued]>
[2024-01-07T19:31:06.338+0000] {taskinstance.py:1159} INFO - Dependencies all met for dep_context=requeueable deps ti=<TaskInstance: ingest_from_postgres_to_GCS_bucket.country_load_dataset_to_bq scheduled__2024-01-05T00:00:00+00:00 [queued]>
[2024-01-07T19:31:06.338+0000] {taskinstance.py:1361} INFO - Starting attempt 2 of 3
[2024-01-07T19:31:06.373+0000] {taskinstance.py:1382} INFO - Executing <Task(GCSToBigQueryOperator): country_load_dataset_to_bq> on 2024-01-05 00:00:00+00:00
[2024-01-07T19:31:06.383+0000] {standard_task_runner.py:57} INFO - Started process 9964 to run task
[2024-01-07T19:31:06.389+0000] {standard_task_runner.py:84} INFO - Running: ['***', 'tasks', 'run', 'ingest_from_postgres_to_GCS_bucket', 'country_load_dataset_to_bq', 'scheduled__2024-01-05T00:00:00+00:00', '--job-id', '445', '--raw', '--subdir', 'DAGS_FOLDER/postgres_to_gcs_staging.py', '--cfg-path', '/tmp/tmpb1pzt9vj']
[2024-01-07T19:31:06.392+0000] {standard_task_runner.py:85} INFO - Job 445: Subtask country_load_dataset_to_bq
[2024-01-07T19:31:06.485+0000] {task_command.py:416} INFO - Running <TaskInstance: ingest_from_postgres_to_GCS_bucket.country_load_dataset_to_bq scheduled__2024-01-05T00:00:00+00:00 [running]> on host 5d007c0b4985
[2024-01-07T19:31:06.709+0000] {taskinstance.py:1662} INFO - Exporting env vars: AIRFLOW_CTX_DAG_EMAIL='franklinmutwiri41@gmail.com' AIRFLOW_CTX_DAG_OWNER='***' AIRFLOW_CTX_DAG_ID='ingest_from_postgres_to_GCS_bucket' AIRFLOW_CTX_TASK_ID='country_load_dataset_to_bq' AIRFLOW_CTX_EXECUTION_DATE='2024-01-05T00:00:00+00:00' AIRFLOW_CTX_TRY_NUMBER='2' AIRFLOW_CTX_DAG_RUN_ID='scheduled__2024-01-05T00:00:00+00:00'
[2024-01-07T19:31:06.733+0000] {connection.py:232} WARNING - Connection schemes (type: google_cloud_platform) shall not contain '_' according to RFC3986.
[2024-01-07T19:31:06.740+0000] {base.py:73} INFO - Using connection ID 'google_cloud_default' for task execution.
[2024-01-07T19:31:06.741+0000] {gcs_to_bigquery.py:376} INFO - Using existing BigQuery table for storing data...
[2024-01-07T19:31:06.800+0000] {gcs_to_bigquery.py:380} INFO - Executing: {'load': {'autodetect': True, 'createDisposition': 'CREATE_NEVER', 'destinationTable': {'projectId': 'data-warehousing-proj', 'datasetId': 'staging_school', 'tableId': 'STG_COUNTRY'}, 'sourceFormat': 'PARQUET', 'sourceUris': ['gs://school_data_lake_data-warehousing-proj/data/country-20240105.parquet'], 'writeDisposition': 'WRITE_TRUNCATE', 'ignoreUnknownValues': False}}
[2024-01-07T19:31:06.801+0000] {bigquery.py:1596} INFO - Inserting job ***_ingest_from_postgres_to_GCS_bucket_country_load_dataset_to_bq_2024_01_05T00_00_00_00_00_631de882fbf9eb4595b1dd8da6bacfbf
[2024-01-07T19:31:11.105+0000] {taskinstance.py:1400} INFO - Marking task as SUCCESS. dag_id=ingest_from_postgres_to_GCS_bucket, task_id=country_load_dataset_to_bq, execution_date=20240105T000000, start_date=20240107T193106, end_date=20240107T193111
[2024-01-07T19:31:11.180+0000] {local_task_job_runner.py:228} INFO - Task exited with return code 0
[2024-01-07T19:31:11.206+0000] {taskinstance.py:2778} INFO - 0 downstream tasks scheduled from follow-on schedule check
[2024-01-07T19:59:16.798+0000] {taskinstance.py:1159} INFO - Dependencies all met for dep_context=non-requeueable deps ti=<TaskInstance: ingest_from_postgres_to_GCS_bucket.country_load_dataset_to_bq scheduled__2024-01-05T00:00:00+00:00 [queued]>
[2024-01-07T19:59:16.816+0000] {taskinstance.py:1159} INFO - Dependencies all met for dep_context=requeueable deps ti=<TaskInstance: ingest_from_postgres_to_GCS_bucket.country_load_dataset_to_bq scheduled__2024-01-05T00:00:00+00:00 [queued]>
[2024-01-07T19:59:16.816+0000] {taskinstance.py:1361} INFO - Starting attempt 2 of 3
[2024-01-07T19:59:16.846+0000] {taskinstance.py:1382} INFO - Executing <Task(GCSToBigQueryOperator): country_load_dataset_to_bq> on 2024-01-05 00:00:00+00:00
[2024-01-07T19:59:16.853+0000] {standard_task_runner.py:57} INFO - Started process 10721 to run task
[2024-01-07T19:59:16.860+0000] {standard_task_runner.py:84} INFO - Running: ['***', 'tasks', 'run', 'ingest_from_postgres_to_GCS_bucket', 'country_load_dataset_to_bq', 'scheduled__2024-01-05T00:00:00+00:00', '--job-id', '466', '--raw', '--subdir', 'DAGS_FOLDER/postgres_to_gcs_staging.py', '--cfg-path', '/tmp/tmp4615hnwp']
[2024-01-07T19:59:16.864+0000] {standard_task_runner.py:85} INFO - Job 466: Subtask country_load_dataset_to_bq
[2024-01-07T19:59:16.952+0000] {task_command.py:416} INFO - Running <TaskInstance: ingest_from_postgres_to_GCS_bucket.country_load_dataset_to_bq scheduled__2024-01-05T00:00:00+00:00 [running]> on host 5d007c0b4985
[2024-01-07T19:59:17.105+0000] {taskinstance.py:1662} INFO - Exporting env vars: AIRFLOW_CTX_DAG_EMAIL='franklinmutwiri41@gmail.com' AIRFLOW_CTX_DAG_OWNER='***' AIRFLOW_CTX_DAG_ID='ingest_from_postgres_to_GCS_bucket' AIRFLOW_CTX_TASK_ID='country_load_dataset_to_bq' AIRFLOW_CTX_EXECUTION_DATE='2024-01-05T00:00:00+00:00' AIRFLOW_CTX_TRY_NUMBER='2' AIRFLOW_CTX_DAG_RUN_ID='scheduled__2024-01-05T00:00:00+00:00'
[2024-01-07T19:59:17.129+0000] {connection.py:232} WARNING - Connection schemes (type: google_cloud_platform) shall not contain '_' according to RFC3986.
[2024-01-07T19:59:17.134+0000] {base.py:73} INFO - Using connection ID 'google_cloud_default' for task execution.
[2024-01-07T19:59:17.135+0000] {gcs_to_bigquery.py:376} INFO - Using existing BigQuery table for storing data...
[2024-01-07T19:59:17.189+0000] {gcs_to_bigquery.py:380} INFO - Executing: {'load': {'autodetect': True, 'createDisposition': 'CREATE_NEVER', 'destinationTable': {'projectId': 'data-warehousing-proj', 'datasetId': 'staging_school', 'tableId': 'STG_COUNTRY'}, 'sourceFormat': 'PARQUET', 'sourceUris': ['gs://school_data_lake_data-warehousing-proj/data/country.parquet'], 'writeDisposition': 'WRITE_TRUNCATE', 'ignoreUnknownValues': False}}
[2024-01-07T19:59:17.194+0000] {bigquery.py:1596} INFO - Inserting job ***_ingest_from_postgres_to_GCS_bucket_country_load_dataset_to_bq_2024_01_05T00_00_00_00_00_e8f88419433cc774633118425c4b7613
[2024-01-07T19:59:23.529+0000] {taskinstance.py:1400} INFO - Marking task as SUCCESS. dag_id=ingest_from_postgres_to_GCS_bucket, task_id=country_load_dataset_to_bq, execution_date=20240105T000000, start_date=20240107T195916, end_date=20240107T195923
[2024-01-07T19:59:23.554+0000] {local_task_job_runner.py:228} INFO - Task exited with return code 0
[2024-01-07T19:59:23.581+0000] {taskinstance.py:2778} INFO - 0 downstream tasks scheduled from follow-on schedule check
[2024-01-07T20:19:25.754+0000] {taskinstance.py:1159} INFO - Dependencies all met for dep_context=non-requeueable deps ti=<TaskInstance: ingest_from_postgres_to_GCS_bucket.country_load_dataset_to_bq scheduled__2024-01-05T00:00:00+00:00 [queued]>
[2024-01-07T20:19:25.782+0000] {taskinstance.py:1159} INFO - Dependencies all met for dep_context=requeueable deps ti=<TaskInstance: ingest_from_postgres_to_GCS_bucket.country_load_dataset_to_bq scheduled__2024-01-05T00:00:00+00:00 [queued]>
[2024-01-07T20:19:25.784+0000] {taskinstance.py:1361} INFO - Starting attempt 2 of 3
[2024-01-07T20:19:25.824+0000] {taskinstance.py:1382} INFO - Executing <Task(GCSToBigQueryOperator): country_load_dataset_to_bq> on 2024-01-05 00:00:00+00:00
[2024-01-07T20:19:25.831+0000] {standard_task_runner.py:57} INFO - Started process 11266 to run task
[2024-01-07T20:19:25.837+0000] {standard_task_runner.py:84} INFO - Running: ['***', 'tasks', 'run', 'ingest_from_postgres_to_GCS_bucket', 'country_load_dataset_to_bq', 'scheduled__2024-01-05T00:00:00+00:00', '--job-id', '479', '--raw', '--subdir', 'DAGS_FOLDER/postgres_to_gcs_staging.py', '--cfg-path', '/tmp/tmpqxitp5v9']
[2024-01-07T20:19:25.842+0000] {standard_task_runner.py:85} INFO - Job 479: Subtask country_load_dataset_to_bq
[2024-01-07T20:19:25.937+0000] {task_command.py:416} INFO - Running <TaskInstance: ingest_from_postgres_to_GCS_bucket.country_load_dataset_to_bq scheduled__2024-01-05T00:00:00+00:00 [running]> on host 5d007c0b4985
[2024-01-07T20:19:26.105+0000] {taskinstance.py:1662} INFO - Exporting env vars: AIRFLOW_CTX_DAG_EMAIL='franklinmutwiri41@gmail.com' AIRFLOW_CTX_DAG_OWNER='***' AIRFLOW_CTX_DAG_ID='ingest_from_postgres_to_GCS_bucket' AIRFLOW_CTX_TASK_ID='country_load_dataset_to_bq' AIRFLOW_CTX_EXECUTION_DATE='2024-01-05T00:00:00+00:00' AIRFLOW_CTX_TRY_NUMBER='2' AIRFLOW_CTX_DAG_RUN_ID='scheduled__2024-01-05T00:00:00+00:00'
[2024-01-07T20:19:26.123+0000] {connection.py:232} WARNING - Connection schemes (type: google_cloud_platform) shall not contain '_' according to RFC3986.
[2024-01-07T20:19:26.128+0000] {base.py:73} INFO - Using connection ID 'google_cloud_default' for task execution.
[2024-01-07T20:19:26.131+0000] {gcs_to_bigquery.py:376} INFO - Using existing BigQuery table for storing data...
[2024-01-07T20:19:26.183+0000] {gcs_to_bigquery.py:380} INFO - Executing: {'load': {'autodetect': True, 'createDisposition': 'CREATE_NEVER', 'destinationTable': {'projectId': 'data-warehousing-proj', 'datasetId': 'staging_school', 'tableId': 'STG_COUNTRY'}, 'sourceFormat': 'PARQUET', 'sourceUris': ['gs://school_data_lake_data-warehousing-proj/data/country.parquet'], 'writeDisposition': 'WRITE_TRUNCATE', 'ignoreUnknownValues': False}}
[2024-01-07T20:19:26.185+0000] {bigquery.py:1596} INFO - Inserting job ***_ingest_from_postgres_to_GCS_bucket_country_load_dataset_to_bq_2024_01_05T00_00_00_00_00_bceff809b8a6e4eb3deee0a97f01bfff
[2024-01-07T20:19:28.486+0000] {taskinstance.py:1937} ERROR - Task failed with exception
Traceback (most recent call last):
  File "/home/airflow/.local/lib/python3.8/site-packages/airflow/providers/google/cloud/transfers/gcs_to_bigquery.py", line 439, in execute
    job.result(timeout=self.result_timeout, retry=self.result_retry)
  File "/home/airflow/.local/lib/python3.8/site-packages/google/cloud/bigquery/job/base.py", line 922, in result
    return super(_AsyncJob, self).result(timeout=timeout, **kwargs)
  File "/home/airflow/.local/lib/python3.8/site-packages/google/api_core/future/polling.py", line 261, in result
    raise self._exception
google.api_core.exceptions.NotFound: 404 Not found: URI gs://school_data_lake_data-warehousing-proj/data/country.parquet
[2024-01-07T20:19:28.503+0000] {taskinstance.py:1400} INFO - Marking task as UP_FOR_RETRY. dag_id=ingest_from_postgres_to_GCS_bucket, task_id=country_load_dataset_to_bq, execution_date=20240105T000000, start_date=20240107T201925, end_date=20240107T201928
[2024-01-07T20:19:28.526+0000] {logging_mixin.py:151} WARNING - /home/***/.local/lib/python3.8/site-packages/***/utils/email.py:154 RemovedInAirflow3Warning: Fetching SMTP credentials from configuration variables will be deprecated in a future release. Please set credentials using a connection instead.
[2024-01-07T20:19:28.526+0000] {configuration.py:1068} WARNING - section/key [smtp/smtp_user] not found in config
[2024-01-07T20:19:28.526+0000] {email.py:270} INFO - Email alerting: attempt 1
[2024-01-07T20:19:28.541+0000] {configuration.py:1068} WARNING - section/key [smtp/smtp_user] not found in config
[2024-01-07T20:19:28.542+0000] {email.py:270} INFO - Email alerting: attempt 1
[2024-01-07T20:19:28.543+0000] {taskinstance.py:2007} ERROR - Failed to send email to: ['franklinmutwiri41@gmail.com']
Traceback (most recent call last):
  File "/home/airflow/.local/lib/python3.8/site-packages/airflow/models/taskinstance.py", line 1518, in _run_raw_task
    self._execute_task_with_callbacks(context, test_mode, session=session)
  File "/home/airflow/.local/lib/python3.8/site-packages/airflow/models/taskinstance.py", line 1681, in _execute_task_with_callbacks
    result = self._execute_task(context, task_orig)
  File "/home/airflow/.local/lib/python3.8/site-packages/airflow/models/taskinstance.py", line 1744, in _execute_task
    result = execute_callable(context=context, **execute_callable_kwargs)
  File "/home/airflow/.local/lib/python3.8/site-packages/airflow/providers/google/cloud/transfers/gcs_to_bigquery.py", line 439, in execute
    job.result(timeout=self.result_timeout, retry=self.result_retry)
  File "/home/airflow/.local/lib/python3.8/site-packages/google/cloud/bigquery/job/base.py", line 922, in result
    return super(_AsyncJob, self).result(timeout=timeout, **kwargs)
  File "/home/airflow/.local/lib/python3.8/site-packages/google/api_core/future/polling.py", line 261, in result
    raise self._exception
google.api_core.exceptions.NotFound: 404 Not found: URI gs://school_data_lake_data-warehousing-proj/data/country.parquet

During handling of the above exception, another exception occurred:

Traceback (most recent call last):
  File "/home/airflow/.local/lib/python3.8/site-packages/airflow/models/taskinstance.py", line 2420, in email_alert
    send_email(task.email, subject, html_content)
  File "/home/airflow/.local/lib/python3.8/site-packages/airflow/utils/email.py", line 80, in send_email
    return backend(
  File "/home/airflow/.local/lib/python3.8/site-packages/airflow/utils/email.py", line 154, in send_email_smtp
    send_mime_email(e_from=mail_from, e_to=recipients, mime_msg=msg, conn_id=conn_id, dryrun=dryrun)
  File "/home/airflow/.local/lib/python3.8/site-packages/airflow/utils/email.py", line 272, in send_mime_email
    smtp_conn = _get_smtp_connection(smtp_host, smtp_port, smtp_timeout, smtp_ssl)
  File "/home/airflow/.local/lib/python3.8/site-packages/airflow/utils/email.py", line 316, in _get_smtp_connection
    return smtplib.SMTP(host=host, port=port, timeout=timeout)
  File "/usr/local/lib/python3.8/smtplib.py", line 255, in __init__
    (code, msg) = self.connect(host, port)
  File "/usr/local/lib/python3.8/smtplib.py", line 339, in connect
    self.sock = self._get_socket(host, port, self.timeout)
  File "/usr/local/lib/python3.8/smtplib.py", line 310, in _get_socket
    return socket.create_connection((host, port), timeout,
  File "/usr/local/lib/python3.8/socket.py", line 808, in create_connection
    raise err
  File "/usr/local/lib/python3.8/socket.py", line 796, in create_connection
    sock.connect(sa)
OSError: [Errno 99] Cannot assign requested address

During handling of the above exception, another exception occurred:

Traceback (most recent call last):
  File "/home/airflow/.local/lib/python3.8/site-packages/airflow/models/taskinstance.py", line 2005, in handle_failure
    self.email_alert(error, task)
  File "/home/airflow/.local/lib/python3.8/site-packages/airflow/models/taskinstance.py", line 2422, in email_alert
    send_email(task.email, subject, html_content_err)
  File "/home/airflow/.local/lib/python3.8/site-packages/airflow/utils/email.py", line 80, in send_email
    return backend(
  File "/home/airflow/.local/lib/python3.8/site-packages/airflow/utils/email.py", line 154, in send_email_smtp
    send_mime_email(e_from=mail_from, e_to=recipients, mime_msg=msg, conn_id=conn_id, dryrun=dryrun)
  File "/home/airflow/.local/lib/python3.8/site-packages/airflow/utils/email.py", line 272, in send_mime_email
    smtp_conn = _get_smtp_connection(smtp_host, smtp_port, smtp_timeout, smtp_ssl)
  File "/home/airflow/.local/lib/python3.8/site-packages/airflow/utils/email.py", line 316, in _get_smtp_connection
    return smtplib.SMTP(host=host, port=port, timeout=timeout)
  File "/usr/local/lib/python3.8/smtplib.py", line 255, in __init__
    (code, msg) = self.connect(host, port)
  File "/usr/local/lib/python3.8/smtplib.py", line 339, in connect
    self.sock = self._get_socket(host, port, self.timeout)
  File "/usr/local/lib/python3.8/smtplib.py", line 310, in _get_socket
    return socket.create_connection((host, port), timeout,
  File "/usr/local/lib/python3.8/socket.py", line 808, in create_connection
    raise err
  File "/usr/local/lib/python3.8/socket.py", line 796, in create_connection
    sock.connect(sa)
OSError: [Errno 99] Cannot assign requested address
[2024-01-07T20:19:28.592+0000] {standard_task_runner.py:104} ERROR - Failed to execute job 479 for task country_load_dataset_to_bq (404 Not found: URI gs://school_data_lake_data-warehousing-proj/data/country.parquet; 11266)
[2024-01-07T20:19:28.625+0000] {local_task_job_runner.py:228} INFO - Task exited with return code 1
[2024-01-07T20:19:28.671+0000] {taskinstance.py:2778} INFO - 0 downstream tasks scheduled from follow-on schedule check
[2024-01-07T21:00:09.781+0000] {taskinstance.py:1159} INFO - Dependencies all met for dep_context=non-requeueable deps ti=<TaskInstance: ingest_from_postgres_to_GCS_bucket.country_load_dataset_to_bq scheduled__2024-01-05T00:00:00+00:00 [queued]>
[2024-01-07T21:00:09.825+0000] {taskinstance.py:1159} INFO - Dependencies all met for dep_context=requeueable deps ti=<TaskInstance: ingest_from_postgres_to_GCS_bucket.country_load_dataset_to_bq scheduled__2024-01-05T00:00:00+00:00 [queued]>
[2024-01-07T21:00:09.825+0000] {taskinstance.py:1361} INFO - Starting attempt 2 of 3
[2024-01-07T21:00:09.890+0000] {taskinstance.py:1382} INFO - Executing <Task(GCSToBigQueryOperator): country_load_dataset_to_bq> on 2024-01-05 00:00:00+00:00
[2024-01-07T21:00:09.899+0000] {standard_task_runner.py:57} INFO - Started process 12345 to run task
[2024-01-07T21:00:09.902+0000] {standard_task_runner.py:84} INFO - Running: ['***', 'tasks', 'run', 'ingest_from_postgres_to_GCS_bucket', 'country_load_dataset_to_bq', 'scheduled__2024-01-05T00:00:00+00:00', '--job-id', '492', '--raw', '--subdir', 'DAGS_FOLDER/postgres_to_gcs_staging.py', '--cfg-path', '/tmp/tmpkpgdxuiq']
[2024-01-07T21:00:09.905+0000] {standard_task_runner.py:85} INFO - Job 492: Subtask country_load_dataset_to_bq
[2024-01-07T21:00:10.026+0000] {task_command.py:416} INFO - Running <TaskInstance: ingest_from_postgres_to_GCS_bucket.country_load_dataset_to_bq scheduled__2024-01-05T00:00:00+00:00 [running]> on host 5d007c0b4985
[2024-01-07T21:00:10.265+0000] {taskinstance.py:1662} INFO - Exporting env vars: AIRFLOW_CTX_DAG_EMAIL='franklinmutwiri41@gmail.com' AIRFLOW_CTX_DAG_OWNER='***' AIRFLOW_CTX_DAG_ID='ingest_from_postgres_to_GCS_bucket' AIRFLOW_CTX_TASK_ID='country_load_dataset_to_bq' AIRFLOW_CTX_EXECUTION_DATE='2024-01-05T00:00:00+00:00' AIRFLOW_CTX_TRY_NUMBER='2' AIRFLOW_CTX_DAG_RUN_ID='scheduled__2024-01-05T00:00:00+00:00'
[2024-01-07T21:00:10.288+0000] {connection.py:232} WARNING - Connection schemes (type: google_cloud_platform) shall not contain '_' according to RFC3986.
[2024-01-07T21:00:10.296+0000] {base.py:73} INFO - Using connection ID 'google_cloud_default' for task execution.
[2024-01-07T21:00:10.298+0000] {gcs_to_bigquery.py:376} INFO - Using existing BigQuery table for storing data...
[2024-01-07T21:00:10.347+0000] {gcs_to_bigquery.py:380} INFO - Executing: {'load': {'autodetect': True, 'createDisposition': 'CREATE_NEVER', 'destinationTable': {'projectId': 'data-warehousing-proj', 'datasetId': 'staging_school', 'tableId': 'STG_COUNTRY'}, 'sourceFormat': 'PARQUET', 'sourceUris': ['gs://school_data_lake_data-warehousing-proj/data/country.parquet'], 'writeDisposition': 'WRITE_TRUNCATE', 'ignoreUnknownValues': False}}
[2024-01-07T21:00:10.348+0000] {bigquery.py:1596} INFO - Inserting job ***_ingest_from_postgres_to_GCS_bucket_country_load_dataset_to_bq_2024_01_05T00_00_00_00_00_b9b65ca089e3a686e7f9df803c15e73b
[2024-01-07T21:00:12.969+0000] {taskinstance.py:1937} ERROR - Task failed with exception
Traceback (most recent call last):
  File "/home/airflow/.local/lib/python3.8/site-packages/airflow/providers/google/cloud/transfers/gcs_to_bigquery.py", line 439, in execute
    job.result(timeout=self.result_timeout, retry=self.result_retry)
  File "/home/airflow/.local/lib/python3.8/site-packages/google/cloud/bigquery/job/base.py", line 922, in result
    return super(_AsyncJob, self).result(timeout=timeout, **kwargs)
  File "/home/airflow/.local/lib/python3.8/site-packages/google/api_core/future/polling.py", line 261, in result
    raise self._exception
google.api_core.exceptions.NotFound: 404 Not found: URI gs://school_data_lake_data-warehousing-proj/data/country.parquet
[2024-01-07T21:00:12.988+0000] {taskinstance.py:1400} INFO - Marking task as UP_FOR_RETRY. dag_id=ingest_from_postgres_to_GCS_bucket, task_id=country_load_dataset_to_bq, execution_date=20240105T000000, start_date=20240107T210009, end_date=20240107T210012
[2024-01-07T21:00:13.018+0000] {logging_mixin.py:151} WARNING - /home/***/.local/lib/python3.8/site-packages/***/utils/email.py:154 RemovedInAirflow3Warning: Fetching SMTP credentials from configuration variables will be deprecated in a future release. Please set credentials using a connection instead.
[2024-01-07T21:00:13.019+0000] {configuration.py:1068} WARNING - section/key [smtp/smtp_user] not found in config
[2024-01-07T21:00:13.019+0000] {email.py:270} INFO - Email alerting: attempt 1
[2024-01-07T21:00:13.036+0000] {configuration.py:1068} WARNING - section/key [smtp/smtp_user] not found in config
[2024-01-07T21:00:13.037+0000] {email.py:270} INFO - Email alerting: attempt 1
[2024-01-07T21:00:13.037+0000] {taskinstance.py:2007} ERROR - Failed to send email to: ['franklinmutwiri41@gmail.com']
Traceback (most recent call last):
  File "/home/airflow/.local/lib/python3.8/site-packages/airflow/models/taskinstance.py", line 1518, in _run_raw_task
    self._execute_task_with_callbacks(context, test_mode, session=session)
  File "/home/airflow/.local/lib/python3.8/site-packages/airflow/models/taskinstance.py", line 1681, in _execute_task_with_callbacks
    result = self._execute_task(context, task_orig)
  File "/home/airflow/.local/lib/python3.8/site-packages/airflow/models/taskinstance.py", line 1744, in _execute_task
    result = execute_callable(context=context, **execute_callable_kwargs)
  File "/home/airflow/.local/lib/python3.8/site-packages/airflow/providers/google/cloud/transfers/gcs_to_bigquery.py", line 439, in execute
    job.result(timeout=self.result_timeout, retry=self.result_retry)
  File "/home/airflow/.local/lib/python3.8/site-packages/google/cloud/bigquery/job/base.py", line 922, in result
    return super(_AsyncJob, self).result(timeout=timeout, **kwargs)
  File "/home/airflow/.local/lib/python3.8/site-packages/google/api_core/future/polling.py", line 261, in result
    raise self._exception
google.api_core.exceptions.NotFound: 404 Not found: URI gs://school_data_lake_data-warehousing-proj/data/country.parquet

During handling of the above exception, another exception occurred:

Traceback (most recent call last):
  File "/home/airflow/.local/lib/python3.8/site-packages/airflow/models/taskinstance.py", line 2420, in email_alert
    send_email(task.email, subject, html_content)
  File "/home/airflow/.local/lib/python3.8/site-packages/airflow/utils/email.py", line 80, in send_email
    return backend(
  File "/home/airflow/.local/lib/python3.8/site-packages/airflow/utils/email.py", line 154, in send_email_smtp
    send_mime_email(e_from=mail_from, e_to=recipients, mime_msg=msg, conn_id=conn_id, dryrun=dryrun)
  File "/home/airflow/.local/lib/python3.8/site-packages/airflow/utils/email.py", line 272, in send_mime_email
    smtp_conn = _get_smtp_connection(smtp_host, smtp_port, smtp_timeout, smtp_ssl)
  File "/home/airflow/.local/lib/python3.8/site-packages/airflow/utils/email.py", line 316, in _get_smtp_connection
    return smtplib.SMTP(host=host, port=port, timeout=timeout)
  File "/usr/local/lib/python3.8/smtplib.py", line 255, in __init__
    (code, msg) = self.connect(host, port)
  File "/usr/local/lib/python3.8/smtplib.py", line 339, in connect
    self.sock = self._get_socket(host, port, self.timeout)
  File "/usr/local/lib/python3.8/smtplib.py", line 310, in _get_socket
    return socket.create_connection((host, port), timeout,
  File "/usr/local/lib/python3.8/socket.py", line 808, in create_connection
    raise err
  File "/usr/local/lib/python3.8/socket.py", line 796, in create_connection
    sock.connect(sa)
OSError: [Errno 99] Cannot assign requested address

During handling of the above exception, another exception occurred:

Traceback (most recent call last):
  File "/home/airflow/.local/lib/python3.8/site-packages/airflow/models/taskinstance.py", line 2005, in handle_failure
    self.email_alert(error, task)
  File "/home/airflow/.local/lib/python3.8/site-packages/airflow/models/taskinstance.py", line 2422, in email_alert
    send_email(task.email, subject, html_content_err)
  File "/home/airflow/.local/lib/python3.8/site-packages/airflow/utils/email.py", line 80, in send_email
    return backend(
  File "/home/airflow/.local/lib/python3.8/site-packages/airflow/utils/email.py", line 154, in send_email_smtp
    send_mime_email(e_from=mail_from, e_to=recipients, mime_msg=msg, conn_id=conn_id, dryrun=dryrun)
  File "/home/airflow/.local/lib/python3.8/site-packages/airflow/utils/email.py", line 272, in send_mime_email
    smtp_conn = _get_smtp_connection(smtp_host, smtp_port, smtp_timeout, smtp_ssl)
  File "/home/airflow/.local/lib/python3.8/site-packages/airflow/utils/email.py", line 316, in _get_smtp_connection
    return smtplib.SMTP(host=host, port=port, timeout=timeout)
  File "/usr/local/lib/python3.8/smtplib.py", line 255, in __init__
    (code, msg) = self.connect(host, port)
  File "/usr/local/lib/python3.8/smtplib.py", line 339, in connect
    self.sock = self._get_socket(host, port, self.timeout)
  File "/usr/local/lib/python3.8/smtplib.py", line 310, in _get_socket
    return socket.create_connection((host, port), timeout,
  File "/usr/local/lib/python3.8/socket.py", line 808, in create_connection
    raise err
  File "/usr/local/lib/python3.8/socket.py", line 796, in create_connection
    sock.connect(sa)
OSError: [Errno 99] Cannot assign requested address
[2024-01-07T21:00:13.123+0000] {standard_task_runner.py:104} ERROR - Failed to execute job 492 for task country_load_dataset_to_bq (404 Not found: URI gs://school_data_lake_data-warehousing-proj/data/country.parquet; 12345)
[2024-01-07T21:00:13.170+0000] {local_task_job_runner.py:228} INFO - Task exited with return code 1
[2024-01-07T21:00:13.204+0000] {taskinstance.py:2778} INFO - 0 downstream tasks scheduled from follow-on schedule check
[2024-01-07T21:11:10.803+0000] {taskinstance.py:1159} INFO - Dependencies all met for dep_context=non-requeueable deps ti=<TaskInstance: ingest_from_postgres_to_GCS_bucket.country_load_dataset_to_bq scheduled__2024-01-05T00:00:00+00:00 [queued]>
[2024-01-07T21:11:10.828+0000] {taskinstance.py:1159} INFO - Dependencies all met for dep_context=requeueable deps ti=<TaskInstance: ingest_from_postgres_to_GCS_bucket.country_load_dataset_to_bq scheduled__2024-01-05T00:00:00+00:00 [queued]>
[2024-01-07T21:11:10.828+0000] {taskinstance.py:1361} INFO - Starting attempt 2 of 3
[2024-01-07T21:11:10.861+0000] {taskinstance.py:1382} INFO - Executing <Task(GCSToBigQueryOperator): country_load_dataset_to_bq> on 2024-01-05 00:00:00+00:00
[2024-01-07T21:11:10.871+0000] {standard_task_runner.py:57} INFO - Started process 12658 to run task
[2024-01-07T21:11:10.877+0000] {standard_task_runner.py:84} INFO - Running: ['***', 'tasks', 'run', 'ingest_from_postgres_to_GCS_bucket', 'country_load_dataset_to_bq', 'scheduled__2024-01-05T00:00:00+00:00', '--job-id', '509', '--raw', '--subdir', 'DAGS_FOLDER/postgres_to_gcs_staging.py', '--cfg-path', '/tmp/tmpf1juqcdf']
[2024-01-07T21:11:10.879+0000] {standard_task_runner.py:85} INFO - Job 509: Subtask country_load_dataset_to_bq
[2024-01-07T21:11:10.975+0000] {task_command.py:416} INFO - Running <TaskInstance: ingest_from_postgres_to_GCS_bucket.country_load_dataset_to_bq scheduled__2024-01-05T00:00:00+00:00 [running]> on host 5d007c0b4985
[2024-01-07T21:11:11.098+0000] {taskinstance.py:1662} INFO - Exporting env vars: AIRFLOW_CTX_DAG_EMAIL='franklinmutwiri41@gmail.com' AIRFLOW_CTX_DAG_OWNER='***' AIRFLOW_CTX_DAG_ID='ingest_from_postgres_to_GCS_bucket' AIRFLOW_CTX_TASK_ID='country_load_dataset_to_bq' AIRFLOW_CTX_EXECUTION_DATE='2024-01-05T00:00:00+00:00' AIRFLOW_CTX_TRY_NUMBER='2' AIRFLOW_CTX_DAG_RUN_ID='scheduled__2024-01-05T00:00:00+00:00'
[2024-01-07T21:11:11.115+0000] {connection.py:232} WARNING - Connection schemes (type: google_cloud_platform) shall not contain '_' according to RFC3986.
[2024-01-07T21:11:11.120+0000] {base.py:73} INFO - Using connection ID 'google_cloud_default' for task execution.
[2024-01-07T21:11:11.121+0000] {gcs_to_bigquery.py:376} INFO - Using existing BigQuery table for storing data...
[2024-01-07T21:11:11.170+0000] {gcs_to_bigquery.py:380} INFO - Executing: {'load': {'autodetect': True, 'createDisposition': 'CREATE_NEVER', 'destinationTable': {'projectId': 'data-warehousing-proj', 'datasetId': 'staging_school', 'tableId': 'STG_COUNTRY'}, 'sourceFormat': 'PARQUET', 'sourceUris': ['gs://school_data_lake_data-warehousing-proj/data/country.parquet'], 'writeDisposition': 'WRITE_TRUNCATE', 'ignoreUnknownValues': False}}
[2024-01-07T21:11:11.172+0000] {bigquery.py:1596} INFO - Inserting job ***_ingest_from_postgres_to_GCS_bucket_country_load_dataset_to_bq_2024_01_05T00_00_00_00_00_b8d8065c651511812ede9698b2c27ea8
[2024-01-07T21:11:13.604+0000] {taskinstance.py:1937} ERROR - Task failed with exception
Traceback (most recent call last):
  File "/home/airflow/.local/lib/python3.8/site-packages/airflow/providers/google/cloud/transfers/gcs_to_bigquery.py", line 439, in execute
    job.result(timeout=self.result_timeout, retry=self.result_retry)
  File "/home/airflow/.local/lib/python3.8/site-packages/google/cloud/bigquery/job/base.py", line 922, in result
    return super(_AsyncJob, self).result(timeout=timeout, **kwargs)
  File "/home/airflow/.local/lib/python3.8/site-packages/google/api_core/future/polling.py", line 261, in result
    raise self._exception
google.api_core.exceptions.NotFound: 404 Not found: URI gs://school_data_lake_data-warehousing-proj/data/country.parquet
[2024-01-07T21:11:13.620+0000] {taskinstance.py:1400} INFO - Marking task as UP_FOR_RETRY. dag_id=ingest_from_postgres_to_GCS_bucket, task_id=country_load_dataset_to_bq, execution_date=20240105T000000, start_date=20240107T211110, end_date=20240107T211113
[2024-01-07T21:11:13.643+0000] {logging_mixin.py:151} WARNING - /home/***/.local/lib/python3.8/site-packages/***/utils/email.py:154 RemovedInAirflow3Warning: Fetching SMTP credentials from configuration variables will be deprecated in a future release. Please set credentials using a connection instead.
[2024-01-07T21:11:13.644+0000] {configuration.py:1068} WARNING - section/key [smtp/smtp_user] not found in config
[2024-01-07T21:11:13.644+0000] {email.py:270} INFO - Email alerting: attempt 1
[2024-01-07T21:11:13.658+0000] {configuration.py:1068} WARNING - section/key [smtp/smtp_user] not found in config
[2024-01-07T21:11:13.659+0000] {email.py:270} INFO - Email alerting: attempt 1
[2024-01-07T21:11:13.660+0000] {taskinstance.py:2007} ERROR - Failed to send email to: ['franklinmutwiri41@gmail.com']
Traceback (most recent call last):
  File "/home/airflow/.local/lib/python3.8/site-packages/airflow/models/taskinstance.py", line 1518, in _run_raw_task
    self._execute_task_with_callbacks(context, test_mode, session=session)
  File "/home/airflow/.local/lib/python3.8/site-packages/airflow/models/taskinstance.py", line 1681, in _execute_task_with_callbacks
    result = self._execute_task(context, task_orig)
  File "/home/airflow/.local/lib/python3.8/site-packages/airflow/models/taskinstance.py", line 1744, in _execute_task
    result = execute_callable(context=context, **execute_callable_kwargs)
  File "/home/airflow/.local/lib/python3.8/site-packages/airflow/providers/google/cloud/transfers/gcs_to_bigquery.py", line 439, in execute
    job.result(timeout=self.result_timeout, retry=self.result_retry)
  File "/home/airflow/.local/lib/python3.8/site-packages/google/cloud/bigquery/job/base.py", line 922, in result
    return super(_AsyncJob, self).result(timeout=timeout, **kwargs)
  File "/home/airflow/.local/lib/python3.8/site-packages/google/api_core/future/polling.py", line 261, in result
    raise self._exception
google.api_core.exceptions.NotFound: 404 Not found: URI gs://school_data_lake_data-warehousing-proj/data/country.parquet

During handling of the above exception, another exception occurred:

Traceback (most recent call last):
  File "/home/airflow/.local/lib/python3.8/site-packages/airflow/models/taskinstance.py", line 2420, in email_alert
    send_email(task.email, subject, html_content)
  File "/home/airflow/.local/lib/python3.8/site-packages/airflow/utils/email.py", line 80, in send_email
    return backend(
  File "/home/airflow/.local/lib/python3.8/site-packages/airflow/utils/email.py", line 154, in send_email_smtp
    send_mime_email(e_from=mail_from, e_to=recipients, mime_msg=msg, conn_id=conn_id, dryrun=dryrun)
  File "/home/airflow/.local/lib/python3.8/site-packages/airflow/utils/email.py", line 272, in send_mime_email
    smtp_conn = _get_smtp_connection(smtp_host, smtp_port, smtp_timeout, smtp_ssl)
  File "/home/airflow/.local/lib/python3.8/site-packages/airflow/utils/email.py", line 316, in _get_smtp_connection
    return smtplib.SMTP(host=host, port=port, timeout=timeout)
  File "/usr/local/lib/python3.8/smtplib.py", line 255, in __init__
    (code, msg) = self.connect(host, port)
  File "/usr/local/lib/python3.8/smtplib.py", line 339, in connect
    self.sock = self._get_socket(host, port, self.timeout)
  File "/usr/local/lib/python3.8/smtplib.py", line 310, in _get_socket
    return socket.create_connection((host, port), timeout,
  File "/usr/local/lib/python3.8/socket.py", line 808, in create_connection
    raise err
  File "/usr/local/lib/python3.8/socket.py", line 796, in create_connection
    sock.connect(sa)
OSError: [Errno 99] Cannot assign requested address

During handling of the above exception, another exception occurred:

Traceback (most recent call last):
  File "/home/airflow/.local/lib/python3.8/site-packages/airflow/models/taskinstance.py", line 2005, in handle_failure
    self.email_alert(error, task)
  File "/home/airflow/.local/lib/python3.8/site-packages/airflow/models/taskinstance.py", line 2422, in email_alert
    send_email(task.email, subject, html_content_err)
  File "/home/airflow/.local/lib/python3.8/site-packages/airflow/utils/email.py", line 80, in send_email
    return backend(
  File "/home/airflow/.local/lib/python3.8/site-packages/airflow/utils/email.py", line 154, in send_email_smtp
    send_mime_email(e_from=mail_from, e_to=recipients, mime_msg=msg, conn_id=conn_id, dryrun=dryrun)
  File "/home/airflow/.local/lib/python3.8/site-packages/airflow/utils/email.py", line 272, in send_mime_email
    smtp_conn = _get_smtp_connection(smtp_host, smtp_port, smtp_timeout, smtp_ssl)
  File "/home/airflow/.local/lib/python3.8/site-packages/airflow/utils/email.py", line 316, in _get_smtp_connection
    return smtplib.SMTP(host=host, port=port, timeout=timeout)
  File "/usr/local/lib/python3.8/smtplib.py", line 255, in __init__
    (code, msg) = self.connect(host, port)
  File "/usr/local/lib/python3.8/smtplib.py", line 339, in connect
    self.sock = self._get_socket(host, port, self.timeout)
  File "/usr/local/lib/python3.8/smtplib.py", line 310, in _get_socket
    return socket.create_connection((host, port), timeout,
  File "/usr/local/lib/python3.8/socket.py", line 808, in create_connection
    raise err
  File "/usr/local/lib/python3.8/socket.py", line 796, in create_connection
    sock.connect(sa)
OSError: [Errno 99] Cannot assign requested address
[2024-01-07T21:11:13.722+0000] {standard_task_runner.py:104} ERROR - Failed to execute job 509 for task country_load_dataset_to_bq (404 Not found: URI gs://school_data_lake_data-warehousing-proj/data/country.parquet; 12658)
[2024-01-07T21:11:13.742+0000] {local_task_job_runner.py:228} INFO - Task exited with return code 1
[2024-01-07T21:11:13.768+0000] {taskinstance.py:2778} INFO - 0 downstream tasks scheduled from follow-on schedule check
[2024-01-07T21:23:38.657+0000] {taskinstance.py:1159} INFO - Dependencies all met for dep_context=non-requeueable deps ti=<TaskInstance: ingest_from_postgres_to_GCS_bucket.country_load_dataset_to_bq scheduled__2024-01-05T00:00:00+00:00 [queued]>
[2024-01-07T21:23:38.673+0000] {taskinstance.py:1159} INFO - Dependencies all met for dep_context=requeueable deps ti=<TaskInstance: ingest_from_postgres_to_GCS_bucket.country_load_dataset_to_bq scheduled__2024-01-05T00:00:00+00:00 [queued]>
[2024-01-07T21:23:38.673+0000] {taskinstance.py:1361} INFO - Starting attempt 2 of 3
[2024-01-07T21:23:38.703+0000] {taskinstance.py:1382} INFO - Executing <Task(GCSToBigQueryOperator): country_load_dataset_to_bq> on 2024-01-05 00:00:00+00:00
[2024-01-07T21:23:38.713+0000] {standard_task_runner.py:57} INFO - Started process 322 to run task
[2024-01-07T21:23:38.719+0000] {standard_task_runner.py:84} INFO - Running: ['***', 'tasks', 'run', 'ingest_from_postgres_to_GCS_bucket', 'country_load_dataset_to_bq', 'scheduled__2024-01-05T00:00:00+00:00', '--job-id', '541', '--raw', '--subdir', 'DAGS_FOLDER/postgres_to_gcs_staging.py', '--cfg-path', '/tmp/tmpnby9z60y']
[2024-01-07T21:23:38.722+0000] {standard_task_runner.py:85} INFO - Job 541: Subtask country_load_dataset_to_bq
[2024-01-07T21:23:38.821+0000] {task_command.py:416} INFO - Running <TaskInstance: ingest_from_postgres_to_GCS_bucket.country_load_dataset_to_bq scheduled__2024-01-05T00:00:00+00:00 [running]> on host 6609460de6e5
[2024-01-07T21:23:38.953+0000] {taskinstance.py:1662} INFO - Exporting env vars: AIRFLOW_CTX_DAG_EMAIL='franklinmutwiri41@gmail.com' AIRFLOW_CTX_DAG_OWNER='***' AIRFLOW_CTX_DAG_ID='ingest_from_postgres_to_GCS_bucket' AIRFLOW_CTX_TASK_ID='country_load_dataset_to_bq' AIRFLOW_CTX_EXECUTION_DATE='2024-01-05T00:00:00+00:00' AIRFLOW_CTX_TRY_NUMBER='2' AIRFLOW_CTX_DAG_RUN_ID='scheduled__2024-01-05T00:00:00+00:00'
[2024-01-07T21:23:38.970+0000] {connection.py:232} WARNING - Connection schemes (type: google_cloud_platform) shall not contain '_' according to RFC3986.
[2024-01-07T21:23:38.979+0000] {base.py:73} INFO - Using connection ID 'google_cloud_default' for task execution.
[2024-01-07T21:23:38.980+0000] {gcs_to_bigquery.py:376} INFO - Using existing BigQuery table for storing data...
[2024-01-07T21:23:39.028+0000] {gcs_to_bigquery.py:380} INFO - Executing: {'load': {'autodetect': True, 'createDisposition': 'CREATE_NEVER', 'destinationTable': {'projectId': 'data-warehousing-proj', 'datasetId': 'staging_school', 'tableId': 'STG_COUNTRY'}, 'sourceFormat': 'PARQUET', 'sourceUris': ['gs://school_data_lake_data-warehousing-proj/data/country.parquet'], 'writeDisposition': 'WRITE_TRUNCATE', 'ignoreUnknownValues': False}}
[2024-01-07T21:23:39.030+0000] {bigquery.py:1596} INFO - Inserting job ***_ingest_from_postgres_to_GCS_bucket_country_load_dataset_to_bq_2024_01_05T00_00_00_00_00_de1e6ce6af0adf747d52cf59ecd31af7
[2024-01-07T21:23:41.153+0000] {taskinstance.py:1937} ERROR - Task failed with exception
Traceback (most recent call last):
  File "/home/airflow/.local/lib/python3.8/site-packages/airflow/providers/google/cloud/transfers/gcs_to_bigquery.py", line 439, in execute
    job.result(timeout=self.result_timeout, retry=self.result_retry)
  File "/home/airflow/.local/lib/python3.8/site-packages/google/cloud/bigquery/job/base.py", line 922, in result
    return super(_AsyncJob, self).result(timeout=timeout, **kwargs)
  File "/home/airflow/.local/lib/python3.8/site-packages/google/api_core/future/polling.py", line 261, in result
    raise self._exception
google.api_core.exceptions.NotFound: 404 Not found: URI gs://school_data_lake_data-warehousing-proj/data/country.parquet
[2024-01-07T21:23:41.174+0000] {taskinstance.py:1400} INFO - Marking task as UP_FOR_RETRY. dag_id=ingest_from_postgres_to_GCS_bucket, task_id=country_load_dataset_to_bq, execution_date=20240105T000000, start_date=20240107T212338, end_date=20240107T212341
[2024-01-07T21:23:41.208+0000] {logging_mixin.py:151} WARNING - /home/***/.local/lib/python3.8/site-packages/***/utils/email.py:154 RemovedInAirflow3Warning: Fetching SMTP credentials from configuration variables will be deprecated in a future release. Please set credentials using a connection instead.
[2024-01-07T21:23:41.210+0000] {configuration.py:1068} WARNING - section/key [smtp/smtp_user] not found in config
[2024-01-07T21:23:41.212+0000] {email.py:270} INFO - Email alerting: attempt 1
[2024-01-07T21:23:41.249+0000] {configuration.py:1068} WARNING - section/key [smtp/smtp_user] not found in config
[2024-01-07T21:23:41.250+0000] {email.py:270} INFO - Email alerting: attempt 1
[2024-01-07T21:23:41.251+0000] {taskinstance.py:2007} ERROR - Failed to send email to: ['franklinmutwiri41@gmail.com']
Traceback (most recent call last):
  File "/home/airflow/.local/lib/python3.8/site-packages/airflow/models/taskinstance.py", line 1518, in _run_raw_task
    self._execute_task_with_callbacks(context, test_mode, session=session)
  File "/home/airflow/.local/lib/python3.8/site-packages/airflow/models/taskinstance.py", line 1681, in _execute_task_with_callbacks
    result = self._execute_task(context, task_orig)
  File "/home/airflow/.local/lib/python3.8/site-packages/airflow/models/taskinstance.py", line 1744, in _execute_task
    result = execute_callable(context=context, **execute_callable_kwargs)
  File "/home/airflow/.local/lib/python3.8/site-packages/airflow/providers/google/cloud/transfers/gcs_to_bigquery.py", line 439, in execute
    job.result(timeout=self.result_timeout, retry=self.result_retry)
  File "/home/airflow/.local/lib/python3.8/site-packages/google/cloud/bigquery/job/base.py", line 922, in result
    return super(_AsyncJob, self).result(timeout=timeout, **kwargs)
  File "/home/airflow/.local/lib/python3.8/site-packages/google/api_core/future/polling.py", line 261, in result
    raise self._exception
google.api_core.exceptions.NotFound: 404 Not found: URI gs://school_data_lake_data-warehousing-proj/data/country.parquet

During handling of the above exception, another exception occurred:

Traceback (most recent call last):
  File "/home/airflow/.local/lib/python3.8/site-packages/airflow/models/taskinstance.py", line 2420, in email_alert
    send_email(task.email, subject, html_content)
  File "/home/airflow/.local/lib/python3.8/site-packages/airflow/utils/email.py", line 80, in send_email
    return backend(
  File "/home/airflow/.local/lib/python3.8/site-packages/airflow/utils/email.py", line 154, in send_email_smtp
    send_mime_email(e_from=mail_from, e_to=recipients, mime_msg=msg, conn_id=conn_id, dryrun=dryrun)
  File "/home/airflow/.local/lib/python3.8/site-packages/airflow/utils/email.py", line 272, in send_mime_email
    smtp_conn = _get_smtp_connection(smtp_host, smtp_port, smtp_timeout, smtp_ssl)
  File "/home/airflow/.local/lib/python3.8/site-packages/airflow/utils/email.py", line 316, in _get_smtp_connection
    return smtplib.SMTP(host=host, port=port, timeout=timeout)
  File "/usr/local/lib/python3.8/smtplib.py", line 255, in __init__
    (code, msg) = self.connect(host, port)
  File "/usr/local/lib/python3.8/smtplib.py", line 339, in connect
    self.sock = self._get_socket(host, port, self.timeout)
  File "/usr/local/lib/python3.8/smtplib.py", line 310, in _get_socket
    return socket.create_connection((host, port), timeout,
  File "/usr/local/lib/python3.8/socket.py", line 808, in create_connection
    raise err
  File "/usr/local/lib/python3.8/socket.py", line 796, in create_connection
    sock.connect(sa)
OSError: [Errno 99] Cannot assign requested address

During handling of the above exception, another exception occurred:

Traceback (most recent call last):
  File "/home/airflow/.local/lib/python3.8/site-packages/airflow/models/taskinstance.py", line 2005, in handle_failure
    self.email_alert(error, task)
  File "/home/airflow/.local/lib/python3.8/site-packages/airflow/models/taskinstance.py", line 2422, in email_alert
    send_email(task.email, subject, html_content_err)
  File "/home/airflow/.local/lib/python3.8/site-packages/airflow/utils/email.py", line 80, in send_email
    return backend(
  File "/home/airflow/.local/lib/python3.8/site-packages/airflow/utils/email.py", line 154, in send_email_smtp
    send_mime_email(e_from=mail_from, e_to=recipients, mime_msg=msg, conn_id=conn_id, dryrun=dryrun)
  File "/home/airflow/.local/lib/python3.8/site-packages/airflow/utils/email.py", line 272, in send_mime_email
    smtp_conn = _get_smtp_connection(smtp_host, smtp_port, smtp_timeout, smtp_ssl)
  File "/home/airflow/.local/lib/python3.8/site-packages/airflow/utils/email.py", line 316, in _get_smtp_connection
    return smtplib.SMTP(host=host, port=port, timeout=timeout)
  File "/usr/local/lib/python3.8/smtplib.py", line 255, in __init__
    (code, msg) = self.connect(host, port)
  File "/usr/local/lib/python3.8/smtplib.py", line 339, in connect
    self.sock = self._get_socket(host, port, self.timeout)
  File "/usr/local/lib/python3.8/smtplib.py", line 310, in _get_socket
    return socket.create_connection((host, port), timeout,
  File "/usr/local/lib/python3.8/socket.py", line 808, in create_connection
    raise err
  File "/usr/local/lib/python3.8/socket.py", line 796, in create_connection
    sock.connect(sa)
OSError: [Errno 99] Cannot assign requested address
[2024-01-07T21:23:41.348+0000] {standard_task_runner.py:104} ERROR - Failed to execute job 541 for task country_load_dataset_to_bq (404 Not found: URI gs://school_data_lake_data-warehousing-proj/data/country.parquet; 322)
[2024-01-07T21:23:41.382+0000] {local_task_job_runner.py:228} INFO - Task exited with return code 1
[2024-01-07T21:23:41.422+0000] {taskinstance.py:2778} INFO - 0 downstream tasks scheduled from follow-on schedule check
