[2024-01-07T00:19:54.504+0000] {taskinstance.py:1159} INFO - Dependencies all met for dep_context=non-requeueable deps ti=<TaskInstance: ingest_from_postgres_to_GCS_bucket.copy_course_Postgres_To_GCS scheduled__2023-11-27T00:00:00+00:00 [queued]>
[2024-01-07T00:19:54.523+0000] {taskinstance.py:1159} INFO - Dependencies all met for dep_context=requeueable deps ti=<TaskInstance: ingest_from_postgres_to_GCS_bucket.copy_course_Postgres_To_GCS scheduled__2023-11-27T00:00:00+00:00 [queued]>
[2024-01-07T00:19:54.523+0000] {taskinstance.py:1361} INFO - Starting attempt 2 of 3
[2024-01-07T00:19:54.552+0000] {taskinstance.py:1382} INFO - Executing <Task(PythonOperator): copy_course_Postgres_To_GCS> on 2023-11-27 00:00:00+00:00
[2024-01-07T00:19:54.563+0000] {standard_task_runner.py:57} INFO - Started process 1670 to run task
[2024-01-07T00:19:54.569+0000] {standard_task_runner.py:84} INFO - Running: ['airflow', 'tasks', 'run', 'ingest_from_postgres_to_GCS_bucket', 'copy_course_Postgres_To_GCS', 'scheduled__2023-11-27T00:00:00+00:00', '--job-id', '343', '--raw', '--subdir', 'DAGS_FOLDER/postgres_to_gcs_staging.py', '--cfg-path', '/tmp/tmpob2oiwql']
[2024-01-07T00:19:54.577+0000] {standard_task_runner.py:85} INFO - Job 343: Subtask copy_course_Postgres_To_GCS
[2024-01-07T00:19:54.691+0000] {task_command.py:416} INFO - Running <TaskInstance: ingest_from_postgres_to_GCS_bucket.copy_course_Postgres_To_GCS scheduled__2023-11-27T00:00:00+00:00 [running]> on host f500624b13d0
[2024-01-07T00:19:54.868+0000] {taskinstance.py:1662} INFO - Exporting env vars: AIRFLOW_CTX_DAG_EMAIL='franklinmutwiri41@gmail.com' AIRFLOW_CTX_DAG_OWNER='airflow' AIRFLOW_CTX_DAG_ID='ingest_from_postgres_to_GCS_bucket' AIRFLOW_CTX_TASK_ID='copy_course_Postgres_To_GCS' AIRFLOW_CTX_EXECUTION_DATE='2023-11-27T00:00:00+00:00' AIRFLOW_CTX_TRY_NUMBER='2' AIRFLOW_CTX_DAG_RUN_ID='scheduled__2023-11-27T00:00:00+00:00'
[2024-01-07T00:19:54.889+0000] {base.py:73} INFO - Using connection ID 'postgres_docker_conn' for task execution.
[2024-01-07T00:19:54.907+0000] {base.py:73} INFO - Using connection ID 'postgres_docker_conn' for task execution.
[2024-01-07T00:19:54.933+0000] {logging_mixin.py:151} WARNING - /home/***/.local/lib/python3.8/site-packages/***/providers/common/sql/hooks/sql.py:219 UserWarning: pandas only supports SQLAlchemy connectable (engine/connection) or database string URI or sqlite3 DBAPI2 connection. Other DBAPI2 objects are not tested. Please consider using SQLAlchemy.
[2024-01-07T00:19:54.940+0000] {postgres_to_gcs_staging.py:47} INFO - Uploading to bucket, course
[2024-01-07T00:19:54.990+0000] {connection.py:232} WARNING - Connection schemes (type: google_cloud_platform) shall not contain '_' according to RFC3986.
[2024-01-07T00:19:54.994+0000] {base.py:73} INFO - Using connection ID 'google_cloud_default' for task execution.
[2024-01-07T00:19:54.995+0000] {taskinstance.py:1937} ERROR - Task failed with exception
Traceback (most recent call last):
  File "/home/airflow/.local/lib/python3.8/site-packages/airflow/operators/python.py", line 192, in execute
    return_value = self.execute_callable()
  File "/home/airflow/.local/lib/python3.8/site-packages/airflow/operators/python.py", line 209, in execute_callable
    return self.python_callable(*self.op_args, **self.op_kwargs)
  File "/opt/airflow/dags/postgres_to_gcs_staging.py", line 61, in Postgres_To_GCS_Bucket
    gcs_hook.upload( BUCKET, gcs_path + parquet_buffer.getvalue(), 'parquet')
TypeError: can only concatenate str (not "bytes") to str
[2024-01-07T00:19:55.017+0000] {taskinstance.py:1400} INFO - Marking task as UP_FOR_RETRY. dag_id=ingest_from_postgres_to_GCS_bucket, task_id=copy_course_Postgres_To_GCS, execution_date=20231127T000000, start_date=20240107T001954, end_date=20240107T001955
[2024-01-07T00:19:55.049+0000] {logging_mixin.py:151} WARNING - /home/***/.local/lib/python3.8/site-packages/***/utils/email.py:154 RemovedInAirflow3Warning: Fetching SMTP credentials from configuration variables will be deprecated in a future release. Please set credentials using a connection instead.
[2024-01-07T00:19:55.050+0000] {configuration.py:1068} WARNING - section/key [smtp/smtp_user] not found in config
[2024-01-07T00:19:55.050+0000] {email.py:270} INFO - Email alerting: attempt 1
[2024-01-07T00:19:55.068+0000] {configuration.py:1068} WARNING - section/key [smtp/smtp_user] not found in config
[2024-01-07T00:19:55.068+0000] {email.py:270} INFO - Email alerting: attempt 1
[2024-01-07T00:19:55.069+0000] {taskinstance.py:2007} ERROR - Failed to send email to: ['franklinmutwiri41@gmail.com']
Traceback (most recent call last):
  File "/home/airflow/.local/lib/python3.8/site-packages/airflow/models/taskinstance.py", line 1518, in _run_raw_task
    self._execute_task_with_callbacks(context, test_mode, session=session)
  File "/home/airflow/.local/lib/python3.8/site-packages/airflow/models/taskinstance.py", line 1681, in _execute_task_with_callbacks
    result = self._execute_task(context, task_orig)
  File "/home/airflow/.local/lib/python3.8/site-packages/airflow/models/taskinstance.py", line 1744, in _execute_task
    result = execute_callable(context=context, **execute_callable_kwargs)
  File "/home/airflow/.local/lib/python3.8/site-packages/airflow/operators/python.py", line 192, in execute
    return_value = self.execute_callable()
  File "/home/airflow/.local/lib/python3.8/site-packages/airflow/operators/python.py", line 209, in execute_callable
    return self.python_callable(*self.op_args, **self.op_kwargs)
  File "/opt/airflow/dags/postgres_to_gcs_staging.py", line 61, in Postgres_To_GCS_Bucket
    gcs_hook.upload( BUCKET, gcs_path + parquet_buffer.getvalue(), 'parquet')
TypeError: can only concatenate str (not "bytes") to str

During handling of the above exception, another exception occurred:

Traceback (most recent call last):
  File "/home/airflow/.local/lib/python3.8/site-packages/airflow/models/taskinstance.py", line 2420, in email_alert
    send_email(task.email, subject, html_content)
  File "/home/airflow/.local/lib/python3.8/site-packages/airflow/utils/email.py", line 80, in send_email
    return backend(
  File "/home/airflow/.local/lib/python3.8/site-packages/airflow/utils/email.py", line 154, in send_email_smtp
    send_mime_email(e_from=mail_from, e_to=recipients, mime_msg=msg, conn_id=conn_id, dryrun=dryrun)
  File "/home/airflow/.local/lib/python3.8/site-packages/airflow/utils/email.py", line 272, in send_mime_email
    smtp_conn = _get_smtp_connection(smtp_host, smtp_port, smtp_timeout, smtp_ssl)
  File "/home/airflow/.local/lib/python3.8/site-packages/airflow/utils/email.py", line 316, in _get_smtp_connection
    return smtplib.SMTP(host=host, port=port, timeout=timeout)
  File "/usr/local/lib/python3.8/smtplib.py", line 255, in __init__
    (code, msg) = self.connect(host, port)
  File "/usr/local/lib/python3.8/smtplib.py", line 339, in connect
    self.sock = self._get_socket(host, port, self.timeout)
  File "/usr/local/lib/python3.8/smtplib.py", line 310, in _get_socket
    return socket.create_connection((host, port), timeout,
  File "/usr/local/lib/python3.8/socket.py", line 808, in create_connection
    raise err
  File "/usr/local/lib/python3.8/socket.py", line 796, in create_connection
    sock.connect(sa)
OSError: [Errno 99] Cannot assign requested address

During handling of the above exception, another exception occurred:

Traceback (most recent call last):
  File "/home/airflow/.local/lib/python3.8/site-packages/airflow/models/taskinstance.py", line 2005, in handle_failure
    self.email_alert(error, task)
  File "/home/airflow/.local/lib/python3.8/site-packages/airflow/models/taskinstance.py", line 2422, in email_alert
    send_email(task.email, subject, html_content_err)
  File "/home/airflow/.local/lib/python3.8/site-packages/airflow/utils/email.py", line 80, in send_email
    return backend(
  File "/home/airflow/.local/lib/python3.8/site-packages/airflow/utils/email.py", line 154, in send_email_smtp
    send_mime_email(e_from=mail_from, e_to=recipients, mime_msg=msg, conn_id=conn_id, dryrun=dryrun)
  File "/home/airflow/.local/lib/python3.8/site-packages/airflow/utils/email.py", line 272, in send_mime_email
    smtp_conn = _get_smtp_connection(smtp_host, smtp_port, smtp_timeout, smtp_ssl)
  File "/home/airflow/.local/lib/python3.8/site-packages/airflow/utils/email.py", line 316, in _get_smtp_connection
    return smtplib.SMTP(host=host, port=port, timeout=timeout)
  File "/usr/local/lib/python3.8/smtplib.py", line 255, in __init__
    (code, msg) = self.connect(host, port)
  File "/usr/local/lib/python3.8/smtplib.py", line 339, in connect
    self.sock = self._get_socket(host, port, self.timeout)
  File "/usr/local/lib/python3.8/smtplib.py", line 310, in _get_socket
    return socket.create_connection((host, port), timeout,
  File "/usr/local/lib/python3.8/socket.py", line 808, in create_connection
    raise err
  File "/usr/local/lib/python3.8/socket.py", line 796, in create_connection
    sock.connect(sa)
OSError: [Errno 99] Cannot assign requested address
[2024-01-07T00:19:55.233+0000] {standard_task_runner.py:104} ERROR - Failed to execute job 343 for task copy_course_Postgres_To_GCS (can only concatenate str (not "bytes") to str; 1670)
[2024-01-07T00:19:55.264+0000] {local_task_job_runner.py:228} INFO - Task exited with return code 1
[2024-01-07T00:19:55.309+0000] {taskinstance.py:2778} INFO - 0 downstream tasks scheduled from follow-on schedule check
[2024-01-07T00:23:52.846+0000] {taskinstance.py:1159} INFO - Dependencies all met for dep_context=non-requeueable deps ti=<TaskInstance: ingest_from_postgres_to_GCS_bucket.copy_course_Postgres_To_GCS scheduled__2023-11-27T00:00:00+00:00 [queued]>
[2024-01-07T00:23:52.866+0000] {taskinstance.py:1159} INFO - Dependencies all met for dep_context=requeueable deps ti=<TaskInstance: ingest_from_postgres_to_GCS_bucket.copy_course_Postgres_To_GCS scheduled__2023-11-27T00:00:00+00:00 [queued]>
[2024-01-07T00:23:52.867+0000] {taskinstance.py:1361} INFO - Starting attempt 2 of 3
[2024-01-07T00:23:52.898+0000] {taskinstance.py:1382} INFO - Executing <Task(PythonOperator): copy_course_Postgres_To_GCS> on 2023-11-27 00:00:00+00:00
[2024-01-07T00:23:52.905+0000] {standard_task_runner.py:57} INFO - Started process 1797 to run task
[2024-01-07T00:23:52.909+0000] {standard_task_runner.py:84} INFO - Running: ['airflow', 'tasks', 'run', 'ingest_from_postgres_to_GCS_bucket', 'copy_course_Postgres_To_GCS', 'scheduled__2023-11-27T00:00:00+00:00', '--job-id', '352', '--raw', '--subdir', 'DAGS_FOLDER/postgres_to_gcs_staging.py', '--cfg-path', '/tmp/tmpbor4qpt7']
[2024-01-07T00:23:52.915+0000] {standard_task_runner.py:85} INFO - Job 352: Subtask copy_course_Postgres_To_GCS
[2024-01-07T00:23:53.128+0000] {task_command.py:416} INFO - Running <TaskInstance: ingest_from_postgres_to_GCS_bucket.copy_course_Postgres_To_GCS scheduled__2023-11-27T00:00:00+00:00 [running]> on host f500624b13d0
[2024-01-07T00:23:53.271+0000] {taskinstance.py:1662} INFO - Exporting env vars: AIRFLOW_CTX_DAG_EMAIL='franklinmutwiri41@gmail.com' AIRFLOW_CTX_DAG_OWNER='airflow' AIRFLOW_CTX_DAG_ID='ingest_from_postgres_to_GCS_bucket' AIRFLOW_CTX_TASK_ID='copy_course_Postgres_To_GCS' AIRFLOW_CTX_EXECUTION_DATE='2023-11-27T00:00:00+00:00' AIRFLOW_CTX_TRY_NUMBER='2' AIRFLOW_CTX_DAG_RUN_ID='scheduled__2023-11-27T00:00:00+00:00'
[2024-01-07T00:23:53.286+0000] {base.py:73} INFO - Using connection ID 'postgres_docker_conn' for task execution.
[2024-01-07T00:23:53.302+0000] {base.py:73} INFO - Using connection ID 'postgres_docker_conn' for task execution.
[2024-01-07T00:23:53.328+0000] {logging_mixin.py:151} WARNING - /home/***/.local/lib/python3.8/site-packages/***/providers/common/sql/hooks/sql.py:219 UserWarning: pandas only supports SQLAlchemy connectable (engine/connection) or database string URI or sqlite3 DBAPI2 connection. Other DBAPI2 objects are not tested. Please consider using SQLAlchemy.
[2024-01-07T00:23:53.335+0000] {postgres_to_gcs_staging.py:47} INFO - Uploading to bucket, course
[2024-01-07T00:23:53.381+0000] {connection.py:232} WARNING - Connection schemes (type: google_cloud_platform) shall not contain '_' according to RFC3986.
[2024-01-07T00:23:53.385+0000] {base.py:73} INFO - Using connection ID 'google_cloud_default' for task execution.
[2024-01-07T00:23:53.444+0000] {taskinstance.py:1937} ERROR - Task failed with exception
Traceback (most recent call last):
  File "/home/airflow/.local/lib/python3.8/site-packages/airflow/operators/python.py", line 192, in execute
    return_value = self.execute_callable()
  File "/home/airflow/.local/lib/python3.8/site-packages/airflow/operators/python.py", line 209, in execute_callable
    return self.python_callable(*self.op_args, **self.op_kwargs)
  File "/opt/airflow/dags/postgres_to_gcs_staging.py", line 61, in Postgres_To_GCS_Bucket
    gcs_hook.upload( BUCKET, gcs_path, parquet_buffer.getvalue(), 'parquet')
  File "/home/airflow/.local/lib/python3.8/site-packages/airflow/providers/google/cloud/hooks/gcs.py", line 541, in upload
    raise ValueError(
ValueError: 'filename' and 'data' parameter provided. Please specify a single parameter, either 'filename' for local file uploads or 'data' for file content uploads.
[2024-01-07T00:23:53.458+0000] {taskinstance.py:1400} INFO - Marking task as UP_FOR_RETRY. dag_id=ingest_from_postgres_to_GCS_bucket, task_id=copy_course_Postgres_To_GCS, execution_date=20231127T000000, start_date=20240107T002352, end_date=20240107T002353
[2024-01-07T00:23:53.472+0000] {logging_mixin.py:151} WARNING - /home/***/.local/lib/python3.8/site-packages/***/utils/email.py:154 RemovedInAirflow3Warning: Fetching SMTP credentials from configuration variables will be deprecated in a future release. Please set credentials using a connection instead.
[2024-01-07T00:23:53.473+0000] {configuration.py:1068} WARNING - section/key [smtp/smtp_user] not found in config
[2024-01-07T00:23:53.473+0000] {email.py:270} INFO - Email alerting: attempt 1
[2024-01-07T00:23:53.488+0000] {configuration.py:1068} WARNING - section/key [smtp/smtp_user] not found in config
[2024-01-07T00:23:53.489+0000] {email.py:270} INFO - Email alerting: attempt 1
[2024-01-07T00:23:53.490+0000] {taskinstance.py:2007} ERROR - Failed to send email to: ['franklinmutwiri41@gmail.com']
Traceback (most recent call last):
  File "/home/airflow/.local/lib/python3.8/site-packages/airflow/models/taskinstance.py", line 1518, in _run_raw_task
    self._execute_task_with_callbacks(context, test_mode, session=session)
  File "/home/airflow/.local/lib/python3.8/site-packages/airflow/models/taskinstance.py", line 1681, in _execute_task_with_callbacks
    result = self._execute_task(context, task_orig)
  File "/home/airflow/.local/lib/python3.8/site-packages/airflow/models/taskinstance.py", line 1744, in _execute_task
    result = execute_callable(context=context, **execute_callable_kwargs)
  File "/home/airflow/.local/lib/python3.8/site-packages/airflow/operators/python.py", line 192, in execute
    return_value = self.execute_callable()
  File "/home/airflow/.local/lib/python3.8/site-packages/airflow/operators/python.py", line 209, in execute_callable
    return self.python_callable(*self.op_args, **self.op_kwargs)
  File "/opt/airflow/dags/postgres_to_gcs_staging.py", line 61, in Postgres_To_GCS_Bucket
    gcs_hook.upload( BUCKET, gcs_path, parquet_buffer.getvalue(), 'parquet')
  File "/home/airflow/.local/lib/python3.8/site-packages/airflow/providers/google/cloud/hooks/gcs.py", line 541, in upload
    raise ValueError(
ValueError: 'filename' and 'data' parameter provided. Please specify a single parameter, either 'filename' for local file uploads or 'data' for file content uploads.

During handling of the above exception, another exception occurred:

Traceback (most recent call last):
  File "/home/airflow/.local/lib/python3.8/site-packages/airflow/models/taskinstance.py", line 2420, in email_alert
    send_email(task.email, subject, html_content)
  File "/home/airflow/.local/lib/python3.8/site-packages/airflow/utils/email.py", line 80, in send_email
    return backend(
  File "/home/airflow/.local/lib/python3.8/site-packages/airflow/utils/email.py", line 154, in send_email_smtp
    send_mime_email(e_from=mail_from, e_to=recipients, mime_msg=msg, conn_id=conn_id, dryrun=dryrun)
  File "/home/airflow/.local/lib/python3.8/site-packages/airflow/utils/email.py", line 272, in send_mime_email
    smtp_conn = _get_smtp_connection(smtp_host, smtp_port, smtp_timeout, smtp_ssl)
  File "/home/airflow/.local/lib/python3.8/site-packages/airflow/utils/email.py", line 316, in _get_smtp_connection
    return smtplib.SMTP(host=host, port=port, timeout=timeout)
  File "/usr/local/lib/python3.8/smtplib.py", line 255, in __init__
    (code, msg) = self.connect(host, port)
  File "/usr/local/lib/python3.8/smtplib.py", line 339, in connect
    self.sock = self._get_socket(host, port, self.timeout)
  File "/usr/local/lib/python3.8/smtplib.py", line 310, in _get_socket
    return socket.create_connection((host, port), timeout,
  File "/usr/local/lib/python3.8/socket.py", line 808, in create_connection
    raise err
  File "/usr/local/lib/python3.8/socket.py", line 796, in create_connection
    sock.connect(sa)
OSError: [Errno 99] Cannot assign requested address

During handling of the above exception, another exception occurred:

Traceback (most recent call last):
  File "/home/airflow/.local/lib/python3.8/site-packages/airflow/models/taskinstance.py", line 2005, in handle_failure
    self.email_alert(error, task)
  File "/home/airflow/.local/lib/python3.8/site-packages/airflow/models/taskinstance.py", line 2422, in email_alert
    send_email(task.email, subject, html_content_err)
  File "/home/airflow/.local/lib/python3.8/site-packages/airflow/utils/email.py", line 80, in send_email
    return backend(
  File "/home/airflow/.local/lib/python3.8/site-packages/airflow/utils/email.py", line 154, in send_email_smtp
    send_mime_email(e_from=mail_from, e_to=recipients, mime_msg=msg, conn_id=conn_id, dryrun=dryrun)
  File "/home/airflow/.local/lib/python3.8/site-packages/airflow/utils/email.py", line 272, in send_mime_email
    smtp_conn = _get_smtp_connection(smtp_host, smtp_port, smtp_timeout, smtp_ssl)
  File "/home/airflow/.local/lib/python3.8/site-packages/airflow/utils/email.py", line 316, in _get_smtp_connection
    return smtplib.SMTP(host=host, port=port, timeout=timeout)
  File "/usr/local/lib/python3.8/smtplib.py", line 255, in __init__
    (code, msg) = self.connect(host, port)
  File "/usr/local/lib/python3.8/smtplib.py", line 339, in connect
    self.sock = self._get_socket(host, port, self.timeout)
  File "/usr/local/lib/python3.8/smtplib.py", line 310, in _get_socket
    return socket.create_connection((host, port), timeout,
  File "/usr/local/lib/python3.8/socket.py", line 808, in create_connection
    raise err
  File "/usr/local/lib/python3.8/socket.py", line 796, in create_connection
    sock.connect(sa)
OSError: [Errno 99] Cannot assign requested address
[2024-01-07T00:23:53.619+0000] {standard_task_runner.py:104} ERROR - Failed to execute job 352 for task copy_course_Postgres_To_GCS ('filename' and 'data' parameter provided. Please specify a single parameter, either 'filename' for local file uploads or 'data' for file content uploads.; 1797)
[2024-01-07T00:23:53.643+0000] {local_task_job_runner.py:228} INFO - Task exited with return code 1
[2024-01-07T00:23:53.685+0000] {taskinstance.py:2778} INFO - 0 downstream tasks scheduled from follow-on schedule check
[2024-01-07T13:10:07.871+0000] {taskinstance.py:1159} INFO - Dependencies all met for dep_context=non-requeueable deps ti=<TaskInstance: ingest_from_postgres_to_GCS_bucket.copy_course_Postgres_To_GCS scheduled__2023-11-27T00:00:00+00:00 [queued]>
[2024-01-07T13:10:07.896+0000] {taskinstance.py:1159} INFO - Dependencies all met for dep_context=requeueable deps ti=<TaskInstance: ingest_from_postgres_to_GCS_bucket.copy_course_Postgres_To_GCS scheduled__2023-11-27T00:00:00+00:00 [queued]>
[2024-01-07T13:10:07.897+0000] {taskinstance.py:1361} INFO - Starting attempt 2 of 3
[2024-01-07T13:10:07.927+0000] {taskinstance.py:1382} INFO - Executing <Task(PythonOperator): copy_course_Postgres_To_GCS> on 2023-11-27 00:00:00+00:00
[2024-01-07T13:10:07.935+0000] {standard_task_runner.py:57} INFO - Started process 1113 to run task
[2024-01-07T13:10:07.942+0000] {standard_task_runner.py:84} INFO - Running: ['***', 'tasks', 'run', 'ingest_from_postgres_to_GCS_bucket', 'copy_course_Postgres_To_GCS', 'scheduled__2023-11-27T00:00:00+00:00', '--job-id', '80', '--raw', '--subdir', 'DAGS_FOLDER/postgres_to_gcs_staging.py', '--cfg-path', '/tmp/tmpsg3yxtpn']
[2024-01-07T13:10:07.947+0000] {standard_task_runner.py:85} INFO - Job 80: Subtask copy_course_Postgres_To_GCS
[2024-01-07T13:10:08.058+0000] {task_command.py:416} INFO - Running <TaskInstance: ingest_from_postgres_to_GCS_bucket.copy_course_Postgres_To_GCS scheduled__2023-11-27T00:00:00+00:00 [running]> on host d5f4b55abf9d
[2024-01-07T13:10:08.222+0000] {taskinstance.py:1662} INFO - Exporting env vars: AIRFLOW_CTX_DAG_EMAIL='franklinmutwiri41@gmail.com' AIRFLOW_CTX_DAG_OWNER='***' AIRFLOW_CTX_DAG_ID='ingest_from_postgres_to_GCS_bucket' AIRFLOW_CTX_TASK_ID='copy_course_Postgres_To_GCS' AIRFLOW_CTX_EXECUTION_DATE='2023-11-27T00:00:00+00:00' AIRFLOW_CTX_TRY_NUMBER='2' AIRFLOW_CTX_DAG_RUN_ID='scheduled__2023-11-27T00:00:00+00:00'
[2024-01-07T13:10:08.267+0000] {taskinstance.py:1937} ERROR - Task failed with exception
Traceback (most recent call last):
  File "/home/airflow/.local/lib/python3.8/site-packages/airflow/operators/python.py", line 192, in execute
    return_value = self.execute_callable()
  File "/home/airflow/.local/lib/python3.8/site-packages/airflow/operators/python.py", line 209, in execute_callable
    return self.python_callable(*self.op_args, **self.op_kwargs)
  File "/opt/airflow/dags/postgres_to_gcs_staging.py", line 36, in Postgres_To_GCS_Bucket
    pg_hook = PostgresHook.get_hook("postgres_docker_conn")
  File "/home/airflow/.local/lib/python3.8/site-packages/airflow/hooks/base.py", line 84, in get_hook
    connection = cls.get_connection(conn_id)
  File "/home/airflow/.local/lib/python3.8/site-packages/airflow/hooks/base.py", line 72, in get_connection
    conn = Connection.get_connection_from_secrets(conn_id)
  File "/home/airflow/.local/lib/python3.8/site-packages/airflow/models/connection.py", line 477, in get_connection_from_secrets
    raise AirflowNotFoundException(f"The conn_id `{conn_id}` isn't defined")
airflow.exceptions.AirflowNotFoundException: The conn_id `postgres_docker_conn` isn't defined
[2024-01-07T13:10:08.272+0000] {taskinstance.py:1400} INFO - Marking task as UP_FOR_RETRY. dag_id=ingest_from_postgres_to_GCS_bucket, task_id=copy_course_Postgres_To_GCS, execution_date=20231127T000000, start_date=20240107T131007, end_date=20240107T131008
[2024-01-07T13:10:08.343+0000] {logging_mixin.py:151} WARNING - /home/***/.local/lib/python3.8/site-packages/***/utils/email.py:154 RemovedInAirflow3Warning: Fetching SMTP credentials from configuration variables will be deprecated in a future release. Please set credentials using a connection instead.
[2024-01-07T13:10:08.348+0000] {configuration.py:1068} WARNING - section/key [smtp/smtp_user] not found in config
[2024-01-07T13:10:08.348+0000] {email.py:270} INFO - Email alerting: attempt 1
[2024-01-07T13:10:08.375+0000] {configuration.py:1068} WARNING - section/key [smtp/smtp_user] not found in config
[2024-01-07T13:10:08.375+0000] {email.py:270} INFO - Email alerting: attempt 1
[2024-01-07T13:10:08.376+0000] {taskinstance.py:2007} ERROR - Failed to send email to: ['franklinmutwiri41@gmail.com']
Traceback (most recent call last):
  File "/home/airflow/.local/lib/python3.8/site-packages/airflow/models/taskinstance.py", line 1518, in _run_raw_task
    self._execute_task_with_callbacks(context, test_mode, session=session)
  File "/home/airflow/.local/lib/python3.8/site-packages/airflow/models/taskinstance.py", line 1681, in _execute_task_with_callbacks
    result = self._execute_task(context, task_orig)
  File "/home/airflow/.local/lib/python3.8/site-packages/airflow/models/taskinstance.py", line 1744, in _execute_task
    result = execute_callable(context=context, **execute_callable_kwargs)
  File "/home/airflow/.local/lib/python3.8/site-packages/airflow/operators/python.py", line 192, in execute
    return_value = self.execute_callable()
  File "/home/airflow/.local/lib/python3.8/site-packages/airflow/operators/python.py", line 209, in execute_callable
    return self.python_callable(*self.op_args, **self.op_kwargs)
  File "/opt/airflow/dags/postgres_to_gcs_staging.py", line 36, in Postgres_To_GCS_Bucket
    pg_hook = PostgresHook.get_hook("postgres_docker_conn")
  File "/home/airflow/.local/lib/python3.8/site-packages/airflow/hooks/base.py", line 84, in get_hook
    connection = cls.get_connection(conn_id)
  File "/home/airflow/.local/lib/python3.8/site-packages/airflow/hooks/base.py", line 72, in get_connection
    conn = Connection.get_connection_from_secrets(conn_id)
  File "/home/airflow/.local/lib/python3.8/site-packages/airflow/models/connection.py", line 477, in get_connection_from_secrets
    raise AirflowNotFoundException(f"The conn_id `{conn_id}` isn't defined")
airflow.exceptions.AirflowNotFoundException: The conn_id `postgres_docker_conn` isn't defined

During handling of the above exception, another exception occurred:

Traceback (most recent call last):
  File "/home/airflow/.local/lib/python3.8/site-packages/airflow/models/taskinstance.py", line 2420, in email_alert
    send_email(task.email, subject, html_content)
  File "/home/airflow/.local/lib/python3.8/site-packages/airflow/utils/email.py", line 80, in send_email
    return backend(
  File "/home/airflow/.local/lib/python3.8/site-packages/airflow/utils/email.py", line 154, in send_email_smtp
    send_mime_email(e_from=mail_from, e_to=recipients, mime_msg=msg, conn_id=conn_id, dryrun=dryrun)
  File "/home/airflow/.local/lib/python3.8/site-packages/airflow/utils/email.py", line 272, in send_mime_email
    smtp_conn = _get_smtp_connection(smtp_host, smtp_port, smtp_timeout, smtp_ssl)
  File "/home/airflow/.local/lib/python3.8/site-packages/airflow/utils/email.py", line 316, in _get_smtp_connection
    return smtplib.SMTP(host=host, port=port, timeout=timeout)
  File "/usr/local/lib/python3.8/smtplib.py", line 255, in __init__
    (code, msg) = self.connect(host, port)
  File "/usr/local/lib/python3.8/smtplib.py", line 339, in connect
    self.sock = self._get_socket(host, port, self.timeout)
  File "/usr/local/lib/python3.8/smtplib.py", line 310, in _get_socket
    return socket.create_connection((host, port), timeout,
  File "/usr/local/lib/python3.8/socket.py", line 808, in create_connection
    raise err
  File "/usr/local/lib/python3.8/socket.py", line 796, in create_connection
    sock.connect(sa)
OSError: [Errno 99] Cannot assign requested address

During handling of the above exception, another exception occurred:

Traceback (most recent call last):
  File "/home/airflow/.local/lib/python3.8/site-packages/airflow/models/taskinstance.py", line 2005, in handle_failure
    self.email_alert(error, task)
  File "/home/airflow/.local/lib/python3.8/site-packages/airflow/models/taskinstance.py", line 2422, in email_alert
    send_email(task.email, subject, html_content_err)
  File "/home/airflow/.local/lib/python3.8/site-packages/airflow/utils/email.py", line 80, in send_email
    return backend(
  File "/home/airflow/.local/lib/python3.8/site-packages/airflow/utils/email.py", line 154, in send_email_smtp
    send_mime_email(e_from=mail_from, e_to=recipients, mime_msg=msg, conn_id=conn_id, dryrun=dryrun)
  File "/home/airflow/.local/lib/python3.8/site-packages/airflow/utils/email.py", line 272, in send_mime_email
    smtp_conn = _get_smtp_connection(smtp_host, smtp_port, smtp_timeout, smtp_ssl)
  File "/home/airflow/.local/lib/python3.8/site-packages/airflow/utils/email.py", line 316, in _get_smtp_connection
    return smtplib.SMTP(host=host, port=port, timeout=timeout)
  File "/usr/local/lib/python3.8/smtplib.py", line 255, in __init__
    (code, msg) = self.connect(host, port)
  File "/usr/local/lib/python3.8/smtplib.py", line 339, in connect
    self.sock = self._get_socket(host, port, self.timeout)
  File "/usr/local/lib/python3.8/smtplib.py", line 310, in _get_socket
    return socket.create_connection((host, port), timeout,
  File "/usr/local/lib/python3.8/socket.py", line 808, in create_connection
    raise err
  File "/usr/local/lib/python3.8/socket.py", line 796, in create_connection
    sock.connect(sa)
OSError: [Errno 99] Cannot assign requested address
[2024-01-07T13:10:08.429+0000] {standard_task_runner.py:104} ERROR - Failed to execute job 80 for task copy_course_Postgres_To_GCS (The conn_id `postgres_docker_conn` isn't defined; 1113)
[2024-01-07T13:10:08.479+0000] {local_task_job_runner.py:228} INFO - Task exited with return code 1
[2024-01-07T13:10:08.606+0000] {taskinstance.py:2778} INFO - 0 downstream tasks scheduled from follow-on schedule check
[2024-01-07T13:42:48.615+0000] {taskinstance.py:1159} INFO - Dependencies all met for dep_context=non-requeueable deps ti=<TaskInstance: ingest_from_postgres_to_GCS_bucket.copy_course_Postgres_To_GCS scheduled__2023-11-27T00:00:00+00:00 [queued]>
[2024-01-07T13:42:48.636+0000] {taskinstance.py:1159} INFO - Dependencies all met for dep_context=requeueable deps ti=<TaskInstance: ingest_from_postgres_to_GCS_bucket.copy_course_Postgres_To_GCS scheduled__2023-11-27T00:00:00+00:00 [queued]>
[2024-01-07T13:42:48.636+0000] {taskinstance.py:1361} INFO - Starting attempt 2 of 3
[2024-01-07T13:42:48.689+0000] {taskinstance.py:1382} INFO - Executing <Task(PythonOperator): copy_course_Postgres_To_GCS> on 2023-11-27 00:00:00+00:00
[2024-01-07T13:42:48.698+0000] {standard_task_runner.py:57} INFO - Started process 368 to run task
[2024-01-07T13:42:48.702+0000] {standard_task_runner.py:84} INFO - Running: ['***', 'tasks', 'run', 'ingest_from_postgres_to_GCS_bucket', 'copy_course_Postgres_To_GCS', 'scheduled__2023-11-27T00:00:00+00:00', '--job-id', '124', '--raw', '--subdir', 'DAGS_FOLDER/postgres_to_gcs_staging.py', '--cfg-path', '/tmp/tmpquv_omyl']
[2024-01-07T13:42:48.708+0000] {standard_task_runner.py:85} INFO - Job 124: Subtask copy_course_Postgres_To_GCS
[2024-01-07T13:42:48.809+0000] {task_command.py:416} INFO - Running <TaskInstance: ingest_from_postgres_to_GCS_bucket.copy_course_Postgres_To_GCS scheduled__2023-11-27T00:00:00+00:00 [running]> on host 5d007c0b4985
[2024-01-07T13:42:49.315+0000] {taskinstance.py:1662} INFO - Exporting env vars: AIRFLOW_CTX_DAG_EMAIL='franklinmutwiri41@gmail.com' AIRFLOW_CTX_DAG_OWNER='***' AIRFLOW_CTX_DAG_ID='ingest_from_postgres_to_GCS_bucket' AIRFLOW_CTX_TASK_ID='copy_course_Postgres_To_GCS' AIRFLOW_CTX_EXECUTION_DATE='2023-11-27T00:00:00+00:00' AIRFLOW_CTX_TRY_NUMBER='2' AIRFLOW_CTX_DAG_RUN_ID='scheduled__2023-11-27T00:00:00+00:00'
[2024-01-07T13:42:49.336+0000] {base.py:73} INFO - Using connection ID 'postgres_docker_conn' for task execution.
[2024-01-07T13:42:49.356+0000] {base.py:73} INFO - Using connection ID 'postgres_docker_conn' for task execution.
[2024-01-07T13:42:49.387+0000] {logging_mixin.py:151} WARNING - /home/***/.local/lib/python3.8/site-packages/***/providers/common/sql/hooks/sql.py:219 UserWarning: pandas only supports SQLAlchemy connectable (engine/connection) or database string URI or sqlite3 DBAPI2 connection. Other DBAPI2 objects are not tested. Please consider using SQLAlchemy.
[2024-01-07T13:42:49.395+0000] {postgres_to_gcs_staging.py:52} INFO - Uploading to bucket, course
[2024-01-07T13:42:49.427+0000] {connection.py:232} WARNING - Connection schemes (type: google_cloud_platform) shall not contain '_' according to RFC3986.
[2024-01-07T13:42:49.430+0000] {base.py:73} INFO - Using connection ID 'google_cloud_default' for task execution.
[2024-01-07T13:42:49.443+0000] {taskinstance.py:1937} ERROR - Task failed with exception
Traceback (most recent call last):
  File "/home/airflow/.local/lib/python3.8/site-packages/airflow/providers/google/common/hooks/base_google.py", line 259, in get_credentials_and_project_id
    keyfile_dict_json = json.loads(keyfile_dict)
  File "/usr/local/lib/python3.8/json/__init__.py", line 357, in loads
    return _default_decoder.decode(s)
  File "/usr/local/lib/python3.8/json/decoder.py", line 337, in decode
    obj, end = self.raw_decode(s, idx=_w(s, 0).end())
  File "/usr/local/lib/python3.8/json/decoder.py", line 355, in raw_decode
    raise JSONDecodeError("Expecting value", s, err.value) from None
json.decoder.JSONDecodeError: Expecting value: line 1 column 1 (char 0)

During handling of the above exception, another exception occurred:

Traceback (most recent call last):
  File "/home/airflow/.local/lib/python3.8/site-packages/airflow/operators/python.py", line 192, in execute
    return_value = self.execute_callable()
  File "/home/airflow/.local/lib/python3.8/site-packages/airflow/operators/python.py", line 209, in execute_callable
    return self.python_callable(*self.op_args, **self.op_kwargs)
  File "/opt/airflow/dags/postgres_to_gcs_staging.py", line 66, in Postgres_To_GCS_Bucket
    gcs_hook.upload( bucket_name=BUCKET, object_name=gcs_path, data=parquet_buffer.getvalue(),  mime_type='application/octet-stream')
  File "/home/airflow/.local/lib/python3.8/site-packages/airflow/providers/google/cloud/hooks/gcs.py", line 530, in upload
    client = self.get_conn()
  File "/home/airflow/.local/lib/python3.8/site-packages/airflow/providers/google/cloud/hooks/gcs.py", line 173, in get_conn
    credentials=self.get_credentials(), client_info=CLIENT_INFO, project=self.project_id
  File "/home/airflow/.local/lib/python3.8/site-packages/airflow/providers/google/common/hooks/base_google.py", line 296, in get_credentials
    credentials, _ = self.get_credentials_and_project_id()
  File "/home/airflow/.local/lib/python3.8/site-packages/airflow/providers/google/common/hooks/base_google.py", line 261, in get_credentials_and_project_id
    raise AirflowException("Invalid key JSON.")
airflow.exceptions.AirflowException: Invalid key JSON.
[2024-01-07T13:42:49.455+0000] {taskinstance.py:1400} INFO - Marking task as UP_FOR_RETRY. dag_id=ingest_from_postgres_to_GCS_bucket, task_id=copy_course_Postgres_To_GCS, execution_date=20231127T000000, start_date=20240107T134248, end_date=20240107T134249
[2024-01-07T13:42:49.509+0000] {logging_mixin.py:151} WARNING - /home/***/.local/lib/python3.8/site-packages/***/utils/email.py:154 RemovedInAirflow3Warning: Fetching SMTP credentials from configuration variables will be deprecated in a future release. Please set credentials using a connection instead.
[2024-01-07T13:42:49.509+0000] {configuration.py:1068} WARNING - section/key [smtp/smtp_user] not found in config
[2024-01-07T13:42:49.510+0000] {email.py:270} INFO - Email alerting: attempt 1
[2024-01-07T13:42:49.524+0000] {configuration.py:1068} WARNING - section/key [smtp/smtp_user] not found in config
[2024-01-07T13:42:49.524+0000] {email.py:270} INFO - Email alerting: attempt 1
[2024-01-07T13:42:49.524+0000] {taskinstance.py:2007} ERROR - Failed to send email to: ['franklinmutwiri41@gmail.com']
Traceback (most recent call last):
  File "/home/airflow/.local/lib/python3.8/site-packages/airflow/providers/google/common/hooks/base_google.py", line 259, in get_credentials_and_project_id
    keyfile_dict_json = json.loads(keyfile_dict)
  File "/usr/local/lib/python3.8/json/__init__.py", line 357, in loads
    return _default_decoder.decode(s)
  File "/usr/local/lib/python3.8/json/decoder.py", line 337, in decode
    obj, end = self.raw_decode(s, idx=_w(s, 0).end())
  File "/usr/local/lib/python3.8/json/decoder.py", line 355, in raw_decode
    raise JSONDecodeError("Expecting value", s, err.value) from None
json.decoder.JSONDecodeError: Expecting value: line 1 column 1 (char 0)

During handling of the above exception, another exception occurred:

Traceback (most recent call last):
  File "/home/airflow/.local/lib/python3.8/site-packages/airflow/models/taskinstance.py", line 1518, in _run_raw_task
    self._execute_task_with_callbacks(context, test_mode, session=session)
  File "/home/airflow/.local/lib/python3.8/site-packages/airflow/models/taskinstance.py", line 1681, in _execute_task_with_callbacks
    result = self._execute_task(context, task_orig)
  File "/home/airflow/.local/lib/python3.8/site-packages/airflow/models/taskinstance.py", line 1744, in _execute_task
    result = execute_callable(context=context, **execute_callable_kwargs)
  File "/home/airflow/.local/lib/python3.8/site-packages/airflow/operators/python.py", line 192, in execute
    return_value = self.execute_callable()
  File "/home/airflow/.local/lib/python3.8/site-packages/airflow/operators/python.py", line 209, in execute_callable
    return self.python_callable(*self.op_args, **self.op_kwargs)
  File "/opt/airflow/dags/postgres_to_gcs_staging.py", line 66, in Postgres_To_GCS_Bucket
    gcs_hook.upload( bucket_name=BUCKET, object_name=gcs_path, data=parquet_buffer.getvalue(),  mime_type='application/octet-stream')
  File "/home/airflow/.local/lib/python3.8/site-packages/airflow/providers/google/cloud/hooks/gcs.py", line 530, in upload
    client = self.get_conn()
  File "/home/airflow/.local/lib/python3.8/site-packages/airflow/providers/google/cloud/hooks/gcs.py", line 173, in get_conn
    credentials=self.get_credentials(), client_info=CLIENT_INFO, project=self.project_id
  File "/home/airflow/.local/lib/python3.8/site-packages/airflow/providers/google/common/hooks/base_google.py", line 296, in get_credentials
    credentials, _ = self.get_credentials_and_project_id()
  File "/home/airflow/.local/lib/python3.8/site-packages/airflow/providers/google/common/hooks/base_google.py", line 261, in get_credentials_and_project_id
    raise AirflowException("Invalid key JSON.")
airflow.exceptions.AirflowException: Invalid key JSON.

During handling of the above exception, another exception occurred:

Traceback (most recent call last):
  File "/home/airflow/.local/lib/python3.8/site-packages/airflow/models/taskinstance.py", line 2420, in email_alert
    send_email(task.email, subject, html_content)
  File "/home/airflow/.local/lib/python3.8/site-packages/airflow/utils/email.py", line 80, in send_email
    return backend(
  File "/home/airflow/.local/lib/python3.8/site-packages/airflow/utils/email.py", line 154, in send_email_smtp
    send_mime_email(e_from=mail_from, e_to=recipients, mime_msg=msg, conn_id=conn_id, dryrun=dryrun)
  File "/home/airflow/.local/lib/python3.8/site-packages/airflow/utils/email.py", line 272, in send_mime_email
    smtp_conn = _get_smtp_connection(smtp_host, smtp_port, smtp_timeout, smtp_ssl)
  File "/home/airflow/.local/lib/python3.8/site-packages/airflow/utils/email.py", line 316, in _get_smtp_connection
    return smtplib.SMTP(host=host, port=port, timeout=timeout)
  File "/usr/local/lib/python3.8/smtplib.py", line 255, in __init__
    (code, msg) = self.connect(host, port)
  File "/usr/local/lib/python3.8/smtplib.py", line 339, in connect
    self.sock = self._get_socket(host, port, self.timeout)
  File "/usr/local/lib/python3.8/smtplib.py", line 310, in _get_socket
    return socket.create_connection((host, port), timeout,
  File "/usr/local/lib/python3.8/socket.py", line 808, in create_connection
    raise err
  File "/usr/local/lib/python3.8/socket.py", line 796, in create_connection
    sock.connect(sa)
OSError: [Errno 99] Cannot assign requested address

During handling of the above exception, another exception occurred:

Traceback (most recent call last):
  File "/home/airflow/.local/lib/python3.8/site-packages/airflow/models/taskinstance.py", line 2005, in handle_failure
    self.email_alert(error, task)
  File "/home/airflow/.local/lib/python3.8/site-packages/airflow/models/taskinstance.py", line 2422, in email_alert
    send_email(task.email, subject, html_content_err)
  File "/home/airflow/.local/lib/python3.8/site-packages/airflow/utils/email.py", line 80, in send_email
    return backend(
  File "/home/airflow/.local/lib/python3.8/site-packages/airflow/utils/email.py", line 154, in send_email_smtp
    send_mime_email(e_from=mail_from, e_to=recipients, mime_msg=msg, conn_id=conn_id, dryrun=dryrun)
  File "/home/airflow/.local/lib/python3.8/site-packages/airflow/utils/email.py", line 272, in send_mime_email
    smtp_conn = _get_smtp_connection(smtp_host, smtp_port, smtp_timeout, smtp_ssl)
  File "/home/airflow/.local/lib/python3.8/site-packages/airflow/utils/email.py", line 316, in _get_smtp_connection
    return smtplib.SMTP(host=host, port=port, timeout=timeout)
  File "/usr/local/lib/python3.8/smtplib.py", line 255, in __init__
    (code, msg) = self.connect(host, port)
  File "/usr/local/lib/python3.8/smtplib.py", line 339, in connect
    self.sock = self._get_socket(host, port, self.timeout)
  File "/usr/local/lib/python3.8/smtplib.py", line 310, in _get_socket
    return socket.create_connection((host, port), timeout,
  File "/usr/local/lib/python3.8/socket.py", line 808, in create_connection
    raise err
  File "/usr/local/lib/python3.8/socket.py", line 796, in create_connection
    sock.connect(sa)
OSError: [Errno 99] Cannot assign requested address
[2024-01-07T13:42:49.584+0000] {standard_task_runner.py:104} ERROR - Failed to execute job 124 for task copy_course_Postgres_To_GCS (Invalid key JSON.; 368)
[2024-01-07T13:42:49.597+0000] {local_task_job_runner.py:228} INFO - Task exited with return code 1
[2024-01-07T13:42:49.621+0000] {taskinstance.py:2778} INFO - 0 downstream tasks scheduled from follow-on schedule check
