[2024-01-07T00:20:28.214+0000] {taskinstance.py:1159} INFO - Dependencies all met for dep_context=non-requeueable deps ti=<TaskInstance: ingest_from_postgres_to_GCS_bucket.copy_course_Postgres_To_GCS scheduled__2023-11-27T00:00:00+00:00 [queued]>
[2024-01-07T00:20:28.230+0000] {taskinstance.py:1159} INFO - Dependencies all met for dep_context=requeueable deps ti=<TaskInstance: ingest_from_postgres_to_GCS_bucket.copy_course_Postgres_To_GCS scheduled__2023-11-27T00:00:00+00:00 [queued]>
[2024-01-07T00:20:28.230+0000] {taskinstance.py:1361} INFO - Starting attempt 3 of 3
[2024-01-07T00:20:28.262+0000] {taskinstance.py:1382} INFO - Executing <Task(PythonOperator): copy_course_Postgres_To_GCS> on 2023-11-27 00:00:00+00:00
[2024-01-07T00:20:28.270+0000] {standard_task_runner.py:57} INFO - Started process 1692 to run task
[2024-01-07T00:20:28.276+0000] {standard_task_runner.py:84} INFO - Running: ['airflow', 'tasks', 'run', 'ingest_from_postgres_to_GCS_bucket', 'copy_course_Postgres_To_GCS', 'scheduled__2023-11-27T00:00:00+00:00', '--job-id', '346', '--raw', '--subdir', 'DAGS_FOLDER/postgres_to_gcs_staging.py', '--cfg-path', '/tmp/tmp2q65k_p6']
[2024-01-07T00:20:28.284+0000] {standard_task_runner.py:85} INFO - Job 346: Subtask copy_course_Postgres_To_GCS
[2024-01-07T00:20:28.403+0000] {task_command.py:416} INFO - Running <TaskInstance: ingest_from_postgres_to_GCS_bucket.copy_course_Postgres_To_GCS scheduled__2023-11-27T00:00:00+00:00 [running]> on host f500624b13d0
[2024-01-07T00:20:28.655+0000] {taskinstance.py:1662} INFO - Exporting env vars: AIRFLOW_CTX_DAG_EMAIL='franklinmutwiri41@gmail.com' AIRFLOW_CTX_DAG_OWNER='airflow' AIRFLOW_CTX_DAG_ID='ingest_from_postgres_to_GCS_bucket' AIRFLOW_CTX_TASK_ID='copy_course_Postgres_To_GCS' AIRFLOW_CTX_EXECUTION_DATE='2023-11-27T00:00:00+00:00' AIRFLOW_CTX_TRY_NUMBER='3' AIRFLOW_CTX_DAG_RUN_ID='scheduled__2023-11-27T00:00:00+00:00'
[2024-01-07T00:20:28.684+0000] {base.py:73} INFO - Using connection ID 'postgres_docker_conn' for task execution.
[2024-01-07T00:20:28.702+0000] {base.py:73} INFO - Using connection ID 'postgres_docker_conn' for task execution.
[2024-01-07T00:20:28.736+0000] {logging_mixin.py:151} WARNING - /home/***/.local/lib/python3.8/site-packages/***/providers/common/sql/hooks/sql.py:219 UserWarning: pandas only supports SQLAlchemy connectable (engine/connection) or database string URI or sqlite3 DBAPI2 connection. Other DBAPI2 objects are not tested. Please consider using SQLAlchemy.
[2024-01-07T00:20:28.745+0000] {postgres_to_gcs_staging.py:47} INFO - Uploading to bucket, course
[2024-01-07T00:20:28.797+0000] {connection.py:232} WARNING - Connection schemes (type: google_cloud_platform) shall not contain '_' according to RFC3986.
[2024-01-07T00:20:28.801+0000] {base.py:73} INFO - Using connection ID 'google_cloud_default' for task execution.
[2024-01-07T00:20:28.802+0000] {taskinstance.py:1937} ERROR - Task failed with exception
Traceback (most recent call last):
  File "/home/airflow/.local/lib/python3.8/site-packages/airflow/operators/python.py", line 192, in execute
    return_value = self.execute_callable()
  File "/home/airflow/.local/lib/python3.8/site-packages/airflow/operators/python.py", line 209, in execute_callable
    return self.python_callable(*self.op_args, **self.op_kwargs)
  File "/opt/airflow/dags/postgres_to_gcs_staging.py", line 61, in Postgres_To_GCS_Bucket
    gcs_hook.upload( BUCKET, gcs_path + parquet_buffer.getvalue(), 'parquet')
TypeError: can only concatenate str (not "bytes") to str
[2024-01-07T00:20:28.823+0000] {taskinstance.py:1400} INFO - Marking task as FAILED. dag_id=ingest_from_postgres_to_GCS_bucket, task_id=copy_course_Postgres_To_GCS, execution_date=20231127T000000, start_date=20240107T002028, end_date=20240107T002028
[2024-01-07T00:20:28.850+0000] {logging_mixin.py:151} WARNING - /home/***/.local/lib/python3.8/site-packages/***/utils/email.py:154 RemovedInAirflow3Warning: Fetching SMTP credentials from configuration variables will be deprecated in a future release. Please set credentials using a connection instead.
[2024-01-07T00:20:28.851+0000] {configuration.py:1068} WARNING - section/key [smtp/smtp_user] not found in config
[2024-01-07T00:20:28.851+0000] {email.py:270} INFO - Email alerting: attempt 1
[2024-01-07T00:20:28.868+0000] {configuration.py:1068} WARNING - section/key [smtp/smtp_user] not found in config
[2024-01-07T00:20:28.869+0000] {email.py:270} INFO - Email alerting: attempt 1
[2024-01-07T00:20:28.870+0000] {taskinstance.py:2007} ERROR - Failed to send email to: ['franklinmutwiri41@gmail.com']
Traceback (most recent call last):
  File "/home/airflow/.local/lib/python3.8/site-packages/airflow/models/taskinstance.py", line 1518, in _run_raw_task
    self._execute_task_with_callbacks(context, test_mode, session=session)
  File "/home/airflow/.local/lib/python3.8/site-packages/airflow/models/taskinstance.py", line 1681, in _execute_task_with_callbacks
    result = self._execute_task(context, task_orig)
  File "/home/airflow/.local/lib/python3.8/site-packages/airflow/models/taskinstance.py", line 1744, in _execute_task
    result = execute_callable(context=context, **execute_callable_kwargs)
  File "/home/airflow/.local/lib/python3.8/site-packages/airflow/operators/python.py", line 192, in execute
    return_value = self.execute_callable()
  File "/home/airflow/.local/lib/python3.8/site-packages/airflow/operators/python.py", line 209, in execute_callable
    return self.python_callable(*self.op_args, **self.op_kwargs)
  File "/opt/airflow/dags/postgres_to_gcs_staging.py", line 61, in Postgres_To_GCS_Bucket
    gcs_hook.upload( BUCKET, gcs_path + parquet_buffer.getvalue(), 'parquet')
TypeError: can only concatenate str (not "bytes") to str

During handling of the above exception, another exception occurred:

Traceback (most recent call last):
  File "/home/airflow/.local/lib/python3.8/site-packages/airflow/models/taskinstance.py", line 2420, in email_alert
    send_email(task.email, subject, html_content)
  File "/home/airflow/.local/lib/python3.8/site-packages/airflow/utils/email.py", line 80, in send_email
    return backend(
  File "/home/airflow/.local/lib/python3.8/site-packages/airflow/utils/email.py", line 154, in send_email_smtp
    send_mime_email(e_from=mail_from, e_to=recipients, mime_msg=msg, conn_id=conn_id, dryrun=dryrun)
  File "/home/airflow/.local/lib/python3.8/site-packages/airflow/utils/email.py", line 272, in send_mime_email
    smtp_conn = _get_smtp_connection(smtp_host, smtp_port, smtp_timeout, smtp_ssl)
  File "/home/airflow/.local/lib/python3.8/site-packages/airflow/utils/email.py", line 316, in _get_smtp_connection
    return smtplib.SMTP(host=host, port=port, timeout=timeout)
  File "/usr/local/lib/python3.8/smtplib.py", line 255, in __init__
    (code, msg) = self.connect(host, port)
  File "/usr/local/lib/python3.8/smtplib.py", line 339, in connect
    self.sock = self._get_socket(host, port, self.timeout)
  File "/usr/local/lib/python3.8/smtplib.py", line 310, in _get_socket
    return socket.create_connection((host, port), timeout,
  File "/usr/local/lib/python3.8/socket.py", line 808, in create_connection
    raise err
  File "/usr/local/lib/python3.8/socket.py", line 796, in create_connection
    sock.connect(sa)
OSError: [Errno 99] Cannot assign requested address

During handling of the above exception, another exception occurred:

Traceback (most recent call last):
  File "/home/airflow/.local/lib/python3.8/site-packages/airflow/models/taskinstance.py", line 2005, in handle_failure
    self.email_alert(error, task)
  File "/home/airflow/.local/lib/python3.8/site-packages/airflow/models/taskinstance.py", line 2422, in email_alert
    send_email(task.email, subject, html_content_err)
  File "/home/airflow/.local/lib/python3.8/site-packages/airflow/utils/email.py", line 80, in send_email
    return backend(
  File "/home/airflow/.local/lib/python3.8/site-packages/airflow/utils/email.py", line 154, in send_email_smtp
    send_mime_email(e_from=mail_from, e_to=recipients, mime_msg=msg, conn_id=conn_id, dryrun=dryrun)
  File "/home/airflow/.local/lib/python3.8/site-packages/airflow/utils/email.py", line 272, in send_mime_email
    smtp_conn = _get_smtp_connection(smtp_host, smtp_port, smtp_timeout, smtp_ssl)
  File "/home/airflow/.local/lib/python3.8/site-packages/airflow/utils/email.py", line 316, in _get_smtp_connection
    return smtplib.SMTP(host=host, port=port, timeout=timeout)
  File "/usr/local/lib/python3.8/smtplib.py", line 255, in __init__
    (code, msg) = self.connect(host, port)
  File "/usr/local/lib/python3.8/smtplib.py", line 339, in connect
    self.sock = self._get_socket(host, port, self.timeout)
  File "/usr/local/lib/python3.8/smtplib.py", line 310, in _get_socket
    return socket.create_connection((host, port), timeout,
  File "/usr/local/lib/python3.8/socket.py", line 808, in create_connection
    raise err
  File "/usr/local/lib/python3.8/socket.py", line 796, in create_connection
    sock.connect(sa)
OSError: [Errno 99] Cannot assign requested address
[2024-01-07T00:20:28.973+0000] {standard_task_runner.py:104} ERROR - Failed to execute job 346 for task copy_course_Postgres_To_GCS (can only concatenate str (not "bytes") to str; 1692)
[2024-01-07T00:20:29.011+0000] {local_task_job_runner.py:228} INFO - Task exited with return code 1
[2024-01-07T00:20:29.048+0000] {taskinstance.py:2778} INFO - 0 downstream tasks scheduled from follow-on schedule check
[2024-01-07T00:24:25.100+0000] {taskinstance.py:1159} INFO - Dependencies all met for dep_context=non-requeueable deps ti=<TaskInstance: ingest_from_postgres_to_GCS_bucket.copy_course_Postgres_To_GCS scheduled__2023-11-27T00:00:00+00:00 [queued]>
[2024-01-07T00:24:25.151+0000] {taskinstance.py:1159} INFO - Dependencies all met for dep_context=requeueable deps ti=<TaskInstance: ingest_from_postgres_to_GCS_bucket.copy_course_Postgres_To_GCS scheduled__2023-11-27T00:00:00+00:00 [queued]>
[2024-01-07T00:24:25.152+0000] {taskinstance.py:1361} INFO - Starting attempt 3 of 3
[2024-01-07T00:24:25.348+0000] {taskinstance.py:1382} INFO - Executing <Task(PythonOperator): copy_course_Postgres_To_GCS> on 2023-11-27 00:00:00+00:00
[2024-01-07T00:24:25.357+0000] {standard_task_runner.py:57} INFO - Started process 1824 to run task
[2024-01-07T00:24:25.361+0000] {standard_task_runner.py:84} INFO - Running: ['airflow', 'tasks', 'run', 'ingest_from_postgres_to_GCS_bucket', 'copy_course_Postgres_To_GCS', 'scheduled__2023-11-27T00:00:00+00:00', '--job-id', '355', '--raw', '--subdir', 'DAGS_FOLDER/postgres_to_gcs_staging.py', '--cfg-path', '/tmp/tmp7h9whcel']
[2024-01-07T00:24:25.368+0000] {standard_task_runner.py:85} INFO - Job 355: Subtask copy_course_Postgres_To_GCS
[2024-01-07T00:24:25.622+0000] {task_command.py:416} INFO - Running <TaskInstance: ingest_from_postgres_to_GCS_bucket.copy_course_Postgres_To_GCS scheduled__2023-11-27T00:00:00+00:00 [running]> on host f500624b13d0
[2024-01-07T00:24:25.863+0000] {taskinstance.py:1662} INFO - Exporting env vars: AIRFLOW_CTX_DAG_EMAIL='franklinmutwiri41@gmail.com' AIRFLOW_CTX_DAG_OWNER='airflow' AIRFLOW_CTX_DAG_ID='ingest_from_postgres_to_GCS_bucket' AIRFLOW_CTX_TASK_ID='copy_course_Postgres_To_GCS' AIRFLOW_CTX_EXECUTION_DATE='2023-11-27T00:00:00+00:00' AIRFLOW_CTX_TRY_NUMBER='3' AIRFLOW_CTX_DAG_RUN_ID='scheduled__2023-11-27T00:00:00+00:00'
[2024-01-07T00:24:25.881+0000] {base.py:73} INFO - Using connection ID 'postgres_docker_conn' for task execution.
[2024-01-07T00:24:25.895+0000] {base.py:73} INFO - Using connection ID 'postgres_docker_conn' for task execution.
[2024-01-07T00:24:25.918+0000] {logging_mixin.py:151} WARNING - /home/***/.local/lib/python3.8/site-packages/***/providers/common/sql/hooks/sql.py:219 UserWarning: pandas only supports SQLAlchemy connectable (engine/connection) or database string URI or sqlite3 DBAPI2 connection. Other DBAPI2 objects are not tested. Please consider using SQLAlchemy.
[2024-01-07T00:24:25.925+0000] {postgres_to_gcs_staging.py:47} INFO - Uploading to bucket, course
[2024-01-07T00:24:25.964+0000] {connection.py:232} WARNING - Connection schemes (type: google_cloud_platform) shall not contain '_' according to RFC3986.
[2024-01-07T00:24:25.967+0000] {base.py:73} INFO - Using connection ID 'google_cloud_default' for task execution.
[2024-01-07T00:24:26.044+0000] {taskinstance.py:1937} ERROR - Task failed with exception
Traceback (most recent call last):
  File "/home/airflow/.local/lib/python3.8/site-packages/airflow/operators/python.py", line 192, in execute
    return_value = self.execute_callable()
  File "/home/airflow/.local/lib/python3.8/site-packages/airflow/operators/python.py", line 209, in execute_callable
    return self.python_callable(*self.op_args, **self.op_kwargs)
  File "/opt/airflow/dags/postgres_to_gcs_staging.py", line 61, in Postgres_To_GCS_Bucket
    gcs_hook.upload( BUCKET, gcs_path, parquet_buffer.getvalue(), 'parquet')
  File "/home/airflow/.local/lib/python3.8/site-packages/airflow/providers/google/cloud/hooks/gcs.py", line 541, in upload
    raise ValueError(
ValueError: 'filename' and 'data' parameter provided. Please specify a single parameter, either 'filename' for local file uploads or 'data' for file content uploads.
[2024-01-07T00:24:26.060+0000] {taskinstance.py:1400} INFO - Marking task as FAILED. dag_id=ingest_from_postgres_to_GCS_bucket, task_id=copy_course_Postgres_To_GCS, execution_date=20231127T000000, start_date=20240107T002425, end_date=20240107T002426
[2024-01-07T00:24:26.078+0000] {logging_mixin.py:151} WARNING - /home/***/.local/lib/python3.8/site-packages/***/utils/email.py:154 RemovedInAirflow3Warning: Fetching SMTP credentials from configuration variables will be deprecated in a future release. Please set credentials using a connection instead.
[2024-01-07T00:24:26.079+0000] {configuration.py:1068} WARNING - section/key [smtp/smtp_user] not found in config
[2024-01-07T00:24:26.079+0000] {email.py:270} INFO - Email alerting: attempt 1
[2024-01-07T00:24:26.095+0000] {configuration.py:1068} WARNING - section/key [smtp/smtp_user] not found in config
[2024-01-07T00:24:26.095+0000] {email.py:270} INFO - Email alerting: attempt 1
[2024-01-07T00:24:26.096+0000] {taskinstance.py:2007} ERROR - Failed to send email to: ['franklinmutwiri41@gmail.com']
Traceback (most recent call last):
  File "/home/airflow/.local/lib/python3.8/site-packages/airflow/models/taskinstance.py", line 1518, in _run_raw_task
    self._execute_task_with_callbacks(context, test_mode, session=session)
  File "/home/airflow/.local/lib/python3.8/site-packages/airflow/models/taskinstance.py", line 1681, in _execute_task_with_callbacks
    result = self._execute_task(context, task_orig)
  File "/home/airflow/.local/lib/python3.8/site-packages/airflow/models/taskinstance.py", line 1744, in _execute_task
    result = execute_callable(context=context, **execute_callable_kwargs)
  File "/home/airflow/.local/lib/python3.8/site-packages/airflow/operators/python.py", line 192, in execute
    return_value = self.execute_callable()
  File "/home/airflow/.local/lib/python3.8/site-packages/airflow/operators/python.py", line 209, in execute_callable
    return self.python_callable(*self.op_args, **self.op_kwargs)
  File "/opt/airflow/dags/postgres_to_gcs_staging.py", line 61, in Postgres_To_GCS_Bucket
    gcs_hook.upload( BUCKET, gcs_path, parquet_buffer.getvalue(), 'parquet')
  File "/home/airflow/.local/lib/python3.8/site-packages/airflow/providers/google/cloud/hooks/gcs.py", line 541, in upload
    raise ValueError(
ValueError: 'filename' and 'data' parameter provided. Please specify a single parameter, either 'filename' for local file uploads or 'data' for file content uploads.

During handling of the above exception, another exception occurred:

Traceback (most recent call last):
  File "/home/airflow/.local/lib/python3.8/site-packages/airflow/models/taskinstance.py", line 2420, in email_alert
    send_email(task.email, subject, html_content)
  File "/home/airflow/.local/lib/python3.8/site-packages/airflow/utils/email.py", line 80, in send_email
    return backend(
  File "/home/airflow/.local/lib/python3.8/site-packages/airflow/utils/email.py", line 154, in send_email_smtp
    send_mime_email(e_from=mail_from, e_to=recipients, mime_msg=msg, conn_id=conn_id, dryrun=dryrun)
  File "/home/airflow/.local/lib/python3.8/site-packages/airflow/utils/email.py", line 272, in send_mime_email
    smtp_conn = _get_smtp_connection(smtp_host, smtp_port, smtp_timeout, smtp_ssl)
  File "/home/airflow/.local/lib/python3.8/site-packages/airflow/utils/email.py", line 316, in _get_smtp_connection
    return smtplib.SMTP(host=host, port=port, timeout=timeout)
  File "/usr/local/lib/python3.8/smtplib.py", line 255, in __init__
    (code, msg) = self.connect(host, port)
  File "/usr/local/lib/python3.8/smtplib.py", line 339, in connect
    self.sock = self._get_socket(host, port, self.timeout)
  File "/usr/local/lib/python3.8/smtplib.py", line 310, in _get_socket
    return socket.create_connection((host, port), timeout,
  File "/usr/local/lib/python3.8/socket.py", line 808, in create_connection
    raise err
  File "/usr/local/lib/python3.8/socket.py", line 796, in create_connection
    sock.connect(sa)
OSError: [Errno 99] Cannot assign requested address

During handling of the above exception, another exception occurred:

Traceback (most recent call last):
  File "/home/airflow/.local/lib/python3.8/site-packages/airflow/models/taskinstance.py", line 2005, in handle_failure
    self.email_alert(error, task)
  File "/home/airflow/.local/lib/python3.8/site-packages/airflow/models/taskinstance.py", line 2422, in email_alert
    send_email(task.email, subject, html_content_err)
  File "/home/airflow/.local/lib/python3.8/site-packages/airflow/utils/email.py", line 80, in send_email
    return backend(
  File "/home/airflow/.local/lib/python3.8/site-packages/airflow/utils/email.py", line 154, in send_email_smtp
    send_mime_email(e_from=mail_from, e_to=recipients, mime_msg=msg, conn_id=conn_id, dryrun=dryrun)
  File "/home/airflow/.local/lib/python3.8/site-packages/airflow/utils/email.py", line 272, in send_mime_email
    smtp_conn = _get_smtp_connection(smtp_host, smtp_port, smtp_timeout, smtp_ssl)
  File "/home/airflow/.local/lib/python3.8/site-packages/airflow/utils/email.py", line 316, in _get_smtp_connection
    return smtplib.SMTP(host=host, port=port, timeout=timeout)
  File "/usr/local/lib/python3.8/smtplib.py", line 255, in __init__
    (code, msg) = self.connect(host, port)
  File "/usr/local/lib/python3.8/smtplib.py", line 339, in connect
    self.sock = self._get_socket(host, port, self.timeout)
  File "/usr/local/lib/python3.8/smtplib.py", line 310, in _get_socket
    return socket.create_connection((host, port), timeout,
  File "/usr/local/lib/python3.8/socket.py", line 808, in create_connection
    raise err
  File "/usr/local/lib/python3.8/socket.py", line 796, in create_connection
    sock.connect(sa)
OSError: [Errno 99] Cannot assign requested address
[2024-01-07T00:24:26.138+0000] {standard_task_runner.py:104} ERROR - Failed to execute job 355 for task copy_course_Postgres_To_GCS ('filename' and 'data' parameter provided. Please specify a single parameter, either 'filename' for local file uploads or 'data' for file content uploads.; 1824)
[2024-01-07T00:24:26.177+0000] {local_task_job_runner.py:228} INFO - Task exited with return code 1
[2024-01-07T00:24:26.212+0000] {taskinstance.py:2778} INFO - 0 downstream tasks scheduled from follow-on schedule check
[2024-01-07T13:10:40.245+0000] {taskinstance.py:1159} INFO - Dependencies all met for dep_context=non-requeueable deps ti=<TaskInstance: ingest_from_postgres_to_GCS_bucket.copy_course_Postgres_To_GCS scheduled__2023-11-27T00:00:00+00:00 [queued]>
[2024-01-07T13:10:40.268+0000] {taskinstance.py:1159} INFO - Dependencies all met for dep_context=requeueable deps ti=<TaskInstance: ingest_from_postgres_to_GCS_bucket.copy_course_Postgres_To_GCS scheduled__2023-11-27T00:00:00+00:00 [queued]>
[2024-01-07T13:10:40.268+0000] {taskinstance.py:1361} INFO - Starting attempt 3 of 3
[2024-01-07T13:10:40.297+0000] {taskinstance.py:1382} INFO - Executing <Task(PythonOperator): copy_course_Postgres_To_GCS> on 2023-11-27 00:00:00+00:00
[2024-01-07T13:10:40.306+0000] {standard_task_runner.py:57} INFO - Started process 1133 to run task
[2024-01-07T13:10:40.311+0000] {standard_task_runner.py:84} INFO - Running: ['***', 'tasks', 'run', 'ingest_from_postgres_to_GCS_bucket', 'copy_course_Postgres_To_GCS', 'scheduled__2023-11-27T00:00:00+00:00', '--job-id', '82', '--raw', '--subdir', 'DAGS_FOLDER/postgres_to_gcs_staging.py', '--cfg-path', '/tmp/tmpc0qfmnhq']
[2024-01-07T13:10:40.316+0000] {standard_task_runner.py:85} INFO - Job 82: Subtask copy_course_Postgres_To_GCS
[2024-01-07T13:10:40.396+0000] {task_command.py:416} INFO - Running <TaskInstance: ingest_from_postgres_to_GCS_bucket.copy_course_Postgres_To_GCS scheduled__2023-11-27T00:00:00+00:00 [running]> on host d5f4b55abf9d
[2024-01-07T13:10:40.562+0000] {taskinstance.py:1662} INFO - Exporting env vars: AIRFLOW_CTX_DAG_EMAIL='franklinmutwiri41@gmail.com' AIRFLOW_CTX_DAG_OWNER='***' AIRFLOW_CTX_DAG_ID='ingest_from_postgres_to_GCS_bucket' AIRFLOW_CTX_TASK_ID='copy_course_Postgres_To_GCS' AIRFLOW_CTX_EXECUTION_DATE='2023-11-27T00:00:00+00:00' AIRFLOW_CTX_TRY_NUMBER='3' AIRFLOW_CTX_DAG_RUN_ID='scheduled__2023-11-27T00:00:00+00:00'
[2024-01-07T13:10:40.613+0000] {taskinstance.py:1937} ERROR - Task failed with exception
Traceback (most recent call last):
  File "/home/airflow/.local/lib/python3.8/site-packages/airflow/operators/python.py", line 192, in execute
    return_value = self.execute_callable()
  File "/home/airflow/.local/lib/python3.8/site-packages/airflow/operators/python.py", line 209, in execute_callable
    return self.python_callable(*self.op_args, **self.op_kwargs)
  File "/opt/airflow/dags/postgres_to_gcs_staging.py", line 36, in Postgres_To_GCS_Bucket
    pg_hook = PostgresHook.get_hook("postgres_docker_conn")
  File "/home/airflow/.local/lib/python3.8/site-packages/airflow/hooks/base.py", line 84, in get_hook
    connection = cls.get_connection(conn_id)
  File "/home/airflow/.local/lib/python3.8/site-packages/airflow/hooks/base.py", line 72, in get_connection
    conn = Connection.get_connection_from_secrets(conn_id)
  File "/home/airflow/.local/lib/python3.8/site-packages/airflow/models/connection.py", line 477, in get_connection_from_secrets
    raise AirflowNotFoundException(f"The conn_id `{conn_id}` isn't defined")
airflow.exceptions.AirflowNotFoundException: The conn_id `postgres_docker_conn` isn't defined
[2024-01-07T13:10:40.618+0000] {taskinstance.py:1400} INFO - Marking task as FAILED. dag_id=ingest_from_postgres_to_GCS_bucket, task_id=copy_course_Postgres_To_GCS, execution_date=20231127T000000, start_date=20240107T131040, end_date=20240107T131040
[2024-01-07T13:10:40.660+0000] {logging_mixin.py:151} WARNING - /home/***/.local/lib/python3.8/site-packages/***/utils/email.py:154 RemovedInAirflow3Warning: Fetching SMTP credentials from configuration variables will be deprecated in a future release. Please set credentials using a connection instead.
[2024-01-07T13:10:40.660+0000] {configuration.py:1068} WARNING - section/key [smtp/smtp_user] not found in config
[2024-01-07T13:10:40.661+0000] {email.py:270} INFO - Email alerting: attempt 1
[2024-01-07T13:10:40.683+0000] {configuration.py:1068} WARNING - section/key [smtp/smtp_user] not found in config
[2024-01-07T13:10:40.684+0000] {email.py:270} INFO - Email alerting: attempt 1
[2024-01-07T13:10:40.684+0000] {taskinstance.py:2007} ERROR - Failed to send email to: ['franklinmutwiri41@gmail.com']
Traceback (most recent call last):
  File "/home/airflow/.local/lib/python3.8/site-packages/airflow/models/taskinstance.py", line 1518, in _run_raw_task
    self._execute_task_with_callbacks(context, test_mode, session=session)
  File "/home/airflow/.local/lib/python3.8/site-packages/airflow/models/taskinstance.py", line 1681, in _execute_task_with_callbacks
    result = self._execute_task(context, task_orig)
  File "/home/airflow/.local/lib/python3.8/site-packages/airflow/models/taskinstance.py", line 1744, in _execute_task
    result = execute_callable(context=context, **execute_callable_kwargs)
  File "/home/airflow/.local/lib/python3.8/site-packages/airflow/operators/python.py", line 192, in execute
    return_value = self.execute_callable()
  File "/home/airflow/.local/lib/python3.8/site-packages/airflow/operators/python.py", line 209, in execute_callable
    return self.python_callable(*self.op_args, **self.op_kwargs)
  File "/opt/airflow/dags/postgres_to_gcs_staging.py", line 36, in Postgres_To_GCS_Bucket
    pg_hook = PostgresHook.get_hook("postgres_docker_conn")
  File "/home/airflow/.local/lib/python3.8/site-packages/airflow/hooks/base.py", line 84, in get_hook
    connection = cls.get_connection(conn_id)
  File "/home/airflow/.local/lib/python3.8/site-packages/airflow/hooks/base.py", line 72, in get_connection
    conn = Connection.get_connection_from_secrets(conn_id)
  File "/home/airflow/.local/lib/python3.8/site-packages/airflow/models/connection.py", line 477, in get_connection_from_secrets
    raise AirflowNotFoundException(f"The conn_id `{conn_id}` isn't defined")
airflow.exceptions.AirflowNotFoundException: The conn_id `postgres_docker_conn` isn't defined

During handling of the above exception, another exception occurred:

Traceback (most recent call last):
  File "/home/airflow/.local/lib/python3.8/site-packages/airflow/models/taskinstance.py", line 2420, in email_alert
    send_email(task.email, subject, html_content)
  File "/home/airflow/.local/lib/python3.8/site-packages/airflow/utils/email.py", line 80, in send_email
    return backend(
  File "/home/airflow/.local/lib/python3.8/site-packages/airflow/utils/email.py", line 154, in send_email_smtp
    send_mime_email(e_from=mail_from, e_to=recipients, mime_msg=msg, conn_id=conn_id, dryrun=dryrun)
  File "/home/airflow/.local/lib/python3.8/site-packages/airflow/utils/email.py", line 272, in send_mime_email
    smtp_conn = _get_smtp_connection(smtp_host, smtp_port, smtp_timeout, smtp_ssl)
  File "/home/airflow/.local/lib/python3.8/site-packages/airflow/utils/email.py", line 316, in _get_smtp_connection
    return smtplib.SMTP(host=host, port=port, timeout=timeout)
  File "/usr/local/lib/python3.8/smtplib.py", line 255, in __init__
    (code, msg) = self.connect(host, port)
  File "/usr/local/lib/python3.8/smtplib.py", line 339, in connect
    self.sock = self._get_socket(host, port, self.timeout)
  File "/usr/local/lib/python3.8/smtplib.py", line 310, in _get_socket
    return socket.create_connection((host, port), timeout,
  File "/usr/local/lib/python3.8/socket.py", line 808, in create_connection
    raise err
  File "/usr/local/lib/python3.8/socket.py", line 796, in create_connection
    sock.connect(sa)
OSError: [Errno 99] Cannot assign requested address

During handling of the above exception, another exception occurred:

Traceback (most recent call last):
  File "/home/airflow/.local/lib/python3.8/site-packages/airflow/models/taskinstance.py", line 2005, in handle_failure
    self.email_alert(error, task)
  File "/home/airflow/.local/lib/python3.8/site-packages/airflow/models/taskinstance.py", line 2422, in email_alert
    send_email(task.email, subject, html_content_err)
  File "/home/airflow/.local/lib/python3.8/site-packages/airflow/utils/email.py", line 80, in send_email
    return backend(
  File "/home/airflow/.local/lib/python3.8/site-packages/airflow/utils/email.py", line 154, in send_email_smtp
    send_mime_email(e_from=mail_from, e_to=recipients, mime_msg=msg, conn_id=conn_id, dryrun=dryrun)
  File "/home/airflow/.local/lib/python3.8/site-packages/airflow/utils/email.py", line 272, in send_mime_email
    smtp_conn = _get_smtp_connection(smtp_host, smtp_port, smtp_timeout, smtp_ssl)
  File "/home/airflow/.local/lib/python3.8/site-packages/airflow/utils/email.py", line 316, in _get_smtp_connection
    return smtplib.SMTP(host=host, port=port, timeout=timeout)
  File "/usr/local/lib/python3.8/smtplib.py", line 255, in __init__
    (code, msg) = self.connect(host, port)
  File "/usr/local/lib/python3.8/smtplib.py", line 339, in connect
    self.sock = self._get_socket(host, port, self.timeout)
  File "/usr/local/lib/python3.8/smtplib.py", line 310, in _get_socket
    return socket.create_connection((host, port), timeout,
  File "/usr/local/lib/python3.8/socket.py", line 808, in create_connection
    raise err
  File "/usr/local/lib/python3.8/socket.py", line 796, in create_connection
    sock.connect(sa)
OSError: [Errno 99] Cannot assign requested address
[2024-01-07T13:10:40.762+0000] {standard_task_runner.py:104} ERROR - Failed to execute job 82 for task copy_course_Postgres_To_GCS (The conn_id `postgres_docker_conn` isn't defined; 1133)
[2024-01-07T13:10:40.803+0000] {local_task_job_runner.py:228} INFO - Task exited with return code 1
[2024-01-07T13:10:40.832+0000] {taskinstance.py:2778} INFO - 0 downstream tasks scheduled from follow-on schedule check
[2024-01-07T13:43:20.911+0000] {taskinstance.py:1159} INFO - Dependencies all met for dep_context=non-requeueable deps ti=<TaskInstance: ingest_from_postgres_to_GCS_bucket.copy_course_Postgres_To_GCS scheduled__2023-11-27T00:00:00+00:00 [queued]>
[2024-01-07T13:43:20.935+0000] {taskinstance.py:1159} INFO - Dependencies all met for dep_context=requeueable deps ti=<TaskInstance: ingest_from_postgres_to_GCS_bucket.copy_course_Postgres_To_GCS scheduled__2023-11-27T00:00:00+00:00 [queued]>
[2024-01-07T13:43:20.936+0000] {taskinstance.py:1361} INFO - Starting attempt 3 of 3
[2024-01-07T13:43:20.964+0000] {taskinstance.py:1382} INFO - Executing <Task(PythonOperator): copy_course_Postgres_To_GCS> on 2023-11-27 00:00:00+00:00
[2024-01-07T13:43:20.971+0000] {standard_task_runner.py:57} INFO - Started process 388 to run task
[2024-01-07T13:43:20.976+0000] {standard_task_runner.py:84} INFO - Running: ['***', 'tasks', 'run', 'ingest_from_postgres_to_GCS_bucket', 'copy_course_Postgres_To_GCS', 'scheduled__2023-11-27T00:00:00+00:00', '--job-id', '126', '--raw', '--subdir', 'DAGS_FOLDER/postgres_to_gcs_staging.py', '--cfg-path', '/tmp/tmpenqlf3s2']
[2024-01-07T13:43:20.985+0000] {standard_task_runner.py:85} INFO - Job 126: Subtask copy_course_Postgres_To_GCS
[2024-01-07T13:43:21.072+0000] {task_command.py:416} INFO - Running <TaskInstance: ingest_from_postgres_to_GCS_bucket.copy_course_Postgres_To_GCS scheduled__2023-11-27T00:00:00+00:00 [running]> on host 5d007c0b4985
[2024-01-07T13:43:21.233+0000] {taskinstance.py:1662} INFO - Exporting env vars: AIRFLOW_CTX_DAG_EMAIL='franklinmutwiri41@gmail.com' AIRFLOW_CTX_DAG_OWNER='***' AIRFLOW_CTX_DAG_ID='ingest_from_postgres_to_GCS_bucket' AIRFLOW_CTX_TASK_ID='copy_course_Postgres_To_GCS' AIRFLOW_CTX_EXECUTION_DATE='2023-11-27T00:00:00+00:00' AIRFLOW_CTX_TRY_NUMBER='3' AIRFLOW_CTX_DAG_RUN_ID='scheduled__2023-11-27T00:00:00+00:00'
[2024-01-07T13:43:21.255+0000] {base.py:73} INFO - Using connection ID 'postgres_docker_conn' for task execution.
[2024-01-07T13:43:21.274+0000] {base.py:73} INFO - Using connection ID 'postgres_docker_conn' for task execution.
[2024-01-07T13:43:21.301+0000] {logging_mixin.py:151} WARNING - /home/***/.local/lib/python3.8/site-packages/***/providers/common/sql/hooks/sql.py:219 UserWarning: pandas only supports SQLAlchemy connectable (engine/connection) or database string URI or sqlite3 DBAPI2 connection. Other DBAPI2 objects are not tested. Please consider using SQLAlchemy.
[2024-01-07T13:43:21.312+0000] {postgres_to_gcs_staging.py:52} INFO - Uploading to bucket, course
[2024-01-07T13:43:21.382+0000] {connection.py:232} WARNING - Connection schemes (type: google_cloud_platform) shall not contain '_' according to RFC3986.
[2024-01-07T13:43:21.387+0000] {base.py:73} INFO - Using connection ID 'google_cloud_default' for task execution.
[2024-01-07T13:43:21.412+0000] {taskinstance.py:1937} ERROR - Task failed with exception
Traceback (most recent call last):
  File "/home/airflow/.local/lib/python3.8/site-packages/airflow/providers/google/common/hooks/base_google.py", line 259, in get_credentials_and_project_id
    keyfile_dict_json = json.loads(keyfile_dict)
  File "/usr/local/lib/python3.8/json/__init__.py", line 357, in loads
    return _default_decoder.decode(s)
  File "/usr/local/lib/python3.8/json/decoder.py", line 337, in decode
    obj, end = self.raw_decode(s, idx=_w(s, 0).end())
  File "/usr/local/lib/python3.8/json/decoder.py", line 355, in raw_decode
    raise JSONDecodeError("Expecting value", s, err.value) from None
json.decoder.JSONDecodeError: Expecting value: line 1 column 1 (char 0)

During handling of the above exception, another exception occurred:

Traceback (most recent call last):
  File "/home/airflow/.local/lib/python3.8/site-packages/airflow/operators/python.py", line 192, in execute
    return_value = self.execute_callable()
  File "/home/airflow/.local/lib/python3.8/site-packages/airflow/operators/python.py", line 209, in execute_callable
    return self.python_callable(*self.op_args, **self.op_kwargs)
  File "/opt/airflow/dags/postgres_to_gcs_staging.py", line 66, in Postgres_To_GCS_Bucket
    gcs_hook.upload( bucket_name=BUCKET, object_name=gcs_path, data=parquet_buffer.getvalue(),  mime_type='application/octet-stream')
  File "/home/airflow/.local/lib/python3.8/site-packages/airflow/providers/google/cloud/hooks/gcs.py", line 530, in upload
    client = self.get_conn()
  File "/home/airflow/.local/lib/python3.8/site-packages/airflow/providers/google/cloud/hooks/gcs.py", line 173, in get_conn
    credentials=self.get_credentials(), client_info=CLIENT_INFO, project=self.project_id
  File "/home/airflow/.local/lib/python3.8/site-packages/airflow/providers/google/common/hooks/base_google.py", line 296, in get_credentials
    credentials, _ = self.get_credentials_and_project_id()
  File "/home/airflow/.local/lib/python3.8/site-packages/airflow/providers/google/common/hooks/base_google.py", line 261, in get_credentials_and_project_id
    raise AirflowException("Invalid key JSON.")
airflow.exceptions.AirflowException: Invalid key JSON.
[2024-01-07T13:43:21.421+0000] {taskinstance.py:1400} INFO - Marking task as FAILED. dag_id=ingest_from_postgres_to_GCS_bucket, task_id=copy_course_Postgres_To_GCS, execution_date=20231127T000000, start_date=20240107T134320, end_date=20240107T134321
[2024-01-07T13:43:21.494+0000] {logging_mixin.py:151} WARNING - /home/***/.local/lib/python3.8/site-packages/***/utils/email.py:154 RemovedInAirflow3Warning: Fetching SMTP credentials from configuration variables will be deprecated in a future release. Please set credentials using a connection instead.
[2024-01-07T13:43:21.495+0000] {configuration.py:1068} WARNING - section/key [smtp/smtp_user] not found in config
[2024-01-07T13:43:21.495+0000] {email.py:270} INFO - Email alerting: attempt 1
[2024-01-07T13:43:21.514+0000] {configuration.py:1068} WARNING - section/key [smtp/smtp_user] not found in config
[2024-01-07T13:43:21.515+0000] {email.py:270} INFO - Email alerting: attempt 1
[2024-01-07T13:43:21.516+0000] {taskinstance.py:2007} ERROR - Failed to send email to: ['franklinmutwiri41@gmail.com']
Traceback (most recent call last):
  File "/home/airflow/.local/lib/python3.8/site-packages/airflow/providers/google/common/hooks/base_google.py", line 259, in get_credentials_and_project_id
    keyfile_dict_json = json.loads(keyfile_dict)
  File "/usr/local/lib/python3.8/json/__init__.py", line 357, in loads
    return _default_decoder.decode(s)
  File "/usr/local/lib/python3.8/json/decoder.py", line 337, in decode
    obj, end = self.raw_decode(s, idx=_w(s, 0).end())
  File "/usr/local/lib/python3.8/json/decoder.py", line 355, in raw_decode
    raise JSONDecodeError("Expecting value", s, err.value) from None
json.decoder.JSONDecodeError: Expecting value: line 1 column 1 (char 0)

During handling of the above exception, another exception occurred:

Traceback (most recent call last):
  File "/home/airflow/.local/lib/python3.8/site-packages/airflow/models/taskinstance.py", line 1518, in _run_raw_task
    self._execute_task_with_callbacks(context, test_mode, session=session)
  File "/home/airflow/.local/lib/python3.8/site-packages/airflow/models/taskinstance.py", line 1681, in _execute_task_with_callbacks
    result = self._execute_task(context, task_orig)
  File "/home/airflow/.local/lib/python3.8/site-packages/airflow/models/taskinstance.py", line 1744, in _execute_task
    result = execute_callable(context=context, **execute_callable_kwargs)
  File "/home/airflow/.local/lib/python3.8/site-packages/airflow/operators/python.py", line 192, in execute
    return_value = self.execute_callable()
  File "/home/airflow/.local/lib/python3.8/site-packages/airflow/operators/python.py", line 209, in execute_callable
    return self.python_callable(*self.op_args, **self.op_kwargs)
  File "/opt/airflow/dags/postgres_to_gcs_staging.py", line 66, in Postgres_To_GCS_Bucket
    gcs_hook.upload( bucket_name=BUCKET, object_name=gcs_path, data=parquet_buffer.getvalue(),  mime_type='application/octet-stream')
  File "/home/airflow/.local/lib/python3.8/site-packages/airflow/providers/google/cloud/hooks/gcs.py", line 530, in upload
    client = self.get_conn()
  File "/home/airflow/.local/lib/python3.8/site-packages/airflow/providers/google/cloud/hooks/gcs.py", line 173, in get_conn
    credentials=self.get_credentials(), client_info=CLIENT_INFO, project=self.project_id
  File "/home/airflow/.local/lib/python3.8/site-packages/airflow/providers/google/common/hooks/base_google.py", line 296, in get_credentials
    credentials, _ = self.get_credentials_and_project_id()
  File "/home/airflow/.local/lib/python3.8/site-packages/airflow/providers/google/common/hooks/base_google.py", line 261, in get_credentials_and_project_id
    raise AirflowException("Invalid key JSON.")
airflow.exceptions.AirflowException: Invalid key JSON.

During handling of the above exception, another exception occurred:

Traceback (most recent call last):
  File "/home/airflow/.local/lib/python3.8/site-packages/airflow/models/taskinstance.py", line 2420, in email_alert
    send_email(task.email, subject, html_content)
  File "/home/airflow/.local/lib/python3.8/site-packages/airflow/utils/email.py", line 80, in send_email
    return backend(
  File "/home/airflow/.local/lib/python3.8/site-packages/airflow/utils/email.py", line 154, in send_email_smtp
    send_mime_email(e_from=mail_from, e_to=recipients, mime_msg=msg, conn_id=conn_id, dryrun=dryrun)
  File "/home/airflow/.local/lib/python3.8/site-packages/airflow/utils/email.py", line 272, in send_mime_email
    smtp_conn = _get_smtp_connection(smtp_host, smtp_port, smtp_timeout, smtp_ssl)
  File "/home/airflow/.local/lib/python3.8/site-packages/airflow/utils/email.py", line 316, in _get_smtp_connection
    return smtplib.SMTP(host=host, port=port, timeout=timeout)
  File "/usr/local/lib/python3.8/smtplib.py", line 255, in __init__
    (code, msg) = self.connect(host, port)
  File "/usr/local/lib/python3.8/smtplib.py", line 339, in connect
    self.sock = self._get_socket(host, port, self.timeout)
  File "/usr/local/lib/python3.8/smtplib.py", line 310, in _get_socket
    return socket.create_connection((host, port), timeout,
  File "/usr/local/lib/python3.8/socket.py", line 808, in create_connection
    raise err
  File "/usr/local/lib/python3.8/socket.py", line 796, in create_connection
    sock.connect(sa)
OSError: [Errno 99] Cannot assign requested address

During handling of the above exception, another exception occurred:

Traceback (most recent call last):
  File "/home/airflow/.local/lib/python3.8/site-packages/airflow/models/taskinstance.py", line 2005, in handle_failure
    self.email_alert(error, task)
  File "/home/airflow/.local/lib/python3.8/site-packages/airflow/models/taskinstance.py", line 2422, in email_alert
    send_email(task.email, subject, html_content_err)
  File "/home/airflow/.local/lib/python3.8/site-packages/airflow/utils/email.py", line 80, in send_email
    return backend(
  File "/home/airflow/.local/lib/python3.8/site-packages/airflow/utils/email.py", line 154, in send_email_smtp
    send_mime_email(e_from=mail_from, e_to=recipients, mime_msg=msg, conn_id=conn_id, dryrun=dryrun)
  File "/home/airflow/.local/lib/python3.8/site-packages/airflow/utils/email.py", line 272, in send_mime_email
    smtp_conn = _get_smtp_connection(smtp_host, smtp_port, smtp_timeout, smtp_ssl)
  File "/home/airflow/.local/lib/python3.8/site-packages/airflow/utils/email.py", line 316, in _get_smtp_connection
    return smtplib.SMTP(host=host, port=port, timeout=timeout)
  File "/usr/local/lib/python3.8/smtplib.py", line 255, in __init__
    (code, msg) = self.connect(host, port)
  File "/usr/local/lib/python3.8/smtplib.py", line 339, in connect
    self.sock = self._get_socket(host, port, self.timeout)
  File "/usr/local/lib/python3.8/smtplib.py", line 310, in _get_socket
    return socket.create_connection((host, port), timeout,
  File "/usr/local/lib/python3.8/socket.py", line 808, in create_connection
    raise err
  File "/usr/local/lib/python3.8/socket.py", line 796, in create_connection
    sock.connect(sa)
OSError: [Errno 99] Cannot assign requested address
[2024-01-07T13:43:21.621+0000] {standard_task_runner.py:104} ERROR - Failed to execute job 126 for task copy_course_Postgres_To_GCS (Invalid key JSON.; 388)
[2024-01-07T13:43:21.637+0000] {local_task_job_runner.py:228} INFO - Task exited with return code 1
[2024-01-07T13:43:21.693+0000] {taskinstance.py:2778} INFO - 0 downstream tasks scheduled from follow-on schedule check
