[2023-12-01T11:47:32.995+0000] {taskinstance.py:1159} INFO - Dependencies all met for dep_context=non-requeueable deps ti=<TaskInstance: ingest_to_gcs_bucket.PostgresToGCS1 scheduled__2023-11-29T00:00:00+00:00 [queued]>
[2023-12-01T11:47:33.012+0000] {taskinstance.py:1159} INFO - Dependencies all met for dep_context=requeueable deps ti=<TaskInstance: ingest_to_gcs_bucket.PostgresToGCS1 scheduled__2023-11-29T00:00:00+00:00 [queued]>
[2023-12-01T11:47:33.012+0000] {taskinstance.py:1361} INFO - Starting attempt 2 of 3
[2023-12-01T11:47:33.052+0000] {taskinstance.py:1382} INFO - Executing <Task(PythonOperator): PostgresToGCS1> on 2023-11-29 00:00:00+00:00
[2023-12-01T11:47:33.060+0000] {standard_task_runner.py:57} INFO - Started process 1328 to run task
[2023-12-01T11:47:33.066+0000] {standard_task_runner.py:84} INFO - Running: ['airflow', 'tasks', 'run', 'ingest_to_gcs_bucket', 'PostgresToGCS1', 'scheduled__2023-11-29T00:00:00+00:00', '--job-id', '215', '--raw', '--subdir', 'DAGS_FOLDER/postgres_to_gcs_staging.py', '--cfg-path', '/tmp/tmpan0h2hub']
[2023-12-01T11:47:33.071+0000] {standard_task_runner.py:85} INFO - Job 215: Subtask PostgresToGCS1
[2023-12-01T11:47:33.164+0000] {task_command.py:416} INFO - Running <TaskInstance: ingest_to_gcs_bucket.PostgresToGCS1 scheduled__2023-11-29T00:00:00+00:00 [running]> on host 363088228d6a
[2023-12-01T11:47:33.338+0000] {taskinstance.py:1662} INFO - Exporting env vars: AIRFLOW_CTX_DAG_EMAIL='franklinmutwiri41@gmail.com' AIRFLOW_CTX_DAG_OWNER='airflow' AIRFLOW_CTX_DAG_ID='ingest_to_gcs_bucket' AIRFLOW_CTX_TASK_ID='PostgresToGCS1' AIRFLOW_CTX_EXECUTION_DATE='2023-11-29T00:00:00+00:00' AIRFLOW_CTX_TRY_NUMBER='2' AIRFLOW_CTX_DAG_RUN_ID='scheduled__2023-11-29T00:00:00+00:00'
[2023-12-01T11:47:33.357+0000] {connection.py:232} WARNING - Connection schemes (type: google_cloud_platform) shall not contain '_' according to RFC3986.
[2023-12-01T11:47:33.362+0000] {base.py:73} INFO - Using connection ID 'google_cloud_default' for task execution.
[2023-12-01T11:47:33.378+0000] {base.py:73} INFO - Using connection ID 'postgres_docker_conn' for task execution.
[2023-12-01T11:47:33.393+0000] {base.py:73} INFO - Using connection ID 'postgres_docker_conn' for task execution.
[2023-12-01T11:47:33.405+0000] {taskinstance.py:1937} ERROR - Task failed with exception
Traceback (most recent call last):
  File "/home/airflow/.local/lib/python3.8/site-packages/airflow/operators/python.py", line 192, in execute
    return_value = self.execute_callable()
  File "/home/airflow/.local/lib/python3.8/site-packages/airflow/operators/python.py", line 209, in execute_callable
    return self.python_callable(*self.op_args, **self.op_kwargs)
  File "/opt/airflow/dags/postgres_to_gcs_staging.py", line 37, in Postgres_To_GCS1
    with open(table +'.csv', 'w') as fp:
PermissionError: [Errno 13] Permission denied: 'course.csv'
[2023-12-01T11:47:33.421+0000] {taskinstance.py:1400} INFO - Marking task as UP_FOR_RETRY. dag_id=ingest_to_gcs_bucket, task_id=PostgresToGCS1, execution_date=20231129T000000, start_date=20231201T114732, end_date=20231201T114733
[2023-12-01T11:47:33.441+0000] {logging_mixin.py:151} WARNING - /home/***/.local/lib/python3.8/site-packages/***/utils/email.py:154 RemovedInAirflow3Warning: Fetching SMTP credentials from configuration variables will be deprecated in a future release. Please set credentials using a connection instead.
[2023-12-01T11:47:33.442+0000] {configuration.py:1068} WARNING - section/key [smtp/smtp_user] not found in config
[2023-12-01T11:47:33.442+0000] {email.py:270} INFO - Email alerting: attempt 1
[2023-12-01T11:47:33.456+0000] {configuration.py:1068} WARNING - section/key [smtp/smtp_user] not found in config
[2023-12-01T11:47:33.456+0000] {email.py:270} INFO - Email alerting: attempt 1
[2023-12-01T11:47:33.457+0000] {taskinstance.py:2007} ERROR - Failed to send email to: ['franklinmutwiri41@gmail.com']
Traceback (most recent call last):
  File "/home/airflow/.local/lib/python3.8/site-packages/airflow/models/taskinstance.py", line 1518, in _run_raw_task
    self._execute_task_with_callbacks(context, test_mode, session=session)
  File "/home/airflow/.local/lib/python3.8/site-packages/airflow/models/taskinstance.py", line 1681, in _execute_task_with_callbacks
    result = self._execute_task(context, task_orig)
  File "/home/airflow/.local/lib/python3.8/site-packages/airflow/models/taskinstance.py", line 1744, in _execute_task
    result = execute_callable(context=context, **execute_callable_kwargs)
  File "/home/airflow/.local/lib/python3.8/site-packages/airflow/operators/python.py", line 192, in execute
    return_value = self.execute_callable()
  File "/home/airflow/.local/lib/python3.8/site-packages/airflow/operators/python.py", line 209, in execute_callable
    return self.python_callable(*self.op_args, **self.op_kwargs)
  File "/opt/airflow/dags/postgres_to_gcs_staging.py", line 37, in Postgres_To_GCS1
    with open(table +'.csv', 'w') as fp:
PermissionError: [Errno 13] Permission denied: 'course.csv'

During handling of the above exception, another exception occurred:

Traceback (most recent call last):
  File "/home/airflow/.local/lib/python3.8/site-packages/airflow/models/taskinstance.py", line 2420, in email_alert
    send_email(task.email, subject, html_content)
  File "/home/airflow/.local/lib/python3.8/site-packages/airflow/utils/email.py", line 80, in send_email
    return backend(
  File "/home/airflow/.local/lib/python3.8/site-packages/airflow/utils/email.py", line 154, in send_email_smtp
    send_mime_email(e_from=mail_from, e_to=recipients, mime_msg=msg, conn_id=conn_id, dryrun=dryrun)
  File "/home/airflow/.local/lib/python3.8/site-packages/airflow/utils/email.py", line 272, in send_mime_email
    smtp_conn = _get_smtp_connection(smtp_host, smtp_port, smtp_timeout, smtp_ssl)
  File "/home/airflow/.local/lib/python3.8/site-packages/airflow/utils/email.py", line 316, in _get_smtp_connection
    return smtplib.SMTP(host=host, port=port, timeout=timeout)
  File "/usr/local/lib/python3.8/smtplib.py", line 255, in __init__
    (code, msg) = self.connect(host, port)
  File "/usr/local/lib/python3.8/smtplib.py", line 339, in connect
    self.sock = self._get_socket(host, port, self.timeout)
  File "/usr/local/lib/python3.8/smtplib.py", line 310, in _get_socket
    return socket.create_connection((host, port), timeout,
  File "/usr/local/lib/python3.8/socket.py", line 808, in create_connection
    raise err
  File "/usr/local/lib/python3.8/socket.py", line 796, in create_connection
    sock.connect(sa)
OSError: [Errno 99] Cannot assign requested address

During handling of the above exception, another exception occurred:

Traceback (most recent call last):
  File "/home/airflow/.local/lib/python3.8/site-packages/airflow/models/taskinstance.py", line 2005, in handle_failure
    self.email_alert(error, task)
  File "/home/airflow/.local/lib/python3.8/site-packages/airflow/models/taskinstance.py", line 2422, in email_alert
    send_email(task.email, subject, html_content_err)
  File "/home/airflow/.local/lib/python3.8/site-packages/airflow/utils/email.py", line 80, in send_email
    return backend(
  File "/home/airflow/.local/lib/python3.8/site-packages/airflow/utils/email.py", line 154, in send_email_smtp
    send_mime_email(e_from=mail_from, e_to=recipients, mime_msg=msg, conn_id=conn_id, dryrun=dryrun)
  File "/home/airflow/.local/lib/python3.8/site-packages/airflow/utils/email.py", line 272, in send_mime_email
    smtp_conn = _get_smtp_connection(smtp_host, smtp_port, smtp_timeout, smtp_ssl)
  File "/home/airflow/.local/lib/python3.8/site-packages/airflow/utils/email.py", line 316, in _get_smtp_connection
    return smtplib.SMTP(host=host, port=port, timeout=timeout)
  File "/usr/local/lib/python3.8/smtplib.py", line 255, in __init__
    (code, msg) = self.connect(host, port)
  File "/usr/local/lib/python3.8/smtplib.py", line 339, in connect
    self.sock = self._get_socket(host, port, self.timeout)
  File "/usr/local/lib/python3.8/smtplib.py", line 310, in _get_socket
    return socket.create_connection((host, port), timeout,
  File "/usr/local/lib/python3.8/socket.py", line 808, in create_connection
    raise err
  File "/usr/local/lib/python3.8/socket.py", line 796, in create_connection
    sock.connect(sa)
OSError: [Errno 99] Cannot assign requested address
[2023-12-01T11:47:33.494+0000] {standard_task_runner.py:104} ERROR - Failed to execute job 215 for task PostgresToGCS1 ([Errno 13] Permission denied: 'course.csv'; 1328)
[2023-12-01T11:47:33.524+0000] {local_task_job_runner.py:228} INFO - Task exited with return code 1
[2023-12-01T11:47:33.561+0000] {taskinstance.py:2778} INFO - 0 downstream tasks scheduled from follow-on schedule check
