[2023-11-30T17:59:14.430+0000] {taskinstance.py:1159} INFO - Dependencies all met for dep_context=non-requeueable deps ti=<TaskInstance: ingest_to_gcs_bucket.PostgresToGCS1 scheduled__2023-11-27T00:00:00+00:00 [queued]>
[2023-11-30T17:59:14.440+0000] {taskinstance.py:1159} INFO - Dependencies all met for dep_context=requeueable deps ti=<TaskInstance: ingest_to_gcs_bucket.PostgresToGCS1 scheduled__2023-11-27T00:00:00+00:00 [queued]>
[2023-11-30T17:59:14.440+0000] {taskinstance.py:1361} INFO - Starting attempt 1 of 3
[2023-11-30T17:59:14.472+0000] {taskinstance.py:1382} INFO - Executing <Task(PythonOperator): PostgresToGCS1> on 2023-11-27 00:00:00+00:00
[2023-11-30T17:59:14.478+0000] {standard_task_runner.py:57} INFO - Started process 574 to run task
[2023-11-30T17:59:14.482+0000] {standard_task_runner.py:84} INFO - Running: ['airflow', 'tasks', 'run', 'ingest_to_gcs_bucket', 'PostgresToGCS1', 'scheduled__2023-11-27T00:00:00+00:00', '--job-id', '179', '--raw', '--subdir', 'DAGS_FOLDER/postgres_to_gcs_staging.py', '--cfg-path', '/tmp/tmpicc9w780']
[2023-11-30T17:59:14.484+0000] {standard_task_runner.py:85} INFO - Job 179: Subtask PostgresToGCS1
[2023-11-30T17:59:14.552+0000] {task_command.py:416} INFO - Running <TaskInstance: ingest_to_gcs_bucket.PostgresToGCS1 scheduled__2023-11-27T00:00:00+00:00 [running]> on host d9318cdc880c
[2023-11-30T17:59:14.764+0000] {taskinstance.py:1662} INFO - Exporting env vars: AIRFLOW_CTX_DAG_EMAIL='franklinmutwiri41@gmail.com' AIRFLOW_CTX_DAG_OWNER='airflow' AIRFLOW_CTX_DAG_ID='ingest_to_gcs_bucket' AIRFLOW_CTX_TASK_ID='PostgresToGCS1' AIRFLOW_CTX_EXECUTION_DATE='2023-11-27T00:00:00+00:00' AIRFLOW_CTX_TRY_NUMBER='1' AIRFLOW_CTX_DAG_RUN_ID='scheduled__2023-11-27T00:00:00+00:00'
[2023-11-30T17:59:14.781+0000] {connection.py:232} WARNING - Connection schemes (type: google_cloud_platform) shall not contain '_' according to RFC3986.
[2023-11-30T17:59:14.783+0000] {base.py:73} INFO - Using connection ID 'google_cloud_default' for task execution.
[2023-11-30T17:59:14.796+0000] {base.py:73} INFO - Using connection ID 'postgres_docker_conn' for task execution.
[2023-11-30T17:59:14.812+0000] {base.py:73} INFO - Using connection ID 'postgres_docker_conn' for task execution.
[2023-11-30T17:59:14.867+0000] {postgres_to_gcs_staging.py:41} INFO - Uploading to bucket, course.csv
[2023-11-30T17:59:14.868+0000] {taskinstance.py:1937} ERROR - Task failed with exception
Traceback (most recent call last):
  File "/home/airflow/.local/lib/python3.8/site-packages/airflow/operators/python.py", line 192, in execute
    return_value = self.execute_callable()
  File "/home/airflow/.local/lib/python3.8/site-packages/airflow/operators/python.py", line 209, in execute_callable
    return self.python_callable(*self.op_args, **self.op_kwargs)
  File "/opt/airflow/dags/postgres_to_gcs_staging.py", line 42, in Postgres_To_GCS1
    gcs_hook.upload(BUCKET, GS_PATH +table + ".csv", table + ".csv")
  File "/home/airflow/.local/lib/python3.8/site-packages/airflow/providers/google/cloud/hooks/gcs.py", line 530, in upload
    client = self.get_conn()
  File "/home/airflow/.local/lib/python3.8/site-packages/airflow/providers/google/cloud/hooks/gcs.py", line 173, in get_conn
    credentials=self.get_credentials(), client_info=CLIENT_INFO, project=self.project_id
  File "/home/airflow/.local/lib/python3.8/site-packages/airflow/providers/google/common/hooks/base_google.py", line 296, in get_credentials
    credentials, _ = self.get_credentials_and_project_id()
  File "/home/airflow/.local/lib/python3.8/site-packages/airflow/providers/google/common/hooks/base_google.py", line 273, in get_credentials_and_project_id
    credentials, project_id = get_credentials_and_project_id(
  File "/home/airflow/.local/lib/python3.8/site-packages/airflow/providers/google/cloud/utils/credentials_provider.py", line 362, in get_credentials_and_project_id
    return _CredentialProvider(*args, **kwargs).get_credentials_and_project()
  File "/home/airflow/.local/lib/python3.8/site-packages/airflow/providers/google/cloud/utils/credentials_provider.py", line 235, in get_credentials_and_project
    credentials, project_id = self._get_credentials_using_key_path()
  File "/home/airflow/.local/lib/python3.8/site-packages/airflow/providers/google/cloud/utils/credentials_provider.py", line 286, in _get_credentials_using_key_path
    credentials = google.oauth2.service_account.Credentials.from_service_account_file(
  File "/home/airflow/.local/lib/python3.8/site-packages/google/oauth2/service_account.py", line 260, in from_service_account_file
    info, signer = _service_account_info.from_filename(
  File "/home/airflow/.local/lib/python3.8/site-packages/google/auth/_service_account_info.py", line 78, in from_filename
    with io.open(filename, "r", encoding="utf-8") as json_file:
FileNotFoundError: [Errno 2] No such file or directory: 'home/mutwiri/gcp/data-warehousing-proj-41aeaea29c3d.json'
[2023-11-30T17:59:14.883+0000] {taskinstance.py:1400} INFO - Marking task as UP_FOR_RETRY. dag_id=ingest_to_gcs_bucket, task_id=PostgresToGCS1, execution_date=20231127T000000, start_date=20231130T175914, end_date=20231130T175914
[2023-11-30T17:59:14.902+0000] {logging_mixin.py:151} WARNING - /home/***/.local/lib/python3.8/site-packages/***/utils/email.py:154 RemovedInAirflow3Warning: Fetching SMTP credentials from configuration variables will be deprecated in a future release. Please set credentials using a connection instead.
[2023-11-30T17:59:14.902+0000] {configuration.py:1068} WARNING - section/key [smtp/smtp_user] not found in config
[2023-11-30T17:59:14.902+0000] {email.py:270} INFO - Email alerting: attempt 1
[2023-11-30T17:59:14.914+0000] {configuration.py:1068} WARNING - section/key [smtp/smtp_user] not found in config
[2023-11-30T17:59:14.915+0000] {email.py:270} INFO - Email alerting: attempt 1
[2023-11-30T17:59:14.915+0000] {taskinstance.py:2007} ERROR - Failed to send email to: ['franklinmutwiri41@gmail.com']
Traceback (most recent call last):
  File "/home/airflow/.local/lib/python3.8/site-packages/airflow/models/taskinstance.py", line 1518, in _run_raw_task
    self._execute_task_with_callbacks(context, test_mode, session=session)
  File "/home/airflow/.local/lib/python3.8/site-packages/airflow/models/taskinstance.py", line 1681, in _execute_task_with_callbacks
    result = self._execute_task(context, task_orig)
  File "/home/airflow/.local/lib/python3.8/site-packages/airflow/models/taskinstance.py", line 1744, in _execute_task
    result = execute_callable(context=context, **execute_callable_kwargs)
  File "/home/airflow/.local/lib/python3.8/site-packages/airflow/operators/python.py", line 192, in execute
    return_value = self.execute_callable()
  File "/home/airflow/.local/lib/python3.8/site-packages/airflow/operators/python.py", line 209, in execute_callable
    return self.python_callable(*self.op_args, **self.op_kwargs)
  File "/opt/airflow/dags/postgres_to_gcs_staging.py", line 42, in Postgres_To_GCS1
    gcs_hook.upload(BUCKET, GS_PATH +table + ".csv", table + ".csv")
  File "/home/airflow/.local/lib/python3.8/site-packages/airflow/providers/google/cloud/hooks/gcs.py", line 530, in upload
    client = self.get_conn()
  File "/home/airflow/.local/lib/python3.8/site-packages/airflow/providers/google/cloud/hooks/gcs.py", line 173, in get_conn
    credentials=self.get_credentials(), client_info=CLIENT_INFO, project=self.project_id
  File "/home/airflow/.local/lib/python3.8/site-packages/airflow/providers/google/common/hooks/base_google.py", line 296, in get_credentials
    credentials, _ = self.get_credentials_and_project_id()
  File "/home/airflow/.local/lib/python3.8/site-packages/airflow/providers/google/common/hooks/base_google.py", line 273, in get_credentials_and_project_id
    credentials, project_id = get_credentials_and_project_id(
  File "/home/airflow/.local/lib/python3.8/site-packages/airflow/providers/google/cloud/utils/credentials_provider.py", line 362, in get_credentials_and_project_id
    return _CredentialProvider(*args, **kwargs).get_credentials_and_project()
  File "/home/airflow/.local/lib/python3.8/site-packages/airflow/providers/google/cloud/utils/credentials_provider.py", line 235, in get_credentials_and_project
    credentials, project_id = self._get_credentials_using_key_path()
  File "/home/airflow/.local/lib/python3.8/site-packages/airflow/providers/google/cloud/utils/credentials_provider.py", line 286, in _get_credentials_using_key_path
    credentials = google.oauth2.service_account.Credentials.from_service_account_file(
  File "/home/airflow/.local/lib/python3.8/site-packages/google/oauth2/service_account.py", line 260, in from_service_account_file
    info, signer = _service_account_info.from_filename(
  File "/home/airflow/.local/lib/python3.8/site-packages/google/auth/_service_account_info.py", line 78, in from_filename
    with io.open(filename, "r", encoding="utf-8") as json_file:
FileNotFoundError: [Errno 2] No such file or directory: 'home/mutwiri/gcp/data-warehousing-proj-41aeaea29c3d.json'

During handling of the above exception, another exception occurred:

Traceback (most recent call last):
  File "/home/airflow/.local/lib/python3.8/site-packages/airflow/models/taskinstance.py", line 2420, in email_alert
    send_email(task.email, subject, html_content)
  File "/home/airflow/.local/lib/python3.8/site-packages/airflow/utils/email.py", line 80, in send_email
    return backend(
  File "/home/airflow/.local/lib/python3.8/site-packages/airflow/utils/email.py", line 154, in send_email_smtp
    send_mime_email(e_from=mail_from, e_to=recipients, mime_msg=msg, conn_id=conn_id, dryrun=dryrun)
  File "/home/airflow/.local/lib/python3.8/site-packages/airflow/utils/email.py", line 272, in send_mime_email
    smtp_conn = _get_smtp_connection(smtp_host, smtp_port, smtp_timeout, smtp_ssl)
  File "/home/airflow/.local/lib/python3.8/site-packages/airflow/utils/email.py", line 316, in _get_smtp_connection
    return smtplib.SMTP(host=host, port=port, timeout=timeout)
  File "/usr/local/lib/python3.8/smtplib.py", line 255, in __init__
    (code, msg) = self.connect(host, port)
  File "/usr/local/lib/python3.8/smtplib.py", line 339, in connect
    self.sock = self._get_socket(host, port, self.timeout)
  File "/usr/local/lib/python3.8/smtplib.py", line 310, in _get_socket
    return socket.create_connection((host, port), timeout,
  File "/usr/local/lib/python3.8/socket.py", line 808, in create_connection
    raise err
  File "/usr/local/lib/python3.8/socket.py", line 796, in create_connection
    sock.connect(sa)
OSError: [Errno 99] Cannot assign requested address

During handling of the above exception, another exception occurred:

Traceback (most recent call last):
  File "/home/airflow/.local/lib/python3.8/site-packages/airflow/models/taskinstance.py", line 2005, in handle_failure
    self.email_alert(error, task)
  File "/home/airflow/.local/lib/python3.8/site-packages/airflow/models/taskinstance.py", line 2422, in email_alert
    send_email(task.email, subject, html_content_err)
  File "/home/airflow/.local/lib/python3.8/site-packages/airflow/utils/email.py", line 80, in send_email
    return backend(
  File "/home/airflow/.local/lib/python3.8/site-packages/airflow/utils/email.py", line 154, in send_email_smtp
    send_mime_email(e_from=mail_from, e_to=recipients, mime_msg=msg, conn_id=conn_id, dryrun=dryrun)
  File "/home/airflow/.local/lib/python3.8/site-packages/airflow/utils/email.py", line 272, in send_mime_email
    smtp_conn = _get_smtp_connection(smtp_host, smtp_port, smtp_timeout, smtp_ssl)
  File "/home/airflow/.local/lib/python3.8/site-packages/airflow/utils/email.py", line 316, in _get_smtp_connection
    return smtplib.SMTP(host=host, port=port, timeout=timeout)
  File "/usr/local/lib/python3.8/smtplib.py", line 255, in __init__
    (code, msg) = self.connect(host, port)
  File "/usr/local/lib/python3.8/smtplib.py", line 339, in connect
    self.sock = self._get_socket(host, port, self.timeout)
  File "/usr/local/lib/python3.8/smtplib.py", line 310, in _get_socket
    return socket.create_connection((host, port), timeout,
  File "/usr/local/lib/python3.8/socket.py", line 808, in create_connection
    raise err
  File "/usr/local/lib/python3.8/socket.py", line 796, in create_connection
    sock.connect(sa)
OSError: [Errno 99] Cannot assign requested address
[2023-11-30T17:59:14.993+0000] {standard_task_runner.py:104} ERROR - Failed to execute job 179 for task PostgresToGCS1 ([Errno 2] No such file or directory: 'home/mutwiri/gcp/data-warehousing-proj-41aeaea29c3d.json'; 574)
[2023-11-30T17:59:15.015+0000] {local_task_job_runner.py:228} INFO - Task exited with return code 1
[2023-11-30T17:59:15.054+0000] {taskinstance.py:2778} INFO - 0 downstream tasks scheduled from follow-on schedule check
[2023-11-30T18:06:16.712+0000] {taskinstance.py:1159} INFO - Dependencies all met for dep_context=non-requeueable deps ti=<TaskInstance: ingest_to_gcs_bucket.PostgresToGCS1 scheduled__2023-11-27T00:00:00+00:00 [queued]>
[2023-11-30T18:06:16.745+0000] {taskinstance.py:1159} INFO - Dependencies all met for dep_context=requeueable deps ti=<TaskInstance: ingest_to_gcs_bucket.PostgresToGCS1 scheduled__2023-11-27T00:00:00+00:00 [queued]>
[2023-11-30T18:06:16.745+0000] {taskinstance.py:1361} INFO - Starting attempt 1 of 3
[2023-11-30T18:06:16.858+0000] {taskinstance.py:1382} INFO - Executing <Task(PythonOperator): PostgresToGCS1> on 2023-11-27 00:00:00+00:00
[2023-11-30T18:06:16.880+0000] {standard_task_runner.py:57} INFO - Started process 750 to run task
[2023-11-30T18:06:16.886+0000] {standard_task_runner.py:84} INFO - Running: ['airflow', 'tasks', 'run', 'ingest_to_gcs_bucket', 'PostgresToGCS1', 'scheduled__2023-11-27T00:00:00+00:00', '--job-id', '182', '--raw', '--subdir', 'DAGS_FOLDER/postgres_to_gcs_staging.py', '--cfg-path', '/tmp/tmpmhf42rp0']
[2023-11-30T18:06:16.900+0000] {standard_task_runner.py:85} INFO - Job 182: Subtask PostgresToGCS1
[2023-11-30T18:06:17.137+0000] {task_command.py:416} INFO - Running <TaskInstance: ingest_to_gcs_bucket.PostgresToGCS1 scheduled__2023-11-27T00:00:00+00:00 [running]> on host d9318cdc880c
[2023-11-30T18:06:17.455+0000] {taskinstance.py:1662} INFO - Exporting env vars: AIRFLOW_CTX_DAG_EMAIL='franklinmutwiri41@gmail.com' AIRFLOW_CTX_DAG_OWNER='airflow' AIRFLOW_CTX_DAG_ID='ingest_to_gcs_bucket' AIRFLOW_CTX_TASK_ID='PostgresToGCS1' AIRFLOW_CTX_EXECUTION_DATE='2023-11-27T00:00:00+00:00' AIRFLOW_CTX_TRY_NUMBER='1' AIRFLOW_CTX_DAG_RUN_ID='scheduled__2023-11-27T00:00:00+00:00'
[2023-11-30T18:06:17.486+0000] {connection.py:232} WARNING - Connection schemes (type: google_cloud_platform) shall not contain '_' according to RFC3986.
[2023-11-30T18:06:17.488+0000] {base.py:73} INFO - Using connection ID 'google_cloud_default' for task execution.
[2023-11-30T18:06:17.528+0000] {base.py:73} INFO - Using connection ID 'postgres_docker_conn' for task execution.
[2023-11-30T18:06:17.557+0000] {base.py:73} INFO - Using connection ID 'postgres_docker_conn' for task execution.
[2023-11-30T18:06:17.599+0000] {postgres_to_gcs_staging.py:41} INFO - Uploading to bucket, course.csv
[2023-11-30T18:06:17.600+0000] {taskinstance.py:1937} ERROR - Task failed with exception
Traceback (most recent call last):
  File "/home/airflow/.local/lib/python3.8/site-packages/airflow/operators/python.py", line 192, in execute
    return_value = self.execute_callable()
  File "/home/airflow/.local/lib/python3.8/site-packages/airflow/operators/python.py", line 209, in execute_callable
    return self.python_callable(*self.op_args, **self.op_kwargs)
  File "/opt/airflow/dags/postgres_to_gcs_staging.py", line 42, in Postgres_To_GCS1
    gcs_hook.upload(BUCKET, GS_PATH +table + ".csv", table + ".csv")
  File "/home/airflow/.local/lib/python3.8/site-packages/airflow/providers/google/cloud/hooks/gcs.py", line 530, in upload
    client = self.get_conn()
  File "/home/airflow/.local/lib/python3.8/site-packages/airflow/providers/google/cloud/hooks/gcs.py", line 173, in get_conn
    credentials=self.get_credentials(), client_info=CLIENT_INFO, project=self.project_id
  File "/home/airflow/.local/lib/python3.8/site-packages/airflow/providers/google/common/hooks/base_google.py", line 296, in get_credentials
    credentials, _ = self.get_credentials_and_project_id()
  File "/home/airflow/.local/lib/python3.8/site-packages/airflow/providers/google/common/hooks/base_google.py", line 273, in get_credentials_and_project_id
    credentials, project_id = get_credentials_and_project_id(
  File "/home/airflow/.local/lib/python3.8/site-packages/airflow/providers/google/cloud/utils/credentials_provider.py", line 362, in get_credentials_and_project_id
    return _CredentialProvider(*args, **kwargs).get_credentials_and_project()
  File "/home/airflow/.local/lib/python3.8/site-packages/airflow/providers/google/cloud/utils/credentials_provider.py", line 235, in get_credentials_and_project
    credentials, project_id = self._get_credentials_using_key_path()
  File "/home/airflow/.local/lib/python3.8/site-packages/airflow/providers/google/cloud/utils/credentials_provider.py", line 286, in _get_credentials_using_key_path
    credentials = google.oauth2.service_account.Credentials.from_service_account_file(
  File "/home/airflow/.local/lib/python3.8/site-packages/google/oauth2/service_account.py", line 260, in from_service_account_file
    info, signer = _service_account_info.from_filename(
  File "/home/airflow/.local/lib/python3.8/site-packages/google/auth/_service_account_info.py", line 78, in from_filename
    with io.open(filename, "r", encoding="utf-8") as json_file:
FileNotFoundError: [Errno 2] No such file or directory: '/home/mutwiri/gcp/data-warehousing-proj-41aeaea29c3d.json'
[2023-11-30T18:06:17.705+0000] {taskinstance.py:1400} INFO - Marking task as UP_FOR_RETRY. dag_id=ingest_to_gcs_bucket, task_id=PostgresToGCS1, execution_date=20231127T000000, start_date=20231130T180616, end_date=20231130T180617
[2023-11-30T18:06:17.783+0000] {logging_mixin.py:151} WARNING - /home/***/.local/lib/python3.8/site-packages/***/utils/email.py:154 RemovedInAirflow3Warning: Fetching SMTP credentials from configuration variables will be deprecated in a future release. Please set credentials using a connection instead.
[2023-11-30T18:06:17.784+0000] {configuration.py:1068} WARNING - section/key [smtp/smtp_user] not found in config
[2023-11-30T18:06:17.784+0000] {email.py:270} INFO - Email alerting: attempt 1
[2023-11-30T18:06:17.824+0000] {configuration.py:1068} WARNING - section/key [smtp/smtp_user] not found in config
[2023-11-30T18:06:17.824+0000] {email.py:270} INFO - Email alerting: attempt 1
[2023-11-30T18:06:17.825+0000] {taskinstance.py:2007} ERROR - Failed to send email to: ['franklinmutwiri41@gmail.com']
Traceback (most recent call last):
  File "/home/airflow/.local/lib/python3.8/site-packages/airflow/models/taskinstance.py", line 1518, in _run_raw_task
    self._execute_task_with_callbacks(context, test_mode, session=session)
  File "/home/airflow/.local/lib/python3.8/site-packages/airflow/models/taskinstance.py", line 1681, in _execute_task_with_callbacks
    result = self._execute_task(context, task_orig)
  File "/home/airflow/.local/lib/python3.8/site-packages/airflow/models/taskinstance.py", line 1744, in _execute_task
    result = execute_callable(context=context, **execute_callable_kwargs)
  File "/home/airflow/.local/lib/python3.8/site-packages/airflow/operators/python.py", line 192, in execute
    return_value = self.execute_callable()
  File "/home/airflow/.local/lib/python3.8/site-packages/airflow/operators/python.py", line 209, in execute_callable
    return self.python_callable(*self.op_args, **self.op_kwargs)
  File "/opt/airflow/dags/postgres_to_gcs_staging.py", line 42, in Postgres_To_GCS1
    gcs_hook.upload(BUCKET, GS_PATH +table + ".csv", table + ".csv")
  File "/home/airflow/.local/lib/python3.8/site-packages/airflow/providers/google/cloud/hooks/gcs.py", line 530, in upload
    client = self.get_conn()
  File "/home/airflow/.local/lib/python3.8/site-packages/airflow/providers/google/cloud/hooks/gcs.py", line 173, in get_conn
    credentials=self.get_credentials(), client_info=CLIENT_INFO, project=self.project_id
  File "/home/airflow/.local/lib/python3.8/site-packages/airflow/providers/google/common/hooks/base_google.py", line 296, in get_credentials
    credentials, _ = self.get_credentials_and_project_id()
  File "/home/airflow/.local/lib/python3.8/site-packages/airflow/providers/google/common/hooks/base_google.py", line 273, in get_credentials_and_project_id
    credentials, project_id = get_credentials_and_project_id(
  File "/home/airflow/.local/lib/python3.8/site-packages/airflow/providers/google/cloud/utils/credentials_provider.py", line 362, in get_credentials_and_project_id
    return _CredentialProvider(*args, **kwargs).get_credentials_and_project()
  File "/home/airflow/.local/lib/python3.8/site-packages/airflow/providers/google/cloud/utils/credentials_provider.py", line 235, in get_credentials_and_project
    credentials, project_id = self._get_credentials_using_key_path()
  File "/home/airflow/.local/lib/python3.8/site-packages/airflow/providers/google/cloud/utils/credentials_provider.py", line 286, in _get_credentials_using_key_path
    credentials = google.oauth2.service_account.Credentials.from_service_account_file(
  File "/home/airflow/.local/lib/python3.8/site-packages/google/oauth2/service_account.py", line 260, in from_service_account_file
    info, signer = _service_account_info.from_filename(
  File "/home/airflow/.local/lib/python3.8/site-packages/google/auth/_service_account_info.py", line 78, in from_filename
    with io.open(filename, "r", encoding="utf-8") as json_file:
FileNotFoundError: [Errno 2] No such file or directory: '/home/mutwiri/gcp/data-warehousing-proj-41aeaea29c3d.json'

During handling of the above exception, another exception occurred:

Traceback (most recent call last):
  File "/home/airflow/.local/lib/python3.8/site-packages/airflow/models/taskinstance.py", line 2420, in email_alert
    send_email(task.email, subject, html_content)
  File "/home/airflow/.local/lib/python3.8/site-packages/airflow/utils/email.py", line 80, in send_email
    return backend(
  File "/home/airflow/.local/lib/python3.8/site-packages/airflow/utils/email.py", line 154, in send_email_smtp
    send_mime_email(e_from=mail_from, e_to=recipients, mime_msg=msg, conn_id=conn_id, dryrun=dryrun)
  File "/home/airflow/.local/lib/python3.8/site-packages/airflow/utils/email.py", line 272, in send_mime_email
    smtp_conn = _get_smtp_connection(smtp_host, smtp_port, smtp_timeout, smtp_ssl)
  File "/home/airflow/.local/lib/python3.8/site-packages/airflow/utils/email.py", line 316, in _get_smtp_connection
    return smtplib.SMTP(host=host, port=port, timeout=timeout)
  File "/usr/local/lib/python3.8/smtplib.py", line 255, in __init__
    (code, msg) = self.connect(host, port)
  File "/usr/local/lib/python3.8/smtplib.py", line 339, in connect
    self.sock = self._get_socket(host, port, self.timeout)
  File "/usr/local/lib/python3.8/smtplib.py", line 310, in _get_socket
    return socket.create_connection((host, port), timeout,
  File "/usr/local/lib/python3.8/socket.py", line 808, in create_connection
    raise err
  File "/usr/local/lib/python3.8/socket.py", line 796, in create_connection
    sock.connect(sa)
OSError: [Errno 99] Cannot assign requested address

During handling of the above exception, another exception occurred:

Traceback (most recent call last):
  File "/home/airflow/.local/lib/python3.8/site-packages/airflow/models/taskinstance.py", line 2005, in handle_failure
    self.email_alert(error, task)
  File "/home/airflow/.local/lib/python3.8/site-packages/airflow/models/taskinstance.py", line 2422, in email_alert
    send_email(task.email, subject, html_content_err)
  File "/home/airflow/.local/lib/python3.8/site-packages/airflow/utils/email.py", line 80, in send_email
    return backend(
  File "/home/airflow/.local/lib/python3.8/site-packages/airflow/utils/email.py", line 154, in send_email_smtp
    send_mime_email(e_from=mail_from, e_to=recipients, mime_msg=msg, conn_id=conn_id, dryrun=dryrun)
  File "/home/airflow/.local/lib/python3.8/site-packages/airflow/utils/email.py", line 272, in send_mime_email
    smtp_conn = _get_smtp_connection(smtp_host, smtp_port, smtp_timeout, smtp_ssl)
  File "/home/airflow/.local/lib/python3.8/site-packages/airflow/utils/email.py", line 316, in _get_smtp_connection
    return smtplib.SMTP(host=host, port=port, timeout=timeout)
  File "/usr/local/lib/python3.8/smtplib.py", line 255, in __init__
    (code, msg) = self.connect(host, port)
  File "/usr/local/lib/python3.8/smtplib.py", line 339, in connect
    self.sock = self._get_socket(host, port, self.timeout)
  File "/usr/local/lib/python3.8/smtplib.py", line 310, in _get_socket
    return socket.create_connection((host, port), timeout,
  File "/usr/local/lib/python3.8/socket.py", line 808, in create_connection
    raise err
  File "/usr/local/lib/python3.8/socket.py", line 796, in create_connection
    sock.connect(sa)
OSError: [Errno 99] Cannot assign requested address
[2023-11-30T18:06:17.893+0000] {standard_task_runner.py:104} ERROR - Failed to execute job 182 for task PostgresToGCS1 ([Errno 2] No such file or directory: '/home/mutwiri/gcp/data-warehousing-proj-41aeaea29c3d.json'; 750)
[2023-11-30T18:06:17.947+0000] {local_task_job_runner.py:228} INFO - Task exited with return code 1
[2023-11-30T18:06:18.009+0000] {taskinstance.py:2778} INFO - 0 downstream tasks scheduled from follow-on schedule check
[2023-11-30T18:57:05.567+0000] {taskinstance.py:1159} INFO - Dependencies all met for dep_context=non-requeueable deps ti=<TaskInstance: ingest_to_gcs_bucket.PostgresToGCS1 scheduled__2023-11-27T00:00:00+00:00 [queued]>
[2023-11-30T18:57:05.591+0000] {taskinstance.py:1159} INFO - Dependencies all met for dep_context=requeueable deps ti=<TaskInstance: ingest_to_gcs_bucket.PostgresToGCS1 scheduled__2023-11-27T00:00:00+00:00 [queued]>
[2023-11-30T18:57:05.592+0000] {taskinstance.py:1361} INFO - Starting attempt 1 of 3
[2023-11-30T18:57:05.617+0000] {taskinstance.py:1382} INFO - Executing <Task(PythonOperator): PostgresToGCS1> on 2023-11-27 00:00:00+00:00
[2023-11-30T18:57:05.622+0000] {standard_task_runner.py:57} INFO - Started process 485 to run task
[2023-11-30T18:57:05.626+0000] {standard_task_runner.py:84} INFO - Running: ['airflow', 'tasks', 'run', 'ingest_to_gcs_bucket', 'PostgresToGCS1', 'scheduled__2023-11-27T00:00:00+00:00', '--job-id', '186', '--raw', '--subdir', 'DAGS_FOLDER/postgres_to_gcs_staging.py', '--cfg-path', '/tmp/tmpc8ezst91']
[2023-11-30T18:57:05.629+0000] {standard_task_runner.py:85} INFO - Job 186: Subtask PostgresToGCS1
[2023-11-30T18:57:05.717+0000] {task_command.py:416} INFO - Running <TaskInstance: ingest_to_gcs_bucket.PostgresToGCS1 scheduled__2023-11-27T00:00:00+00:00 [running]> on host d9318cdc880c
[2023-11-30T18:57:05.832+0000] {taskinstance.py:1662} INFO - Exporting env vars: AIRFLOW_CTX_DAG_EMAIL='franklinmutwiri41@gmail.com' AIRFLOW_CTX_DAG_OWNER='airflow' AIRFLOW_CTX_DAG_ID='ingest_to_gcs_bucket' AIRFLOW_CTX_TASK_ID='PostgresToGCS1' AIRFLOW_CTX_EXECUTION_DATE='2023-11-27T00:00:00+00:00' AIRFLOW_CTX_TRY_NUMBER='1' AIRFLOW_CTX_DAG_RUN_ID='scheduled__2023-11-27T00:00:00+00:00'
[2023-11-30T18:57:05.849+0000] {connection.py:232} WARNING - Connection schemes (type: google_cloud_platform) shall not contain '_' according to RFC3986.
[2023-11-30T18:57:05.851+0000] {base.py:73} INFO - Using connection ID 'google_cloud_default' for task execution.
[2023-11-30T18:57:05.866+0000] {base.py:73} INFO - Using connection ID 'postgres_docker_conn' for task execution.
[2023-11-30T18:57:05.878+0000] {base.py:73} INFO - Using connection ID 'postgres_docker_conn' for task execution.
[2023-11-30T18:57:05.926+0000] {postgres_to_gcs_staging.py:41} INFO - Uploading to bucket, course.csv
[2023-11-30T18:57:05.935+0000] {taskinstance.py:1937} ERROR - Task failed with exception
Traceback (most recent call last):
  File "/home/airflow/.local/lib/python3.8/site-packages/airflow/operators/python.py", line 192, in execute
    return_value = self.execute_callable()
  File "/home/airflow/.local/lib/python3.8/site-packages/airflow/operators/python.py", line 209, in execute_callable
    return self.python_callable(*self.op_args, **self.op_kwargs)
  File "/opt/airflow/dags/postgres_to_gcs_staging.py", line 42, in Postgres_To_GCS1
    gcs_hook.upload(BUCKET, GS_PATH +table + ".csv", table + ".csv")
  File "/home/airflow/.local/lib/python3.8/site-packages/airflow/providers/google/cloud/hooks/gcs.py", line 530, in upload
    client = self.get_conn()
  File "/home/airflow/.local/lib/python3.8/site-packages/airflow/providers/google/cloud/hooks/gcs.py", line 173, in get_conn
    credentials=self.get_credentials(), client_info=CLIENT_INFO, project=self.project_id
  File "/home/airflow/.local/lib/python3.8/site-packages/airflow/providers/google/common/hooks/base_google.py", line 296, in get_credentials
    credentials, _ = self.get_credentials_and_project_id()
  File "/home/airflow/.local/lib/python3.8/site-packages/airflow/providers/google/common/hooks/base_google.py", line 273, in get_credentials_and_project_id
    credentials, project_id = get_credentials_and_project_id(
  File "/home/airflow/.local/lib/python3.8/site-packages/airflow/providers/google/cloud/utils/credentials_provider.py", line 362, in get_credentials_and_project_id
    return _CredentialProvider(*args, **kwargs).get_credentials_and_project()
  File "/home/airflow/.local/lib/python3.8/site-packages/airflow/providers/google/cloud/utils/credentials_provider.py", line 235, in get_credentials_and_project
    credentials, project_id = self._get_credentials_using_key_path()
  File "/home/airflow/.local/lib/python3.8/site-packages/airflow/providers/google/cloud/utils/credentials_provider.py", line 286, in _get_credentials_using_key_path
    credentials = google.oauth2.service_account.Credentials.from_service_account_file(
  File "/home/airflow/.local/lib/python3.8/site-packages/google/oauth2/service_account.py", line 260, in from_service_account_file
    info, signer = _service_account_info.from_filename(
  File "/home/airflow/.local/lib/python3.8/site-packages/google/auth/_service_account_info.py", line 78, in from_filename
    with io.open(filename, "r", encoding="utf-8") as json_file:
FileNotFoundError: [Errno 2] No such file or directory: '/home/mutwiri/gcp/data-warehousing-proj-41aeaea29c3d.json'
[2023-11-30T18:57:05.971+0000] {taskinstance.py:1400} INFO - Marking task as UP_FOR_RETRY. dag_id=ingest_to_gcs_bucket, task_id=PostgresToGCS1, execution_date=20231127T000000, start_date=20231130T185705, end_date=20231130T185705
[2023-11-30T18:57:05.992+0000] {logging_mixin.py:151} WARNING - /home/***/.local/lib/python3.8/site-packages/***/utils/email.py:154 RemovedInAirflow3Warning: Fetching SMTP credentials from configuration variables will be deprecated in a future release. Please set credentials using a connection instead.
[2023-11-30T18:57:05.993+0000] {configuration.py:1068} WARNING - section/key [smtp/smtp_user] not found in config
[2023-11-30T18:57:05.993+0000] {email.py:270} INFO - Email alerting: attempt 1
[2023-11-30T18:57:06.006+0000] {configuration.py:1068} WARNING - section/key [smtp/smtp_user] not found in config
[2023-11-30T18:57:06.007+0000] {email.py:270} INFO - Email alerting: attempt 1
[2023-11-30T18:57:06.007+0000] {taskinstance.py:2007} ERROR - Failed to send email to: ['franklinmutwiri41@gmail.com']
Traceback (most recent call last):
  File "/home/airflow/.local/lib/python3.8/site-packages/airflow/models/taskinstance.py", line 1518, in _run_raw_task
    self._execute_task_with_callbacks(context, test_mode, session=session)
  File "/home/airflow/.local/lib/python3.8/site-packages/airflow/models/taskinstance.py", line 1681, in _execute_task_with_callbacks
    result = self._execute_task(context, task_orig)
  File "/home/airflow/.local/lib/python3.8/site-packages/airflow/models/taskinstance.py", line 1744, in _execute_task
    result = execute_callable(context=context, **execute_callable_kwargs)
  File "/home/airflow/.local/lib/python3.8/site-packages/airflow/operators/python.py", line 192, in execute
    return_value = self.execute_callable()
  File "/home/airflow/.local/lib/python3.8/site-packages/airflow/operators/python.py", line 209, in execute_callable
    return self.python_callable(*self.op_args, **self.op_kwargs)
  File "/opt/airflow/dags/postgres_to_gcs_staging.py", line 42, in Postgres_To_GCS1
    gcs_hook.upload(BUCKET, GS_PATH +table + ".csv", table + ".csv")
  File "/home/airflow/.local/lib/python3.8/site-packages/airflow/providers/google/cloud/hooks/gcs.py", line 530, in upload
    client = self.get_conn()
  File "/home/airflow/.local/lib/python3.8/site-packages/airflow/providers/google/cloud/hooks/gcs.py", line 173, in get_conn
    credentials=self.get_credentials(), client_info=CLIENT_INFO, project=self.project_id
  File "/home/airflow/.local/lib/python3.8/site-packages/airflow/providers/google/common/hooks/base_google.py", line 296, in get_credentials
    credentials, _ = self.get_credentials_and_project_id()
  File "/home/airflow/.local/lib/python3.8/site-packages/airflow/providers/google/common/hooks/base_google.py", line 273, in get_credentials_and_project_id
    credentials, project_id = get_credentials_and_project_id(
  File "/home/airflow/.local/lib/python3.8/site-packages/airflow/providers/google/cloud/utils/credentials_provider.py", line 362, in get_credentials_and_project_id
    return _CredentialProvider(*args, **kwargs).get_credentials_and_project()
  File "/home/airflow/.local/lib/python3.8/site-packages/airflow/providers/google/cloud/utils/credentials_provider.py", line 235, in get_credentials_and_project
    credentials, project_id = self._get_credentials_using_key_path()
  File "/home/airflow/.local/lib/python3.8/site-packages/airflow/providers/google/cloud/utils/credentials_provider.py", line 286, in _get_credentials_using_key_path
    credentials = google.oauth2.service_account.Credentials.from_service_account_file(
  File "/home/airflow/.local/lib/python3.8/site-packages/google/oauth2/service_account.py", line 260, in from_service_account_file
    info, signer = _service_account_info.from_filename(
  File "/home/airflow/.local/lib/python3.8/site-packages/google/auth/_service_account_info.py", line 78, in from_filename
    with io.open(filename, "r", encoding="utf-8") as json_file:
FileNotFoundError: [Errno 2] No such file or directory: '/home/mutwiri/gcp/data-warehousing-proj-41aeaea29c3d.json'

During handling of the above exception, another exception occurred:

Traceback (most recent call last):
  File "/home/airflow/.local/lib/python3.8/site-packages/airflow/models/taskinstance.py", line 2420, in email_alert
    send_email(task.email, subject, html_content)
  File "/home/airflow/.local/lib/python3.8/site-packages/airflow/utils/email.py", line 80, in send_email
    return backend(
  File "/home/airflow/.local/lib/python3.8/site-packages/airflow/utils/email.py", line 154, in send_email_smtp
    send_mime_email(e_from=mail_from, e_to=recipients, mime_msg=msg, conn_id=conn_id, dryrun=dryrun)
  File "/home/airflow/.local/lib/python3.8/site-packages/airflow/utils/email.py", line 272, in send_mime_email
    smtp_conn = _get_smtp_connection(smtp_host, smtp_port, smtp_timeout, smtp_ssl)
  File "/home/airflow/.local/lib/python3.8/site-packages/airflow/utils/email.py", line 316, in _get_smtp_connection
    return smtplib.SMTP(host=host, port=port, timeout=timeout)
  File "/usr/local/lib/python3.8/smtplib.py", line 255, in __init__
    (code, msg) = self.connect(host, port)
  File "/usr/local/lib/python3.8/smtplib.py", line 339, in connect
    self.sock = self._get_socket(host, port, self.timeout)
  File "/usr/local/lib/python3.8/smtplib.py", line 310, in _get_socket
    return socket.create_connection((host, port), timeout,
  File "/usr/local/lib/python3.8/socket.py", line 808, in create_connection
    raise err
  File "/usr/local/lib/python3.8/socket.py", line 796, in create_connection
    sock.connect(sa)
OSError: [Errno 99] Cannot assign requested address

During handling of the above exception, another exception occurred:

Traceback (most recent call last):
  File "/home/airflow/.local/lib/python3.8/site-packages/airflow/models/taskinstance.py", line 2005, in handle_failure
    self.email_alert(error, task)
  File "/home/airflow/.local/lib/python3.8/site-packages/airflow/models/taskinstance.py", line 2422, in email_alert
    send_email(task.email, subject, html_content_err)
  File "/home/airflow/.local/lib/python3.8/site-packages/airflow/utils/email.py", line 80, in send_email
    return backend(
  File "/home/airflow/.local/lib/python3.8/site-packages/airflow/utils/email.py", line 154, in send_email_smtp
    send_mime_email(e_from=mail_from, e_to=recipients, mime_msg=msg, conn_id=conn_id, dryrun=dryrun)
  File "/home/airflow/.local/lib/python3.8/site-packages/airflow/utils/email.py", line 272, in send_mime_email
    smtp_conn = _get_smtp_connection(smtp_host, smtp_port, smtp_timeout, smtp_ssl)
  File "/home/airflow/.local/lib/python3.8/site-packages/airflow/utils/email.py", line 316, in _get_smtp_connection
    return smtplib.SMTP(host=host, port=port, timeout=timeout)
  File "/usr/local/lib/python3.8/smtplib.py", line 255, in __init__
    (code, msg) = self.connect(host, port)
  File "/usr/local/lib/python3.8/smtplib.py", line 339, in connect
    self.sock = self._get_socket(host, port, self.timeout)
  File "/usr/local/lib/python3.8/smtplib.py", line 310, in _get_socket
    return socket.create_connection((host, port), timeout,
  File "/usr/local/lib/python3.8/socket.py", line 808, in create_connection
    raise err
  File "/usr/local/lib/python3.8/socket.py", line 796, in create_connection
    sock.connect(sa)
OSError: [Errno 99] Cannot assign requested address
[2023-11-30T18:57:06.060+0000] {standard_task_runner.py:104} ERROR - Failed to execute job 186 for task PostgresToGCS1 ([Errno 2] No such file or directory: '/home/mutwiri/gcp/data-warehousing-proj-41aeaea29c3d.json'; 485)
[2023-11-30T18:57:06.079+0000] {local_task_job_runner.py:228} INFO - Task exited with return code 1
[2023-11-30T18:57:06.118+0000] {taskinstance.py:2778} INFO - 0 downstream tasks scheduled from follow-on schedule check
[2023-11-30T19:10:19.872+0000] {taskinstance.py:1159} INFO - Dependencies all met for dep_context=non-requeueable deps ti=<TaskInstance: ingest_to_gcs_bucket.PostgresToGCS1 scheduled__2023-11-27T00:00:00+00:00 [queued]>
[2023-11-30T19:10:19.902+0000] {taskinstance.py:1159} INFO - Dependencies all met for dep_context=requeueable deps ti=<TaskInstance: ingest_to_gcs_bucket.PostgresToGCS1 scheduled__2023-11-27T00:00:00+00:00 [queued]>
[2023-11-30T19:10:19.903+0000] {taskinstance.py:1361} INFO - Starting attempt 1 of 3
[2023-11-30T19:10:19.935+0000] {taskinstance.py:1382} INFO - Executing <Task(PythonOperator): PostgresToGCS1> on 2023-11-27 00:00:00+00:00
[2023-11-30T19:10:19.942+0000] {standard_task_runner.py:57} INFO - Started process 809 to run task
[2023-11-30T19:10:19.947+0000] {standard_task_runner.py:84} INFO - Running: ['airflow', 'tasks', 'run', 'ingest_to_gcs_bucket', 'PostgresToGCS1', 'scheduled__2023-11-27T00:00:00+00:00', '--job-id', '192', '--raw', '--subdir', 'DAGS_FOLDER/postgres_to_gcs_staging.py', '--cfg-path', '/tmp/tmpiix0ntly']
[2023-11-30T19:10:19.950+0000] {standard_task_runner.py:85} INFO - Job 192: Subtask PostgresToGCS1
[2023-11-30T19:10:20.038+0000] {task_command.py:416} INFO - Running <TaskInstance: ingest_to_gcs_bucket.PostgresToGCS1 scheduled__2023-11-27T00:00:00+00:00 [running]> on host d9318cdc880c
[2023-11-30T19:10:20.267+0000] {taskinstance.py:1662} INFO - Exporting env vars: AIRFLOW_CTX_DAG_EMAIL='franklinmutwiri41@gmail.com' AIRFLOW_CTX_DAG_OWNER='airflow' AIRFLOW_CTX_DAG_ID='ingest_to_gcs_bucket' AIRFLOW_CTX_TASK_ID='PostgresToGCS1' AIRFLOW_CTX_EXECUTION_DATE='2023-11-27T00:00:00+00:00' AIRFLOW_CTX_TRY_NUMBER='1' AIRFLOW_CTX_DAG_RUN_ID='scheduled__2023-11-27T00:00:00+00:00'
[2023-11-30T19:10:20.284+0000] {connection.py:232} WARNING - Connection schemes (type: google_cloud_platform) shall not contain '_' according to RFC3986.
[2023-11-30T19:10:20.300+0000] {base.py:73} INFO - Using connection ID 'google_cloud_default' for task execution.
[2023-11-30T19:10:20.316+0000] {base.py:73} INFO - Using connection ID 'postgres_docker_conn' for task execution.
[2023-11-30T19:10:20.333+0000] {base.py:73} INFO - Using connection ID 'postgres_docker_conn' for task execution.
[2023-11-30T19:10:20.347+0000] {postgres_to_gcs_staging.py:41} INFO - Uploading to bucket, course.csv
[2023-11-30T19:10:20.522+0000] {taskinstance.py:1937} ERROR - Task failed with exception
Traceback (most recent call last):
  File "/home/airflow/.local/lib/python3.8/site-packages/airflow/operators/python.py", line 192, in execute
    return_value = self.execute_callable()
  File "/home/airflow/.local/lib/python3.8/site-packages/airflow/operators/python.py", line 209, in execute_callable
    return self.python_callable(*self.op_args, **self.op_kwargs)
  File "/opt/airflow/dags/postgres_to_gcs_staging.py", line 42, in Postgres_To_GCS1
    gcs_hook.upload(BUCKET, GS_PATH +table + ".csv", table + ".csv")
  File "/home/airflow/.local/lib/python3.8/site-packages/airflow/providers/google/cloud/hooks/gcs.py", line 556, in upload
    _call_with_retry(
  File "/home/airflow/.local/lib/python3.8/site-packages/airflow/providers/google/cloud/hooks/gcs.py", line 514, in _call_with_retry
    f()
  File "/home/airflow/.local/lib/python3.8/site-packages/google/cloud/storage/blob.py", line 2924, in upload_from_filename
    self._handle_filename_and_upload(
  File "/home/airflow/.local/lib/python3.8/site-packages/google/cloud/storage/blob.py", line 2794, in _handle_filename_and_upload
    self._prep_and_do_upload(
  File "/home/airflow/.local/lib/python3.8/site-packages/google/cloud/storage/blob.py", line 2602, in _prep_and_do_upload
    created_json = self._do_upload(
  File "/home/airflow/.local/lib/python3.8/site-packages/google/cloud/storage/blob.py", line 2408, in _do_upload
    response = self._do_multipart_upload(
  File "/home/airflow/.local/lib/python3.8/site-packages/google/cloud/storage/blob.py", line 1879, in _do_multipart_upload
    hostname=hostname, bucket_path=self.bucket.path, api_version=_API_VERSION
  File "/home/airflow/.local/lib/python3.8/site-packages/google/cloud/storage/bucket.py", line 1167, in path
    raise ValueError("Cannot determine path without bucket name.")
ValueError: Cannot determine path without bucket name.
[2023-11-30T19:10:20.567+0000] {taskinstance.py:1400} INFO - Marking task as UP_FOR_RETRY. dag_id=ingest_to_gcs_bucket, task_id=PostgresToGCS1, execution_date=20231127T000000, start_date=20231130T191019, end_date=20231130T191020
[2023-11-30T19:10:20.588+0000] {logging_mixin.py:151} WARNING - /home/***/.local/lib/python3.8/site-packages/***/utils/email.py:154 RemovedInAirflow3Warning: Fetching SMTP credentials from configuration variables will be deprecated in a future release. Please set credentials using a connection instead.
[2023-11-30T19:10:20.589+0000] {configuration.py:1068} WARNING - section/key [smtp/smtp_user] not found in config
[2023-11-30T19:10:20.589+0000] {email.py:270} INFO - Email alerting: attempt 1
[2023-11-30T19:10:20.661+0000] {configuration.py:1068} WARNING - section/key [smtp/smtp_user] not found in config
[2023-11-30T19:10:20.661+0000] {email.py:270} INFO - Email alerting: attempt 1
[2023-11-30T19:10:20.662+0000] {taskinstance.py:2007} ERROR - Failed to send email to: ['franklinmutwiri41@gmail.com']
Traceback (most recent call last):
  File "/home/airflow/.local/lib/python3.8/site-packages/airflow/models/taskinstance.py", line 1518, in _run_raw_task
    self._execute_task_with_callbacks(context, test_mode, session=session)
  File "/home/airflow/.local/lib/python3.8/site-packages/airflow/models/taskinstance.py", line 1681, in _execute_task_with_callbacks
    result = self._execute_task(context, task_orig)
  File "/home/airflow/.local/lib/python3.8/site-packages/airflow/models/taskinstance.py", line 1744, in _execute_task
    result = execute_callable(context=context, **execute_callable_kwargs)
  File "/home/airflow/.local/lib/python3.8/site-packages/airflow/operators/python.py", line 192, in execute
    return_value = self.execute_callable()
  File "/home/airflow/.local/lib/python3.8/site-packages/airflow/operators/python.py", line 209, in execute_callable
    return self.python_callable(*self.op_args, **self.op_kwargs)
  File "/opt/airflow/dags/postgres_to_gcs_staging.py", line 42, in Postgres_To_GCS1
    gcs_hook.upload(BUCKET, GS_PATH +table + ".csv", table + ".csv")
  File "/home/airflow/.local/lib/python3.8/site-packages/airflow/providers/google/cloud/hooks/gcs.py", line 556, in upload
    _call_with_retry(
  File "/home/airflow/.local/lib/python3.8/site-packages/airflow/providers/google/cloud/hooks/gcs.py", line 514, in _call_with_retry
    f()
  File "/home/airflow/.local/lib/python3.8/site-packages/google/cloud/storage/blob.py", line 2924, in upload_from_filename
    self._handle_filename_and_upload(
  File "/home/airflow/.local/lib/python3.8/site-packages/google/cloud/storage/blob.py", line 2794, in _handle_filename_and_upload
    self._prep_and_do_upload(
  File "/home/airflow/.local/lib/python3.8/site-packages/google/cloud/storage/blob.py", line 2602, in _prep_and_do_upload
    created_json = self._do_upload(
  File "/home/airflow/.local/lib/python3.8/site-packages/google/cloud/storage/blob.py", line 2408, in _do_upload
    response = self._do_multipart_upload(
  File "/home/airflow/.local/lib/python3.8/site-packages/google/cloud/storage/blob.py", line 1879, in _do_multipart_upload
    hostname=hostname, bucket_path=self.bucket.path, api_version=_API_VERSION
  File "/home/airflow/.local/lib/python3.8/site-packages/google/cloud/storage/bucket.py", line 1167, in path
    raise ValueError("Cannot determine path without bucket name.")
ValueError: Cannot determine path without bucket name.

During handling of the above exception, another exception occurred:

Traceback (most recent call last):
  File "/home/airflow/.local/lib/python3.8/site-packages/airflow/models/taskinstance.py", line 2420, in email_alert
    send_email(task.email, subject, html_content)
  File "/home/airflow/.local/lib/python3.8/site-packages/airflow/utils/email.py", line 80, in send_email
    return backend(
  File "/home/airflow/.local/lib/python3.8/site-packages/airflow/utils/email.py", line 154, in send_email_smtp
    send_mime_email(e_from=mail_from, e_to=recipients, mime_msg=msg, conn_id=conn_id, dryrun=dryrun)
  File "/home/airflow/.local/lib/python3.8/site-packages/airflow/utils/email.py", line 272, in send_mime_email
    smtp_conn = _get_smtp_connection(smtp_host, smtp_port, smtp_timeout, smtp_ssl)
  File "/home/airflow/.local/lib/python3.8/site-packages/airflow/utils/email.py", line 316, in _get_smtp_connection
    return smtplib.SMTP(host=host, port=port, timeout=timeout)
  File "/usr/local/lib/python3.8/smtplib.py", line 255, in __init__
    (code, msg) = self.connect(host, port)
  File "/usr/local/lib/python3.8/smtplib.py", line 339, in connect
    self.sock = self._get_socket(host, port, self.timeout)
  File "/usr/local/lib/python3.8/smtplib.py", line 310, in _get_socket
    return socket.create_connection((host, port), timeout,
  File "/usr/local/lib/python3.8/socket.py", line 808, in create_connection
    raise err
  File "/usr/local/lib/python3.8/socket.py", line 796, in create_connection
    sock.connect(sa)
OSError: [Errno 99] Cannot assign requested address

During handling of the above exception, another exception occurred:

Traceback (most recent call last):
  File "/home/airflow/.local/lib/python3.8/site-packages/airflow/models/taskinstance.py", line 2005, in handle_failure
    self.email_alert(error, task)
  File "/home/airflow/.local/lib/python3.8/site-packages/airflow/models/taskinstance.py", line 2422, in email_alert
    send_email(task.email, subject, html_content_err)
  File "/home/airflow/.local/lib/python3.8/site-packages/airflow/utils/email.py", line 80, in send_email
    return backend(
  File "/home/airflow/.local/lib/python3.8/site-packages/airflow/utils/email.py", line 154, in send_email_smtp
    send_mime_email(e_from=mail_from, e_to=recipients, mime_msg=msg, conn_id=conn_id, dryrun=dryrun)
  File "/home/airflow/.local/lib/python3.8/site-packages/airflow/utils/email.py", line 272, in send_mime_email
    smtp_conn = _get_smtp_connection(smtp_host, smtp_port, smtp_timeout, smtp_ssl)
  File "/home/airflow/.local/lib/python3.8/site-packages/airflow/utils/email.py", line 316, in _get_smtp_connection
    return smtplib.SMTP(host=host, port=port, timeout=timeout)
  File "/usr/local/lib/python3.8/smtplib.py", line 255, in __init__
    (code, msg) = self.connect(host, port)
  File "/usr/local/lib/python3.8/smtplib.py", line 339, in connect
    self.sock = self._get_socket(host, port, self.timeout)
  File "/usr/local/lib/python3.8/smtplib.py", line 310, in _get_socket
    return socket.create_connection((host, port), timeout,
  File "/usr/local/lib/python3.8/socket.py", line 808, in create_connection
    raise err
  File "/usr/local/lib/python3.8/socket.py", line 796, in create_connection
    sock.connect(sa)
OSError: [Errno 99] Cannot assign requested address
[2023-11-30T19:10:20.835+0000] {standard_task_runner.py:104} ERROR - Failed to execute job 192 for task PostgresToGCS1 (Cannot determine path without bucket name.; 809)
[2023-11-30T19:10:20.882+0000] {local_task_job_runner.py:228} INFO - Task exited with return code 1
[2023-11-30T19:10:20.934+0000] {taskinstance.py:2778} INFO - 0 downstream tasks scheduled from follow-on schedule check
[2023-11-30T19:15:08.896+0000] {taskinstance.py:1159} INFO - Dependencies all met for dep_context=non-requeueable deps ti=<TaskInstance: ingest_to_gcs_bucket.PostgresToGCS1 scheduled__2023-11-27T00:00:00+00:00 [queued]>
[2023-11-30T19:15:08.919+0000] {taskinstance.py:1159} INFO - Dependencies all met for dep_context=requeueable deps ti=<TaskInstance: ingest_to_gcs_bucket.PostgresToGCS1 scheduled__2023-11-27T00:00:00+00:00 [queued]>
[2023-11-30T19:15:08.919+0000] {taskinstance.py:1361} INFO - Starting attempt 1 of 3
[2023-11-30T19:15:08.945+0000] {taskinstance.py:1382} INFO - Executing <Task(PythonOperator): PostgresToGCS1> on 2023-11-27 00:00:00+00:00
[2023-11-30T19:15:08.951+0000] {standard_task_runner.py:57} INFO - Started process 928 to run task
[2023-11-30T19:15:08.955+0000] {standard_task_runner.py:84} INFO - Running: ['airflow', 'tasks', 'run', 'ingest_to_gcs_bucket', 'PostgresToGCS1', 'scheduled__2023-11-27T00:00:00+00:00', '--job-id', '195', '--raw', '--subdir', 'DAGS_FOLDER/postgres_to_gcs_staging.py', '--cfg-path', '/tmp/tmprnyyzdwe']
[2023-11-30T19:15:08.958+0000] {standard_task_runner.py:85} INFO - Job 195: Subtask PostgresToGCS1
[2023-11-30T19:15:09.026+0000] {task_command.py:416} INFO - Running <TaskInstance: ingest_to_gcs_bucket.PostgresToGCS1 scheduled__2023-11-27T00:00:00+00:00 [running]> on host d9318cdc880c
[2023-11-30T19:15:09.161+0000] {taskinstance.py:1662} INFO - Exporting env vars: AIRFLOW_CTX_DAG_EMAIL='franklinmutwiri41@gmail.com' AIRFLOW_CTX_DAG_OWNER='airflow' AIRFLOW_CTX_DAG_ID='ingest_to_gcs_bucket' AIRFLOW_CTX_TASK_ID='PostgresToGCS1' AIRFLOW_CTX_EXECUTION_DATE='2023-11-27T00:00:00+00:00' AIRFLOW_CTX_TRY_NUMBER='1' AIRFLOW_CTX_DAG_RUN_ID='scheduled__2023-11-27T00:00:00+00:00'
[2023-11-30T19:15:09.176+0000] {connection.py:232} WARNING - Connection schemes (type: google_cloud_platform) shall not contain '_' according to RFC3986.
[2023-11-30T19:15:09.181+0000] {base.py:73} INFO - Using connection ID 'google_cloud_default' for task execution.
[2023-11-30T19:15:09.195+0000] {base.py:73} INFO - Using connection ID 'postgres_docker_conn' for task execution.
[2023-11-30T19:15:09.207+0000] {base.py:73} INFO - Using connection ID 'postgres_docker_conn' for task execution.
[2023-11-30T19:15:09.218+0000] {postgres_to_gcs_staging.py:41} INFO - Uploading to bucket, course.csv
[2023-11-30T19:15:09.267+0000] {taskinstance.py:1937} ERROR - Task failed with exception
Traceback (most recent call last):
  File "/home/airflow/.local/lib/python3.8/site-packages/airflow/operators/python.py", line 192, in execute
    return_value = self.execute_callable()
  File "/home/airflow/.local/lib/python3.8/site-packages/airflow/operators/python.py", line 209, in execute_callable
    return self.python_callable(*self.op_args, **self.op_kwargs)
  File "/opt/airflow/dags/postgres_to_gcs_staging.py", line 42, in Postgres_To_GCS1
    gcs_hook.upload(BUCKET, GS_PATH +table + ".csv", table + ".csv")
  File "/home/airflow/.local/lib/python3.8/site-packages/airflow/providers/google/cloud/hooks/gcs.py", line 556, in upload
    _call_with_retry(
  File "/home/airflow/.local/lib/python3.8/site-packages/airflow/providers/google/cloud/hooks/gcs.py", line 514, in _call_with_retry
    f()
  File "/home/airflow/.local/lib/python3.8/site-packages/google/cloud/storage/blob.py", line 2924, in upload_from_filename
    self._handle_filename_and_upload(
  File "/home/airflow/.local/lib/python3.8/site-packages/google/cloud/storage/blob.py", line 2794, in _handle_filename_and_upload
    self._prep_and_do_upload(
  File "/home/airflow/.local/lib/python3.8/site-packages/google/cloud/storage/blob.py", line 2602, in _prep_and_do_upload
    created_json = self._do_upload(
  File "/home/airflow/.local/lib/python3.8/site-packages/google/cloud/storage/blob.py", line 2408, in _do_upload
    response = self._do_multipart_upload(
  File "/home/airflow/.local/lib/python3.8/site-packages/google/cloud/storage/blob.py", line 1879, in _do_multipart_upload
    hostname=hostname, bucket_path=self.bucket.path, api_version=_API_VERSION
  File "/home/airflow/.local/lib/python3.8/site-packages/google/cloud/storage/bucket.py", line 1167, in path
    raise ValueError("Cannot determine path without bucket name.")
ValueError: Cannot determine path without bucket name.
[2023-11-30T19:15:09.282+0000] {taskinstance.py:1400} INFO - Marking task as UP_FOR_RETRY. dag_id=ingest_to_gcs_bucket, task_id=PostgresToGCS1, execution_date=20231127T000000, start_date=20231130T191508, end_date=20231130T191509
[2023-11-30T19:15:09.299+0000] {logging_mixin.py:151} WARNING - /home/***/.local/lib/python3.8/site-packages/***/utils/email.py:154 RemovedInAirflow3Warning: Fetching SMTP credentials from configuration variables will be deprecated in a future release. Please set credentials using a connection instead.
[2023-11-30T19:15:09.299+0000] {configuration.py:1068} WARNING - section/key [smtp/smtp_user] not found in config
[2023-11-30T19:15:09.300+0000] {email.py:270} INFO - Email alerting: attempt 1
[2023-11-30T19:15:09.312+0000] {configuration.py:1068} WARNING - section/key [smtp/smtp_user] not found in config
[2023-11-30T19:15:09.312+0000] {email.py:270} INFO - Email alerting: attempt 1
[2023-11-30T19:15:09.312+0000] {taskinstance.py:2007} ERROR - Failed to send email to: ['franklinmutwiri41@gmail.com']
Traceback (most recent call last):
  File "/home/airflow/.local/lib/python3.8/site-packages/airflow/models/taskinstance.py", line 1518, in _run_raw_task
    self._execute_task_with_callbacks(context, test_mode, session=session)
  File "/home/airflow/.local/lib/python3.8/site-packages/airflow/models/taskinstance.py", line 1681, in _execute_task_with_callbacks
    result = self._execute_task(context, task_orig)
  File "/home/airflow/.local/lib/python3.8/site-packages/airflow/models/taskinstance.py", line 1744, in _execute_task
    result = execute_callable(context=context, **execute_callable_kwargs)
  File "/home/airflow/.local/lib/python3.8/site-packages/airflow/operators/python.py", line 192, in execute
    return_value = self.execute_callable()
  File "/home/airflow/.local/lib/python3.8/site-packages/airflow/operators/python.py", line 209, in execute_callable
    return self.python_callable(*self.op_args, **self.op_kwargs)
  File "/opt/airflow/dags/postgres_to_gcs_staging.py", line 42, in Postgres_To_GCS1
    gcs_hook.upload(BUCKET, GS_PATH +table + ".csv", table + ".csv")
  File "/home/airflow/.local/lib/python3.8/site-packages/airflow/providers/google/cloud/hooks/gcs.py", line 556, in upload
    _call_with_retry(
  File "/home/airflow/.local/lib/python3.8/site-packages/airflow/providers/google/cloud/hooks/gcs.py", line 514, in _call_with_retry
    f()
  File "/home/airflow/.local/lib/python3.8/site-packages/google/cloud/storage/blob.py", line 2924, in upload_from_filename
    self._handle_filename_and_upload(
  File "/home/airflow/.local/lib/python3.8/site-packages/google/cloud/storage/blob.py", line 2794, in _handle_filename_and_upload
    self._prep_and_do_upload(
  File "/home/airflow/.local/lib/python3.8/site-packages/google/cloud/storage/blob.py", line 2602, in _prep_and_do_upload
    created_json = self._do_upload(
  File "/home/airflow/.local/lib/python3.8/site-packages/google/cloud/storage/blob.py", line 2408, in _do_upload
    response = self._do_multipart_upload(
  File "/home/airflow/.local/lib/python3.8/site-packages/google/cloud/storage/blob.py", line 1879, in _do_multipart_upload
    hostname=hostname, bucket_path=self.bucket.path, api_version=_API_VERSION
  File "/home/airflow/.local/lib/python3.8/site-packages/google/cloud/storage/bucket.py", line 1167, in path
    raise ValueError("Cannot determine path without bucket name.")
ValueError: Cannot determine path without bucket name.

During handling of the above exception, another exception occurred:

Traceback (most recent call last):
  File "/home/airflow/.local/lib/python3.8/site-packages/airflow/models/taskinstance.py", line 2420, in email_alert
    send_email(task.email, subject, html_content)
  File "/home/airflow/.local/lib/python3.8/site-packages/airflow/utils/email.py", line 80, in send_email
    return backend(
  File "/home/airflow/.local/lib/python3.8/site-packages/airflow/utils/email.py", line 154, in send_email_smtp
    send_mime_email(e_from=mail_from, e_to=recipients, mime_msg=msg, conn_id=conn_id, dryrun=dryrun)
  File "/home/airflow/.local/lib/python3.8/site-packages/airflow/utils/email.py", line 272, in send_mime_email
    smtp_conn = _get_smtp_connection(smtp_host, smtp_port, smtp_timeout, smtp_ssl)
  File "/home/airflow/.local/lib/python3.8/site-packages/airflow/utils/email.py", line 316, in _get_smtp_connection
    return smtplib.SMTP(host=host, port=port, timeout=timeout)
  File "/usr/local/lib/python3.8/smtplib.py", line 255, in __init__
    (code, msg) = self.connect(host, port)
  File "/usr/local/lib/python3.8/smtplib.py", line 339, in connect
    self.sock = self._get_socket(host, port, self.timeout)
  File "/usr/local/lib/python3.8/smtplib.py", line 310, in _get_socket
    return socket.create_connection((host, port), timeout,
  File "/usr/local/lib/python3.8/socket.py", line 808, in create_connection
    raise err
  File "/usr/local/lib/python3.8/socket.py", line 796, in create_connection
    sock.connect(sa)
OSError: [Errno 99] Cannot assign requested address

During handling of the above exception, another exception occurred:

Traceback (most recent call last):
  File "/home/airflow/.local/lib/python3.8/site-packages/airflow/models/taskinstance.py", line 2005, in handle_failure
    self.email_alert(error, task)
  File "/home/airflow/.local/lib/python3.8/site-packages/airflow/models/taskinstance.py", line 2422, in email_alert
    send_email(task.email, subject, html_content_err)
  File "/home/airflow/.local/lib/python3.8/site-packages/airflow/utils/email.py", line 80, in send_email
    return backend(
  File "/home/airflow/.local/lib/python3.8/site-packages/airflow/utils/email.py", line 154, in send_email_smtp
    send_mime_email(e_from=mail_from, e_to=recipients, mime_msg=msg, conn_id=conn_id, dryrun=dryrun)
  File "/home/airflow/.local/lib/python3.8/site-packages/airflow/utils/email.py", line 272, in send_mime_email
    smtp_conn = _get_smtp_connection(smtp_host, smtp_port, smtp_timeout, smtp_ssl)
  File "/home/airflow/.local/lib/python3.8/site-packages/airflow/utils/email.py", line 316, in _get_smtp_connection
    return smtplib.SMTP(host=host, port=port, timeout=timeout)
  File "/usr/local/lib/python3.8/smtplib.py", line 255, in __init__
    (code, msg) = self.connect(host, port)
  File "/usr/local/lib/python3.8/smtplib.py", line 339, in connect
    self.sock = self._get_socket(host, port, self.timeout)
  File "/usr/local/lib/python3.8/smtplib.py", line 310, in _get_socket
    return socket.create_connection((host, port), timeout,
  File "/usr/local/lib/python3.8/socket.py", line 808, in create_connection
    raise err
  File "/usr/local/lib/python3.8/socket.py", line 796, in create_connection
    sock.connect(sa)
OSError: [Errno 99] Cannot assign requested address
[2023-11-30T19:15:09.344+0000] {standard_task_runner.py:104} ERROR - Failed to execute job 195 for task PostgresToGCS1 (Cannot determine path without bucket name.; 928)
[2023-11-30T19:15:09.367+0000] {local_task_job_runner.py:228} INFO - Task exited with return code 1
[2023-11-30T19:15:09.404+0000] {taskinstance.py:2778} INFO - 0 downstream tasks scheduled from follow-on schedule check
[2023-11-30T19:35:32.275+0000] {taskinstance.py:1159} INFO - Dependencies all met for dep_context=non-requeueable deps ti=<TaskInstance: ingest_to_gcs_bucket.PostgresToGCS1 scheduled__2023-11-27T00:00:00+00:00 [queued]>
[2023-11-30T19:35:32.301+0000] {taskinstance.py:1159} INFO - Dependencies all met for dep_context=requeueable deps ti=<TaskInstance: ingest_to_gcs_bucket.PostgresToGCS1 scheduled__2023-11-27T00:00:00+00:00 [queued]>
[2023-11-30T19:35:32.301+0000] {taskinstance.py:1361} INFO - Starting attempt 1 of 3
[2023-11-30T19:35:32.325+0000] {taskinstance.py:1382} INFO - Executing <Task(PythonOperator): PostgresToGCS1> on 2023-11-27 00:00:00+00:00
[2023-11-30T19:35:32.331+0000] {standard_task_runner.py:57} INFO - Started process 1415 to run task
[2023-11-30T19:35:32.335+0000] {standard_task_runner.py:84} INFO - Running: ['airflow', 'tasks', 'run', 'ingest_to_gcs_bucket', 'PostgresToGCS1', 'scheduled__2023-11-27T00:00:00+00:00', '--job-id', '198', '--raw', '--subdir', 'DAGS_FOLDER/postgres_to_gcs_staging.py', '--cfg-path', '/tmp/tmp8xx3s_0f']
[2023-11-30T19:35:32.338+0000] {standard_task_runner.py:85} INFO - Job 198: Subtask PostgresToGCS1
[2023-11-30T19:35:32.442+0000] {task_command.py:416} INFO - Running <TaskInstance: ingest_to_gcs_bucket.PostgresToGCS1 scheduled__2023-11-27T00:00:00+00:00 [running]> on host d9318cdc880c
[2023-11-30T19:35:32.623+0000] {taskinstance.py:1662} INFO - Exporting env vars: AIRFLOW_CTX_DAG_EMAIL='franklinmutwiri41@gmail.com' AIRFLOW_CTX_DAG_OWNER='airflow' AIRFLOW_CTX_DAG_ID='ingest_to_gcs_bucket' AIRFLOW_CTX_TASK_ID='PostgresToGCS1' AIRFLOW_CTX_EXECUTION_DATE='2023-11-27T00:00:00+00:00' AIRFLOW_CTX_TRY_NUMBER='1' AIRFLOW_CTX_DAG_RUN_ID='scheduled__2023-11-27T00:00:00+00:00'
[2023-11-30T19:35:32.642+0000] {connection.py:232} WARNING - Connection schemes (type: google_cloud_platform) shall not contain '_' according to RFC3986.
[2023-11-30T19:35:32.647+0000] {base.py:73} INFO - Using connection ID 'google_cloud_default' for task execution.
[2023-11-30T19:35:32.666+0000] {base.py:73} INFO - Using connection ID 'postgres_docker_conn' for task execution.
[2023-11-30T19:35:32.683+0000] {base.py:73} INFO - Using connection ID 'postgres_docker_conn' for task execution.
[2023-11-30T19:35:32.698+0000] {postgres_to_gcs_staging.py:41} INFO - Uploading to bucket, course.csv
[2023-11-30T19:35:32.714+0000] {taskinstance.py:1937} ERROR - Task failed with exception
Traceback (most recent call last):
  File "/home/airflow/.local/lib/python3.8/site-packages/airflow/providers/google/common/hooks/base_google.py", line 259, in get_credentials_and_project_id
    keyfile_dict_json = json.loads(keyfile_dict)
  File "/usr/local/lib/python3.8/json/__init__.py", line 357, in loads
    return _default_decoder.decode(s)
  File "/usr/local/lib/python3.8/json/decoder.py", line 340, in decode
    raise JSONDecodeError("Extra data", s, end)
json.decoder.JSONDecodeError: Extra data: line 1 column 2406 (char 2405)

During handling of the above exception, another exception occurred:

Traceback (most recent call last):
  File "/home/airflow/.local/lib/python3.8/site-packages/airflow/operators/python.py", line 192, in execute
    return_value = self.execute_callable()
  File "/home/airflow/.local/lib/python3.8/site-packages/airflow/operators/python.py", line 209, in execute_callable
    return self.python_callable(*self.op_args, **self.op_kwargs)
  File "/opt/airflow/dags/postgres_to_gcs_staging.py", line 42, in Postgres_To_GCS1
    gcs_hook.upload(BUCKET, GS_PATH +table + ".csv", table + ".csv")
  File "/home/airflow/.local/lib/python3.8/site-packages/airflow/providers/google/cloud/hooks/gcs.py", line 530, in upload
    client = self.get_conn()
  File "/home/airflow/.local/lib/python3.8/site-packages/airflow/providers/google/cloud/hooks/gcs.py", line 173, in get_conn
    credentials=self.get_credentials(), client_info=CLIENT_INFO, project=self.project_id
  File "/home/airflow/.local/lib/python3.8/site-packages/airflow/providers/google/common/hooks/base_google.py", line 296, in get_credentials
    credentials, _ = self.get_credentials_and_project_id()
  File "/home/airflow/.local/lib/python3.8/site-packages/airflow/providers/google/common/hooks/base_google.py", line 261, in get_credentials_and_project_id
    raise AirflowException("Invalid key JSON.")
airflow.exceptions.AirflowException: Invalid key JSON.
[2023-11-30T19:35:32.762+0000] {taskinstance.py:1400} INFO - Marking task as UP_FOR_RETRY. dag_id=ingest_to_gcs_bucket, task_id=PostgresToGCS1, execution_date=20231127T000000, start_date=20231130T193532, end_date=20231130T193532
[2023-11-30T19:35:32.795+0000] {logging_mixin.py:151} WARNING - /home/***/.local/lib/python3.8/site-packages/***/utils/email.py:154 RemovedInAirflow3Warning: Fetching SMTP credentials from configuration variables will be deprecated in a future release. Please set credentials using a connection instead.
[2023-11-30T19:35:32.796+0000] {configuration.py:1068} WARNING - section/key [smtp/smtp_user] not found in config
[2023-11-30T19:35:32.796+0000] {email.py:270} INFO - Email alerting: attempt 1
[2023-11-30T19:35:32.813+0000] {configuration.py:1068} WARNING - section/key [smtp/smtp_user] not found in config
[2023-11-30T19:35:32.814+0000] {email.py:270} INFO - Email alerting: attempt 1
[2023-11-30T19:35:32.814+0000] {taskinstance.py:2007} ERROR - Failed to send email to: ['franklinmutwiri41@gmail.com']
Traceback (most recent call last):
  File "/home/airflow/.local/lib/python3.8/site-packages/airflow/providers/google/common/hooks/base_google.py", line 259, in get_credentials_and_project_id
    keyfile_dict_json = json.loads(keyfile_dict)
  File "/usr/local/lib/python3.8/json/__init__.py", line 357, in loads
    return _default_decoder.decode(s)
  File "/usr/local/lib/python3.8/json/decoder.py", line 340, in decode
    raise JSONDecodeError("Extra data", s, end)
json.decoder.JSONDecodeError: Extra data: line 1 column 2406 (char 2405)

During handling of the above exception, another exception occurred:

Traceback (most recent call last):
  File "/home/airflow/.local/lib/python3.8/site-packages/airflow/models/taskinstance.py", line 1518, in _run_raw_task
    self._execute_task_with_callbacks(context, test_mode, session=session)
  File "/home/airflow/.local/lib/python3.8/site-packages/airflow/models/taskinstance.py", line 1681, in _execute_task_with_callbacks
    result = self._execute_task(context, task_orig)
  File "/home/airflow/.local/lib/python3.8/site-packages/airflow/models/taskinstance.py", line 1744, in _execute_task
    result = execute_callable(context=context, **execute_callable_kwargs)
  File "/home/airflow/.local/lib/python3.8/site-packages/airflow/operators/python.py", line 192, in execute
    return_value = self.execute_callable()
  File "/home/airflow/.local/lib/python3.8/site-packages/airflow/operators/python.py", line 209, in execute_callable
    return self.python_callable(*self.op_args, **self.op_kwargs)
  File "/opt/airflow/dags/postgres_to_gcs_staging.py", line 42, in Postgres_To_GCS1
    gcs_hook.upload(BUCKET, GS_PATH +table + ".csv", table + ".csv")
  File "/home/airflow/.local/lib/python3.8/site-packages/airflow/providers/google/cloud/hooks/gcs.py", line 530, in upload
    client = self.get_conn()
  File "/home/airflow/.local/lib/python3.8/site-packages/airflow/providers/google/cloud/hooks/gcs.py", line 173, in get_conn
    credentials=self.get_credentials(), client_info=CLIENT_INFO, project=self.project_id
  File "/home/airflow/.local/lib/python3.8/site-packages/airflow/providers/google/common/hooks/base_google.py", line 296, in get_credentials
    credentials, _ = self.get_credentials_and_project_id()
  File "/home/airflow/.local/lib/python3.8/site-packages/airflow/providers/google/common/hooks/base_google.py", line 261, in get_credentials_and_project_id
    raise AirflowException("Invalid key JSON.")
airflow.exceptions.AirflowException: Invalid key JSON.

During handling of the above exception, another exception occurred:

Traceback (most recent call last):
  File "/home/airflow/.local/lib/python3.8/site-packages/airflow/models/taskinstance.py", line 2420, in email_alert
    send_email(task.email, subject, html_content)
  File "/home/airflow/.local/lib/python3.8/site-packages/airflow/utils/email.py", line 80, in send_email
    return backend(
  File "/home/airflow/.local/lib/python3.8/site-packages/airflow/utils/email.py", line 154, in send_email_smtp
    send_mime_email(e_from=mail_from, e_to=recipients, mime_msg=msg, conn_id=conn_id, dryrun=dryrun)
  File "/home/airflow/.local/lib/python3.8/site-packages/airflow/utils/email.py", line 272, in send_mime_email
    smtp_conn = _get_smtp_connection(smtp_host, smtp_port, smtp_timeout, smtp_ssl)
  File "/home/airflow/.local/lib/python3.8/site-packages/airflow/utils/email.py", line 316, in _get_smtp_connection
    return smtplib.SMTP(host=host, port=port, timeout=timeout)
  File "/usr/local/lib/python3.8/smtplib.py", line 255, in __init__
    (code, msg) = self.connect(host, port)
  File "/usr/local/lib/python3.8/smtplib.py", line 339, in connect
    self.sock = self._get_socket(host, port, self.timeout)
  File "/usr/local/lib/python3.8/smtplib.py", line 310, in _get_socket
    return socket.create_connection((host, port), timeout,
  File "/usr/local/lib/python3.8/socket.py", line 808, in create_connection
    raise err
  File "/usr/local/lib/python3.8/socket.py", line 796, in create_connection
    sock.connect(sa)
OSError: [Errno 99] Cannot assign requested address

During handling of the above exception, another exception occurred:

Traceback (most recent call last):
  File "/home/airflow/.local/lib/python3.8/site-packages/airflow/models/taskinstance.py", line 2005, in handle_failure
    self.email_alert(error, task)
  File "/home/airflow/.local/lib/python3.8/site-packages/airflow/models/taskinstance.py", line 2422, in email_alert
    send_email(task.email, subject, html_content_err)
  File "/home/airflow/.local/lib/python3.8/site-packages/airflow/utils/email.py", line 80, in send_email
    return backend(
  File "/home/airflow/.local/lib/python3.8/site-packages/airflow/utils/email.py", line 154, in send_email_smtp
    send_mime_email(e_from=mail_from, e_to=recipients, mime_msg=msg, conn_id=conn_id, dryrun=dryrun)
  File "/home/airflow/.local/lib/python3.8/site-packages/airflow/utils/email.py", line 272, in send_mime_email
    smtp_conn = _get_smtp_connection(smtp_host, smtp_port, smtp_timeout, smtp_ssl)
  File "/home/airflow/.local/lib/python3.8/site-packages/airflow/utils/email.py", line 316, in _get_smtp_connection
    return smtplib.SMTP(host=host, port=port, timeout=timeout)
  File "/usr/local/lib/python3.8/smtplib.py", line 255, in __init__
    (code, msg) = self.connect(host, port)
  File "/usr/local/lib/python3.8/smtplib.py", line 339, in connect
    self.sock = self._get_socket(host, port, self.timeout)
  File "/usr/local/lib/python3.8/smtplib.py", line 310, in _get_socket
    return socket.create_connection((host, port), timeout,
  File "/usr/local/lib/python3.8/socket.py", line 808, in create_connection
    raise err
  File "/usr/local/lib/python3.8/socket.py", line 796, in create_connection
    sock.connect(sa)
OSError: [Errno 99] Cannot assign requested address
[2023-11-30T19:35:32.868+0000] {standard_task_runner.py:104} ERROR - Failed to execute job 198 for task PostgresToGCS1 (Invalid key JSON.; 1415)
[2023-11-30T19:35:32.909+0000] {local_task_job_runner.py:228} INFO - Task exited with return code 1
[2023-11-30T19:35:32.948+0000] {taskinstance.py:2778} INFO - 0 downstream tasks scheduled from follow-on schedule check
[2023-11-30T20:01:32.806+0000] {taskinstance.py:1159} INFO - Dependencies all met for dep_context=non-requeueable deps ti=<TaskInstance: ingest_to_gcs_bucket.PostgresToGCS1 scheduled__2023-11-27T00:00:00+00:00 [queued]>
[2023-11-30T20:01:32.834+0000] {taskinstance.py:1159} INFO - Dependencies all met for dep_context=requeueable deps ti=<TaskInstance: ingest_to_gcs_bucket.PostgresToGCS1 scheduled__2023-11-27T00:00:00+00:00 [queued]>
[2023-11-30T20:01:32.835+0000] {taskinstance.py:1361} INFO - Starting attempt 1 of 3
[2023-11-30T20:01:32.869+0000] {taskinstance.py:1382} INFO - Executing <Task(PythonOperator): PostgresToGCS1> on 2023-11-27 00:00:00+00:00
[2023-11-30T20:01:32.876+0000] {standard_task_runner.py:57} INFO - Started process 512 to run task
[2023-11-30T20:01:32.882+0000] {standard_task_runner.py:84} INFO - Running: ['airflow', 'tasks', 'run', 'ingest_to_gcs_bucket', 'PostgresToGCS1', 'scheduled__2023-11-27T00:00:00+00:00', '--job-id', '203', '--raw', '--subdir', 'DAGS_FOLDER/postgres_to_gcs_staging.py', '--cfg-path', '/tmp/tmpsc0grc8x']
[2023-11-30T20:01:32.886+0000] {standard_task_runner.py:85} INFO - Job 203: Subtask PostgresToGCS1
[2023-11-30T20:01:33.064+0000] {task_command.py:416} INFO - Running <TaskInstance: ingest_to_gcs_bucket.PostgresToGCS1 scheduled__2023-11-27T00:00:00+00:00 [running]> on host 478ddcb97012
[2023-11-30T20:01:33.546+0000] {taskinstance.py:1662} INFO - Exporting env vars: AIRFLOW_CTX_DAG_EMAIL='franklinmutwiri41@gmail.com' AIRFLOW_CTX_DAG_OWNER='airflow' AIRFLOW_CTX_DAG_ID='ingest_to_gcs_bucket' AIRFLOW_CTX_TASK_ID='PostgresToGCS1' AIRFLOW_CTX_EXECUTION_DATE='2023-11-27T00:00:00+00:00' AIRFLOW_CTX_TRY_NUMBER='1' AIRFLOW_CTX_DAG_RUN_ID='scheduled__2023-11-27T00:00:00+00:00'
[2023-11-30T20:01:33.573+0000] {connection.py:232} WARNING - Connection schemes (type: google_cloud_platform) shall not contain '_' according to RFC3986.
[2023-11-30T20:01:33.580+0000] {base.py:73} INFO - Using connection ID 'google_cloud_default' for task execution.
[2023-11-30T20:01:33.598+0000] {base.py:73} INFO - Using connection ID 'postgres_docker_conn' for task execution.
[2023-11-30T20:01:33.615+0000] {base.py:73} INFO - Using connection ID 'postgres_docker_conn' for task execution.
[2023-11-30T20:01:33.645+0000] {postgres_to_gcs_staging.py:41} INFO - Uploading to bucket, course.csv
[2023-11-30T20:01:33.667+0000] {taskinstance.py:1937} ERROR - Task failed with exception
Traceback (most recent call last):
  File "/home/airflow/.local/lib/python3.8/site-packages/airflow/providers/google/common/hooks/base_google.py", line 259, in get_credentials_and_project_id
    keyfile_dict_json = json.loads(keyfile_dict)
  File "/usr/local/lib/python3.8/json/__init__.py", line 357, in loads
    return _default_decoder.decode(s)
  File "/usr/local/lib/python3.8/json/decoder.py", line 340, in decode
    raise JSONDecodeError("Extra data", s, end)
json.decoder.JSONDecodeError: Extra data: line 1 column 2406 (char 2405)

During handling of the above exception, another exception occurred:

Traceback (most recent call last):
  File "/home/airflow/.local/lib/python3.8/site-packages/airflow/operators/python.py", line 192, in execute
    return_value = self.execute_callable()
  File "/home/airflow/.local/lib/python3.8/site-packages/airflow/operators/python.py", line 209, in execute_callable
    return self.python_callable(*self.op_args, **self.op_kwargs)
  File "/opt/airflow/dags/postgres_to_gcs_staging.py", line 42, in Postgres_To_GCS1
    gcs_hook.upload(BUCKET, GS_PATH +table + ".csv", table + ".csv")
  File "/home/airflow/.local/lib/python3.8/site-packages/airflow/providers/google/cloud/hooks/gcs.py", line 530, in upload
    client = self.get_conn()
  File "/home/airflow/.local/lib/python3.8/site-packages/airflow/providers/google/cloud/hooks/gcs.py", line 173, in get_conn
    credentials=self.get_credentials(), client_info=CLIENT_INFO, project=self.project_id
  File "/home/airflow/.local/lib/python3.8/site-packages/airflow/providers/google/common/hooks/base_google.py", line 296, in get_credentials
    credentials, _ = self.get_credentials_and_project_id()
  File "/home/airflow/.local/lib/python3.8/site-packages/airflow/providers/google/common/hooks/base_google.py", line 261, in get_credentials_and_project_id
    raise AirflowException("Invalid key JSON.")
airflow.exceptions.AirflowException: Invalid key JSON.
[2023-11-30T20:01:33.671+0000] {taskinstance.py:1400} INFO - Marking task as UP_FOR_RETRY. dag_id=ingest_to_gcs_bucket, task_id=PostgresToGCS1, execution_date=20231127T000000, start_date=20231130T200132, end_date=20231130T200133
[2023-11-30T20:01:33.707+0000] {logging_mixin.py:151} WARNING - /home/***/.local/lib/python3.8/site-packages/***/utils/email.py:154 RemovedInAirflow3Warning: Fetching SMTP credentials from configuration variables will be deprecated in a future release. Please set credentials using a connection instead.
[2023-11-30T20:01:33.708+0000] {configuration.py:1068} WARNING - section/key [smtp/smtp_user] not found in config
[2023-11-30T20:01:33.708+0000] {email.py:270} INFO - Email alerting: attempt 1
[2023-11-30T20:01:33.727+0000] {configuration.py:1068} WARNING - section/key [smtp/smtp_user] not found in config
[2023-11-30T20:01:33.728+0000] {email.py:270} INFO - Email alerting: attempt 1
[2023-11-30T20:01:33.729+0000] {taskinstance.py:2007} ERROR - Failed to send email to: ['franklinmutwiri41@gmail.com']
Traceback (most recent call last):
  File "/home/airflow/.local/lib/python3.8/site-packages/airflow/providers/google/common/hooks/base_google.py", line 259, in get_credentials_and_project_id
    keyfile_dict_json = json.loads(keyfile_dict)
  File "/usr/local/lib/python3.8/json/__init__.py", line 357, in loads
    return _default_decoder.decode(s)
  File "/usr/local/lib/python3.8/json/decoder.py", line 340, in decode
    raise JSONDecodeError("Extra data", s, end)
json.decoder.JSONDecodeError: Extra data: line 1 column 2406 (char 2405)

During handling of the above exception, another exception occurred:

Traceback (most recent call last):
  File "/home/airflow/.local/lib/python3.8/site-packages/airflow/models/taskinstance.py", line 1518, in _run_raw_task
    self._execute_task_with_callbacks(context, test_mode, session=session)
  File "/home/airflow/.local/lib/python3.8/site-packages/airflow/models/taskinstance.py", line 1681, in _execute_task_with_callbacks
    result = self._execute_task(context, task_orig)
  File "/home/airflow/.local/lib/python3.8/site-packages/airflow/models/taskinstance.py", line 1744, in _execute_task
    result = execute_callable(context=context, **execute_callable_kwargs)
  File "/home/airflow/.local/lib/python3.8/site-packages/airflow/operators/python.py", line 192, in execute
    return_value = self.execute_callable()
  File "/home/airflow/.local/lib/python3.8/site-packages/airflow/operators/python.py", line 209, in execute_callable
    return self.python_callable(*self.op_args, **self.op_kwargs)
  File "/opt/airflow/dags/postgres_to_gcs_staging.py", line 42, in Postgres_To_GCS1
    gcs_hook.upload(BUCKET, GS_PATH +table + ".csv", table + ".csv")
  File "/home/airflow/.local/lib/python3.8/site-packages/airflow/providers/google/cloud/hooks/gcs.py", line 530, in upload
    client = self.get_conn()
  File "/home/airflow/.local/lib/python3.8/site-packages/airflow/providers/google/cloud/hooks/gcs.py", line 173, in get_conn
    credentials=self.get_credentials(), client_info=CLIENT_INFO, project=self.project_id
  File "/home/airflow/.local/lib/python3.8/site-packages/airflow/providers/google/common/hooks/base_google.py", line 296, in get_credentials
    credentials, _ = self.get_credentials_and_project_id()
  File "/home/airflow/.local/lib/python3.8/site-packages/airflow/providers/google/common/hooks/base_google.py", line 261, in get_credentials_and_project_id
    raise AirflowException("Invalid key JSON.")
airflow.exceptions.AirflowException: Invalid key JSON.

During handling of the above exception, another exception occurred:

Traceback (most recent call last):
  File "/home/airflow/.local/lib/python3.8/site-packages/airflow/models/taskinstance.py", line 2420, in email_alert
    send_email(task.email, subject, html_content)
  File "/home/airflow/.local/lib/python3.8/site-packages/airflow/utils/email.py", line 80, in send_email
    return backend(
  File "/home/airflow/.local/lib/python3.8/site-packages/airflow/utils/email.py", line 154, in send_email_smtp
    send_mime_email(e_from=mail_from, e_to=recipients, mime_msg=msg, conn_id=conn_id, dryrun=dryrun)
  File "/home/airflow/.local/lib/python3.8/site-packages/airflow/utils/email.py", line 272, in send_mime_email
    smtp_conn = _get_smtp_connection(smtp_host, smtp_port, smtp_timeout, smtp_ssl)
  File "/home/airflow/.local/lib/python3.8/site-packages/airflow/utils/email.py", line 316, in _get_smtp_connection
    return smtplib.SMTP(host=host, port=port, timeout=timeout)
  File "/usr/local/lib/python3.8/smtplib.py", line 255, in __init__
    (code, msg) = self.connect(host, port)
  File "/usr/local/lib/python3.8/smtplib.py", line 339, in connect
    self.sock = self._get_socket(host, port, self.timeout)
  File "/usr/local/lib/python3.8/smtplib.py", line 310, in _get_socket
    return socket.create_connection((host, port), timeout,
  File "/usr/local/lib/python3.8/socket.py", line 808, in create_connection
    raise err
  File "/usr/local/lib/python3.8/socket.py", line 796, in create_connection
    sock.connect(sa)
OSError: [Errno 99] Cannot assign requested address

During handling of the above exception, another exception occurred:

Traceback (most recent call last):
  File "/home/airflow/.local/lib/python3.8/site-packages/airflow/models/taskinstance.py", line 2005, in handle_failure
    self.email_alert(error, task)
  File "/home/airflow/.local/lib/python3.8/site-packages/airflow/models/taskinstance.py", line 2422, in email_alert
    send_email(task.email, subject, html_content_err)
  File "/home/airflow/.local/lib/python3.8/site-packages/airflow/utils/email.py", line 80, in send_email
    return backend(
  File "/home/airflow/.local/lib/python3.8/site-packages/airflow/utils/email.py", line 154, in send_email_smtp
    send_mime_email(e_from=mail_from, e_to=recipients, mime_msg=msg, conn_id=conn_id, dryrun=dryrun)
  File "/home/airflow/.local/lib/python3.8/site-packages/airflow/utils/email.py", line 272, in send_mime_email
    smtp_conn = _get_smtp_connection(smtp_host, smtp_port, smtp_timeout, smtp_ssl)
  File "/home/airflow/.local/lib/python3.8/site-packages/airflow/utils/email.py", line 316, in _get_smtp_connection
    return smtplib.SMTP(host=host, port=port, timeout=timeout)
  File "/usr/local/lib/python3.8/smtplib.py", line 255, in __init__
    (code, msg) = self.connect(host, port)
  File "/usr/local/lib/python3.8/smtplib.py", line 339, in connect
    self.sock = self._get_socket(host, port, self.timeout)
  File "/usr/local/lib/python3.8/smtplib.py", line 310, in _get_socket
    return socket.create_connection((host, port), timeout,
  File "/usr/local/lib/python3.8/socket.py", line 808, in create_connection
    raise err
  File "/usr/local/lib/python3.8/socket.py", line 796, in create_connection
    sock.connect(sa)
OSError: [Errno 99] Cannot assign requested address
[2023-11-30T20:01:33.766+0000] {standard_task_runner.py:104} ERROR - Failed to execute job 203 for task PostgresToGCS1 (Invalid key JSON.; 512)
[2023-11-30T20:01:33.797+0000] {local_task_job_runner.py:228} INFO - Task exited with return code 1
[2023-11-30T20:01:33.858+0000] {taskinstance.py:2778} INFO - 0 downstream tasks scheduled from follow-on schedule check
[2023-12-01T11:24:58.085+0000] {taskinstance.py:1159} INFO - Dependencies all met for dep_context=non-requeueable deps ti=<TaskInstance: ingest_to_gcs_bucket.PostgresToGCS1 scheduled__2023-11-27T00:00:00+00:00 [queued]>
[2023-12-01T11:24:58.105+0000] {taskinstance.py:1159} INFO - Dependencies all met for dep_context=requeueable deps ti=<TaskInstance: ingest_to_gcs_bucket.PostgresToGCS1 scheduled__2023-11-27T00:00:00+00:00 [queued]>
[2023-12-01T11:24:58.105+0000] {taskinstance.py:1361} INFO - Starting attempt 1 of 3
[2023-12-01T11:24:58.137+0000] {taskinstance.py:1382} INFO - Executing <Task(PythonOperator): PostgresToGCS1> on 2023-11-27 00:00:00+00:00
[2023-12-01T11:24:58.144+0000] {standard_task_runner.py:57} INFO - Started process 415 to run task
[2023-12-01T11:24:58.150+0000] {standard_task_runner.py:84} INFO - Running: ['airflow', 'tasks', 'run', 'ingest_to_gcs_bucket', 'PostgresToGCS1', 'scheduled__2023-11-27T00:00:00+00:00', '--job-id', '207', '--raw', '--subdir', 'DAGS_FOLDER/postgres_to_gcs_staging.py', '--cfg-path', '/tmp/tmpx73nzgix']
[2023-12-01T11:24:58.154+0000] {standard_task_runner.py:85} INFO - Job 207: Subtask PostgresToGCS1
[2023-12-01T11:24:58.238+0000] {task_command.py:416} INFO - Running <TaskInstance: ingest_to_gcs_bucket.PostgresToGCS1 scheduled__2023-11-27T00:00:00+00:00 [running]> on host 363088228d6a
[2023-12-01T11:24:58.386+0000] {taskinstance.py:1662} INFO - Exporting env vars: AIRFLOW_CTX_DAG_EMAIL='franklinmutwiri41@gmail.com' AIRFLOW_CTX_DAG_OWNER='airflow' AIRFLOW_CTX_DAG_ID='ingest_to_gcs_bucket' AIRFLOW_CTX_TASK_ID='PostgresToGCS1' AIRFLOW_CTX_EXECUTION_DATE='2023-11-27T00:00:00+00:00' AIRFLOW_CTX_TRY_NUMBER='1' AIRFLOW_CTX_DAG_RUN_ID='scheduled__2023-11-27T00:00:00+00:00'
[2023-12-01T11:24:58.427+0000] {connection.py:232} WARNING - Connection schemes (type: google_cloud_platform) shall not contain '_' according to RFC3986.
[2023-12-01T11:24:58.432+0000] {base.py:73} INFO - Using connection ID 'google_cloud_default' for task execution.
[2023-12-01T11:24:58.447+0000] {base.py:73} INFO - Using connection ID 'postgres_docker_conn' for task execution.
[2023-12-01T11:24:58.463+0000] {base.py:73} INFO - Using connection ID 'postgres_docker_conn' for task execution.
[2023-12-01T11:24:58.475+0000] {postgres_to_gcs_staging.py:41} INFO - Uploading to bucket, course.csv
[2023-12-01T11:24:58.493+0000] {taskinstance.py:1937} ERROR - Task failed with exception
Traceback (most recent call last):
  File "/home/airflow/.local/lib/python3.8/site-packages/airflow/providers/google/common/hooks/base_google.py", line 259, in get_credentials_and_project_id
    keyfile_dict_json = json.loads(keyfile_dict)
  File "/usr/local/lib/python3.8/json/__init__.py", line 357, in loads
    return _default_decoder.decode(s)
  File "/usr/local/lib/python3.8/json/decoder.py", line 340, in decode
    raise JSONDecodeError("Extra data", s, end)
json.decoder.JSONDecodeError: Extra data: line 1 column 2406 (char 2405)

During handling of the above exception, another exception occurred:

Traceback (most recent call last):
  File "/home/airflow/.local/lib/python3.8/site-packages/airflow/operators/python.py", line 192, in execute
    return_value = self.execute_callable()
  File "/home/airflow/.local/lib/python3.8/site-packages/airflow/operators/python.py", line 209, in execute_callable
    return self.python_callable(*self.op_args, **self.op_kwargs)
  File "/opt/airflow/dags/postgres_to_gcs_staging.py", line 42, in Postgres_To_GCS1
    gcs_hook.upload(BUCKET, GS_PATH +table + ".csv", table + ".csv")
  File "/home/airflow/.local/lib/python3.8/site-packages/airflow/providers/google/cloud/hooks/gcs.py", line 530, in upload
    client = self.get_conn()
  File "/home/airflow/.local/lib/python3.8/site-packages/airflow/providers/google/cloud/hooks/gcs.py", line 173, in get_conn
    credentials=self.get_credentials(), client_info=CLIENT_INFO, project=self.project_id
  File "/home/airflow/.local/lib/python3.8/site-packages/airflow/providers/google/common/hooks/base_google.py", line 296, in get_credentials
    credentials, _ = self.get_credentials_and_project_id()
  File "/home/airflow/.local/lib/python3.8/site-packages/airflow/providers/google/common/hooks/base_google.py", line 261, in get_credentials_and_project_id
    raise AirflowException("Invalid key JSON.")
airflow.exceptions.AirflowException: Invalid key JSON.
[2023-12-01T11:24:58.497+0000] {taskinstance.py:1400} INFO - Marking task as UP_FOR_RETRY. dag_id=ingest_to_gcs_bucket, task_id=PostgresToGCS1, execution_date=20231127T000000, start_date=20231201T112458, end_date=20231201T112458
[2023-12-01T11:24:58.531+0000] {logging_mixin.py:151} WARNING - /home/***/.local/lib/python3.8/site-packages/***/utils/email.py:154 RemovedInAirflow3Warning: Fetching SMTP credentials from configuration variables will be deprecated in a future release. Please set credentials using a connection instead.
[2023-12-01T11:24:58.533+0000] {configuration.py:1068} WARNING - section/key [smtp/smtp_user] not found in config
[2023-12-01T11:24:58.533+0000] {email.py:270} INFO - Email alerting: attempt 1
[2023-12-01T11:24:58.560+0000] {configuration.py:1068} WARNING - section/key [smtp/smtp_user] not found in config
[2023-12-01T11:24:58.561+0000] {email.py:270} INFO - Email alerting: attempt 1
[2023-12-01T11:24:58.562+0000] {taskinstance.py:2007} ERROR - Failed to send email to: ['franklinmutwiri41@gmail.com']
Traceback (most recent call last):
  File "/home/airflow/.local/lib/python3.8/site-packages/airflow/providers/google/common/hooks/base_google.py", line 259, in get_credentials_and_project_id
    keyfile_dict_json = json.loads(keyfile_dict)
  File "/usr/local/lib/python3.8/json/__init__.py", line 357, in loads
    return _default_decoder.decode(s)
  File "/usr/local/lib/python3.8/json/decoder.py", line 340, in decode
    raise JSONDecodeError("Extra data", s, end)
json.decoder.JSONDecodeError: Extra data: line 1 column 2406 (char 2405)

During handling of the above exception, another exception occurred:

Traceback (most recent call last):
  File "/home/airflow/.local/lib/python3.8/site-packages/airflow/models/taskinstance.py", line 1518, in _run_raw_task
    self._execute_task_with_callbacks(context, test_mode, session=session)
  File "/home/airflow/.local/lib/python3.8/site-packages/airflow/models/taskinstance.py", line 1681, in _execute_task_with_callbacks
    result = self._execute_task(context, task_orig)
  File "/home/airflow/.local/lib/python3.8/site-packages/airflow/models/taskinstance.py", line 1744, in _execute_task
    result = execute_callable(context=context, **execute_callable_kwargs)
  File "/home/airflow/.local/lib/python3.8/site-packages/airflow/operators/python.py", line 192, in execute
    return_value = self.execute_callable()
  File "/home/airflow/.local/lib/python3.8/site-packages/airflow/operators/python.py", line 209, in execute_callable
    return self.python_callable(*self.op_args, **self.op_kwargs)
  File "/opt/airflow/dags/postgres_to_gcs_staging.py", line 42, in Postgres_To_GCS1
    gcs_hook.upload(BUCKET, GS_PATH +table + ".csv", table + ".csv")
  File "/home/airflow/.local/lib/python3.8/site-packages/airflow/providers/google/cloud/hooks/gcs.py", line 530, in upload
    client = self.get_conn()
  File "/home/airflow/.local/lib/python3.8/site-packages/airflow/providers/google/cloud/hooks/gcs.py", line 173, in get_conn
    credentials=self.get_credentials(), client_info=CLIENT_INFO, project=self.project_id
  File "/home/airflow/.local/lib/python3.8/site-packages/airflow/providers/google/common/hooks/base_google.py", line 296, in get_credentials
    credentials, _ = self.get_credentials_and_project_id()
  File "/home/airflow/.local/lib/python3.8/site-packages/airflow/providers/google/common/hooks/base_google.py", line 261, in get_credentials_and_project_id
    raise AirflowException("Invalid key JSON.")
airflow.exceptions.AirflowException: Invalid key JSON.

During handling of the above exception, another exception occurred:

Traceback (most recent call last):
  File "/home/airflow/.local/lib/python3.8/site-packages/airflow/models/taskinstance.py", line 2420, in email_alert
    send_email(task.email, subject, html_content)
  File "/home/airflow/.local/lib/python3.8/site-packages/airflow/utils/email.py", line 80, in send_email
    return backend(
  File "/home/airflow/.local/lib/python3.8/site-packages/airflow/utils/email.py", line 154, in send_email_smtp
    send_mime_email(e_from=mail_from, e_to=recipients, mime_msg=msg, conn_id=conn_id, dryrun=dryrun)
  File "/home/airflow/.local/lib/python3.8/site-packages/airflow/utils/email.py", line 272, in send_mime_email
    smtp_conn = _get_smtp_connection(smtp_host, smtp_port, smtp_timeout, smtp_ssl)
  File "/home/airflow/.local/lib/python3.8/site-packages/airflow/utils/email.py", line 316, in _get_smtp_connection
    return smtplib.SMTP(host=host, port=port, timeout=timeout)
  File "/usr/local/lib/python3.8/smtplib.py", line 255, in __init__
    (code, msg) = self.connect(host, port)
  File "/usr/local/lib/python3.8/smtplib.py", line 339, in connect
    self.sock = self._get_socket(host, port, self.timeout)
  File "/usr/local/lib/python3.8/smtplib.py", line 310, in _get_socket
    return socket.create_connection((host, port), timeout,
  File "/usr/local/lib/python3.8/socket.py", line 808, in create_connection
    raise err
  File "/usr/local/lib/python3.8/socket.py", line 796, in create_connection
    sock.connect(sa)
OSError: [Errno 99] Cannot assign requested address

During handling of the above exception, another exception occurred:

Traceback (most recent call last):
  File "/home/airflow/.local/lib/python3.8/site-packages/airflow/models/taskinstance.py", line 2005, in handle_failure
    self.email_alert(error, task)
  File "/home/airflow/.local/lib/python3.8/site-packages/airflow/models/taskinstance.py", line 2422, in email_alert
    send_email(task.email, subject, html_content_err)
  File "/home/airflow/.local/lib/python3.8/site-packages/airflow/utils/email.py", line 80, in send_email
    return backend(
  File "/home/airflow/.local/lib/python3.8/site-packages/airflow/utils/email.py", line 154, in send_email_smtp
    send_mime_email(e_from=mail_from, e_to=recipients, mime_msg=msg, conn_id=conn_id, dryrun=dryrun)
  File "/home/airflow/.local/lib/python3.8/site-packages/airflow/utils/email.py", line 272, in send_mime_email
    smtp_conn = _get_smtp_connection(smtp_host, smtp_port, smtp_timeout, smtp_ssl)
  File "/home/airflow/.local/lib/python3.8/site-packages/airflow/utils/email.py", line 316, in _get_smtp_connection
    return smtplib.SMTP(host=host, port=port, timeout=timeout)
  File "/usr/local/lib/python3.8/smtplib.py", line 255, in __init__
    (code, msg) = self.connect(host, port)
  File "/usr/local/lib/python3.8/smtplib.py", line 339, in connect
    self.sock = self._get_socket(host, port, self.timeout)
  File "/usr/local/lib/python3.8/smtplib.py", line 310, in _get_socket
    return socket.create_connection((host, port), timeout,
  File "/usr/local/lib/python3.8/socket.py", line 808, in create_connection
    raise err
  File "/usr/local/lib/python3.8/socket.py", line 796, in create_connection
    sock.connect(sa)
OSError: [Errno 99] Cannot assign requested address
[2023-12-01T11:24:58.613+0000] {standard_task_runner.py:104} ERROR - Failed to execute job 207 for task PostgresToGCS1 (Invalid key JSON.; 415)
[2023-12-01T11:24:58.643+0000] {local_task_job_runner.py:228} INFO - Task exited with return code 1
[2023-12-01T11:24:58.691+0000] {taskinstance.py:2778} INFO - 0 downstream tasks scheduled from follow-on schedule check
[2023-12-01T12:11:36.415+0000] {taskinstance.py:1159} INFO - Dependencies all met for dep_context=non-requeueable deps ti=<TaskInstance: ingest_to_gcs_bucket.PostgresToGCS1 scheduled__2023-11-27T00:00:00+00:00 [queued]>
[2023-12-01T12:11:36.451+0000] {taskinstance.py:1159} INFO - Dependencies all met for dep_context=requeueable deps ti=<TaskInstance: ingest_to_gcs_bucket.PostgresToGCS1 scheduled__2023-11-27T00:00:00+00:00 [queued]>
[2023-12-01T12:11:36.452+0000] {taskinstance.py:1361} INFO - Starting attempt 1 of 3
[2023-12-01T12:11:36.486+0000] {taskinstance.py:1382} INFO - Executing <Task(PythonOperator): PostgresToGCS1> on 2023-11-27 00:00:00+00:00
[2023-12-01T12:11:36.492+0000] {standard_task_runner.py:57} INFO - Started process 284 to run task
[2023-12-01T12:11:36.496+0000] {standard_task_runner.py:84} INFO - Running: ['airflow', 'tasks', 'run', 'ingest_to_gcs_bucket', 'PostgresToGCS1', 'scheduled__2023-11-27T00:00:00+00:00', '--job-id', '229', '--raw', '--subdir', 'DAGS_FOLDER/postgres_to_gcs_staging.py', '--cfg-path', '/tmp/tmpf30q284d']
[2023-12-01T12:11:36.499+0000] {standard_task_runner.py:85} INFO - Job 229: Subtask PostgresToGCS1
[2023-12-01T12:11:36.567+0000] {task_command.py:416} INFO - Running <TaskInstance: ingest_to_gcs_bucket.PostgresToGCS1 scheduled__2023-11-27T00:00:00+00:00 [running]> on host 40ff33dd73db
[2023-12-01T12:11:36.690+0000] {taskinstance.py:1662} INFO - Exporting env vars: AIRFLOW_CTX_DAG_EMAIL='franklinmutwiri41@gmail.com' AIRFLOW_CTX_DAG_OWNER='airflow' AIRFLOW_CTX_DAG_ID='ingest_to_gcs_bucket' AIRFLOW_CTX_TASK_ID='PostgresToGCS1' AIRFLOW_CTX_EXECUTION_DATE='2023-11-27T00:00:00+00:00' AIRFLOW_CTX_TRY_NUMBER='1' AIRFLOW_CTX_DAG_RUN_ID='scheduled__2023-11-27T00:00:00+00:00'
[2023-12-01T12:11:36.691+0000] {logging_mixin.py:151} INFO - Current working directory: /opt/airflow
[2023-12-01T12:11:36.705+0000] {connection.py:232} WARNING - Connection schemes (type: google_cloud_platform) shall not contain '_' according to RFC3986.
[2023-12-01T12:11:36.710+0000] {base.py:73} INFO - Using connection ID 'google_cloud_default' for task execution.
[2023-12-01T12:11:36.724+0000] {base.py:73} INFO - Using connection ID 'postgres_docker_conn' for task execution.
[2023-12-01T12:11:36.736+0000] {base.py:73} INFO - Using connection ID 'postgres_docker_conn' for task execution.
[2023-12-01T12:11:36.746+0000] {postgres_to_gcs_staging.py:42} INFO - Uploading to bucket, course.csv
[2023-12-01T12:11:36.760+0000] {taskinstance.py:1937} ERROR - Task failed with exception
Traceback (most recent call last):
  File "/home/airflow/.local/lib/python3.8/site-packages/airflow/operators/python.py", line 192, in execute
    return_value = self.execute_callable()
  File "/home/airflow/.local/lib/python3.8/site-packages/airflow/operators/python.py", line 209, in execute_callable
    return self.python_callable(*self.op_args, **self.op_kwargs)
  File "/opt/airflow/dags/postgres_to_gcs_staging.py", line 43, in Postgres_To_GCS1
    gcs_hook.upload(BUCKET, table + ".csv", table + ".csv")
  File "/home/airflow/.local/lib/python3.8/site-packages/airflow/providers/google/cloud/hooks/gcs.py", line 530, in upload
    client = self.get_conn()
  File "/home/airflow/.local/lib/python3.8/site-packages/airflow/providers/google/cloud/hooks/gcs.py", line 173, in get_conn
    credentials=self.get_credentials(), client_info=CLIENT_INFO, project=self.project_id
  File "/home/airflow/.local/lib/python3.8/site-packages/airflow/providers/google/common/hooks/base_google.py", line 296, in get_credentials
    credentials, _ = self.get_credentials_and_project_id()
  File "/home/airflow/.local/lib/python3.8/site-packages/airflow/providers/google/common/hooks/base_google.py", line 273, in get_credentials_and_project_id
    credentials, project_id = get_credentials_and_project_id(
  File "/home/airflow/.local/lib/python3.8/site-packages/airflow/providers/google/cloud/utils/credentials_provider.py", line 362, in get_credentials_and_project_id
    return _CredentialProvider(*args, **kwargs).get_credentials_and_project()
  File "/home/airflow/.local/lib/python3.8/site-packages/airflow/providers/google/cloud/utils/credentials_provider.py", line 213, in __init__
    raise AirflowException(
airflow.exceptions.AirflowException: The `keyfile_dict`, `key_path`, and `key_secret_name` fields are all mutually exclusive. Please provide only one value.
[2023-12-01T12:11:36.764+0000] {taskinstance.py:1400} INFO - Marking task as UP_FOR_RETRY. dag_id=ingest_to_gcs_bucket, task_id=PostgresToGCS1, execution_date=20231127T000000, start_date=20231201T121136, end_date=20231201T121136
[2023-12-01T12:11:36.801+0000] {logging_mixin.py:151} WARNING - /home/***/.local/lib/python3.8/site-packages/***/utils/email.py:154 RemovedInAirflow3Warning: Fetching SMTP credentials from configuration variables will be deprecated in a future release. Please set credentials using a connection instead.
[2023-12-01T12:11:36.802+0000] {configuration.py:1068} WARNING - section/key [smtp/smtp_user] not found in config
[2023-12-01T12:11:36.802+0000] {email.py:270} INFO - Email alerting: attempt 1
[2023-12-01T12:11:36.814+0000] {configuration.py:1068} WARNING - section/key [smtp/smtp_user] not found in config
[2023-12-01T12:11:36.815+0000] {email.py:270} INFO - Email alerting: attempt 1
[2023-12-01T12:11:36.815+0000] {taskinstance.py:2007} ERROR - Failed to send email to: ['franklinmutwiri41@gmail.com']
Traceback (most recent call last):
  File "/home/airflow/.local/lib/python3.8/site-packages/airflow/models/taskinstance.py", line 1518, in _run_raw_task
    self._execute_task_with_callbacks(context, test_mode, session=session)
  File "/home/airflow/.local/lib/python3.8/site-packages/airflow/models/taskinstance.py", line 1681, in _execute_task_with_callbacks
    result = self._execute_task(context, task_orig)
  File "/home/airflow/.local/lib/python3.8/site-packages/airflow/models/taskinstance.py", line 1744, in _execute_task
    result = execute_callable(context=context, **execute_callable_kwargs)
  File "/home/airflow/.local/lib/python3.8/site-packages/airflow/operators/python.py", line 192, in execute
    return_value = self.execute_callable()
  File "/home/airflow/.local/lib/python3.8/site-packages/airflow/operators/python.py", line 209, in execute_callable
    return self.python_callable(*self.op_args, **self.op_kwargs)
  File "/opt/airflow/dags/postgres_to_gcs_staging.py", line 43, in Postgres_To_GCS1
    gcs_hook.upload(BUCKET, table + ".csv", table + ".csv")
  File "/home/airflow/.local/lib/python3.8/site-packages/airflow/providers/google/cloud/hooks/gcs.py", line 530, in upload
    client = self.get_conn()
  File "/home/airflow/.local/lib/python3.8/site-packages/airflow/providers/google/cloud/hooks/gcs.py", line 173, in get_conn
    credentials=self.get_credentials(), client_info=CLIENT_INFO, project=self.project_id
  File "/home/airflow/.local/lib/python3.8/site-packages/airflow/providers/google/common/hooks/base_google.py", line 296, in get_credentials
    credentials, _ = self.get_credentials_and_project_id()
  File "/home/airflow/.local/lib/python3.8/site-packages/airflow/providers/google/common/hooks/base_google.py", line 273, in get_credentials_and_project_id
    credentials, project_id = get_credentials_and_project_id(
  File "/home/airflow/.local/lib/python3.8/site-packages/airflow/providers/google/cloud/utils/credentials_provider.py", line 362, in get_credentials_and_project_id
    return _CredentialProvider(*args, **kwargs).get_credentials_and_project()
  File "/home/airflow/.local/lib/python3.8/site-packages/airflow/providers/google/cloud/utils/credentials_provider.py", line 213, in __init__
    raise AirflowException(
airflow.exceptions.AirflowException: The `keyfile_dict`, `key_path`, and `key_secret_name` fields are all mutually exclusive. Please provide only one value.

During handling of the above exception, another exception occurred:

Traceback (most recent call last):
  File "/home/airflow/.local/lib/python3.8/site-packages/airflow/models/taskinstance.py", line 2420, in email_alert
    send_email(task.email, subject, html_content)
  File "/home/airflow/.local/lib/python3.8/site-packages/airflow/utils/email.py", line 80, in send_email
    return backend(
  File "/home/airflow/.local/lib/python3.8/site-packages/airflow/utils/email.py", line 154, in send_email_smtp
    send_mime_email(e_from=mail_from, e_to=recipients, mime_msg=msg, conn_id=conn_id, dryrun=dryrun)
  File "/home/airflow/.local/lib/python3.8/site-packages/airflow/utils/email.py", line 272, in send_mime_email
    smtp_conn = _get_smtp_connection(smtp_host, smtp_port, smtp_timeout, smtp_ssl)
  File "/home/airflow/.local/lib/python3.8/site-packages/airflow/utils/email.py", line 316, in _get_smtp_connection
    return smtplib.SMTP(host=host, port=port, timeout=timeout)
  File "/usr/local/lib/python3.8/smtplib.py", line 255, in __init__
    (code, msg) = self.connect(host, port)
  File "/usr/local/lib/python3.8/smtplib.py", line 339, in connect
    self.sock = self._get_socket(host, port, self.timeout)
  File "/usr/local/lib/python3.8/smtplib.py", line 310, in _get_socket
    return socket.create_connection((host, port), timeout,
  File "/usr/local/lib/python3.8/socket.py", line 808, in create_connection
    raise err
  File "/usr/local/lib/python3.8/socket.py", line 796, in create_connection
    sock.connect(sa)
OSError: [Errno 99] Cannot assign requested address

During handling of the above exception, another exception occurred:

Traceback (most recent call last):
  File "/home/airflow/.local/lib/python3.8/site-packages/airflow/models/taskinstance.py", line 2005, in handle_failure
    self.email_alert(error, task)
  File "/home/airflow/.local/lib/python3.8/site-packages/airflow/models/taskinstance.py", line 2422, in email_alert
    send_email(task.email, subject, html_content_err)
  File "/home/airflow/.local/lib/python3.8/site-packages/airflow/utils/email.py", line 80, in send_email
    return backend(
  File "/home/airflow/.local/lib/python3.8/site-packages/airflow/utils/email.py", line 154, in send_email_smtp
    send_mime_email(e_from=mail_from, e_to=recipients, mime_msg=msg, conn_id=conn_id, dryrun=dryrun)
  File "/home/airflow/.local/lib/python3.8/site-packages/airflow/utils/email.py", line 272, in send_mime_email
    smtp_conn = _get_smtp_connection(smtp_host, smtp_port, smtp_timeout, smtp_ssl)
  File "/home/airflow/.local/lib/python3.8/site-packages/airflow/utils/email.py", line 316, in _get_smtp_connection
    return smtplib.SMTP(host=host, port=port, timeout=timeout)
  File "/usr/local/lib/python3.8/smtplib.py", line 255, in __init__
    (code, msg) = self.connect(host, port)
  File "/usr/local/lib/python3.8/smtplib.py", line 339, in connect
    self.sock = self._get_socket(host, port, self.timeout)
  File "/usr/local/lib/python3.8/smtplib.py", line 310, in _get_socket
    return socket.create_connection((host, port), timeout,
  File "/usr/local/lib/python3.8/socket.py", line 808, in create_connection
    raise err
  File "/usr/local/lib/python3.8/socket.py", line 796, in create_connection
    sock.connect(sa)
OSError: [Errno 99] Cannot assign requested address
[2023-12-01T12:11:36.840+0000] {standard_task_runner.py:104} ERROR - Failed to execute job 229 for task PostgresToGCS1 (The `keyfile_dict`, `key_path`, and `key_secret_name` fields are all mutually exclusive. Please provide only one value.; 284)
[2023-12-01T12:11:36.869+0000] {local_task_job_runner.py:228} INFO - Task exited with return code 1
[2023-12-01T12:11:36.935+0000] {taskinstance.py:2778} INFO - 0 downstream tasks scheduled from follow-on schedule check
[2023-12-01T12:22:06.322+0000] {taskinstance.py:1159} INFO - Dependencies all met for dep_context=non-requeueable deps ti=<TaskInstance: ingest_to_gcs_bucket.PostgresToGCS1 scheduled__2023-11-27T00:00:00+00:00 [queued]>
[2023-12-01T12:22:06.356+0000] {taskinstance.py:1159} INFO - Dependencies all met for dep_context=requeueable deps ti=<TaskInstance: ingest_to_gcs_bucket.PostgresToGCS1 scheduled__2023-11-27T00:00:00+00:00 [queued]>
[2023-12-01T12:22:06.356+0000] {taskinstance.py:1361} INFO - Starting attempt 1 of 3
[2023-12-01T12:22:06.390+0000] {taskinstance.py:1382} INFO - Executing <Task(PythonOperator): PostgresToGCS1> on 2023-11-27 00:00:00+00:00
[2023-12-01T12:22:06.395+0000] {standard_task_runner.py:57} INFO - Started process 548 to run task
[2023-12-01T12:22:06.399+0000] {standard_task_runner.py:84} INFO - Running: ['airflow', 'tasks', 'run', 'ingest_to_gcs_bucket', 'PostgresToGCS1', 'scheduled__2023-11-27T00:00:00+00:00', '--job-id', '233', '--raw', '--subdir', 'DAGS_FOLDER/postgres_to_gcs_staging.py', '--cfg-path', '/tmp/tmpzu928ftk']
[2023-12-01T12:22:06.402+0000] {standard_task_runner.py:85} INFO - Job 233: Subtask PostgresToGCS1
[2023-12-01T12:22:06.469+0000] {task_command.py:416} INFO - Running <TaskInstance: ingest_to_gcs_bucket.PostgresToGCS1 scheduled__2023-11-27T00:00:00+00:00 [running]> on host 40ff33dd73db
[2023-12-01T12:22:06.650+0000] {taskinstance.py:1662} INFO - Exporting env vars: AIRFLOW_CTX_DAG_EMAIL='franklinmutwiri41@gmail.com' AIRFLOW_CTX_DAG_OWNER='airflow' AIRFLOW_CTX_DAG_ID='ingest_to_gcs_bucket' AIRFLOW_CTX_TASK_ID='PostgresToGCS1' AIRFLOW_CTX_EXECUTION_DATE='2023-11-27T00:00:00+00:00' AIRFLOW_CTX_TRY_NUMBER='1' AIRFLOW_CTX_DAG_RUN_ID='scheduled__2023-11-27T00:00:00+00:00'
[2023-12-01T12:22:06.652+0000] {logging_mixin.py:151} INFO - Current working directory: /opt/airflow
[2023-12-01T12:22:06.665+0000] {connection.py:232} WARNING - Connection schemes (type: google_cloud_platform) shall not contain '_' according to RFC3986.
[2023-12-01T12:22:06.666+0000] {base.py:73} INFO - Using connection ID 'google_cloud_conn' for task execution.
[2023-12-01T12:22:06.678+0000] {base.py:73} INFO - Using connection ID 'postgres_docker_conn' for task execution.
[2023-12-01T12:22:06.691+0000] {base.py:73} INFO - Using connection ID 'postgres_docker_conn' for task execution.
[2023-12-01T12:22:06.700+0000] {postgres_to_gcs_staging.py:42} INFO - Uploading to bucket, course.csv
[2023-12-01T12:22:06.771+0000] {taskinstance.py:1937} ERROR - Task failed with exception
Traceback (most recent call last):
  File "/home/airflow/.local/lib/python3.8/site-packages/airflow/operators/python.py", line 192, in execute
    return_value = self.execute_callable()
  File "/home/airflow/.local/lib/python3.8/site-packages/airflow/operators/python.py", line 209, in execute_callable
    return self.python_callable(*self.op_args, **self.op_kwargs)
  File "/opt/airflow/dags/postgres_to_gcs_staging.py", line 43, in Postgres_To_GCS1
    gcs_hook.upload(BUCKET, table + ".csv", table + ".csv")
  File "/home/airflow/.local/lib/python3.8/site-packages/airflow/providers/google/cloud/hooks/gcs.py", line 556, in upload
    _call_with_retry(
  File "/home/airflow/.local/lib/python3.8/site-packages/airflow/providers/google/cloud/hooks/gcs.py", line 514, in _call_with_retry
    f()
  File "/home/airflow/.local/lib/python3.8/site-packages/google/cloud/storage/blob.py", line 2924, in upload_from_filename
    self._handle_filename_and_upload(
  File "/home/airflow/.local/lib/python3.8/site-packages/google/cloud/storage/blob.py", line 2794, in _handle_filename_and_upload
    self._prep_and_do_upload(
  File "/home/airflow/.local/lib/python3.8/site-packages/google/cloud/storage/blob.py", line 2602, in _prep_and_do_upload
    created_json = self._do_upload(
  File "/home/airflow/.local/lib/python3.8/site-packages/google/cloud/storage/blob.py", line 2408, in _do_upload
    response = self._do_multipart_upload(
  File "/home/airflow/.local/lib/python3.8/site-packages/google/cloud/storage/blob.py", line 1879, in _do_multipart_upload
    hostname=hostname, bucket_path=self.bucket.path, api_version=_API_VERSION
  File "/home/airflow/.local/lib/python3.8/site-packages/google/cloud/storage/bucket.py", line 1167, in path
    raise ValueError("Cannot determine path without bucket name.")
ValueError: Cannot determine path without bucket name.
[2023-12-01T12:22:06.787+0000] {taskinstance.py:1400} INFO - Marking task as UP_FOR_RETRY. dag_id=ingest_to_gcs_bucket, task_id=PostgresToGCS1, execution_date=20231127T000000, start_date=20231201T122206, end_date=20231201T122206
[2023-12-01T12:22:06.804+0000] {logging_mixin.py:151} WARNING - /home/***/.local/lib/python3.8/site-packages/***/utils/email.py:154 RemovedInAirflow3Warning: Fetching SMTP credentials from configuration variables will be deprecated in a future release. Please set credentials using a connection instead.
[2023-12-01T12:22:06.804+0000] {configuration.py:1068} WARNING - section/key [smtp/smtp_user] not found in config
[2023-12-01T12:22:06.804+0000] {email.py:270} INFO - Email alerting: attempt 1
[2023-12-01T12:22:06.816+0000] {configuration.py:1068} WARNING - section/key [smtp/smtp_user] not found in config
[2023-12-01T12:22:06.817+0000] {email.py:270} INFO - Email alerting: attempt 1
[2023-12-01T12:22:06.817+0000] {taskinstance.py:2007} ERROR - Failed to send email to: ['franklinmutwiri41@gmail.com']
Traceback (most recent call last):
  File "/home/airflow/.local/lib/python3.8/site-packages/airflow/models/taskinstance.py", line 1518, in _run_raw_task
    self._execute_task_with_callbacks(context, test_mode, session=session)
  File "/home/airflow/.local/lib/python3.8/site-packages/airflow/models/taskinstance.py", line 1681, in _execute_task_with_callbacks
    result = self._execute_task(context, task_orig)
  File "/home/airflow/.local/lib/python3.8/site-packages/airflow/models/taskinstance.py", line 1744, in _execute_task
    result = execute_callable(context=context, **execute_callable_kwargs)
  File "/home/airflow/.local/lib/python3.8/site-packages/airflow/operators/python.py", line 192, in execute
    return_value = self.execute_callable()
  File "/home/airflow/.local/lib/python3.8/site-packages/airflow/operators/python.py", line 209, in execute_callable
    return self.python_callable(*self.op_args, **self.op_kwargs)
  File "/opt/airflow/dags/postgres_to_gcs_staging.py", line 43, in Postgres_To_GCS1
    gcs_hook.upload(BUCKET, table + ".csv", table + ".csv")
  File "/home/airflow/.local/lib/python3.8/site-packages/airflow/providers/google/cloud/hooks/gcs.py", line 556, in upload
    _call_with_retry(
  File "/home/airflow/.local/lib/python3.8/site-packages/airflow/providers/google/cloud/hooks/gcs.py", line 514, in _call_with_retry
    f()
  File "/home/airflow/.local/lib/python3.8/site-packages/google/cloud/storage/blob.py", line 2924, in upload_from_filename
    self._handle_filename_and_upload(
  File "/home/airflow/.local/lib/python3.8/site-packages/google/cloud/storage/blob.py", line 2794, in _handle_filename_and_upload
    self._prep_and_do_upload(
  File "/home/airflow/.local/lib/python3.8/site-packages/google/cloud/storage/blob.py", line 2602, in _prep_and_do_upload
    created_json = self._do_upload(
  File "/home/airflow/.local/lib/python3.8/site-packages/google/cloud/storage/blob.py", line 2408, in _do_upload
    response = self._do_multipart_upload(
  File "/home/airflow/.local/lib/python3.8/site-packages/google/cloud/storage/blob.py", line 1879, in _do_multipart_upload
    hostname=hostname, bucket_path=self.bucket.path, api_version=_API_VERSION
  File "/home/airflow/.local/lib/python3.8/site-packages/google/cloud/storage/bucket.py", line 1167, in path
    raise ValueError("Cannot determine path without bucket name.")
ValueError: Cannot determine path without bucket name.

During handling of the above exception, another exception occurred:

Traceback (most recent call last):
  File "/home/airflow/.local/lib/python3.8/site-packages/airflow/models/taskinstance.py", line 2420, in email_alert
    send_email(task.email, subject, html_content)
  File "/home/airflow/.local/lib/python3.8/site-packages/airflow/utils/email.py", line 80, in send_email
    return backend(
  File "/home/airflow/.local/lib/python3.8/site-packages/airflow/utils/email.py", line 154, in send_email_smtp
    send_mime_email(e_from=mail_from, e_to=recipients, mime_msg=msg, conn_id=conn_id, dryrun=dryrun)
  File "/home/airflow/.local/lib/python3.8/site-packages/airflow/utils/email.py", line 272, in send_mime_email
    smtp_conn = _get_smtp_connection(smtp_host, smtp_port, smtp_timeout, smtp_ssl)
  File "/home/airflow/.local/lib/python3.8/site-packages/airflow/utils/email.py", line 316, in _get_smtp_connection
    return smtplib.SMTP(host=host, port=port, timeout=timeout)
  File "/usr/local/lib/python3.8/smtplib.py", line 255, in __init__
    (code, msg) = self.connect(host, port)
  File "/usr/local/lib/python3.8/smtplib.py", line 339, in connect
    self.sock = self._get_socket(host, port, self.timeout)
  File "/usr/local/lib/python3.8/smtplib.py", line 310, in _get_socket
    return socket.create_connection((host, port), timeout,
  File "/usr/local/lib/python3.8/socket.py", line 808, in create_connection
    raise err
  File "/usr/local/lib/python3.8/socket.py", line 796, in create_connection
    sock.connect(sa)
OSError: [Errno 99] Cannot assign requested address

During handling of the above exception, another exception occurred:

Traceback (most recent call last):
  File "/home/airflow/.local/lib/python3.8/site-packages/airflow/models/taskinstance.py", line 2005, in handle_failure
    self.email_alert(error, task)
  File "/home/airflow/.local/lib/python3.8/site-packages/airflow/models/taskinstance.py", line 2422, in email_alert
    send_email(task.email, subject, html_content_err)
  File "/home/airflow/.local/lib/python3.8/site-packages/airflow/utils/email.py", line 80, in send_email
    return backend(
  File "/home/airflow/.local/lib/python3.8/site-packages/airflow/utils/email.py", line 154, in send_email_smtp
    send_mime_email(e_from=mail_from, e_to=recipients, mime_msg=msg, conn_id=conn_id, dryrun=dryrun)
  File "/home/airflow/.local/lib/python3.8/site-packages/airflow/utils/email.py", line 272, in send_mime_email
    smtp_conn = _get_smtp_connection(smtp_host, smtp_port, smtp_timeout, smtp_ssl)
  File "/home/airflow/.local/lib/python3.8/site-packages/airflow/utils/email.py", line 316, in _get_smtp_connection
    return smtplib.SMTP(host=host, port=port, timeout=timeout)
  File "/usr/local/lib/python3.8/smtplib.py", line 255, in __init__
    (code, msg) = self.connect(host, port)
  File "/usr/local/lib/python3.8/smtplib.py", line 339, in connect
    self.sock = self._get_socket(host, port, self.timeout)
  File "/usr/local/lib/python3.8/smtplib.py", line 310, in _get_socket
    return socket.create_connection((host, port), timeout,
  File "/usr/local/lib/python3.8/socket.py", line 808, in create_connection
    raise err
  File "/usr/local/lib/python3.8/socket.py", line 796, in create_connection
    sock.connect(sa)
OSError: [Errno 99] Cannot assign requested address
[2023-12-01T12:22:06.854+0000] {standard_task_runner.py:104} ERROR - Failed to execute job 233 for task PostgresToGCS1 (Cannot determine path without bucket name.; 548)
[2023-12-01T12:22:06.892+0000] {local_task_job_runner.py:228} INFO - Task exited with return code 1
[2023-12-01T12:22:06.923+0000] {taskinstance.py:2778} INFO - 0 downstream tasks scheduled from follow-on schedule check
[2023-12-01T12:53:02.648+0000] {taskinstance.py:1159} INFO - Dependencies all met for dep_context=non-requeueable deps ti=<TaskInstance: ingest_to_gcs_bucket.PostgresToGCS1 scheduled__2023-11-27T00:00:00+00:00 [queued]>
[2023-12-01T12:53:02.685+0000] {taskinstance.py:1159} INFO - Dependencies all met for dep_context=requeueable deps ti=<TaskInstance: ingest_to_gcs_bucket.PostgresToGCS1 scheduled__2023-11-27T00:00:00+00:00 [queued]>
[2023-12-01T12:53:02.685+0000] {taskinstance.py:1361} INFO - Starting attempt 1 of 3
[2023-12-01T12:53:02.712+0000] {taskinstance.py:1382} INFO - Executing <Task(PythonOperator): PostgresToGCS1> on 2023-11-27 00:00:00+00:00
[2023-12-01T12:53:02.718+0000] {standard_task_runner.py:57} INFO - Started process 1314 to run task
[2023-12-01T12:53:02.722+0000] {standard_task_runner.py:84} INFO - Running: ['airflow', 'tasks', 'run', 'ingest_to_gcs_bucket', 'PostgresToGCS1', 'scheduled__2023-11-27T00:00:00+00:00', '--job-id', '236', '--raw', '--subdir', 'DAGS_FOLDER/postgres_to_gcs_staging.py', '--cfg-path', '/tmp/tmpe1a330g2']
[2023-12-01T12:53:02.725+0000] {standard_task_runner.py:85} INFO - Job 236: Subtask PostgresToGCS1
[2023-12-01T12:53:02.986+0000] {task_command.py:416} INFO - Running <TaskInstance: ingest_to_gcs_bucket.PostgresToGCS1 scheduled__2023-11-27T00:00:00+00:00 [running]> on host 40ff33dd73db
[2023-12-01T12:53:03.151+0000] {taskinstance.py:1662} INFO - Exporting env vars: AIRFLOW_CTX_DAG_EMAIL='franklinmutwiri41@gmail.com' AIRFLOW_CTX_DAG_OWNER='airflow' AIRFLOW_CTX_DAG_ID='ingest_to_gcs_bucket' AIRFLOW_CTX_TASK_ID='PostgresToGCS1' AIRFLOW_CTX_EXECUTION_DATE='2023-11-27T00:00:00+00:00' AIRFLOW_CTX_TRY_NUMBER='1' AIRFLOW_CTX_DAG_RUN_ID='scheduled__2023-11-27T00:00:00+00:00'
[2023-12-01T12:53:03.152+0000] {logging_mixin.py:151} INFO - Current working directory: /opt/airflow
[2023-12-01T12:53:03.171+0000] {connection.py:232} WARNING - Connection schemes (type: google_cloud_platform) shall not contain '_' according to RFC3986.
[2023-12-01T12:53:03.173+0000] {base.py:73} INFO - Using connection ID 'google_cloud_conn' for task execution.
[2023-12-01T12:53:03.190+0000] {base.py:73} INFO - Using connection ID 'postgres_docker_conn' for task execution.
[2023-12-01T12:53:03.206+0000] {base.py:73} INFO - Using connection ID 'postgres_docker_conn' for task execution.
[2023-12-01T12:53:03.231+0000] {postgres_to_gcs_staging.py:42} INFO - Uploading to bucket, course.csv
[2023-12-01T12:53:05.555+0000] {gcs.py:562} INFO - File course.csv uploaded to course.csv in school_data_lake_data-warehousing-proj bucket
[2023-12-01T12:53:05.571+0000] {connection.py:232} WARNING - Connection schemes (type: google_cloud_platform) shall not contain '_' according to RFC3986.
[2023-12-01T12:53:05.572+0000] {base.py:73} INFO - Using connection ID 'google_cloud_conn' for task execution.
[2023-12-01T12:53:05.588+0000] {base.py:73} INFO - Using connection ID 'postgres_docker_conn' for task execution.
[2023-12-01T12:53:05.603+0000] {base.py:73} INFO - Using connection ID 'postgres_docker_conn' for task execution.
[2023-12-01T12:53:05.616+0000] {postgres_to_gcs_staging.py:42} INFO - Uploading to bucket, country.csv
[2023-12-01T12:53:07.267+0000] {gcs.py:562} INFO - File country.csv uploaded to country.csv in school_data_lake_data-warehousing-proj bucket
[2023-12-01T12:53:07.278+0000] {connection.py:232} WARNING - Connection schemes (type: google_cloud_platform) shall not contain '_' according to RFC3986.
[2023-12-01T12:53:07.279+0000] {base.py:73} INFO - Using connection ID 'google_cloud_conn' for task execution.
[2023-12-01T12:53:07.291+0000] {base.py:73} INFO - Using connection ID 'postgres_docker_conn' for task execution.
[2023-12-01T12:53:07.304+0000] {base.py:73} INFO - Using connection ID 'postgres_docker_conn' for task execution.
[2023-12-01T12:53:07.316+0000] {postgres_to_gcs_staging.py:42} INFO - Uploading to bucket, department.csv
[2023-12-01T12:53:08.947+0000] {gcs.py:562} INFO - File department.csv uploaded to department.csv in school_data_lake_data-warehousing-proj bucket
[2023-12-01T12:53:08.947+0000] {python.py:194} INFO - Done. Returned value was: None
[2023-12-01T12:53:08.970+0000] {taskinstance.py:1400} INFO - Marking task as SUCCESS. dag_id=ingest_to_gcs_bucket, task_id=PostgresToGCS1, execution_date=20231127T000000, start_date=20231201T125302, end_date=20231201T125308
[2023-12-01T12:53:09.006+0000] {local_task_job_runner.py:228} INFO - Task exited with return code 0
[2023-12-01T12:53:09.031+0000] {taskinstance.py:2778} INFO - 0 downstream tasks scheduled from follow-on schedule check
[2023-12-01T16:51:18.314+0000] {taskinstance.py:1159} INFO - Dependencies all met for dep_context=non-requeueable deps ti=<TaskInstance: ingest_to_gcs_bucket.PostgresToGCS1 scheduled__2023-11-27T00:00:00+00:00 [queued]>
[2023-12-01T16:51:18.373+0000] {taskinstance.py:1159} INFO - Dependencies all met for dep_context=requeueable deps ti=<TaskInstance: ingest_to_gcs_bucket.PostgresToGCS1 scheduled__2023-11-27T00:00:00+00:00 [queued]>
[2023-12-01T16:51:18.373+0000] {taskinstance.py:1361} INFO - Starting attempt 1 of 3
[2023-12-01T16:51:18.423+0000] {taskinstance.py:1382} INFO - Executing <Task(PythonOperator): PostgresToGCS1> on 2023-11-27 00:00:00+00:00
[2023-12-01T16:51:18.434+0000] {standard_task_runner.py:57} INFO - Started process 6565 to run task
[2023-12-01T16:51:18.441+0000] {standard_task_runner.py:84} INFO - Running: ['airflow', 'tasks', 'run', 'ingest_to_gcs_bucket', 'PostgresToGCS1', 'scheduled__2023-11-27T00:00:00+00:00', '--job-id', '242', '--raw', '--subdir', 'DAGS_FOLDER/postgres_to_gcs_staging.py', '--cfg-path', '/tmp/tmp05qayq7n']
[2023-12-01T16:51:18.445+0000] {standard_task_runner.py:85} INFO - Job 242: Subtask PostgresToGCS1
[2023-12-01T16:51:18.614+0000] {task_command.py:416} INFO - Running <TaskInstance: ingest_to_gcs_bucket.PostgresToGCS1 scheduled__2023-11-27T00:00:00+00:00 [running]> on host 40ff33dd73db
[2023-12-01T16:51:19.506+0000] {taskinstance.py:1662} INFO - Exporting env vars: AIRFLOW_CTX_DAG_EMAIL='franklinmutwiri41@gmail.com' AIRFLOW_CTX_DAG_OWNER='airflow' AIRFLOW_CTX_DAG_ID='ingest_to_gcs_bucket' AIRFLOW_CTX_TASK_ID='PostgresToGCS1' AIRFLOW_CTX_EXECUTION_DATE='2023-11-27T00:00:00+00:00' AIRFLOW_CTX_TRY_NUMBER='1' AIRFLOW_CTX_DAG_RUN_ID='scheduled__2023-11-27T00:00:00+00:00'
[2023-12-01T16:51:19.512+0000] {logging_mixin.py:151} INFO - Current working directory: /opt/airflow
[2023-12-01T16:51:19.538+0000] {connection.py:232} WARNING - Connection schemes (type: google_cloud_platform) shall not contain '_' according to RFC3986.
[2023-12-01T16:51:19.540+0000] {base.py:73} INFO - Using connection ID 'google_cloud_conn' for task execution.
[2023-12-01T16:51:19.567+0000] {base.py:73} INFO - Using connection ID 'postgres_docker_conn' for task execution.
[2023-12-01T16:51:19.699+0000] {base.py:73} INFO - Using connection ID 'postgres_docker_conn' for task execution.
[2023-12-01T16:51:19.956+0000] {postgres_to_gcs_staging.py:44} INFO - Uploading to bucket, course.csv
[2023-12-01T16:51:23.734+0000] {gcs.py:562} INFO - File course.csv uploaded to course.csv in school_data_lake_data-warehousing-proj bucket
[2023-12-01T16:51:23.788+0000] {connection.py:232} WARNING - Connection schemes (type: google_cloud_platform) shall not contain '_' according to RFC3986.
[2023-12-01T16:51:23.794+0000] {base.py:73} INFO - Using connection ID 'google_cloud_conn' for task execution.
[2023-12-01T16:51:23.814+0000] {base.py:73} INFO - Using connection ID 'postgres_docker_conn' for task execution.
[2023-12-01T16:51:23.835+0000] {base.py:73} INFO - Using connection ID 'postgres_docker_conn' for task execution.
[2023-12-01T16:51:23.858+0000] {postgres_to_gcs_staging.py:44} INFO - Uploading to bucket, country.csv
[2023-12-01T16:51:25.532+0000] {gcs.py:562} INFO - File country.csv uploaded to country.csv in school_data_lake_data-warehousing-proj bucket
[2023-12-01T16:51:25.553+0000] {connection.py:232} WARNING - Connection schemes (type: google_cloud_platform) shall not contain '_' according to RFC3986.
[2023-12-01T16:51:25.554+0000] {base.py:73} INFO - Using connection ID 'google_cloud_conn' for task execution.
[2023-12-01T16:51:25.575+0000] {base.py:73} INFO - Using connection ID 'postgres_docker_conn' for task execution.
[2023-12-01T16:51:25.597+0000] {base.py:73} INFO - Using connection ID 'postgres_docker_conn' for task execution.
[2023-12-01T16:51:25.622+0000] {postgres_to_gcs_staging.py:44} INFO - Uploading to bucket, department.csv
[2023-12-01T16:51:27.314+0000] {gcs.py:562} INFO - File department.csv uploaded to department.csv in school_data_lake_data-warehousing-proj bucket
[2023-12-01T16:51:27.314+0000] {python.py:194} INFO - Done. Returned value was: None
[2023-12-01T16:51:27.330+0000] {taskinstance.py:1400} INFO - Marking task as SUCCESS. dag_id=ingest_to_gcs_bucket, task_id=PostgresToGCS1, execution_date=20231127T000000, start_date=20231201T165118, end_date=20231201T165127
[2023-12-01T16:51:27.374+0000] {local_task_job_runner.py:228} INFO - Task exited with return code 0
[2023-12-01T16:51:27.409+0000] {taskinstance.py:2778} INFO - 1 downstream tasks scheduled from follow-on schedule check
