[2024-01-07T15:59:27.158+0000] {taskinstance.py:1159} INFO - Dependencies all met for dep_context=non-requeueable deps ti=<TaskInstance: ingest_from_postgres_to_GCS_bucket.copy_course_Postgres_To_GCS scheduled__2024-01-05T00:00:00+00:00 [queued]>
[2024-01-07T15:59:27.174+0000] {taskinstance.py:1159} INFO - Dependencies all met for dep_context=requeueable deps ti=<TaskInstance: ingest_from_postgres_to_GCS_bucket.copy_course_Postgres_To_GCS scheduled__2024-01-05T00:00:00+00:00 [queued]>
[2024-01-07T15:59:27.175+0000] {taskinstance.py:1361} INFO - Starting attempt 3 of 3
[2024-01-07T15:59:27.197+0000] {taskinstance.py:1382} INFO - Executing <Task(PythonOperator): copy_course_Postgres_To_GCS> on 2024-01-05 00:00:00+00:00
[2024-01-07T15:59:27.206+0000] {standard_task_runner.py:57} INFO - Started process 4475 to run task
[2024-01-07T15:59:27.211+0000] {standard_task_runner.py:84} INFO - Running: ['***', 'tasks', 'run', 'ingest_from_postgres_to_GCS_bucket', 'copy_course_Postgres_To_GCS', 'scheduled__2024-01-05T00:00:00+00:00', '--job-id', '371', '--raw', '--subdir', 'DAGS_FOLDER/postgres_to_gcs_staging.py', '--cfg-path', '/tmp/tmpz6gc3t5u']
[2024-01-07T15:59:27.217+0000] {standard_task_runner.py:85} INFO - Job 371: Subtask copy_course_Postgres_To_GCS
[2024-01-07T15:59:27.298+0000] {task_command.py:416} INFO - Running <TaskInstance: ingest_from_postgres_to_GCS_bucket.copy_course_Postgres_To_GCS scheduled__2024-01-05T00:00:00+00:00 [running]> on host 5d007c0b4985
[2024-01-07T15:59:27.426+0000] {taskinstance.py:1662} INFO - Exporting env vars: AIRFLOW_CTX_DAG_EMAIL='franklinmutwiri41@gmail.com' AIRFLOW_CTX_DAG_OWNER='***' AIRFLOW_CTX_DAG_ID='ingest_from_postgres_to_GCS_bucket' AIRFLOW_CTX_TASK_ID='copy_course_Postgres_To_GCS' AIRFLOW_CTX_EXECUTION_DATE='2024-01-05T00:00:00+00:00' AIRFLOW_CTX_TRY_NUMBER='3' AIRFLOW_CTX_DAG_RUN_ID='scheduled__2024-01-05T00:00:00+00:00'
[2024-01-07T15:59:27.444+0000] {base.py:73} INFO - Using connection ID 'postgres_docker_conn' for task execution.
[2024-01-07T15:59:27.458+0000] {base.py:73} INFO - Using connection ID 'postgres_docker_conn' for task execution.
[2024-01-07T15:59:27.478+0000] {logging_mixin.py:151} WARNING - /home/***/.local/lib/python3.8/site-packages/***/providers/common/sql/hooks/sql.py:219 UserWarning: pandas only supports SQLAlchemy connectable (engine/connection) or database string URI or sqlite3 DBAPI2 connection. Other DBAPI2 objects are not tested. Please consider using SQLAlchemy.
[2024-01-07T15:59:27.484+0000] {postgres_to_gcs_staging.py:52} INFO - Uploading to bucket, course
[2024-01-07T15:59:27.503+0000] {taskinstance.py:1937} ERROR - Task failed with exception
Traceback (most recent call last):
  File "/home/airflow/.local/lib/python3.8/site-packages/airflow/operators/python.py", line 192, in execute
    return_value = self.execute_callable()
  File "/home/airflow/.local/lib/python3.8/site-packages/airflow/operators/python.py", line 209, in execute_callable
    return self.python_callable(*self.op_args, **self.op_kwargs)
  File "/opt/airflow/dags/postgres_to_gcs_staging.py", line 61, in Postgres_To_GCS_Bucket
    date = {{ ds_nodash }}
NameError: name 'ds_nodash' is not defined
[2024-01-07T15:59:27.517+0000] {taskinstance.py:1400} INFO - Marking task as FAILED. dag_id=ingest_from_postgres_to_GCS_bucket, task_id=copy_course_Postgres_To_GCS, execution_date=20240105T000000, start_date=20240107T155927, end_date=20240107T155927
[2024-01-07T15:59:27.531+0000] {logging_mixin.py:151} WARNING - /home/***/.local/lib/python3.8/site-packages/***/utils/email.py:154 RemovedInAirflow3Warning: Fetching SMTP credentials from configuration variables will be deprecated in a future release. Please set credentials using a connection instead.
[2024-01-07T15:59:27.532+0000] {configuration.py:1068} WARNING - section/key [smtp/smtp_user] not found in config
[2024-01-07T15:59:27.532+0000] {email.py:270} INFO - Email alerting: attempt 1
[2024-01-07T15:59:27.544+0000] {configuration.py:1068} WARNING - section/key [smtp/smtp_user] not found in config
[2024-01-07T15:59:27.545+0000] {email.py:270} INFO - Email alerting: attempt 1
[2024-01-07T15:59:27.545+0000] {taskinstance.py:2007} ERROR - Failed to send email to: ['franklinmutwiri41@gmail.com']
Traceback (most recent call last):
  File "/home/airflow/.local/lib/python3.8/site-packages/airflow/models/taskinstance.py", line 1518, in _run_raw_task
    self._execute_task_with_callbacks(context, test_mode, session=session)
  File "/home/airflow/.local/lib/python3.8/site-packages/airflow/models/taskinstance.py", line 1681, in _execute_task_with_callbacks
    result = self._execute_task(context, task_orig)
  File "/home/airflow/.local/lib/python3.8/site-packages/airflow/models/taskinstance.py", line 1744, in _execute_task
    result = execute_callable(context=context, **execute_callable_kwargs)
  File "/home/airflow/.local/lib/python3.8/site-packages/airflow/operators/python.py", line 192, in execute
    return_value = self.execute_callable()
  File "/home/airflow/.local/lib/python3.8/site-packages/airflow/operators/python.py", line 209, in execute_callable
    return self.python_callable(*self.op_args, **self.op_kwargs)
  File "/opt/airflow/dags/postgres_to_gcs_staging.py", line 61, in Postgres_To_GCS_Bucket
    date = {{ ds_nodash }}
NameError: name 'ds_nodash' is not defined

During handling of the above exception, another exception occurred:

Traceback (most recent call last):
  File "/home/airflow/.local/lib/python3.8/site-packages/airflow/models/taskinstance.py", line 2420, in email_alert
    send_email(task.email, subject, html_content)
  File "/home/airflow/.local/lib/python3.8/site-packages/airflow/utils/email.py", line 80, in send_email
    return backend(
  File "/home/airflow/.local/lib/python3.8/site-packages/airflow/utils/email.py", line 154, in send_email_smtp
    send_mime_email(e_from=mail_from, e_to=recipients, mime_msg=msg, conn_id=conn_id, dryrun=dryrun)
  File "/home/airflow/.local/lib/python3.8/site-packages/airflow/utils/email.py", line 272, in send_mime_email
    smtp_conn = _get_smtp_connection(smtp_host, smtp_port, smtp_timeout, smtp_ssl)
  File "/home/airflow/.local/lib/python3.8/site-packages/airflow/utils/email.py", line 316, in _get_smtp_connection
    return smtplib.SMTP(host=host, port=port, timeout=timeout)
  File "/usr/local/lib/python3.8/smtplib.py", line 255, in __init__
    (code, msg) = self.connect(host, port)
  File "/usr/local/lib/python3.8/smtplib.py", line 339, in connect
    self.sock = self._get_socket(host, port, self.timeout)
  File "/usr/local/lib/python3.8/smtplib.py", line 310, in _get_socket
    return socket.create_connection((host, port), timeout,
  File "/usr/local/lib/python3.8/socket.py", line 808, in create_connection
    raise err
  File "/usr/local/lib/python3.8/socket.py", line 796, in create_connection
    sock.connect(sa)
OSError: [Errno 99] Cannot assign requested address

During handling of the above exception, another exception occurred:

Traceback (most recent call last):
  File "/home/airflow/.local/lib/python3.8/site-packages/airflow/models/taskinstance.py", line 2005, in handle_failure
    self.email_alert(error, task)
  File "/home/airflow/.local/lib/python3.8/site-packages/airflow/models/taskinstance.py", line 2422, in email_alert
    send_email(task.email, subject, html_content_err)
  File "/home/airflow/.local/lib/python3.8/site-packages/airflow/utils/email.py", line 80, in send_email
    return backend(
  File "/home/airflow/.local/lib/python3.8/site-packages/airflow/utils/email.py", line 154, in send_email_smtp
    send_mime_email(e_from=mail_from, e_to=recipients, mime_msg=msg, conn_id=conn_id, dryrun=dryrun)
  File "/home/airflow/.local/lib/python3.8/site-packages/airflow/utils/email.py", line 272, in send_mime_email
    smtp_conn = _get_smtp_connection(smtp_host, smtp_port, smtp_timeout, smtp_ssl)
  File "/home/airflow/.local/lib/python3.8/site-packages/airflow/utils/email.py", line 316, in _get_smtp_connection
    return smtplib.SMTP(host=host, port=port, timeout=timeout)
  File "/usr/local/lib/python3.8/smtplib.py", line 255, in __init__
    (code, msg) = self.connect(host, port)
  File "/usr/local/lib/python3.8/smtplib.py", line 339, in connect
    self.sock = self._get_socket(host, port, self.timeout)
  File "/usr/local/lib/python3.8/smtplib.py", line 310, in _get_socket
    return socket.create_connection((host, port), timeout,
  File "/usr/local/lib/python3.8/socket.py", line 808, in create_connection
    raise err
  File "/usr/local/lib/python3.8/socket.py", line 796, in create_connection
    sock.connect(sa)
OSError: [Errno 99] Cannot assign requested address
[2024-01-07T15:59:27.574+0000] {standard_task_runner.py:104} ERROR - Failed to execute job 371 for task copy_course_Postgres_To_GCS (name 'ds_nodash' is not defined; 4475)
[2024-01-07T15:59:27.623+0000] {local_task_job_runner.py:228} INFO - Task exited with return code 1
[2024-01-07T15:59:27.647+0000] {taskinstance.py:2778} INFO - 0 downstream tasks scheduled from follow-on schedule check
[2024-01-07T21:00:33.834+0000] {taskinstance.py:1159} INFO - Dependencies all met for dep_context=non-requeueable deps ti=<TaskInstance: ingest_from_postgres_to_GCS_bucket.copy_course_Postgres_To_GCS scheduled__2024-01-05T00:00:00+00:00 [queued]>
[2024-01-07T21:00:33.868+0000] {taskinstance.py:1159} INFO - Dependencies all met for dep_context=requeueable deps ti=<TaskInstance: ingest_from_postgres_to_GCS_bucket.copy_course_Postgres_To_GCS scheduled__2024-01-05T00:00:00+00:00 [queued]>
[2024-01-07T21:00:33.869+0000] {taskinstance.py:1361} INFO - Starting attempt 3 of 3
[2024-01-07T21:00:33.893+0000] {taskinstance.py:1382} INFO - Executing <Task(PythonOperator): copy_course_Postgres_To_GCS> on 2024-01-05 00:00:00+00:00
[2024-01-07T21:00:33.903+0000] {standard_task_runner.py:57} INFO - Started process 12361 to run task
[2024-01-07T21:00:33.907+0000] {standard_task_runner.py:84} INFO - Running: ['***', 'tasks', 'run', 'ingest_from_postgres_to_GCS_bucket', 'copy_course_Postgres_To_GCS', 'scheduled__2024-01-05T00:00:00+00:00', '--job-id', '493', '--raw', '--subdir', 'DAGS_FOLDER/postgres_to_gcs_staging.py', '--cfg-path', '/tmp/tmply96s28y']
[2024-01-07T21:00:33.910+0000] {standard_task_runner.py:85} INFO - Job 493: Subtask copy_course_Postgres_To_GCS
[2024-01-07T21:00:34.023+0000] {task_command.py:416} INFO - Running <TaskInstance: ingest_from_postgres_to_GCS_bucket.copy_course_Postgres_To_GCS scheduled__2024-01-05T00:00:00+00:00 [running]> on host 5d007c0b4985
[2024-01-07T21:00:34.170+0000] {taskinstance.py:1662} INFO - Exporting env vars: AIRFLOW_CTX_DAG_EMAIL='franklinmutwiri41@gmail.com' AIRFLOW_CTX_DAG_OWNER='***' AIRFLOW_CTX_DAG_ID='ingest_from_postgres_to_GCS_bucket' AIRFLOW_CTX_TASK_ID='copy_course_Postgres_To_GCS' AIRFLOW_CTX_EXECUTION_DATE='2024-01-05T00:00:00+00:00' AIRFLOW_CTX_TRY_NUMBER='3' AIRFLOW_CTX_DAG_RUN_ID='scheduled__2024-01-05T00:00:00+00:00'
[2024-01-07T21:00:34.194+0000] {base.py:73} INFO - Using connection ID 'postgres_docker_conn' for task execution.
[2024-01-07T21:00:34.215+0000] {base.py:73} INFO - Using connection ID 'postgres_docker_conn' for task execution.
[2024-01-07T21:00:34.241+0000] {logging_mixin.py:151} WARNING - /home/***/.local/lib/python3.8/site-packages/***/providers/common/sql/hooks/sql.py:219 UserWarning: pandas only supports SQLAlchemy connectable (engine/connection) or database string URI or sqlite3 DBAPI2 connection. Other DBAPI2 objects are not tested. Please consider using SQLAlchemy.
[2024-01-07T21:00:34.267+0000] {connection.py:232} WARNING - Connection schemes (type: google_cloud_platform) shall not contain '_' according to RFC3986.
[2024-01-07T21:00:34.276+0000] {base.py:73} INFO - Using connection ID 'google_cloud_default' for task execution.
[2024-01-07T21:00:36.719+0000] {taskinstance.py:1937} ERROR - Task failed with exception
Traceback (most recent call last):
  File "/home/airflow/.local/lib/python3.8/site-packages/airflow/operators/python.py", line 192, in execute
    return_value = self.execute_callable()
  File "/home/airflow/.local/lib/python3.8/site-packages/airflow/operators/python.py", line 209, in execute_callable
    return self.python_callable(*self.op_args, **self.op_kwargs)
  File "/opt/airflow/dags/postgres_to_gcs_staging.py", line 62, in Postgres_To_GCS_Bucket
    gcs_hook.delete(bucket_name=BUCKET, object_name=gcs_path)
  File "/home/airflow/.local/lib/python3.8/site-packages/airflow/providers/google/cloud/hooks/gcs.py", line 698, in delete
    blob.delete()
  File "/home/airflow/.local/lib/python3.8/site-packages/google/cloud/storage/blob.py", line 763, in delete
    self.bucket.delete_blob(
  File "/home/airflow/.local/lib/python3.8/site-packages/google/cloud/storage/bucket.py", line 1647, in delete_blob
    client._delete_resource(
  File "/home/airflow/.local/lib/python3.8/site-packages/google/cloud/storage/client.py", line 685, in _delete_resource
    return self._connection.api_request(
  File "/home/airflow/.local/lib/python3.8/site-packages/google/cloud/storage/_http.py", line 72, in api_request
    return call()
  File "/home/airflow/.local/lib/python3.8/site-packages/google/cloud/_http/__init__.py", line 494, in api_request
    raise exceptions.from_http_response(response)
google.api_core.exceptions.NotFound: 404 DELETE https://storage.googleapis.com/storage/v1/b/school_data_lake_data-warehousing-proj/o/data%2Fcourse.parquet?prettyPrint=false: No such object: school_data_lake_data-warehousing-proj/data/course.parquet
[2024-01-07T21:00:36.742+0000] {taskinstance.py:1400} INFO - Marking task as FAILED. dag_id=ingest_from_postgres_to_GCS_bucket, task_id=copy_course_Postgres_To_GCS, execution_date=20240105T000000, start_date=20240107T210033, end_date=20240107T210036
[2024-01-07T21:00:36.772+0000] {logging_mixin.py:151} WARNING - /home/***/.local/lib/python3.8/site-packages/***/utils/email.py:154 RemovedInAirflow3Warning: Fetching SMTP credentials from configuration variables will be deprecated in a future release. Please set credentials using a connection instead.
[2024-01-07T21:00:36.774+0000] {configuration.py:1068} WARNING - section/key [smtp/smtp_user] not found in config
[2024-01-07T21:00:36.774+0000] {email.py:270} INFO - Email alerting: attempt 1
[2024-01-07T21:00:36.801+0000] {configuration.py:1068} WARNING - section/key [smtp/smtp_user] not found in config
[2024-01-07T21:00:36.803+0000] {email.py:270} INFO - Email alerting: attempt 1
[2024-01-07T21:00:36.804+0000] {taskinstance.py:2007} ERROR - Failed to send email to: ['franklinmutwiri41@gmail.com']
Traceback (most recent call last):
  File "/home/airflow/.local/lib/python3.8/site-packages/airflow/models/taskinstance.py", line 1518, in _run_raw_task
    self._execute_task_with_callbacks(context, test_mode, session=session)
  File "/home/airflow/.local/lib/python3.8/site-packages/airflow/models/taskinstance.py", line 1681, in _execute_task_with_callbacks
    result = self._execute_task(context, task_orig)
  File "/home/airflow/.local/lib/python3.8/site-packages/airflow/models/taskinstance.py", line 1744, in _execute_task
    result = execute_callable(context=context, **execute_callable_kwargs)
  File "/home/airflow/.local/lib/python3.8/site-packages/airflow/operators/python.py", line 192, in execute
    return_value = self.execute_callable()
  File "/home/airflow/.local/lib/python3.8/site-packages/airflow/operators/python.py", line 209, in execute_callable
    return self.python_callable(*self.op_args, **self.op_kwargs)
  File "/opt/airflow/dags/postgres_to_gcs_staging.py", line 62, in Postgres_To_GCS_Bucket
    gcs_hook.delete(bucket_name=BUCKET, object_name=gcs_path)
  File "/home/airflow/.local/lib/python3.8/site-packages/airflow/providers/google/cloud/hooks/gcs.py", line 698, in delete
    blob.delete()
  File "/home/airflow/.local/lib/python3.8/site-packages/google/cloud/storage/blob.py", line 763, in delete
    self.bucket.delete_blob(
  File "/home/airflow/.local/lib/python3.8/site-packages/google/cloud/storage/bucket.py", line 1647, in delete_blob
    client._delete_resource(
  File "/home/airflow/.local/lib/python3.8/site-packages/google/cloud/storage/client.py", line 685, in _delete_resource
    return self._connection.api_request(
  File "/home/airflow/.local/lib/python3.8/site-packages/google/cloud/storage/_http.py", line 72, in api_request
    return call()
  File "/home/airflow/.local/lib/python3.8/site-packages/google/cloud/_http/__init__.py", line 494, in api_request
    raise exceptions.from_http_response(response)
google.api_core.exceptions.NotFound: 404 DELETE https://storage.googleapis.com/storage/v1/b/school_data_lake_data-warehousing-proj/o/data%2Fcourse.parquet?prettyPrint=false: No such object: school_data_lake_data-warehousing-proj/data/course.parquet

During handling of the above exception, another exception occurred:

Traceback (most recent call last):
  File "/home/airflow/.local/lib/python3.8/site-packages/airflow/models/taskinstance.py", line 2420, in email_alert
    send_email(task.email, subject, html_content)
  File "/home/airflow/.local/lib/python3.8/site-packages/airflow/utils/email.py", line 80, in send_email
    return backend(
  File "/home/airflow/.local/lib/python3.8/site-packages/airflow/utils/email.py", line 154, in send_email_smtp
    send_mime_email(e_from=mail_from, e_to=recipients, mime_msg=msg, conn_id=conn_id, dryrun=dryrun)
  File "/home/airflow/.local/lib/python3.8/site-packages/airflow/utils/email.py", line 272, in send_mime_email
    smtp_conn = _get_smtp_connection(smtp_host, smtp_port, smtp_timeout, smtp_ssl)
  File "/home/airflow/.local/lib/python3.8/site-packages/airflow/utils/email.py", line 316, in _get_smtp_connection
    return smtplib.SMTP(host=host, port=port, timeout=timeout)
  File "/usr/local/lib/python3.8/smtplib.py", line 255, in __init__
    (code, msg) = self.connect(host, port)
  File "/usr/local/lib/python3.8/smtplib.py", line 339, in connect
    self.sock = self._get_socket(host, port, self.timeout)
  File "/usr/local/lib/python3.8/smtplib.py", line 310, in _get_socket
    return socket.create_connection((host, port), timeout,
  File "/usr/local/lib/python3.8/socket.py", line 808, in create_connection
    raise err
  File "/usr/local/lib/python3.8/socket.py", line 796, in create_connection
    sock.connect(sa)
OSError: [Errno 99] Cannot assign requested address

During handling of the above exception, another exception occurred:

Traceback (most recent call last):
  File "/home/airflow/.local/lib/python3.8/site-packages/airflow/models/taskinstance.py", line 2005, in handle_failure
    self.email_alert(error, task)
  File "/home/airflow/.local/lib/python3.8/site-packages/airflow/models/taskinstance.py", line 2422, in email_alert
    send_email(task.email, subject, html_content_err)
  File "/home/airflow/.local/lib/python3.8/site-packages/airflow/utils/email.py", line 80, in send_email
    return backend(
  File "/home/airflow/.local/lib/python3.8/site-packages/airflow/utils/email.py", line 154, in send_email_smtp
    send_mime_email(e_from=mail_from, e_to=recipients, mime_msg=msg, conn_id=conn_id, dryrun=dryrun)
  File "/home/airflow/.local/lib/python3.8/site-packages/airflow/utils/email.py", line 272, in send_mime_email
    smtp_conn = _get_smtp_connection(smtp_host, smtp_port, smtp_timeout, smtp_ssl)
  File "/home/airflow/.local/lib/python3.8/site-packages/airflow/utils/email.py", line 316, in _get_smtp_connection
    return smtplib.SMTP(host=host, port=port, timeout=timeout)
  File "/usr/local/lib/python3.8/smtplib.py", line 255, in __init__
    (code, msg) = self.connect(host, port)
  File "/usr/local/lib/python3.8/smtplib.py", line 339, in connect
    self.sock = self._get_socket(host, port, self.timeout)
  File "/usr/local/lib/python3.8/smtplib.py", line 310, in _get_socket
    return socket.create_connection((host, port), timeout,
  File "/usr/local/lib/python3.8/socket.py", line 808, in create_connection
    raise err
  File "/usr/local/lib/python3.8/socket.py", line 796, in create_connection
    sock.connect(sa)
OSError: [Errno 99] Cannot assign requested address
[2024-01-07T21:00:36.851+0000] {standard_task_runner.py:104} ERROR - Failed to execute job 493 for task copy_course_Postgres_To_GCS (404 DELETE https://storage.googleapis.com/storage/v1/b/school_data_lake_data-warehousing-proj/o/data%2Fcourse.parquet?prettyPrint=false: No such object: school_data_lake_data-warehousing-proj/data/course.parquet; 12361)
[2024-01-07T21:00:36.891+0000] {local_task_job_runner.py:228} INFO - Task exited with return code 1
[2024-01-07T21:00:36.941+0000] {taskinstance.py:2778} INFO - 0 downstream tasks scheduled from follow-on schedule check
[2024-01-07T21:11:34.296+0000] {taskinstance.py:1159} INFO - Dependencies all met for dep_context=non-requeueable deps ti=<TaskInstance: ingest_from_postgres_to_GCS_bucket.copy_course_Postgres_To_GCS scheduled__2024-01-05T00:00:00+00:00 [queued]>
[2024-01-07T21:11:34.324+0000] {taskinstance.py:1159} INFO - Dependencies all met for dep_context=requeueable deps ti=<TaskInstance: ingest_from_postgres_to_GCS_bucket.copy_course_Postgres_To_GCS scheduled__2024-01-05T00:00:00+00:00 [queued]>
[2024-01-07T21:11:34.324+0000] {taskinstance.py:1361} INFO - Starting attempt 3 of 3
[2024-01-07T21:11:34.355+0000] {taskinstance.py:1382} INFO - Executing <Task(PythonOperator): copy_course_Postgres_To_GCS> on 2024-01-05 00:00:00+00:00
[2024-01-07T21:11:34.365+0000] {standard_task_runner.py:57} INFO - Started process 12676 to run task
[2024-01-07T21:11:34.369+0000] {standard_task_runner.py:84} INFO - Running: ['***', 'tasks', 'run', 'ingest_from_postgres_to_GCS_bucket', 'copy_course_Postgres_To_GCS', 'scheduled__2024-01-05T00:00:00+00:00', '--job-id', '511', '--raw', '--subdir', 'DAGS_FOLDER/postgres_to_gcs_staging.py', '--cfg-path', '/tmp/tmp42yzdunl']
[2024-01-07T21:11:34.372+0000] {standard_task_runner.py:85} INFO - Job 511: Subtask copy_course_Postgres_To_GCS
[2024-01-07T21:11:34.456+0000] {task_command.py:416} INFO - Running <TaskInstance: ingest_from_postgres_to_GCS_bucket.copy_course_Postgres_To_GCS scheduled__2024-01-05T00:00:00+00:00 [running]> on host 5d007c0b4985
[2024-01-07T21:11:34.588+0000] {taskinstance.py:1662} INFO - Exporting env vars: AIRFLOW_CTX_DAG_EMAIL='franklinmutwiri41@gmail.com' AIRFLOW_CTX_DAG_OWNER='***' AIRFLOW_CTX_DAG_ID='ingest_from_postgres_to_GCS_bucket' AIRFLOW_CTX_TASK_ID='copy_course_Postgres_To_GCS' AIRFLOW_CTX_EXECUTION_DATE='2024-01-05T00:00:00+00:00' AIRFLOW_CTX_TRY_NUMBER='3' AIRFLOW_CTX_DAG_RUN_ID='scheduled__2024-01-05T00:00:00+00:00'
[2024-01-07T21:11:34.604+0000] {base.py:73} INFO - Using connection ID 'postgres_docker_conn' for task execution.
[2024-01-07T21:11:34.621+0000] {base.py:73} INFO - Using connection ID 'postgres_docker_conn' for task execution.
[2024-01-07T21:11:34.643+0000] {logging_mixin.py:151} WARNING - /home/***/.local/lib/python3.8/site-packages/***/providers/common/sql/hooks/sql.py:219 UserWarning: pandas only supports SQLAlchemy connectable (engine/connection) or database string URI or sqlite3 DBAPI2 connection. Other DBAPI2 objects are not tested. Please consider using SQLAlchemy.
[2024-01-07T21:11:34.671+0000] {connection.py:232} WARNING - Connection schemes (type: google_cloud_platform) shall not contain '_' according to RFC3986.
[2024-01-07T21:11:34.679+0000] {base.py:73} INFO - Using connection ID 'google_cloud_default' for task execution.
[2024-01-07T21:11:36.664+0000] {taskinstance.py:1937} ERROR - Task failed with exception
Traceback (most recent call last):
  File "/home/airflow/.local/lib/python3.8/site-packages/airflow/operators/python.py", line 192, in execute
    return_value = self.execute_callable()
  File "/home/airflow/.local/lib/python3.8/site-packages/airflow/operators/python.py", line 209, in execute_callable
    return self.python_callable(*self.op_args, **self.op_kwargs)
  File "/opt/airflow/dags/postgres_to_gcs_staging.py", line 62, in Postgres_To_GCS_Bucket
    gcs_hook.delete(bucket_name=BUCKET, object_name=gcs_path)
  File "/home/airflow/.local/lib/python3.8/site-packages/airflow/providers/google/cloud/hooks/gcs.py", line 698, in delete
    blob.delete()
  File "/home/airflow/.local/lib/python3.8/site-packages/google/cloud/storage/blob.py", line 763, in delete
    self.bucket.delete_blob(
  File "/home/airflow/.local/lib/python3.8/site-packages/google/cloud/storage/bucket.py", line 1647, in delete_blob
    client._delete_resource(
  File "/home/airflow/.local/lib/python3.8/site-packages/google/cloud/storage/client.py", line 685, in _delete_resource
    return self._connection.api_request(
  File "/home/airflow/.local/lib/python3.8/site-packages/google/cloud/storage/_http.py", line 72, in api_request
    return call()
  File "/home/airflow/.local/lib/python3.8/site-packages/google/cloud/_http/__init__.py", line 494, in api_request
    raise exceptions.from_http_response(response)
google.api_core.exceptions.NotFound: 404 DELETE https://storage.googleapis.com/storage/v1/b/school_data_lake_data-warehousing-proj/o/data%2Fcourse.parquet?prettyPrint=false: No such object: school_data_lake_data-warehousing-proj/data/course.parquet
[2024-01-07T21:11:36.682+0000] {taskinstance.py:1400} INFO - Marking task as FAILED. dag_id=ingest_from_postgres_to_GCS_bucket, task_id=copy_course_Postgres_To_GCS, execution_date=20240105T000000, start_date=20240107T211134, end_date=20240107T211136
[2024-01-07T21:11:36.698+0000] {logging_mixin.py:151} WARNING - /home/***/.local/lib/python3.8/site-packages/***/utils/email.py:154 RemovedInAirflow3Warning: Fetching SMTP credentials from configuration variables will be deprecated in a future release. Please set credentials using a connection instead.
[2024-01-07T21:11:36.699+0000] {configuration.py:1068} WARNING - section/key [smtp/smtp_user] not found in config
[2024-01-07T21:11:36.699+0000] {email.py:270} INFO - Email alerting: attempt 1
[2024-01-07T21:11:36.714+0000] {configuration.py:1068} WARNING - section/key [smtp/smtp_user] not found in config
[2024-01-07T21:11:36.714+0000] {email.py:270} INFO - Email alerting: attempt 1
[2024-01-07T21:11:36.715+0000] {taskinstance.py:2007} ERROR - Failed to send email to: ['franklinmutwiri41@gmail.com']
Traceback (most recent call last):
  File "/home/airflow/.local/lib/python3.8/site-packages/airflow/models/taskinstance.py", line 1518, in _run_raw_task
    self._execute_task_with_callbacks(context, test_mode, session=session)
  File "/home/airflow/.local/lib/python3.8/site-packages/airflow/models/taskinstance.py", line 1681, in _execute_task_with_callbacks
    result = self._execute_task(context, task_orig)
  File "/home/airflow/.local/lib/python3.8/site-packages/airflow/models/taskinstance.py", line 1744, in _execute_task
    result = execute_callable(context=context, **execute_callable_kwargs)
  File "/home/airflow/.local/lib/python3.8/site-packages/airflow/operators/python.py", line 192, in execute
    return_value = self.execute_callable()
  File "/home/airflow/.local/lib/python3.8/site-packages/airflow/operators/python.py", line 209, in execute_callable
    return self.python_callable(*self.op_args, **self.op_kwargs)
  File "/opt/airflow/dags/postgres_to_gcs_staging.py", line 62, in Postgres_To_GCS_Bucket
    gcs_hook.delete(bucket_name=BUCKET, object_name=gcs_path)
  File "/home/airflow/.local/lib/python3.8/site-packages/airflow/providers/google/cloud/hooks/gcs.py", line 698, in delete
    blob.delete()
  File "/home/airflow/.local/lib/python3.8/site-packages/google/cloud/storage/blob.py", line 763, in delete
    self.bucket.delete_blob(
  File "/home/airflow/.local/lib/python3.8/site-packages/google/cloud/storage/bucket.py", line 1647, in delete_blob
    client._delete_resource(
  File "/home/airflow/.local/lib/python3.8/site-packages/google/cloud/storage/client.py", line 685, in _delete_resource
    return self._connection.api_request(
  File "/home/airflow/.local/lib/python3.8/site-packages/google/cloud/storage/_http.py", line 72, in api_request
    return call()
  File "/home/airflow/.local/lib/python3.8/site-packages/google/cloud/_http/__init__.py", line 494, in api_request
    raise exceptions.from_http_response(response)
google.api_core.exceptions.NotFound: 404 DELETE https://storage.googleapis.com/storage/v1/b/school_data_lake_data-warehousing-proj/o/data%2Fcourse.parquet?prettyPrint=false: No such object: school_data_lake_data-warehousing-proj/data/course.parquet

During handling of the above exception, another exception occurred:

Traceback (most recent call last):
  File "/home/airflow/.local/lib/python3.8/site-packages/airflow/models/taskinstance.py", line 2420, in email_alert
    send_email(task.email, subject, html_content)
  File "/home/airflow/.local/lib/python3.8/site-packages/airflow/utils/email.py", line 80, in send_email
    return backend(
  File "/home/airflow/.local/lib/python3.8/site-packages/airflow/utils/email.py", line 154, in send_email_smtp
    send_mime_email(e_from=mail_from, e_to=recipients, mime_msg=msg, conn_id=conn_id, dryrun=dryrun)
  File "/home/airflow/.local/lib/python3.8/site-packages/airflow/utils/email.py", line 272, in send_mime_email
    smtp_conn = _get_smtp_connection(smtp_host, smtp_port, smtp_timeout, smtp_ssl)
  File "/home/airflow/.local/lib/python3.8/site-packages/airflow/utils/email.py", line 316, in _get_smtp_connection
    return smtplib.SMTP(host=host, port=port, timeout=timeout)
  File "/usr/local/lib/python3.8/smtplib.py", line 255, in __init__
    (code, msg) = self.connect(host, port)
  File "/usr/local/lib/python3.8/smtplib.py", line 339, in connect
    self.sock = self._get_socket(host, port, self.timeout)
  File "/usr/local/lib/python3.8/smtplib.py", line 310, in _get_socket
    return socket.create_connection((host, port), timeout,
  File "/usr/local/lib/python3.8/socket.py", line 808, in create_connection
    raise err
  File "/usr/local/lib/python3.8/socket.py", line 796, in create_connection
    sock.connect(sa)
OSError: [Errno 99] Cannot assign requested address

During handling of the above exception, another exception occurred:

Traceback (most recent call last):
  File "/home/airflow/.local/lib/python3.8/site-packages/airflow/models/taskinstance.py", line 2005, in handle_failure
    self.email_alert(error, task)
  File "/home/airflow/.local/lib/python3.8/site-packages/airflow/models/taskinstance.py", line 2422, in email_alert
    send_email(task.email, subject, html_content_err)
  File "/home/airflow/.local/lib/python3.8/site-packages/airflow/utils/email.py", line 80, in send_email
    return backend(
  File "/home/airflow/.local/lib/python3.8/site-packages/airflow/utils/email.py", line 154, in send_email_smtp
    send_mime_email(e_from=mail_from, e_to=recipients, mime_msg=msg, conn_id=conn_id, dryrun=dryrun)
  File "/home/airflow/.local/lib/python3.8/site-packages/airflow/utils/email.py", line 272, in send_mime_email
    smtp_conn = _get_smtp_connection(smtp_host, smtp_port, smtp_timeout, smtp_ssl)
  File "/home/airflow/.local/lib/python3.8/site-packages/airflow/utils/email.py", line 316, in _get_smtp_connection
    return smtplib.SMTP(host=host, port=port, timeout=timeout)
  File "/usr/local/lib/python3.8/smtplib.py", line 255, in __init__
    (code, msg) = self.connect(host, port)
  File "/usr/local/lib/python3.8/smtplib.py", line 339, in connect
    self.sock = self._get_socket(host, port, self.timeout)
  File "/usr/local/lib/python3.8/smtplib.py", line 310, in _get_socket
    return socket.create_connection((host, port), timeout,
  File "/usr/local/lib/python3.8/socket.py", line 808, in create_connection
    raise err
  File "/usr/local/lib/python3.8/socket.py", line 796, in create_connection
    sock.connect(sa)
OSError: [Errno 99] Cannot assign requested address
[2024-01-07T21:11:36.745+0000] {standard_task_runner.py:104} ERROR - Failed to execute job 511 for task copy_course_Postgres_To_GCS (404 DELETE https://storage.googleapis.com/storage/v1/b/school_data_lake_data-warehousing-proj/o/data%2Fcourse.parquet?prettyPrint=false: No such object: school_data_lake_data-warehousing-proj/data/course.parquet; 12676)
[2024-01-07T21:11:36.792+0000] {local_task_job_runner.py:228} INFO - Task exited with return code 1
[2024-01-07T21:11:36.819+0000] {taskinstance.py:2778} INFO - 0 downstream tasks scheduled from follow-on schedule check
[2024-01-07T21:23:55.575+0000] {taskinstance.py:1159} INFO - Dependencies all met for dep_context=non-requeueable deps ti=<TaskInstance: ingest_from_postgres_to_GCS_bucket.copy_course_Postgres_To_GCS scheduled__2024-01-05T00:00:00+00:00 [queued]>
[2024-01-07T21:23:55.602+0000] {taskinstance.py:1159} INFO - Dependencies all met for dep_context=requeueable deps ti=<TaskInstance: ingest_from_postgres_to_GCS_bucket.copy_course_Postgres_To_GCS scheduled__2024-01-05T00:00:00+00:00 [queued]>
[2024-01-07T21:23:55.603+0000] {taskinstance.py:1361} INFO - Starting attempt 3 of 3
[2024-01-07T21:23:55.633+0000] {taskinstance.py:1382} INFO - Executing <Task(PythonOperator): copy_course_Postgres_To_GCS> on 2024-01-05 00:00:00+00:00
[2024-01-07T21:23:55.643+0000] {standard_task_runner.py:57} INFO - Started process 332 to run task
[2024-01-07T21:23:55.648+0000] {standard_task_runner.py:84} INFO - Running: ['***', 'tasks', 'run', 'ingest_from_postgres_to_GCS_bucket', 'copy_course_Postgres_To_GCS', 'scheduled__2024-01-05T00:00:00+00:00', '--job-id', '542', '--raw', '--subdir', 'DAGS_FOLDER/postgres_to_gcs_staging.py', '--cfg-path', '/tmp/tmpkf41azno']
[2024-01-07T21:23:55.651+0000] {standard_task_runner.py:85} INFO - Job 542: Subtask copy_course_Postgres_To_GCS
[2024-01-07T21:23:55.738+0000] {task_command.py:416} INFO - Running <TaskInstance: ingest_from_postgres_to_GCS_bucket.copy_course_Postgres_To_GCS scheduled__2024-01-05T00:00:00+00:00 [running]> on host 6609460de6e5
[2024-01-07T21:23:55.906+0000] {taskinstance.py:1662} INFO - Exporting env vars: AIRFLOW_CTX_DAG_EMAIL='franklinmutwiri41@gmail.com' AIRFLOW_CTX_DAG_OWNER='***' AIRFLOW_CTX_DAG_ID='ingest_from_postgres_to_GCS_bucket' AIRFLOW_CTX_TASK_ID='copy_course_Postgres_To_GCS' AIRFLOW_CTX_EXECUTION_DATE='2024-01-05T00:00:00+00:00' AIRFLOW_CTX_TRY_NUMBER='3' AIRFLOW_CTX_DAG_RUN_ID='scheduled__2024-01-05T00:00:00+00:00'
[2024-01-07T21:23:55.933+0000] {base.py:73} INFO - Using connection ID 'postgres_docker_conn' for task execution.
[2024-01-07T21:23:55.952+0000] {base.py:73} INFO - Using connection ID 'postgres_docker_conn' for task execution.
[2024-01-07T21:23:55.979+0000] {logging_mixin.py:151} WARNING - /home/***/.local/lib/python3.8/site-packages/***/providers/common/sql/hooks/sql.py:219 UserWarning: pandas only supports SQLAlchemy connectable (engine/connection) or database string URI or sqlite3 DBAPI2 connection. Other DBAPI2 objects are not tested. Please consider using SQLAlchemy.
[2024-01-07T21:23:56.004+0000] {connection.py:232} WARNING - Connection schemes (type: google_cloud_platform) shall not contain '_' according to RFC3986.
[2024-01-07T21:23:56.013+0000] {base.py:73} INFO - Using connection ID 'google_cloud_default' for task execution.
[2024-01-07T21:23:58.040+0000] {taskinstance.py:1937} ERROR - Task failed with exception
Traceback (most recent call last):
  File "/home/airflow/.local/lib/python3.8/site-packages/airflow/operators/python.py", line 192, in execute
    return_value = self.execute_callable()
  File "/home/airflow/.local/lib/python3.8/site-packages/airflow/operators/python.py", line 209, in execute_callable
    return self.python_callable(*self.op_args, **self.op_kwargs)
  File "/opt/airflow/dags/postgres_to_gcs_staging.py", line 62, in Postgres_To_GCS_Bucket
    gcs_hook.delete(bucket_name=BUCKET, object_name=gcs_path)
  File "/home/airflow/.local/lib/python3.8/site-packages/airflow/providers/google/cloud/hooks/gcs.py", line 698, in delete
    blob.delete()
  File "/home/airflow/.local/lib/python3.8/site-packages/google/cloud/storage/blob.py", line 763, in delete
    self.bucket.delete_blob(
  File "/home/airflow/.local/lib/python3.8/site-packages/google/cloud/storage/bucket.py", line 1647, in delete_blob
    client._delete_resource(
  File "/home/airflow/.local/lib/python3.8/site-packages/google/cloud/storage/client.py", line 685, in _delete_resource
    return self._connection.api_request(
  File "/home/airflow/.local/lib/python3.8/site-packages/google/cloud/storage/_http.py", line 72, in api_request
    return call()
  File "/home/airflow/.local/lib/python3.8/site-packages/google/cloud/_http/__init__.py", line 494, in api_request
    raise exceptions.from_http_response(response)
google.api_core.exceptions.NotFound: 404 DELETE https://storage.googleapis.com/storage/v1/b/school_data_lake_data-warehousing-proj/o/data%2Fcourse.parquet?prettyPrint=false: No such object: school_data_lake_data-warehousing-proj/data/course.parquet
[2024-01-07T21:23:58.061+0000] {taskinstance.py:1400} INFO - Marking task as FAILED. dag_id=ingest_from_postgres_to_GCS_bucket, task_id=copy_course_Postgres_To_GCS, execution_date=20240105T000000, start_date=20240107T212355, end_date=20240107T212358
[2024-01-07T21:23:58.080+0000] {logging_mixin.py:151} WARNING - /home/***/.local/lib/python3.8/site-packages/***/utils/email.py:154 RemovedInAirflow3Warning: Fetching SMTP credentials from configuration variables will be deprecated in a future release. Please set credentials using a connection instead.
[2024-01-07T21:23:58.082+0000] {configuration.py:1068} WARNING - section/key [smtp/smtp_user] not found in config
[2024-01-07T21:23:58.082+0000] {email.py:270} INFO - Email alerting: attempt 1
[2024-01-07T21:23:58.097+0000] {configuration.py:1068} WARNING - section/key [smtp/smtp_user] not found in config
[2024-01-07T21:23:58.097+0000] {email.py:270} INFO - Email alerting: attempt 1
[2024-01-07T21:23:58.099+0000] {taskinstance.py:2007} ERROR - Failed to send email to: ['franklinmutwiri41@gmail.com']
Traceback (most recent call last):
  File "/home/airflow/.local/lib/python3.8/site-packages/airflow/models/taskinstance.py", line 1518, in _run_raw_task
    self._execute_task_with_callbacks(context, test_mode, session=session)
  File "/home/airflow/.local/lib/python3.8/site-packages/airflow/models/taskinstance.py", line 1681, in _execute_task_with_callbacks
    result = self._execute_task(context, task_orig)
  File "/home/airflow/.local/lib/python3.8/site-packages/airflow/models/taskinstance.py", line 1744, in _execute_task
    result = execute_callable(context=context, **execute_callable_kwargs)
  File "/home/airflow/.local/lib/python3.8/site-packages/airflow/operators/python.py", line 192, in execute
    return_value = self.execute_callable()
  File "/home/airflow/.local/lib/python3.8/site-packages/airflow/operators/python.py", line 209, in execute_callable
    return self.python_callable(*self.op_args, **self.op_kwargs)
  File "/opt/airflow/dags/postgres_to_gcs_staging.py", line 62, in Postgres_To_GCS_Bucket
    gcs_hook.delete(bucket_name=BUCKET, object_name=gcs_path)
  File "/home/airflow/.local/lib/python3.8/site-packages/airflow/providers/google/cloud/hooks/gcs.py", line 698, in delete
    blob.delete()
  File "/home/airflow/.local/lib/python3.8/site-packages/google/cloud/storage/blob.py", line 763, in delete
    self.bucket.delete_blob(
  File "/home/airflow/.local/lib/python3.8/site-packages/google/cloud/storage/bucket.py", line 1647, in delete_blob
    client._delete_resource(
  File "/home/airflow/.local/lib/python3.8/site-packages/google/cloud/storage/client.py", line 685, in _delete_resource
    return self._connection.api_request(
  File "/home/airflow/.local/lib/python3.8/site-packages/google/cloud/storage/_http.py", line 72, in api_request
    return call()
  File "/home/airflow/.local/lib/python3.8/site-packages/google/cloud/_http/__init__.py", line 494, in api_request
    raise exceptions.from_http_response(response)
google.api_core.exceptions.NotFound: 404 DELETE https://storage.googleapis.com/storage/v1/b/school_data_lake_data-warehousing-proj/o/data%2Fcourse.parquet?prettyPrint=false: No such object: school_data_lake_data-warehousing-proj/data/course.parquet

During handling of the above exception, another exception occurred:

Traceback (most recent call last):
  File "/home/airflow/.local/lib/python3.8/site-packages/airflow/models/taskinstance.py", line 2420, in email_alert
    send_email(task.email, subject, html_content)
  File "/home/airflow/.local/lib/python3.8/site-packages/airflow/utils/email.py", line 80, in send_email
    return backend(
  File "/home/airflow/.local/lib/python3.8/site-packages/airflow/utils/email.py", line 154, in send_email_smtp
    send_mime_email(e_from=mail_from, e_to=recipients, mime_msg=msg, conn_id=conn_id, dryrun=dryrun)
  File "/home/airflow/.local/lib/python3.8/site-packages/airflow/utils/email.py", line 272, in send_mime_email
    smtp_conn = _get_smtp_connection(smtp_host, smtp_port, smtp_timeout, smtp_ssl)
  File "/home/airflow/.local/lib/python3.8/site-packages/airflow/utils/email.py", line 316, in _get_smtp_connection
    return smtplib.SMTP(host=host, port=port, timeout=timeout)
  File "/usr/local/lib/python3.8/smtplib.py", line 255, in __init__
    (code, msg) = self.connect(host, port)
  File "/usr/local/lib/python3.8/smtplib.py", line 339, in connect
    self.sock = self._get_socket(host, port, self.timeout)
  File "/usr/local/lib/python3.8/smtplib.py", line 310, in _get_socket
    return socket.create_connection((host, port), timeout,
  File "/usr/local/lib/python3.8/socket.py", line 808, in create_connection
    raise err
  File "/usr/local/lib/python3.8/socket.py", line 796, in create_connection
    sock.connect(sa)
OSError: [Errno 99] Cannot assign requested address

During handling of the above exception, another exception occurred:

Traceback (most recent call last):
  File "/home/airflow/.local/lib/python3.8/site-packages/airflow/models/taskinstance.py", line 2005, in handle_failure
    self.email_alert(error, task)
  File "/home/airflow/.local/lib/python3.8/site-packages/airflow/models/taskinstance.py", line 2422, in email_alert
    send_email(task.email, subject, html_content_err)
  File "/home/airflow/.local/lib/python3.8/site-packages/airflow/utils/email.py", line 80, in send_email
    return backend(
  File "/home/airflow/.local/lib/python3.8/site-packages/airflow/utils/email.py", line 154, in send_email_smtp
    send_mime_email(e_from=mail_from, e_to=recipients, mime_msg=msg, conn_id=conn_id, dryrun=dryrun)
  File "/home/airflow/.local/lib/python3.8/site-packages/airflow/utils/email.py", line 272, in send_mime_email
    smtp_conn = _get_smtp_connection(smtp_host, smtp_port, smtp_timeout, smtp_ssl)
  File "/home/airflow/.local/lib/python3.8/site-packages/airflow/utils/email.py", line 316, in _get_smtp_connection
    return smtplib.SMTP(host=host, port=port, timeout=timeout)
  File "/usr/local/lib/python3.8/smtplib.py", line 255, in __init__
    (code, msg) = self.connect(host, port)
  File "/usr/local/lib/python3.8/smtplib.py", line 339, in connect
    self.sock = self._get_socket(host, port, self.timeout)
  File "/usr/local/lib/python3.8/smtplib.py", line 310, in _get_socket
    return socket.create_connection((host, port), timeout,
  File "/usr/local/lib/python3.8/socket.py", line 808, in create_connection
    raise err
  File "/usr/local/lib/python3.8/socket.py", line 796, in create_connection
    sock.connect(sa)
OSError: [Errno 99] Cannot assign requested address
[2024-01-07T21:23:58.226+0000] {standard_task_runner.py:104} ERROR - Failed to execute job 542 for task copy_course_Postgres_To_GCS (404 DELETE https://storage.googleapis.com/storage/v1/b/school_data_lake_data-warehousing-proj/o/data%2Fcourse.parquet?prettyPrint=false: No such object: school_data_lake_data-warehousing-proj/data/course.parquet; 332)
[2024-01-07T21:23:58.272+0000] {local_task_job_runner.py:228} INFO - Task exited with return code 1
[2024-01-07T21:23:58.316+0000] {taskinstance.py:2778} INFO - 0 downstream tasks scheduled from follow-on schedule check
[2024-01-07T21:35:19.715+0000] {taskinstance.py:1159} INFO - Dependencies all met for dep_context=non-requeueable deps ti=<TaskInstance: ingest_from_postgres_to_GCS_bucket.copy_course_Postgres_To_GCS scheduled__2024-01-05T00:00:00+00:00 [queued]>
[2024-01-07T21:35:19.748+0000] {taskinstance.py:1159} INFO - Dependencies all met for dep_context=requeueable deps ti=<TaskInstance: ingest_from_postgres_to_GCS_bucket.copy_course_Postgres_To_GCS scheduled__2024-01-05T00:00:00+00:00 [queued]>
[2024-01-07T21:35:19.748+0000] {taskinstance.py:1361} INFO - Starting attempt 3 of 3
[2024-01-07T21:35:19.780+0000] {taskinstance.py:1382} INFO - Executing <Task(PythonOperator): copy_course_Postgres_To_GCS> on 2024-01-05 00:00:00+00:00
[2024-01-07T21:35:19.794+0000] {standard_task_runner.py:57} INFO - Started process 660 to run task
[2024-01-07T21:35:19.801+0000] {standard_task_runner.py:84} INFO - Running: ['***', 'tasks', 'run', 'ingest_from_postgres_to_GCS_bucket', 'copy_course_Postgres_To_GCS', 'scheduled__2024-01-05T00:00:00+00:00', '--job-id', '553', '--raw', '--subdir', 'DAGS_FOLDER/postgres_to_gcs_staging.py', '--cfg-path', '/tmp/tmpz9jeiait']
[2024-01-07T21:35:19.809+0000] {standard_task_runner.py:85} INFO - Job 553: Subtask copy_course_Postgres_To_GCS
[2024-01-07T21:35:19.941+0000] {task_command.py:416} INFO - Running <TaskInstance: ingest_from_postgres_to_GCS_bucket.copy_course_Postgres_To_GCS scheduled__2024-01-05T00:00:00+00:00 [running]> on host 6609460de6e5
[2024-01-07T21:35:20.124+0000] {taskinstance.py:1662} INFO - Exporting env vars: AIRFLOW_CTX_DAG_EMAIL='franklinmutwiri41@gmail.com' AIRFLOW_CTX_DAG_OWNER='***' AIRFLOW_CTX_DAG_ID='ingest_from_postgres_to_GCS_bucket' AIRFLOW_CTX_TASK_ID='copy_course_Postgres_To_GCS' AIRFLOW_CTX_EXECUTION_DATE='2024-01-05T00:00:00+00:00' AIRFLOW_CTX_TRY_NUMBER='3' AIRFLOW_CTX_DAG_RUN_ID='scheduled__2024-01-05T00:00:00+00:00'
[2024-01-07T21:35:20.160+0000] {base.py:73} INFO - Using connection ID 'postgres_docker_conn' for task execution.
[2024-01-07T21:35:20.181+0000] {base.py:73} INFO - Using connection ID 'postgres_docker_conn' for task execution.
[2024-01-07T21:35:20.271+0000] {logging_mixin.py:151} WARNING - /home/***/.local/lib/python3.8/site-packages/***/providers/common/sql/hooks/sql.py:219 UserWarning: pandas only supports SQLAlchemy connectable (engine/connection) or database string URI or sqlite3 DBAPI2 connection. Other DBAPI2 objects are not tested. Please consider using SQLAlchemy.
[2024-01-07T21:35:20.529+0000] {connection.py:232} WARNING - Connection schemes (type: google_cloud_platform) shall not contain '_' according to RFC3986.
[2024-01-07T21:35:20.540+0000] {base.py:73} INFO - Using connection ID 'google_cloud_default' for task execution.
[2024-01-07T21:35:23.050+0000] {taskinstance.py:1937} ERROR - Task failed with exception
Traceback (most recent call last):
  File "/home/airflow/.local/lib/python3.8/site-packages/airflow/operators/python.py", line 192, in execute
    return_value = self.execute_callable()
  File "/home/airflow/.local/lib/python3.8/site-packages/airflow/operators/python.py", line 209, in execute_callable
    return self.python_callable(*self.op_args, **self.op_kwargs)
  File "/opt/airflow/dags/postgres_to_gcs_staging.py", line 64, in Postgres_To_GCS_Bucket
    gcs_hook.delete(bucket_name=BUCKET, object_name=gcs_path)
  File "/home/airflow/.local/lib/python3.8/site-packages/airflow/providers/google/cloud/hooks/gcs.py", line 698, in delete
    blob.delete()
  File "/home/airflow/.local/lib/python3.8/site-packages/google/cloud/storage/blob.py", line 763, in delete
    self.bucket.delete_blob(
  File "/home/airflow/.local/lib/python3.8/site-packages/google/cloud/storage/bucket.py", line 1647, in delete_blob
    client._delete_resource(
  File "/home/airflow/.local/lib/python3.8/site-packages/google/cloud/storage/client.py", line 685, in _delete_resource
    return self._connection.api_request(
  File "/home/airflow/.local/lib/python3.8/site-packages/google/cloud/storage/_http.py", line 72, in api_request
    return call()
  File "/home/airflow/.local/lib/python3.8/site-packages/google/cloud/_http/__init__.py", line 494, in api_request
    raise exceptions.from_http_response(response)
google.api_core.exceptions.NotFound: 404 DELETE https://storage.googleapis.com/storage/v1/b/school_data_lake_data-warehousing-proj/o/data%2Fcourse.parquet?prettyPrint=false: No such object: school_data_lake_data-warehousing-proj/data/course.parquet
[2024-01-07T21:35:23.101+0000] {taskinstance.py:1400} INFO - Marking task as FAILED. dag_id=ingest_from_postgres_to_GCS_bucket, task_id=copy_course_Postgres_To_GCS, execution_date=20240105T000000, start_date=20240107T213519, end_date=20240107T213523
[2024-01-07T21:35:23.128+0000] {logging_mixin.py:151} WARNING - /home/***/.local/lib/python3.8/site-packages/***/utils/email.py:154 RemovedInAirflow3Warning: Fetching SMTP credentials from configuration variables will be deprecated in a future release. Please set credentials using a connection instead.
[2024-01-07T21:35:23.131+0000] {configuration.py:1068} WARNING - section/key [smtp/smtp_user] not found in config
[2024-01-07T21:35:23.131+0000] {email.py:270} INFO - Email alerting: attempt 1
[2024-01-07T21:35:23.152+0000] {configuration.py:1068} WARNING - section/key [smtp/smtp_user] not found in config
[2024-01-07T21:35:23.152+0000] {email.py:270} INFO - Email alerting: attempt 1
[2024-01-07T21:35:23.153+0000] {taskinstance.py:2007} ERROR - Failed to send email to: ['franklinmutwiri41@gmail.com']
Traceback (most recent call last):
  File "/home/airflow/.local/lib/python3.8/site-packages/airflow/models/taskinstance.py", line 1518, in _run_raw_task
    self._execute_task_with_callbacks(context, test_mode, session=session)
  File "/home/airflow/.local/lib/python3.8/site-packages/airflow/models/taskinstance.py", line 1681, in _execute_task_with_callbacks
    result = self._execute_task(context, task_orig)
  File "/home/airflow/.local/lib/python3.8/site-packages/airflow/models/taskinstance.py", line 1744, in _execute_task
    result = execute_callable(context=context, **execute_callable_kwargs)
  File "/home/airflow/.local/lib/python3.8/site-packages/airflow/operators/python.py", line 192, in execute
    return_value = self.execute_callable()
  File "/home/airflow/.local/lib/python3.8/site-packages/airflow/operators/python.py", line 209, in execute_callable
    return self.python_callable(*self.op_args, **self.op_kwargs)
  File "/opt/airflow/dags/postgres_to_gcs_staging.py", line 64, in Postgres_To_GCS_Bucket
    gcs_hook.delete(bucket_name=BUCKET, object_name=gcs_path)
  File "/home/airflow/.local/lib/python3.8/site-packages/airflow/providers/google/cloud/hooks/gcs.py", line 698, in delete
    blob.delete()
  File "/home/airflow/.local/lib/python3.8/site-packages/google/cloud/storage/blob.py", line 763, in delete
    self.bucket.delete_blob(
  File "/home/airflow/.local/lib/python3.8/site-packages/google/cloud/storage/bucket.py", line 1647, in delete_blob
    client._delete_resource(
  File "/home/airflow/.local/lib/python3.8/site-packages/google/cloud/storage/client.py", line 685, in _delete_resource
    return self._connection.api_request(
  File "/home/airflow/.local/lib/python3.8/site-packages/google/cloud/storage/_http.py", line 72, in api_request
    return call()
  File "/home/airflow/.local/lib/python3.8/site-packages/google/cloud/_http/__init__.py", line 494, in api_request
    raise exceptions.from_http_response(response)
google.api_core.exceptions.NotFound: 404 DELETE https://storage.googleapis.com/storage/v1/b/school_data_lake_data-warehousing-proj/o/data%2Fcourse.parquet?prettyPrint=false: No such object: school_data_lake_data-warehousing-proj/data/course.parquet

During handling of the above exception, another exception occurred:

Traceback (most recent call last):
  File "/home/airflow/.local/lib/python3.8/site-packages/airflow/models/taskinstance.py", line 2420, in email_alert
    send_email(task.email, subject, html_content)
  File "/home/airflow/.local/lib/python3.8/site-packages/airflow/utils/email.py", line 80, in send_email
    return backend(
  File "/home/airflow/.local/lib/python3.8/site-packages/airflow/utils/email.py", line 154, in send_email_smtp
    send_mime_email(e_from=mail_from, e_to=recipients, mime_msg=msg, conn_id=conn_id, dryrun=dryrun)
  File "/home/airflow/.local/lib/python3.8/site-packages/airflow/utils/email.py", line 272, in send_mime_email
    smtp_conn = _get_smtp_connection(smtp_host, smtp_port, smtp_timeout, smtp_ssl)
  File "/home/airflow/.local/lib/python3.8/site-packages/airflow/utils/email.py", line 316, in _get_smtp_connection
    return smtplib.SMTP(host=host, port=port, timeout=timeout)
  File "/usr/local/lib/python3.8/smtplib.py", line 255, in __init__
    (code, msg) = self.connect(host, port)
  File "/usr/local/lib/python3.8/smtplib.py", line 339, in connect
    self.sock = self._get_socket(host, port, self.timeout)
  File "/usr/local/lib/python3.8/smtplib.py", line 310, in _get_socket
    return socket.create_connection((host, port), timeout,
  File "/usr/local/lib/python3.8/socket.py", line 808, in create_connection
    raise err
  File "/usr/local/lib/python3.8/socket.py", line 796, in create_connection
    sock.connect(sa)
OSError: [Errno 99] Cannot assign requested address

During handling of the above exception, another exception occurred:

Traceback (most recent call last):
  File "/home/airflow/.local/lib/python3.8/site-packages/airflow/models/taskinstance.py", line 2005, in handle_failure
    self.email_alert(error, task)
  File "/home/airflow/.local/lib/python3.8/site-packages/airflow/models/taskinstance.py", line 2422, in email_alert
    send_email(task.email, subject, html_content_err)
  File "/home/airflow/.local/lib/python3.8/site-packages/airflow/utils/email.py", line 80, in send_email
    return backend(
  File "/home/airflow/.local/lib/python3.8/site-packages/airflow/utils/email.py", line 154, in send_email_smtp
    send_mime_email(e_from=mail_from, e_to=recipients, mime_msg=msg, conn_id=conn_id, dryrun=dryrun)
  File "/home/airflow/.local/lib/python3.8/site-packages/airflow/utils/email.py", line 272, in send_mime_email
    smtp_conn = _get_smtp_connection(smtp_host, smtp_port, smtp_timeout, smtp_ssl)
  File "/home/airflow/.local/lib/python3.8/site-packages/airflow/utils/email.py", line 316, in _get_smtp_connection
    return smtplib.SMTP(host=host, port=port, timeout=timeout)
  File "/usr/local/lib/python3.8/smtplib.py", line 255, in __init__
    (code, msg) = self.connect(host, port)
  File "/usr/local/lib/python3.8/smtplib.py", line 339, in connect
    self.sock = self._get_socket(host, port, self.timeout)
  File "/usr/local/lib/python3.8/smtplib.py", line 310, in _get_socket
    return socket.create_connection((host, port), timeout,
  File "/usr/local/lib/python3.8/socket.py", line 808, in create_connection
    raise err
  File "/usr/local/lib/python3.8/socket.py", line 796, in create_connection
    sock.connect(sa)
OSError: [Errno 99] Cannot assign requested address
[2024-01-07T21:35:23.433+0000] {standard_task_runner.py:104} ERROR - Failed to execute job 553 for task copy_course_Postgres_To_GCS (404 DELETE https://storage.googleapis.com/storage/v1/b/school_data_lake_data-warehousing-proj/o/data%2Fcourse.parquet?prettyPrint=false: No such object: school_data_lake_data-warehousing-proj/data/course.parquet; 660)
[2024-01-07T21:35:23.478+0000] {local_task_job_runner.py:228} INFO - Task exited with return code 1
[2024-01-07T21:35:23.510+0000] {taskinstance.py:2778} INFO - 0 downstream tasks scheduled from follow-on schedule check
