[2024-01-06T21:16:15.751+0000] {taskinstance.py:1159} INFO - Dependencies all met for dep_context=non-requeueable deps ti=<TaskInstance: ingest_to_gcs_to_bq.country_load_dataset_to_bq scheduled__2023-12-02T00:00:00+00:00 [queued]>
[2024-01-06T21:16:15.767+0000] {taskinstance.py:1159} INFO - Dependencies all met for dep_context=requeueable deps ti=<TaskInstance: ingest_to_gcs_to_bq.country_load_dataset_to_bq scheduled__2023-12-02T00:00:00+00:00 [queued]>
[2024-01-06T21:16:15.767+0000] {taskinstance.py:1361} INFO - Starting attempt 3 of 3
[2024-01-06T21:16:15.828+0000] {taskinstance.py:1382} INFO - Executing <Task(GCSToBigQueryOperator): country_load_dataset_to_bq> on 2023-12-02 00:00:00+00:00
[2024-01-06T21:16:15.837+0000] {standard_task_runner.py:57} INFO - Started process 260 to run task
[2024-01-06T21:16:15.841+0000] {standard_task_runner.py:84} INFO - Running: ['airflow', 'tasks', 'run', 'ingest_to_gcs_to_bq', 'country_load_dataset_to_bq', 'scheduled__2023-12-02T00:00:00+00:00', '--job-id', '330', '--raw', '--subdir', 'DAGS_FOLDER/postgres_to_gcs_staging.py', '--cfg-path', '/tmp/tmp8b2wml_i']
[2024-01-06T21:16:15.845+0000] {standard_task_runner.py:85} INFO - Job 330: Subtask country_load_dataset_to_bq
[2024-01-06T21:16:16.005+0000] {task_command.py:416} INFO - Running <TaskInstance: ingest_to_gcs_to_bq.country_load_dataset_to_bq scheduled__2023-12-02T00:00:00+00:00 [running]> on host 728034eac417
[2024-01-06T21:16:16.231+0000] {taskinstance.py:1662} INFO - Exporting env vars: AIRFLOW_CTX_DAG_EMAIL='franklinmutwiri41@gmail.com' AIRFLOW_CTX_DAG_OWNER='airflow' AIRFLOW_CTX_DAG_ID='ingest_to_gcs_to_bq' AIRFLOW_CTX_TASK_ID='country_load_dataset_to_bq' AIRFLOW_CTX_EXECUTION_DATE='2023-12-02T00:00:00+00:00' AIRFLOW_CTX_TRY_NUMBER='3' AIRFLOW_CTX_DAG_RUN_ID='scheduled__2023-12-02T00:00:00+00:00'
[2024-01-06T21:16:16.253+0000] {connection.py:232} WARNING - Connection schemes (type: google_cloud_platform) shall not contain '_' according to RFC3986.
[2024-01-06T21:16:16.255+0000] {base.py:73} INFO - Using connection ID 'google_cloud_default' for task execution.
[2024-01-06T21:16:16.257+0000] {gcs_to_bigquery.py:376} INFO - Using existing BigQuery table for storing data...
[2024-01-06T21:16:16.323+0000] {gcs_to_bigquery.py:380} INFO - Executing: {'load': {'autodetect': True, 'createDisposition': 'CREATE_NEVER', 'destinationTable': {'projectId': 'data-warehousing-proj', 'datasetId': 'staging_school', 'tableId': 'STG_COUNTRY'}, 'sourceFormat': 'CSV', 'sourceUris': ['gs://school_data_lake_data-warehousing-proj/country.csv'], 'writeDisposition': 'WRITE_TRUNCATE', 'ignoreUnknownValues': False, 'skipLeadingRows': 1, 'fieldDelimiter': ',', 'quote': None, 'allowQuotedNewlines': 'true', 'encoding': 'UTF-8'}}
[2024-01-06T21:16:16.325+0000] {bigquery.py:1596} INFO - Inserting job airflow_ingest_to_gcs_to_bq_country_load_dataset_to_bq_2023_12_02T00_00_00_00_00_16b14725c3c78a1b6cd115e0185a5c45
[2024-01-06T21:16:18.769+0000] {taskinstance.py:1937} ERROR - Task failed with exception
Traceback (most recent call last):
  File "/home/airflow/.local/lib/python3.8/site-packages/airflow/providers/google/cloud/transfers/gcs_to_bigquery.py", line 439, in execute
    job.result(timeout=self.result_timeout, retry=self.result_retry)
  File "/home/airflow/.local/lib/python3.8/site-packages/google/cloud/bigquery/job/base.py", line 922, in result
    return super(_AsyncJob, self).result(timeout=timeout, **kwargs)
  File "/home/airflow/.local/lib/python3.8/site-packages/google/api_core/future/polling.py", line 261, in result
    raise self._exception
google.api_core.exceptions.NotFound: 404 Not found: URI gs://school_data_lake_data-warehousing-proj/country.csv
[2024-01-06T21:16:18.792+0000] {taskinstance.py:1400} INFO - Marking task as FAILED. dag_id=ingest_to_gcs_to_bq, task_id=country_load_dataset_to_bq, execution_date=20231202T000000, start_date=20240106T211615, end_date=20240106T211618
[2024-01-06T21:16:18.837+0000] {logging_mixin.py:151} WARNING - /home/airflow/.local/lib/python3.8/site-packages/airflow/utils/email.py:154 RemovedInAirflow3Warning: Fetching SMTP credentials from configuration variables will be deprecated in a future release. Please set credentials using a connection instead.
[2024-01-06T21:16:18.837+0000] {configuration.py:1068} WARNING - section/key [smtp/smtp_user] not found in config
[2024-01-06T21:16:18.838+0000] {email.py:270} INFO - Email alerting: attempt 1
[2024-01-06T21:16:18.860+0000] {configuration.py:1068} WARNING - section/key [smtp/smtp_user] not found in config
[2024-01-06T21:16:18.861+0000] {email.py:270} INFO - Email alerting: attempt 1
[2024-01-06T21:16:18.862+0000] {taskinstance.py:2007} ERROR - Failed to send email to: ['franklinmutwiri41@gmail.com']
Traceback (most recent call last):
  File "/home/airflow/.local/lib/python3.8/site-packages/airflow/models/taskinstance.py", line 1518, in _run_raw_task
    self._execute_task_with_callbacks(context, test_mode, session=session)
  File "/home/airflow/.local/lib/python3.8/site-packages/airflow/models/taskinstance.py", line 1681, in _execute_task_with_callbacks
    result = self._execute_task(context, task_orig)
  File "/home/airflow/.local/lib/python3.8/site-packages/airflow/models/taskinstance.py", line 1744, in _execute_task
    result = execute_callable(context=context, **execute_callable_kwargs)
  File "/home/airflow/.local/lib/python3.8/site-packages/airflow/providers/google/cloud/transfers/gcs_to_bigquery.py", line 439, in execute
    job.result(timeout=self.result_timeout, retry=self.result_retry)
  File "/home/airflow/.local/lib/python3.8/site-packages/google/cloud/bigquery/job/base.py", line 922, in result
    return super(_AsyncJob, self).result(timeout=timeout, **kwargs)
  File "/home/airflow/.local/lib/python3.8/site-packages/google/api_core/future/polling.py", line 261, in result
    raise self._exception
google.api_core.exceptions.NotFound: 404 Not found: URI gs://school_data_lake_data-warehousing-proj/country.csv

During handling of the above exception, another exception occurred:

Traceback (most recent call last):
  File "/home/airflow/.local/lib/python3.8/site-packages/airflow/models/taskinstance.py", line 2420, in email_alert
    send_email(task.email, subject, html_content)
  File "/home/airflow/.local/lib/python3.8/site-packages/airflow/utils/email.py", line 80, in send_email
    return backend(
  File "/home/airflow/.local/lib/python3.8/site-packages/airflow/utils/email.py", line 154, in send_email_smtp
    send_mime_email(e_from=mail_from, e_to=recipients, mime_msg=msg, conn_id=conn_id, dryrun=dryrun)
  File "/home/airflow/.local/lib/python3.8/site-packages/airflow/utils/email.py", line 272, in send_mime_email
    smtp_conn = _get_smtp_connection(smtp_host, smtp_port, smtp_timeout, smtp_ssl)
  File "/home/airflow/.local/lib/python3.8/site-packages/airflow/utils/email.py", line 316, in _get_smtp_connection
    return smtplib.SMTP(host=host, port=port, timeout=timeout)
  File "/usr/local/lib/python3.8/smtplib.py", line 255, in __init__
    (code, msg) = self.connect(host, port)
  File "/usr/local/lib/python3.8/smtplib.py", line 339, in connect
    self.sock = self._get_socket(host, port, self.timeout)
  File "/usr/local/lib/python3.8/smtplib.py", line 310, in _get_socket
    return socket.create_connection((host, port), timeout,
  File "/usr/local/lib/python3.8/socket.py", line 808, in create_connection
    raise err
  File "/usr/local/lib/python3.8/socket.py", line 796, in create_connection
    sock.connect(sa)
OSError: [Errno 99] Cannot assign requested address

During handling of the above exception, another exception occurred:

Traceback (most recent call last):
  File "/home/airflow/.local/lib/python3.8/site-packages/airflow/models/taskinstance.py", line 2005, in handle_failure
    self.email_alert(error, task)
  File "/home/airflow/.local/lib/python3.8/site-packages/airflow/models/taskinstance.py", line 2422, in email_alert
    send_email(task.email, subject, html_content_err)
  File "/home/airflow/.local/lib/python3.8/site-packages/airflow/utils/email.py", line 80, in send_email
    return backend(
  File "/home/airflow/.local/lib/python3.8/site-packages/airflow/utils/email.py", line 154, in send_email_smtp
    send_mime_email(e_from=mail_from, e_to=recipients, mime_msg=msg, conn_id=conn_id, dryrun=dryrun)
  File "/home/airflow/.local/lib/python3.8/site-packages/airflow/utils/email.py", line 272, in send_mime_email
    smtp_conn = _get_smtp_connection(smtp_host, smtp_port, smtp_timeout, smtp_ssl)
  File "/home/airflow/.local/lib/python3.8/site-packages/airflow/utils/email.py", line 316, in _get_smtp_connection
    return smtplib.SMTP(host=host, port=port, timeout=timeout)
  File "/usr/local/lib/python3.8/smtplib.py", line 255, in __init__
    (code, msg) = self.connect(host, port)
  File "/usr/local/lib/python3.8/smtplib.py", line 339, in connect
    self.sock = self._get_socket(host, port, self.timeout)
  File "/usr/local/lib/python3.8/smtplib.py", line 310, in _get_socket
    return socket.create_connection((host, port), timeout,
  File "/usr/local/lib/python3.8/socket.py", line 808, in create_connection
    raise err
  File "/usr/local/lib/python3.8/socket.py", line 796, in create_connection
    sock.connect(sa)
OSError: [Errno 99] Cannot assign requested address
[2024-01-06T21:16:19.195+0000] {standard_task_runner.py:104} ERROR - Failed to execute job 330 for task country_load_dataset_to_bq (404 Not found: URI gs://school_data_lake_data-warehousing-proj/country.csv; 260)
[2024-01-06T21:16:19.232+0000] {local_task_job_runner.py:228} INFO - Task exited with return code 1
[2024-01-06T21:16:19.515+0000] {taskinstance.py:2778} INFO - 0 downstream tasks scheduled from follow-on schedule check
