[2023-11-30T06:01:58.221+0000] {taskinstance.py:1159} INFO - Dependencies all met for dep_context=non-requeueable deps ti=<TaskInstance: ingest_to_postgres.upload_to_gcs_department scheduled__2023-11-27T00:00:00+00:00 [queued]>
[2023-11-30T06:01:58.240+0000] {taskinstance.py:1159} INFO - Dependencies all met for dep_context=requeueable deps ti=<TaskInstance: ingest_to_postgres.upload_to_gcs_department scheduled__2023-11-27T00:00:00+00:00 [queued]>
[2023-11-30T06:01:58.243+0000] {taskinstance.py:1361} INFO - Starting attempt 3 of 6
[2023-11-30T06:01:58.277+0000] {taskinstance.py:1382} INFO - Executing <Task(PostgresToGCSOperator): upload_to_gcs_department> on 2023-11-27 00:00:00+00:00
[2023-11-30T06:01:58.290+0000] {standard_task_runner.py:57} INFO - Started process 14794 to run task
[2023-11-30T06:01:58.295+0000] {standard_task_runner.py:84} INFO - Running: ['airflow', 'tasks', 'run', 'ingest_to_postgres', 'upload_to_gcs_department', 'scheduled__2023-11-27T00:00:00+00:00', '--job-id', '110', '--raw', '--subdir', 'DAGS_FOLDER/postgres_to_gcs_staging.py', '--cfg-path', '/tmp/tmpw5wccztm']
[2023-11-30T06:01:58.300+0000] {standard_task_runner.py:85} INFO - Job 110: Subtask upload_to_gcs_department
[2023-11-30T06:01:58.433+0000] {task_command.py:416} INFO - Running <TaskInstance: ingest_to_postgres.upload_to_gcs_department scheduled__2023-11-27T00:00:00+00:00 [running]> on host f212b4329056
[2023-11-30T06:01:58.539+0000] {logging_mixin.py:151} WARNING - /home/airflow/.local/lib/python3.8/site-packages/airflow/utils/context.py:206 AirflowContextDeprecationWarning: Accessing 'execution_date' from the template is deprecated and will be removed in a future version. Please use 'data_interval_start' or 'logical_date' instead.
[2023-11-30T06:01:58.624+0000] {taskinstance.py:1662} INFO - Exporting env vars: AIRFLOW_CTX_DAG_EMAIL='franklinmutwiri41@gmail.com' AIRFLOW_CTX_DAG_OWNER='airflow' AIRFLOW_CTX_DAG_ID='ingest_to_postgres' AIRFLOW_CTX_TASK_ID='upload_to_gcs_department' AIRFLOW_CTX_EXECUTION_DATE='2023-11-27T00:00:00+00:00' AIRFLOW_CTX_TRY_NUMBER='3' AIRFLOW_CTX_DAG_RUN_ID='scheduled__2023-11-27T00:00:00+00:00'
[2023-11-30T06:01:58.626+0000] {sql_to_gcs.py:161} INFO - Executing query
[2023-11-30T06:01:58.651+0000] {base.py:73} INFO - Using connection ID 'postgres_docker' for task execution.
[2023-11-30T06:01:58.657+0000] {taskinstance.py:1937} ERROR - Task failed with exception
Traceback (most recent call last):
  File "/home/airflow/.local/lib/python3.8/site-packages/airflow/providers/google/cloud/transfers/sql_to_gcs.py", line 162, in execute
    cursor = self.query()
  File "/home/airflow/.local/lib/python3.8/site-packages/airflow/providers/google/cloud/transfers/postgres_to_gcs.py", line 120, in query
    conn = hook.get_conn()
  File "/home/airflow/.local/lib/python3.8/site-packages/airflow/providers/postgres/hooks/postgres.py", line 155, in get_conn
    self.conn = psycopg2.connect(**conn_args)
  File "/home/airflow/.local/lib/python3.8/site-packages/psycopg2/__init__.py", line 122, in connect
    conn = _connect(dsn, connection_factory=connection_factory, **kwasync)
psycopg2.OperationalError: connection to server at "postgres" (172.21.0.2), port 54320 failed: Connection refused
	Is the server running on that host and accepting TCP/IP connections?

[2023-11-30T06:01:58.685+0000] {taskinstance.py:1400} INFO - Marking task as UP_FOR_RETRY. dag_id=ingest_to_postgres, task_id=upload_to_gcs_department, execution_date=20231127T000000, start_date=20231130T060158, end_date=20231130T060158
[2023-11-30T06:01:58.711+0000] {logging_mixin.py:151} WARNING - /home/***/.local/lib/python3.8/site-packages/***/utils/email.py:154 RemovedInAirflow3Warning: Fetching SMTP credentials from configuration variables will be deprecated in a future release. Please set credentials using a connection instead.
[2023-11-30T06:01:58.712+0000] {configuration.py:1068} WARNING - section/key [smtp/smtp_user] not found in config
[2023-11-30T06:01:58.712+0000] {email.py:270} INFO - Email alerting: attempt 1
[2023-11-30T06:01:58.730+0000] {configuration.py:1068} WARNING - section/key [smtp/smtp_user] not found in config
[2023-11-30T06:01:58.731+0000] {email.py:270} INFO - Email alerting: attempt 1
[2023-11-30T06:01:58.733+0000] {taskinstance.py:2007} ERROR - Failed to send email to: ['franklinmutwiri41@gmail.com']
Traceback (most recent call last):
  File "/home/airflow/.local/lib/python3.8/site-packages/airflow/models/taskinstance.py", line 1518, in _run_raw_task
    self._execute_task_with_callbacks(context, test_mode, session=session)
  File "/home/airflow/.local/lib/python3.8/site-packages/airflow/models/taskinstance.py", line 1681, in _execute_task_with_callbacks
    result = self._execute_task(context, task_orig)
  File "/home/airflow/.local/lib/python3.8/site-packages/airflow/models/taskinstance.py", line 1744, in _execute_task
    result = execute_callable(context=context, **execute_callable_kwargs)
  File "/home/airflow/.local/lib/python3.8/site-packages/airflow/providers/google/cloud/transfers/sql_to_gcs.py", line 162, in execute
    cursor = self.query()
  File "/home/airflow/.local/lib/python3.8/site-packages/airflow/providers/google/cloud/transfers/postgres_to_gcs.py", line 120, in query
    conn = hook.get_conn()
  File "/home/airflow/.local/lib/python3.8/site-packages/airflow/providers/postgres/hooks/postgres.py", line 155, in get_conn
    self.conn = psycopg2.connect(**conn_args)
  File "/home/airflow/.local/lib/python3.8/site-packages/psycopg2/__init__.py", line 122, in connect
    conn = _connect(dsn, connection_factory=connection_factory, **kwasync)
psycopg2.OperationalError: connection to server at "postgres" (172.21.0.2), port 54320 failed: Connection refused
	Is the server running on that host and accepting TCP/IP connections?


During handling of the above exception, another exception occurred:

Traceback (most recent call last):
  File "/home/airflow/.local/lib/python3.8/site-packages/airflow/models/taskinstance.py", line 2420, in email_alert
    send_email(task.email, subject, html_content)
  File "/home/airflow/.local/lib/python3.8/site-packages/airflow/utils/email.py", line 80, in send_email
    return backend(
  File "/home/airflow/.local/lib/python3.8/site-packages/airflow/utils/email.py", line 154, in send_email_smtp
    send_mime_email(e_from=mail_from, e_to=recipients, mime_msg=msg, conn_id=conn_id, dryrun=dryrun)
  File "/home/airflow/.local/lib/python3.8/site-packages/airflow/utils/email.py", line 272, in send_mime_email
    smtp_conn = _get_smtp_connection(smtp_host, smtp_port, smtp_timeout, smtp_ssl)
  File "/home/airflow/.local/lib/python3.8/site-packages/airflow/utils/email.py", line 316, in _get_smtp_connection
    return smtplib.SMTP(host=host, port=port, timeout=timeout)
  File "/usr/local/lib/python3.8/smtplib.py", line 255, in __init__
    (code, msg) = self.connect(host, port)
  File "/usr/local/lib/python3.8/smtplib.py", line 339, in connect
    self.sock = self._get_socket(host, port, self.timeout)
  File "/usr/local/lib/python3.8/smtplib.py", line 310, in _get_socket
    return socket.create_connection((host, port), timeout,
  File "/usr/local/lib/python3.8/socket.py", line 808, in create_connection
    raise err
  File "/usr/local/lib/python3.8/socket.py", line 796, in create_connection
    sock.connect(sa)
OSError: [Errno 99] Cannot assign requested address

During handling of the above exception, another exception occurred:

Traceback (most recent call last):
  File "/home/airflow/.local/lib/python3.8/site-packages/airflow/models/taskinstance.py", line 2005, in handle_failure
    self.email_alert(error, task)
  File "/home/airflow/.local/lib/python3.8/site-packages/airflow/models/taskinstance.py", line 2422, in email_alert
    send_email(task.email, subject, html_content_err)
  File "/home/airflow/.local/lib/python3.8/site-packages/airflow/utils/email.py", line 80, in send_email
    return backend(
  File "/home/airflow/.local/lib/python3.8/site-packages/airflow/utils/email.py", line 154, in send_email_smtp
    send_mime_email(e_from=mail_from, e_to=recipients, mime_msg=msg, conn_id=conn_id, dryrun=dryrun)
  File "/home/airflow/.local/lib/python3.8/site-packages/airflow/utils/email.py", line 272, in send_mime_email
    smtp_conn = _get_smtp_connection(smtp_host, smtp_port, smtp_timeout, smtp_ssl)
  File "/home/airflow/.local/lib/python3.8/site-packages/airflow/utils/email.py", line 316, in _get_smtp_connection
    return smtplib.SMTP(host=host, port=port, timeout=timeout)
  File "/usr/local/lib/python3.8/smtplib.py", line 255, in __init__
    (code, msg) = self.connect(host, port)
  File "/usr/local/lib/python3.8/smtplib.py", line 339, in connect
    self.sock = self._get_socket(host, port, self.timeout)
  File "/usr/local/lib/python3.8/smtplib.py", line 310, in _get_socket
    return socket.create_connection((host, port), timeout,
  File "/usr/local/lib/python3.8/socket.py", line 808, in create_connection
    raise err
  File "/usr/local/lib/python3.8/socket.py", line 796, in create_connection
    sock.connect(sa)
OSError: [Errno 99] Cannot assign requested address
[2023-11-30T06:01:58.774+0000] {standard_task_runner.py:104} ERROR - Failed to execute job 110 for task upload_to_gcs_department (connection to server at "postgres" (172.21.0.2), port 54320 failed: Connection refused
	Is the server running on that host and accepting TCP/IP connections?
; 14794)
[2023-11-30T06:01:58.791+0000] {local_task_job_runner.py:228} INFO - Task exited with return code 1
[2023-11-30T06:01:58.828+0000] {taskinstance.py:2778} INFO - 0 downstream tasks scheduled from follow-on schedule check
[2023-11-30T06:03:45.485+0000] {taskinstance.py:1159} INFO - Dependencies all met for dep_context=non-requeueable deps ti=<TaskInstance: ingest_to_postgres.upload_to_gcs_department scheduled__2023-11-27T00:00:00+00:00 [queued]>
[2023-11-30T06:03:45.502+0000] {taskinstance.py:1159} INFO - Dependencies all met for dep_context=requeueable deps ti=<TaskInstance: ingest_to_postgres.upload_to_gcs_department scheduled__2023-11-27T00:00:00+00:00 [queued]>
[2023-11-30T06:03:45.502+0000] {taskinstance.py:1361} INFO - Starting attempt 3 of 3
[2023-11-30T06:03:45.531+0000] {taskinstance.py:1382} INFO - Executing <Task(PostgresToGCSOperator): upload_to_gcs_department> on 2023-11-27 00:00:00+00:00
[2023-11-30T06:03:45.540+0000] {standard_task_runner.py:57} INFO - Started process 14868 to run task
[2023-11-30T06:03:45.546+0000] {standard_task_runner.py:84} INFO - Running: ['airflow', 'tasks', 'run', 'ingest_to_postgres', 'upload_to_gcs_department', 'scheduled__2023-11-27T00:00:00+00:00', '--job-id', '119', '--raw', '--subdir', 'DAGS_FOLDER/postgres_to_gcs_staging.py', '--cfg-path', '/tmp/tmpnfw9jlww']
[2023-11-30T06:03:45.551+0000] {standard_task_runner.py:85} INFO - Job 119: Subtask upload_to_gcs_department
[2023-11-30T06:03:45.653+0000] {task_command.py:416} INFO - Running <TaskInstance: ingest_to_postgres.upload_to_gcs_department scheduled__2023-11-27T00:00:00+00:00 [running]> on host f212b4329056
[2023-11-30T06:03:45.763+0000] {logging_mixin.py:151} WARNING - /home/airflow/.local/lib/python3.8/site-packages/airflow/utils/context.py:206 AirflowContextDeprecationWarning: Accessing 'execution_date' from the template is deprecated and will be removed in a future version. Please use 'data_interval_start' or 'logical_date' instead.
[2023-11-30T06:03:45.826+0000] {taskinstance.py:1662} INFO - Exporting env vars: AIRFLOW_CTX_DAG_EMAIL='franklinmutwiri41@gmail.com' AIRFLOW_CTX_DAG_OWNER='airflow' AIRFLOW_CTX_DAG_ID='ingest_to_postgres' AIRFLOW_CTX_TASK_ID='upload_to_gcs_department' AIRFLOW_CTX_EXECUTION_DATE='2023-11-27T00:00:00+00:00' AIRFLOW_CTX_TRY_NUMBER='3' AIRFLOW_CTX_DAG_RUN_ID='scheduled__2023-11-27T00:00:00+00:00'
[2023-11-30T06:03:45.828+0000] {sql_to_gcs.py:161} INFO - Executing query
[2023-11-30T06:03:45.850+0000] {base.py:73} INFO - Using connection ID 'postgres_docker' for task execution.
[2023-11-30T06:03:45.852+0000] {taskinstance.py:1937} ERROR - Task failed with exception
Traceback (most recent call last):
  File "/home/airflow/.local/lib/python3.8/site-packages/airflow/providers/google/cloud/transfers/sql_to_gcs.py", line 162, in execute
    cursor = self.query()
  File "/home/airflow/.local/lib/python3.8/site-packages/airflow/providers/google/cloud/transfers/postgres_to_gcs.py", line 120, in query
    conn = hook.get_conn()
  File "/home/airflow/.local/lib/python3.8/site-packages/airflow/providers/postgres/hooks/postgres.py", line 155, in get_conn
    self.conn = psycopg2.connect(**conn_args)
  File "/home/airflow/.local/lib/python3.8/site-packages/psycopg2/__init__.py", line 122, in connect
    conn = _connect(dsn, connection_factory=connection_factory, **kwasync)
psycopg2.OperationalError: connection to server at "postgres" (172.21.0.2), port 54320 failed: Connection refused
	Is the server running on that host and accepting TCP/IP connections?

[2023-11-30T06:03:45.871+0000] {taskinstance.py:1400} INFO - Marking task as FAILED. dag_id=ingest_to_postgres, task_id=upload_to_gcs_department, execution_date=20231127T000000, start_date=20231130T060345, end_date=20231130T060345
[2023-11-30T06:03:45.889+0000] {logging_mixin.py:151} WARNING - /home/***/.local/lib/python3.8/site-packages/***/utils/email.py:154 RemovedInAirflow3Warning: Fetching SMTP credentials from configuration variables will be deprecated in a future release. Please set credentials using a connection instead.
[2023-11-30T06:03:45.889+0000] {configuration.py:1068} WARNING - section/key [smtp/smtp_user] not found in config
[2023-11-30T06:03:45.890+0000] {email.py:270} INFO - Email alerting: attempt 1
[2023-11-30T06:03:45.906+0000] {configuration.py:1068} WARNING - section/key [smtp/smtp_user] not found in config
[2023-11-30T06:03:45.907+0000] {email.py:270} INFO - Email alerting: attempt 1
[2023-11-30T06:03:45.908+0000] {taskinstance.py:2007} ERROR - Failed to send email to: ['franklinmutwiri41@gmail.com']
Traceback (most recent call last):
  File "/home/airflow/.local/lib/python3.8/site-packages/airflow/models/taskinstance.py", line 1518, in _run_raw_task
    self._execute_task_with_callbacks(context, test_mode, session=session)
  File "/home/airflow/.local/lib/python3.8/site-packages/airflow/models/taskinstance.py", line 1681, in _execute_task_with_callbacks
    result = self._execute_task(context, task_orig)
  File "/home/airflow/.local/lib/python3.8/site-packages/airflow/models/taskinstance.py", line 1744, in _execute_task
    result = execute_callable(context=context, **execute_callable_kwargs)
  File "/home/airflow/.local/lib/python3.8/site-packages/airflow/providers/google/cloud/transfers/sql_to_gcs.py", line 162, in execute
    cursor = self.query()
  File "/home/airflow/.local/lib/python3.8/site-packages/airflow/providers/google/cloud/transfers/postgres_to_gcs.py", line 120, in query
    conn = hook.get_conn()
  File "/home/airflow/.local/lib/python3.8/site-packages/airflow/providers/postgres/hooks/postgres.py", line 155, in get_conn
    self.conn = psycopg2.connect(**conn_args)
  File "/home/airflow/.local/lib/python3.8/site-packages/psycopg2/__init__.py", line 122, in connect
    conn = _connect(dsn, connection_factory=connection_factory, **kwasync)
psycopg2.OperationalError: connection to server at "postgres" (172.21.0.2), port 54320 failed: Connection refused
	Is the server running on that host and accepting TCP/IP connections?


During handling of the above exception, another exception occurred:

Traceback (most recent call last):
  File "/home/airflow/.local/lib/python3.8/site-packages/airflow/models/taskinstance.py", line 2420, in email_alert
    send_email(task.email, subject, html_content)
  File "/home/airflow/.local/lib/python3.8/site-packages/airflow/utils/email.py", line 80, in send_email
    return backend(
  File "/home/airflow/.local/lib/python3.8/site-packages/airflow/utils/email.py", line 154, in send_email_smtp
    send_mime_email(e_from=mail_from, e_to=recipients, mime_msg=msg, conn_id=conn_id, dryrun=dryrun)
  File "/home/airflow/.local/lib/python3.8/site-packages/airflow/utils/email.py", line 272, in send_mime_email
    smtp_conn = _get_smtp_connection(smtp_host, smtp_port, smtp_timeout, smtp_ssl)
  File "/home/airflow/.local/lib/python3.8/site-packages/airflow/utils/email.py", line 316, in _get_smtp_connection
    return smtplib.SMTP(host=host, port=port, timeout=timeout)
  File "/usr/local/lib/python3.8/smtplib.py", line 255, in __init__
    (code, msg) = self.connect(host, port)
  File "/usr/local/lib/python3.8/smtplib.py", line 339, in connect
    self.sock = self._get_socket(host, port, self.timeout)
  File "/usr/local/lib/python3.8/smtplib.py", line 310, in _get_socket
    return socket.create_connection((host, port), timeout,
  File "/usr/local/lib/python3.8/socket.py", line 808, in create_connection
    raise err
  File "/usr/local/lib/python3.8/socket.py", line 796, in create_connection
    sock.connect(sa)
OSError: [Errno 99] Cannot assign requested address

During handling of the above exception, another exception occurred:

Traceback (most recent call last):
  File "/home/airflow/.local/lib/python3.8/site-packages/airflow/models/taskinstance.py", line 2005, in handle_failure
    self.email_alert(error, task)
  File "/home/airflow/.local/lib/python3.8/site-packages/airflow/models/taskinstance.py", line 2422, in email_alert
    send_email(task.email, subject, html_content_err)
  File "/home/airflow/.local/lib/python3.8/site-packages/airflow/utils/email.py", line 80, in send_email
    return backend(
  File "/home/airflow/.local/lib/python3.8/site-packages/airflow/utils/email.py", line 154, in send_email_smtp
    send_mime_email(e_from=mail_from, e_to=recipients, mime_msg=msg, conn_id=conn_id, dryrun=dryrun)
  File "/home/airflow/.local/lib/python3.8/site-packages/airflow/utils/email.py", line 272, in send_mime_email
    smtp_conn = _get_smtp_connection(smtp_host, smtp_port, smtp_timeout, smtp_ssl)
  File "/home/airflow/.local/lib/python3.8/site-packages/airflow/utils/email.py", line 316, in _get_smtp_connection
    return smtplib.SMTP(host=host, port=port, timeout=timeout)
  File "/usr/local/lib/python3.8/smtplib.py", line 255, in __init__
    (code, msg) = self.connect(host, port)
  File "/usr/local/lib/python3.8/smtplib.py", line 339, in connect
    self.sock = self._get_socket(host, port, self.timeout)
  File "/usr/local/lib/python3.8/smtplib.py", line 310, in _get_socket
    return socket.create_connection((host, port), timeout,
  File "/usr/local/lib/python3.8/socket.py", line 808, in create_connection
    raise err
  File "/usr/local/lib/python3.8/socket.py", line 796, in create_connection
    sock.connect(sa)
OSError: [Errno 99] Cannot assign requested address
[2023-11-30T06:03:45.941+0000] {standard_task_runner.py:104} ERROR - Failed to execute job 119 for task upload_to_gcs_department (connection to server at "postgres" (172.21.0.2), port 54320 failed: Connection refused
	Is the server running on that host and accepting TCP/IP connections?
; 14868)
[2023-11-30T06:03:45.958+0000] {local_task_job_runner.py:228} INFO - Task exited with return code 1
[2023-11-30T06:03:45.995+0000] {taskinstance.py:2778} INFO - 0 downstream tasks scheduled from follow-on schedule check
[2023-11-30T06:15:23.934+0000] {taskinstance.py:1159} INFO - Dependencies all met for dep_context=non-requeueable deps ti=<TaskInstance: ingest_to_postgres.upload_to_gcs_department scheduled__2023-11-27T00:00:00+00:00 [queued]>
[2023-11-30T06:15:23.967+0000] {taskinstance.py:1159} INFO - Dependencies all met for dep_context=requeueable deps ti=<TaskInstance: ingest_to_postgres.upload_to_gcs_department scheduled__2023-11-27T00:00:00+00:00 [queued]>
[2023-11-30T06:15:23.968+0000] {taskinstance.py:1361} INFO - Starting attempt 3 of 3
[2023-11-30T06:15:24.005+0000] {taskinstance.py:1382} INFO - Executing <Task(PostgresToGCSOperator): upload_to_gcs_department> on 2023-11-27 00:00:00+00:00
[2023-11-30T06:15:24.020+0000] {standard_task_runner.py:57} INFO - Started process 15166 to run task
[2023-11-30T06:15:24.054+0000] {standard_task_runner.py:84} INFO - Running: ['airflow', 'tasks', 'run', 'ingest_to_postgres', 'upload_to_gcs_department', 'scheduled__2023-11-27T00:00:00+00:00', '--job-id', '126', '--raw', '--subdir', 'DAGS_FOLDER/postgres_to_gcs_staging.py', '--cfg-path', '/tmp/tmpmj046sj7']
[2023-11-30T06:15:24.067+0000] {standard_task_runner.py:85} INFO - Job 126: Subtask upload_to_gcs_department
[2023-11-30T06:15:24.377+0000] {task_command.py:416} INFO - Running <TaskInstance: ingest_to_postgres.upload_to_gcs_department scheduled__2023-11-27T00:00:00+00:00 [running]> on host f212b4329056
[2023-11-30T06:15:24.506+0000] {logging_mixin.py:151} WARNING - /home/airflow/.local/lib/python3.8/site-packages/airflow/utils/context.py:206 AirflowContextDeprecationWarning: Accessing 'execution_date' from the template is deprecated and will be removed in a future version. Please use 'data_interval_start' or 'logical_date' instead.
[2023-11-30T06:15:24.580+0000] {taskinstance.py:1662} INFO - Exporting env vars: AIRFLOW_CTX_DAG_EMAIL='franklinmutwiri41@gmail.com' AIRFLOW_CTX_DAG_OWNER='airflow' AIRFLOW_CTX_DAG_ID='ingest_to_postgres' AIRFLOW_CTX_TASK_ID='upload_to_gcs_department' AIRFLOW_CTX_EXECUTION_DATE='2023-11-27T00:00:00+00:00' AIRFLOW_CTX_TRY_NUMBER='3' AIRFLOW_CTX_DAG_RUN_ID='scheduled__2023-11-27T00:00:00+00:00'
[2023-11-30T06:15:24.582+0000] {sql_to_gcs.py:161} INFO - Executing query
[2023-11-30T06:15:24.604+0000] {base.py:73} INFO - Using connection ID 'postgres_docker' for task execution.
[2023-11-30T06:15:24.606+0000] {taskinstance.py:1937} ERROR - Task failed with exception
Traceback (most recent call last):
  File "/home/airflow/.local/lib/python3.8/site-packages/airflow/providers/google/cloud/transfers/sql_to_gcs.py", line 162, in execute
    cursor = self.query()
  File "/home/airflow/.local/lib/python3.8/site-packages/airflow/providers/google/cloud/transfers/postgres_to_gcs.py", line 120, in query
    conn = hook.get_conn()
  File "/home/airflow/.local/lib/python3.8/site-packages/airflow/providers/postgres/hooks/postgres.py", line 155, in get_conn
    self.conn = psycopg2.connect(**conn_args)
  File "/home/airflow/.local/lib/python3.8/site-packages/psycopg2/__init__.py", line 122, in connect
    conn = _connect(dsn, connection_factory=connection_factory, **kwasync)
psycopg2.OperationalError: connection to server at "postgres" (172.21.0.2), port 54320 failed: Connection refused
	Is the server running on that host and accepting TCP/IP connections?

[2023-11-30T06:15:24.628+0000] {taskinstance.py:1400} INFO - Marking task as FAILED. dag_id=ingest_to_postgres, task_id=upload_to_gcs_department, execution_date=20231127T000000, start_date=20231130T061523, end_date=20231130T061524
[2023-11-30T06:15:24.648+0000] {logging_mixin.py:151} WARNING - /home/***/.local/lib/python3.8/site-packages/***/utils/email.py:154 RemovedInAirflow3Warning: Fetching SMTP credentials from configuration variables will be deprecated in a future release. Please set credentials using a connection instead.
[2023-11-30T06:15:24.649+0000] {configuration.py:1068} WARNING - section/key [smtp/smtp_user] not found in config
[2023-11-30T06:15:24.650+0000] {email.py:270} INFO - Email alerting: attempt 1
[2023-11-30T06:15:24.672+0000] {configuration.py:1068} WARNING - section/key [smtp/smtp_user] not found in config
[2023-11-30T06:15:24.672+0000] {email.py:270} INFO - Email alerting: attempt 1
[2023-11-30T06:15:24.673+0000] {taskinstance.py:2007} ERROR - Failed to send email to: ['franklinmutwiri41@gmail.com']
Traceback (most recent call last):
  File "/home/airflow/.local/lib/python3.8/site-packages/airflow/models/taskinstance.py", line 1518, in _run_raw_task
    self._execute_task_with_callbacks(context, test_mode, session=session)
  File "/home/airflow/.local/lib/python3.8/site-packages/airflow/models/taskinstance.py", line 1681, in _execute_task_with_callbacks
    result = self._execute_task(context, task_orig)
  File "/home/airflow/.local/lib/python3.8/site-packages/airflow/models/taskinstance.py", line 1744, in _execute_task
    result = execute_callable(context=context, **execute_callable_kwargs)
  File "/home/airflow/.local/lib/python3.8/site-packages/airflow/providers/google/cloud/transfers/sql_to_gcs.py", line 162, in execute
    cursor = self.query()
  File "/home/airflow/.local/lib/python3.8/site-packages/airflow/providers/google/cloud/transfers/postgres_to_gcs.py", line 120, in query
    conn = hook.get_conn()
  File "/home/airflow/.local/lib/python3.8/site-packages/airflow/providers/postgres/hooks/postgres.py", line 155, in get_conn
    self.conn = psycopg2.connect(**conn_args)
  File "/home/airflow/.local/lib/python3.8/site-packages/psycopg2/__init__.py", line 122, in connect
    conn = _connect(dsn, connection_factory=connection_factory, **kwasync)
psycopg2.OperationalError: connection to server at "postgres" (172.21.0.2), port 54320 failed: Connection refused
	Is the server running on that host and accepting TCP/IP connections?


During handling of the above exception, another exception occurred:

Traceback (most recent call last):
  File "/home/airflow/.local/lib/python3.8/site-packages/airflow/models/taskinstance.py", line 2420, in email_alert
    send_email(task.email, subject, html_content)
  File "/home/airflow/.local/lib/python3.8/site-packages/airflow/utils/email.py", line 80, in send_email
    return backend(
  File "/home/airflow/.local/lib/python3.8/site-packages/airflow/utils/email.py", line 154, in send_email_smtp
    send_mime_email(e_from=mail_from, e_to=recipients, mime_msg=msg, conn_id=conn_id, dryrun=dryrun)
  File "/home/airflow/.local/lib/python3.8/site-packages/airflow/utils/email.py", line 272, in send_mime_email
    smtp_conn = _get_smtp_connection(smtp_host, smtp_port, smtp_timeout, smtp_ssl)
  File "/home/airflow/.local/lib/python3.8/site-packages/airflow/utils/email.py", line 316, in _get_smtp_connection
    return smtplib.SMTP(host=host, port=port, timeout=timeout)
  File "/usr/local/lib/python3.8/smtplib.py", line 255, in __init__
    (code, msg) = self.connect(host, port)
  File "/usr/local/lib/python3.8/smtplib.py", line 339, in connect
    self.sock = self._get_socket(host, port, self.timeout)
  File "/usr/local/lib/python3.8/smtplib.py", line 310, in _get_socket
    return socket.create_connection((host, port), timeout,
  File "/usr/local/lib/python3.8/socket.py", line 808, in create_connection
    raise err
  File "/usr/local/lib/python3.8/socket.py", line 796, in create_connection
    sock.connect(sa)
OSError: [Errno 99] Cannot assign requested address

During handling of the above exception, another exception occurred:

Traceback (most recent call last):
  File "/home/airflow/.local/lib/python3.8/site-packages/airflow/models/taskinstance.py", line 2005, in handle_failure
    self.email_alert(error, task)
  File "/home/airflow/.local/lib/python3.8/site-packages/airflow/models/taskinstance.py", line 2422, in email_alert
    send_email(task.email, subject, html_content_err)
  File "/home/airflow/.local/lib/python3.8/site-packages/airflow/utils/email.py", line 80, in send_email
    return backend(
  File "/home/airflow/.local/lib/python3.8/site-packages/airflow/utils/email.py", line 154, in send_email_smtp
    send_mime_email(e_from=mail_from, e_to=recipients, mime_msg=msg, conn_id=conn_id, dryrun=dryrun)
  File "/home/airflow/.local/lib/python3.8/site-packages/airflow/utils/email.py", line 272, in send_mime_email
    smtp_conn = _get_smtp_connection(smtp_host, smtp_port, smtp_timeout, smtp_ssl)
  File "/home/airflow/.local/lib/python3.8/site-packages/airflow/utils/email.py", line 316, in _get_smtp_connection
    return smtplib.SMTP(host=host, port=port, timeout=timeout)
  File "/usr/local/lib/python3.8/smtplib.py", line 255, in __init__
    (code, msg) = self.connect(host, port)
  File "/usr/local/lib/python3.8/smtplib.py", line 339, in connect
    self.sock = self._get_socket(host, port, self.timeout)
  File "/usr/local/lib/python3.8/smtplib.py", line 310, in _get_socket
    return socket.create_connection((host, port), timeout,
  File "/usr/local/lib/python3.8/socket.py", line 808, in create_connection
    raise err
  File "/usr/local/lib/python3.8/socket.py", line 796, in create_connection
    sock.connect(sa)
OSError: [Errno 99] Cannot assign requested address
[2023-11-30T06:15:24.703+0000] {standard_task_runner.py:104} ERROR - Failed to execute job 126 for task upload_to_gcs_department (connection to server at "postgres" (172.21.0.2), port 54320 failed: Connection refused
	Is the server running on that host and accepting TCP/IP connections?
; 15166)
[2023-11-30T06:15:24.722+0000] {local_task_job_runner.py:228} INFO - Task exited with return code 1
[2023-11-30T06:15:24.779+0000] {taskinstance.py:2778} INFO - 0 downstream tasks scheduled from follow-on schedule check
[2023-11-30T06:18:41.522+0000] {taskinstance.py:1159} INFO - Dependencies all met for dep_context=non-requeueable deps ti=<TaskInstance: ingest_to_postgres.upload_to_gcs_department scheduled__2023-11-27T00:00:00+00:00 [queued]>
[2023-11-30T06:18:41.546+0000] {taskinstance.py:1159} INFO - Dependencies all met for dep_context=requeueable deps ti=<TaskInstance: ingest_to_postgres.upload_to_gcs_department scheduled__2023-11-27T00:00:00+00:00 [queued]>
[2023-11-30T06:18:41.547+0000] {taskinstance.py:1361} INFO - Starting attempt 3 of 3
[2023-11-30T06:18:41.576+0000] {taskinstance.py:1382} INFO - Executing <Task(PostgresToGCSOperator): upload_to_gcs_department> on 2023-11-27 00:00:00+00:00
[2023-11-30T06:18:41.585+0000] {standard_task_runner.py:57} INFO - Started process 15271 to run task
[2023-11-30T06:18:41.593+0000] {standard_task_runner.py:84} INFO - Running: ['airflow', 'tasks', 'run', 'ingest_to_postgres', 'upload_to_gcs_department', 'scheduled__2023-11-27T00:00:00+00:00', '--job-id', '135', '--raw', '--subdir', 'DAGS_FOLDER/postgres_to_gcs_staging.py', '--cfg-path', '/tmp/tmps0rh2d0t']
[2023-11-30T06:18:41.598+0000] {standard_task_runner.py:85} INFO - Job 135: Subtask upload_to_gcs_department
[2023-11-30T06:18:41.739+0000] {task_command.py:416} INFO - Running <TaskInstance: ingest_to_postgres.upload_to_gcs_department scheduled__2023-11-27T00:00:00+00:00 [running]> on host f212b4329056
[2023-11-30T06:18:41.934+0000] {logging_mixin.py:151} WARNING - /home/airflow/.local/lib/python3.8/site-packages/airflow/utils/context.py:206 AirflowContextDeprecationWarning: Accessing 'execution_date' from the template is deprecated and will be removed in a future version. Please use 'data_interval_start' or 'logical_date' instead.
[2023-11-30T06:18:42.053+0000] {taskinstance.py:1662} INFO - Exporting env vars: AIRFLOW_CTX_DAG_EMAIL='franklinmutwiri41@gmail.com' AIRFLOW_CTX_DAG_OWNER='airflow' AIRFLOW_CTX_DAG_ID='ingest_to_postgres' AIRFLOW_CTX_TASK_ID='upload_to_gcs_department' AIRFLOW_CTX_EXECUTION_DATE='2023-11-27T00:00:00+00:00' AIRFLOW_CTX_TRY_NUMBER='3' AIRFLOW_CTX_DAG_RUN_ID='scheduled__2023-11-27T00:00:00+00:00'
[2023-11-30T06:18:42.055+0000] {sql_to_gcs.py:161} INFO - Executing query
[2023-11-30T06:18:42.085+0000] {base.py:73} INFO - Using connection ID 'postgres_docker' for task execution.
[2023-11-30T06:18:42.088+0000] {taskinstance.py:1937} ERROR - Task failed with exception
Traceback (most recent call last):
  File "/home/airflow/.local/lib/python3.8/site-packages/airflow/providers/google/cloud/transfers/sql_to_gcs.py", line 162, in execute
    cursor = self.query()
  File "/home/airflow/.local/lib/python3.8/site-packages/airflow/providers/google/cloud/transfers/postgres_to_gcs.py", line 120, in query
    conn = hook.get_conn()
  File "/home/airflow/.local/lib/python3.8/site-packages/airflow/providers/postgres/hooks/postgres.py", line 155, in get_conn
    self.conn = psycopg2.connect(**conn_args)
  File "/home/airflow/.local/lib/python3.8/site-packages/psycopg2/__init__.py", line 122, in connect
    conn = _connect(dsn, connection_factory=connection_factory, **kwasync)
psycopg2.OperationalError: connection to server at "postgres" (172.21.0.2), port 54320 failed: Connection refused
	Is the server running on that host and accepting TCP/IP connections?

[2023-11-30T06:18:42.125+0000] {taskinstance.py:1400} INFO - Marking task as FAILED. dag_id=ingest_to_postgres, task_id=upload_to_gcs_department, execution_date=20231127T000000, start_date=20231130T061841, end_date=20231130T061842
[2023-11-30T06:18:42.154+0000] {logging_mixin.py:151} WARNING - /home/***/.local/lib/python3.8/site-packages/***/utils/email.py:154 RemovedInAirflow3Warning: Fetching SMTP credentials from configuration variables will be deprecated in a future release. Please set credentials using a connection instead.
[2023-11-30T06:18:42.154+0000] {configuration.py:1068} WARNING - section/key [smtp/smtp_user] not found in config
[2023-11-30T06:18:42.155+0000] {email.py:270} INFO - Email alerting: attempt 1
[2023-11-30T06:18:42.219+0000] {configuration.py:1068} WARNING - section/key [smtp/smtp_user] not found in config
[2023-11-30T06:18:42.219+0000] {email.py:270} INFO - Email alerting: attempt 1
[2023-11-30T06:18:42.220+0000] {taskinstance.py:2007} ERROR - Failed to send email to: ['franklinmutwiri41@gmail.com']
Traceback (most recent call last):
  File "/home/airflow/.local/lib/python3.8/site-packages/airflow/models/taskinstance.py", line 1518, in _run_raw_task
    self._execute_task_with_callbacks(context, test_mode, session=session)
  File "/home/airflow/.local/lib/python3.8/site-packages/airflow/models/taskinstance.py", line 1681, in _execute_task_with_callbacks
    result = self._execute_task(context, task_orig)
  File "/home/airflow/.local/lib/python3.8/site-packages/airflow/models/taskinstance.py", line 1744, in _execute_task
    result = execute_callable(context=context, **execute_callable_kwargs)
  File "/home/airflow/.local/lib/python3.8/site-packages/airflow/providers/google/cloud/transfers/sql_to_gcs.py", line 162, in execute
    cursor = self.query()
  File "/home/airflow/.local/lib/python3.8/site-packages/airflow/providers/google/cloud/transfers/postgres_to_gcs.py", line 120, in query
    conn = hook.get_conn()
  File "/home/airflow/.local/lib/python3.8/site-packages/airflow/providers/postgres/hooks/postgres.py", line 155, in get_conn
    self.conn = psycopg2.connect(**conn_args)
  File "/home/airflow/.local/lib/python3.8/site-packages/psycopg2/__init__.py", line 122, in connect
    conn = _connect(dsn, connection_factory=connection_factory, **kwasync)
psycopg2.OperationalError: connection to server at "postgres" (172.21.0.2), port 54320 failed: Connection refused
	Is the server running on that host and accepting TCP/IP connections?


During handling of the above exception, another exception occurred:

Traceback (most recent call last):
  File "/home/airflow/.local/lib/python3.8/site-packages/airflow/models/taskinstance.py", line 2420, in email_alert
    send_email(task.email, subject, html_content)
  File "/home/airflow/.local/lib/python3.8/site-packages/airflow/utils/email.py", line 80, in send_email
    return backend(
  File "/home/airflow/.local/lib/python3.8/site-packages/airflow/utils/email.py", line 154, in send_email_smtp
    send_mime_email(e_from=mail_from, e_to=recipients, mime_msg=msg, conn_id=conn_id, dryrun=dryrun)
  File "/home/airflow/.local/lib/python3.8/site-packages/airflow/utils/email.py", line 272, in send_mime_email
    smtp_conn = _get_smtp_connection(smtp_host, smtp_port, smtp_timeout, smtp_ssl)
  File "/home/airflow/.local/lib/python3.8/site-packages/airflow/utils/email.py", line 316, in _get_smtp_connection
    return smtplib.SMTP(host=host, port=port, timeout=timeout)
  File "/usr/local/lib/python3.8/smtplib.py", line 255, in __init__
    (code, msg) = self.connect(host, port)
  File "/usr/local/lib/python3.8/smtplib.py", line 339, in connect
    self.sock = self._get_socket(host, port, self.timeout)
  File "/usr/local/lib/python3.8/smtplib.py", line 310, in _get_socket
    return socket.create_connection((host, port), timeout,
  File "/usr/local/lib/python3.8/socket.py", line 808, in create_connection
    raise err
  File "/usr/local/lib/python3.8/socket.py", line 796, in create_connection
    sock.connect(sa)
OSError: [Errno 99] Cannot assign requested address

During handling of the above exception, another exception occurred:

Traceback (most recent call last):
  File "/home/airflow/.local/lib/python3.8/site-packages/airflow/models/taskinstance.py", line 2005, in handle_failure
    self.email_alert(error, task)
  File "/home/airflow/.local/lib/python3.8/site-packages/airflow/models/taskinstance.py", line 2422, in email_alert
    send_email(task.email, subject, html_content_err)
  File "/home/airflow/.local/lib/python3.8/site-packages/airflow/utils/email.py", line 80, in send_email
    return backend(
  File "/home/airflow/.local/lib/python3.8/site-packages/airflow/utils/email.py", line 154, in send_email_smtp
    send_mime_email(e_from=mail_from, e_to=recipients, mime_msg=msg, conn_id=conn_id, dryrun=dryrun)
  File "/home/airflow/.local/lib/python3.8/site-packages/airflow/utils/email.py", line 272, in send_mime_email
    smtp_conn = _get_smtp_connection(smtp_host, smtp_port, smtp_timeout, smtp_ssl)
  File "/home/airflow/.local/lib/python3.8/site-packages/airflow/utils/email.py", line 316, in _get_smtp_connection
    return smtplib.SMTP(host=host, port=port, timeout=timeout)
  File "/usr/local/lib/python3.8/smtplib.py", line 255, in __init__
    (code, msg) = self.connect(host, port)
  File "/usr/local/lib/python3.8/smtplib.py", line 339, in connect
    self.sock = self._get_socket(host, port, self.timeout)
  File "/usr/local/lib/python3.8/smtplib.py", line 310, in _get_socket
    return socket.create_connection((host, port), timeout,
  File "/usr/local/lib/python3.8/socket.py", line 808, in create_connection
    raise err
  File "/usr/local/lib/python3.8/socket.py", line 796, in create_connection
    sock.connect(sa)
OSError: [Errno 99] Cannot assign requested address
[2023-11-30T06:18:42.274+0000] {standard_task_runner.py:104} ERROR - Failed to execute job 135 for task upload_to_gcs_department (connection to server at "postgres" (172.21.0.2), port 54320 failed: Connection refused
	Is the server running on that host and accepting TCP/IP connections?
; 15271)
[2023-11-30T06:18:42.324+0000] {local_task_job_runner.py:228} INFO - Task exited with return code 1
[2023-11-30T06:18:42.467+0000] {taskinstance.py:2778} INFO - 0 downstream tasks scheduled from follow-on schedule check
[2023-11-30T06:53:18.086+0000] {taskinstance.py:1159} INFO - Dependencies all met for dep_context=non-requeueable deps ti=<TaskInstance: ingest_to_postgres.upload_to_gcs_department scheduled__2023-11-27T00:00:00+00:00 [queued]>
[2023-11-30T06:53:18.118+0000] {taskinstance.py:1159} INFO - Dependencies all met for dep_context=requeueable deps ti=<TaskInstance: ingest_to_postgres.upload_to_gcs_department scheduled__2023-11-27T00:00:00+00:00 [queued]>
[2023-11-30T06:53:18.118+0000] {taskinstance.py:1361} INFO - Starting attempt 3 of 3
[2023-11-30T06:53:18.156+0000] {taskinstance.py:1382} INFO - Executing <Task(PostgresToGCSOperator): upload_to_gcs_department> on 2023-11-27 00:00:00+00:00
[2023-11-30T06:53:18.165+0000] {standard_task_runner.py:57} INFO - Started process 16119 to run task
[2023-11-30T06:53:18.171+0000] {standard_task_runner.py:84} INFO - Running: ['airflow', 'tasks', 'run', 'ingest_to_postgres', 'upload_to_gcs_department', 'scheduled__2023-11-27T00:00:00+00:00', '--job-id', '146', '--raw', '--subdir', 'DAGS_FOLDER/postgres_to_gcs_staging.py', '--cfg-path', '/tmp/tmpkgsjj3to']
[2023-11-30T06:53:18.175+0000] {standard_task_runner.py:85} INFO - Job 146: Subtask upload_to_gcs_department
[2023-11-30T06:53:18.360+0000] {task_command.py:416} INFO - Running <TaskInstance: ingest_to_postgres.upload_to_gcs_department scheduled__2023-11-27T00:00:00+00:00 [running]> on host f212b4329056
[2023-11-30T06:53:18.488+0000] {logging_mixin.py:151} WARNING - /home/airflow/.local/lib/python3.8/site-packages/airflow/utils/context.py:206 AirflowContextDeprecationWarning: Accessing 'execution_date' from the template is deprecated and will be removed in a future version. Please use 'data_interval_start' or 'logical_date' instead.
[2023-11-30T06:53:18.601+0000] {taskinstance.py:1662} INFO - Exporting env vars: AIRFLOW_CTX_DAG_EMAIL='franklinmutwiri41@gmail.com' AIRFLOW_CTX_DAG_OWNER='airflow' AIRFLOW_CTX_DAG_ID='ingest_to_postgres' AIRFLOW_CTX_TASK_ID='upload_to_gcs_department' AIRFLOW_CTX_EXECUTION_DATE='2023-11-27T00:00:00+00:00' AIRFLOW_CTX_TRY_NUMBER='3' AIRFLOW_CTX_DAG_RUN_ID='scheduled__2023-11-27T00:00:00+00:00'
[2023-11-30T06:53:18.603+0000] {sql_to_gcs.py:161} INFO - Executing query
[2023-11-30T06:53:18.632+0000] {base.py:73} INFO - Using connection ID 'postgres_docker' for task execution.
[2023-11-30T06:53:18.639+0000] {taskinstance.py:1937} ERROR - Task failed with exception
Traceback (most recent call last):
  File "/home/airflow/.local/lib/python3.8/site-packages/airflow/providers/google/cloud/transfers/sql_to_gcs.py", line 162, in execute
    cursor = self.query()
  File "/home/airflow/.local/lib/python3.8/site-packages/airflow/providers/google/cloud/transfers/postgres_to_gcs.py", line 120, in query
    conn = hook.get_conn()
  File "/home/airflow/.local/lib/python3.8/site-packages/airflow/providers/postgres/hooks/postgres.py", line 155, in get_conn
    self.conn = psycopg2.connect(**conn_args)
  File "/home/airflow/.local/lib/python3.8/site-packages/psycopg2/__init__.py", line 122, in connect
    conn = _connect(dsn, connection_factory=connection_factory, **kwasync)
psycopg2.OperationalError: could not translate host name "host.docker.internal" to address: Name or service not known

[2023-11-30T06:53:18.671+0000] {taskinstance.py:1400} INFO - Marking task as FAILED. dag_id=ingest_to_postgres, task_id=upload_to_gcs_department, execution_date=20231127T000000, start_date=20231130T065318, end_date=20231130T065318
[2023-11-30T06:53:18.700+0000] {logging_mixin.py:151} WARNING - /home/***/.local/lib/python3.8/site-packages/***/utils/email.py:154 RemovedInAirflow3Warning: Fetching SMTP credentials from configuration variables will be deprecated in a future release. Please set credentials using a connection instead.
[2023-11-30T06:53:18.700+0000] {configuration.py:1068} WARNING - section/key [smtp/smtp_user] not found in config
[2023-11-30T06:53:18.701+0000] {email.py:270} INFO - Email alerting: attempt 1
[2023-11-30T06:53:18.720+0000] {configuration.py:1068} WARNING - section/key [smtp/smtp_user] not found in config
[2023-11-30T06:53:18.720+0000] {email.py:270} INFO - Email alerting: attempt 1
[2023-11-30T06:53:18.721+0000] {taskinstance.py:2007} ERROR - Failed to send email to: ['franklinmutwiri41@gmail.com']
Traceback (most recent call last):
  File "/home/airflow/.local/lib/python3.8/site-packages/airflow/models/taskinstance.py", line 1518, in _run_raw_task
    self._execute_task_with_callbacks(context, test_mode, session=session)
  File "/home/airflow/.local/lib/python3.8/site-packages/airflow/models/taskinstance.py", line 1681, in _execute_task_with_callbacks
    result = self._execute_task(context, task_orig)
  File "/home/airflow/.local/lib/python3.8/site-packages/airflow/models/taskinstance.py", line 1744, in _execute_task
    result = execute_callable(context=context, **execute_callable_kwargs)
  File "/home/airflow/.local/lib/python3.8/site-packages/airflow/providers/google/cloud/transfers/sql_to_gcs.py", line 162, in execute
    cursor = self.query()
  File "/home/airflow/.local/lib/python3.8/site-packages/airflow/providers/google/cloud/transfers/postgres_to_gcs.py", line 120, in query
    conn = hook.get_conn()
  File "/home/airflow/.local/lib/python3.8/site-packages/airflow/providers/postgres/hooks/postgres.py", line 155, in get_conn
    self.conn = psycopg2.connect(**conn_args)
  File "/home/airflow/.local/lib/python3.8/site-packages/psycopg2/__init__.py", line 122, in connect
    conn = _connect(dsn, connection_factory=connection_factory, **kwasync)
psycopg2.OperationalError: could not translate host name "host.docker.internal" to address: Name or service not known


During handling of the above exception, another exception occurred:

Traceback (most recent call last):
  File "/home/airflow/.local/lib/python3.8/site-packages/airflow/models/taskinstance.py", line 2420, in email_alert
    send_email(task.email, subject, html_content)
  File "/home/airflow/.local/lib/python3.8/site-packages/airflow/utils/email.py", line 80, in send_email
    return backend(
  File "/home/airflow/.local/lib/python3.8/site-packages/airflow/utils/email.py", line 154, in send_email_smtp
    send_mime_email(e_from=mail_from, e_to=recipients, mime_msg=msg, conn_id=conn_id, dryrun=dryrun)
  File "/home/airflow/.local/lib/python3.8/site-packages/airflow/utils/email.py", line 272, in send_mime_email
    smtp_conn = _get_smtp_connection(smtp_host, smtp_port, smtp_timeout, smtp_ssl)
  File "/home/airflow/.local/lib/python3.8/site-packages/airflow/utils/email.py", line 316, in _get_smtp_connection
    return smtplib.SMTP(host=host, port=port, timeout=timeout)
  File "/usr/local/lib/python3.8/smtplib.py", line 255, in __init__
    (code, msg) = self.connect(host, port)
  File "/usr/local/lib/python3.8/smtplib.py", line 339, in connect
    self.sock = self._get_socket(host, port, self.timeout)
  File "/usr/local/lib/python3.8/smtplib.py", line 310, in _get_socket
    return socket.create_connection((host, port), timeout,
  File "/usr/local/lib/python3.8/socket.py", line 808, in create_connection
    raise err
  File "/usr/local/lib/python3.8/socket.py", line 796, in create_connection
    sock.connect(sa)
OSError: [Errno 99] Cannot assign requested address

During handling of the above exception, another exception occurred:

Traceback (most recent call last):
  File "/home/airflow/.local/lib/python3.8/site-packages/airflow/models/taskinstance.py", line 2005, in handle_failure
    self.email_alert(error, task)
  File "/home/airflow/.local/lib/python3.8/site-packages/airflow/models/taskinstance.py", line 2422, in email_alert
    send_email(task.email, subject, html_content_err)
  File "/home/airflow/.local/lib/python3.8/site-packages/airflow/utils/email.py", line 80, in send_email
    return backend(
  File "/home/airflow/.local/lib/python3.8/site-packages/airflow/utils/email.py", line 154, in send_email_smtp
    send_mime_email(e_from=mail_from, e_to=recipients, mime_msg=msg, conn_id=conn_id, dryrun=dryrun)
  File "/home/airflow/.local/lib/python3.8/site-packages/airflow/utils/email.py", line 272, in send_mime_email
    smtp_conn = _get_smtp_connection(smtp_host, smtp_port, smtp_timeout, smtp_ssl)
  File "/home/airflow/.local/lib/python3.8/site-packages/airflow/utils/email.py", line 316, in _get_smtp_connection
    return smtplib.SMTP(host=host, port=port, timeout=timeout)
  File "/usr/local/lib/python3.8/smtplib.py", line 255, in __init__
    (code, msg) = self.connect(host, port)
  File "/usr/local/lib/python3.8/smtplib.py", line 339, in connect
    self.sock = self._get_socket(host, port, self.timeout)
  File "/usr/local/lib/python3.8/smtplib.py", line 310, in _get_socket
    return socket.create_connection((host, port), timeout,
  File "/usr/local/lib/python3.8/socket.py", line 808, in create_connection
    raise err
  File "/usr/local/lib/python3.8/socket.py", line 796, in create_connection
    sock.connect(sa)
OSError: [Errno 99] Cannot assign requested address
[2023-11-30T06:53:18.765+0000] {standard_task_runner.py:104} ERROR - Failed to execute job 146 for task upload_to_gcs_department (could not translate host name "host.docker.internal" to address: Name or service not known
; 16119)
[2023-11-30T06:53:18.790+0000] {local_task_job_runner.py:228} INFO - Task exited with return code 1
[2023-11-30T06:53:18.861+0000] {taskinstance.py:2778} INFO - 0 downstream tasks scheduled from follow-on schedule check
[2023-11-30T07:19:25.796+0000] {taskinstance.py:1159} INFO - Dependencies all met for dep_context=non-requeueable deps ti=<TaskInstance: ingest_to_postgres.upload_to_gcs_department scheduled__2023-11-27T00:00:00+00:00 [queued]>
[2023-11-30T07:19:25.813+0000] {taskinstance.py:1159} INFO - Dependencies all met for dep_context=requeueable deps ti=<TaskInstance: ingest_to_postgres.upload_to_gcs_department scheduled__2023-11-27T00:00:00+00:00 [queued]>
[2023-11-30T07:19:25.814+0000] {taskinstance.py:1361} INFO - Starting attempt 3 of 3
[2023-11-30T07:19:25.876+0000] {taskinstance.py:1382} INFO - Executing <Task(PostgresToGCSOperator): upload_to_gcs_department> on 2023-11-27 00:00:00+00:00
[2023-11-30T07:19:25.909+0000] {standard_task_runner.py:57} INFO - Started process 16788 to run task
[2023-11-30T07:19:25.915+0000] {standard_task_runner.py:84} INFO - Running: ['airflow', 'tasks', 'run', 'ingest_to_postgres', 'upload_to_gcs_department', 'scheduled__2023-11-27T00:00:00+00:00', '--job-id', '163', '--raw', '--subdir', 'DAGS_FOLDER/postgres_to_gcs_staging.py', '--cfg-path', '/tmp/tmpb5gj6utp']
[2023-11-30T07:19:25.920+0000] {standard_task_runner.py:85} INFO - Job 163: Subtask upload_to_gcs_department
[2023-11-30T07:19:26.075+0000] {task_command.py:416} INFO - Running <TaskInstance: ingest_to_postgres.upload_to_gcs_department scheduled__2023-11-27T00:00:00+00:00 [running]> on host f212b4329056
[2023-11-30T07:19:26.214+0000] {logging_mixin.py:151} WARNING - /home/airflow/.local/lib/python3.8/site-packages/airflow/utils/context.py:206 AirflowContextDeprecationWarning: Accessing 'execution_date' from the template is deprecated and will be removed in a future version. Please use 'data_interval_start' or 'logical_date' instead.
[2023-11-30T07:19:26.297+0000] {taskinstance.py:1662} INFO - Exporting env vars: AIRFLOW_CTX_DAG_EMAIL='franklinmutwiri41@gmail.com' AIRFLOW_CTX_DAG_OWNER='airflow' AIRFLOW_CTX_DAG_ID='ingest_to_postgres' AIRFLOW_CTX_TASK_ID='upload_to_gcs_department' AIRFLOW_CTX_EXECUTION_DATE='2023-11-27T00:00:00+00:00' AIRFLOW_CTX_TRY_NUMBER='3' AIRFLOW_CTX_DAG_RUN_ID='scheduled__2023-11-27T00:00:00+00:00'
[2023-11-30T07:19:26.299+0000] {sql_to_gcs.py:161} INFO - Executing query
[2023-11-30T07:19:26.324+0000] {base.py:73} INFO - Using connection ID 'postgres_docker' for task execution.
[2023-11-30T07:19:26.340+0000] {taskinstance.py:1937} ERROR - Task failed with exception
Traceback (most recent call last):
  File "/home/airflow/.local/lib/python3.8/site-packages/airflow/providers/google/cloud/transfers/sql_to_gcs.py", line 162, in execute
    cursor = self.query()
  File "/home/airflow/.local/lib/python3.8/site-packages/airflow/providers/google/cloud/transfers/postgres_to_gcs.py", line 120, in query
    conn = hook.get_conn()
  File "/home/airflow/.local/lib/python3.8/site-packages/airflow/providers/postgres/hooks/postgres.py", line 155, in get_conn
    self.conn = psycopg2.connect(**conn_args)
  File "/home/airflow/.local/lib/python3.8/site-packages/psycopg2/__init__.py", line 122, in connect
    conn = _connect(dsn, connection_factory=connection_factory, **kwasync)
psycopg2.OperationalError: connection to server at "postgres" (172.21.0.2), port 5432 failed: FATAL:  database "public" does not exist

[2023-11-30T07:19:26.365+0000] {taskinstance.py:1400} INFO - Marking task as FAILED. dag_id=ingest_to_postgres, task_id=upload_to_gcs_department, execution_date=20231127T000000, start_date=20231130T071925, end_date=20231130T071926
[2023-11-30T07:19:26.394+0000] {logging_mixin.py:151} WARNING - /home/***/.local/lib/python3.8/site-packages/***/utils/email.py:154 RemovedInAirflow3Warning: Fetching SMTP credentials from configuration variables will be deprecated in a future release. Please set credentials using a connection instead.
[2023-11-30T07:19:26.395+0000] {configuration.py:1068} WARNING - section/key [smtp/smtp_user] not found in config
[2023-11-30T07:19:26.395+0000] {email.py:270} INFO - Email alerting: attempt 1
[2023-11-30T07:19:26.416+0000] {configuration.py:1068} WARNING - section/key [smtp/smtp_user] not found in config
[2023-11-30T07:19:26.417+0000] {email.py:270} INFO - Email alerting: attempt 1
[2023-11-30T07:19:26.417+0000] {taskinstance.py:2007} ERROR - Failed to send email to: ['franklinmutwiri41@gmail.com']
Traceback (most recent call last):
  File "/home/airflow/.local/lib/python3.8/site-packages/airflow/models/taskinstance.py", line 1518, in _run_raw_task
    self._execute_task_with_callbacks(context, test_mode, session=session)
  File "/home/airflow/.local/lib/python3.8/site-packages/airflow/models/taskinstance.py", line 1681, in _execute_task_with_callbacks
    result = self._execute_task(context, task_orig)
  File "/home/airflow/.local/lib/python3.8/site-packages/airflow/models/taskinstance.py", line 1744, in _execute_task
    result = execute_callable(context=context, **execute_callable_kwargs)
  File "/home/airflow/.local/lib/python3.8/site-packages/airflow/providers/google/cloud/transfers/sql_to_gcs.py", line 162, in execute
    cursor = self.query()
  File "/home/airflow/.local/lib/python3.8/site-packages/airflow/providers/google/cloud/transfers/postgres_to_gcs.py", line 120, in query
    conn = hook.get_conn()
  File "/home/airflow/.local/lib/python3.8/site-packages/airflow/providers/postgres/hooks/postgres.py", line 155, in get_conn
    self.conn = psycopg2.connect(**conn_args)
  File "/home/airflow/.local/lib/python3.8/site-packages/psycopg2/__init__.py", line 122, in connect
    conn = _connect(dsn, connection_factory=connection_factory, **kwasync)
psycopg2.OperationalError: connection to server at "postgres" (172.21.0.2), port 5432 failed: FATAL:  database "public" does not exist


During handling of the above exception, another exception occurred:

Traceback (most recent call last):
  File "/home/airflow/.local/lib/python3.8/site-packages/airflow/models/taskinstance.py", line 2420, in email_alert
    send_email(task.email, subject, html_content)
  File "/home/airflow/.local/lib/python3.8/site-packages/airflow/utils/email.py", line 80, in send_email
    return backend(
  File "/home/airflow/.local/lib/python3.8/site-packages/airflow/utils/email.py", line 154, in send_email_smtp
    send_mime_email(e_from=mail_from, e_to=recipients, mime_msg=msg, conn_id=conn_id, dryrun=dryrun)
  File "/home/airflow/.local/lib/python3.8/site-packages/airflow/utils/email.py", line 272, in send_mime_email
    smtp_conn = _get_smtp_connection(smtp_host, smtp_port, smtp_timeout, smtp_ssl)
  File "/home/airflow/.local/lib/python3.8/site-packages/airflow/utils/email.py", line 316, in _get_smtp_connection
    return smtplib.SMTP(host=host, port=port, timeout=timeout)
  File "/usr/local/lib/python3.8/smtplib.py", line 255, in __init__
    (code, msg) = self.connect(host, port)
  File "/usr/local/lib/python3.8/smtplib.py", line 339, in connect
    self.sock = self._get_socket(host, port, self.timeout)
  File "/usr/local/lib/python3.8/smtplib.py", line 310, in _get_socket
    return socket.create_connection((host, port), timeout,
  File "/usr/local/lib/python3.8/socket.py", line 808, in create_connection
    raise err
  File "/usr/local/lib/python3.8/socket.py", line 796, in create_connection
    sock.connect(sa)
OSError: [Errno 99] Cannot assign requested address

During handling of the above exception, another exception occurred:

Traceback (most recent call last):
  File "/home/airflow/.local/lib/python3.8/site-packages/airflow/models/taskinstance.py", line 2005, in handle_failure
    self.email_alert(error, task)
  File "/home/airflow/.local/lib/python3.8/site-packages/airflow/models/taskinstance.py", line 2422, in email_alert
    send_email(task.email, subject, html_content_err)
  File "/home/airflow/.local/lib/python3.8/site-packages/airflow/utils/email.py", line 80, in send_email
    return backend(
  File "/home/airflow/.local/lib/python3.8/site-packages/airflow/utils/email.py", line 154, in send_email_smtp
    send_mime_email(e_from=mail_from, e_to=recipients, mime_msg=msg, conn_id=conn_id, dryrun=dryrun)
  File "/home/airflow/.local/lib/python3.8/site-packages/airflow/utils/email.py", line 272, in send_mime_email
    smtp_conn = _get_smtp_connection(smtp_host, smtp_port, smtp_timeout, smtp_ssl)
  File "/home/airflow/.local/lib/python3.8/site-packages/airflow/utils/email.py", line 316, in _get_smtp_connection
    return smtplib.SMTP(host=host, port=port, timeout=timeout)
  File "/usr/local/lib/python3.8/smtplib.py", line 255, in __init__
    (code, msg) = self.connect(host, port)
  File "/usr/local/lib/python3.8/smtplib.py", line 339, in connect
    self.sock = self._get_socket(host, port, self.timeout)
  File "/usr/local/lib/python3.8/smtplib.py", line 310, in _get_socket
    return socket.create_connection((host, port), timeout,
  File "/usr/local/lib/python3.8/socket.py", line 808, in create_connection
    raise err
  File "/usr/local/lib/python3.8/socket.py", line 796, in create_connection
    sock.connect(sa)
OSError: [Errno 99] Cannot assign requested address
[2023-11-30T07:19:26.450+0000] {standard_task_runner.py:104} ERROR - Failed to execute job 163 for task upload_to_gcs_department (connection to server at "postgres" (172.21.0.2), port 5432 failed: FATAL:  database "public" does not exist
; 16788)
[2023-11-30T07:19:26.470+0000] {local_task_job_runner.py:228} INFO - Task exited with return code 1
[2023-11-30T07:19:26.512+0000] {taskinstance.py:2778} INFO - 0 downstream tasks scheduled from follow-on schedule check
[2023-11-30T07:35:53.761+0000] {taskinstance.py:1159} INFO - Dependencies all met for dep_context=non-requeueable deps ti=<TaskInstance: ingest_to_postgres.upload_to_gcs_department scheduled__2023-11-27T00:00:00+00:00 [queued]>
[2023-11-30T07:35:53.792+0000] {taskinstance.py:1159} INFO - Dependencies all met for dep_context=requeueable deps ti=<TaskInstance: ingest_to_postgres.upload_to_gcs_department scheduled__2023-11-27T00:00:00+00:00 [queued]>
[2023-11-30T07:35:53.793+0000] {taskinstance.py:1361} INFO - Starting attempt 3 of 3
[2023-11-30T07:35:53.928+0000] {taskinstance.py:1382} INFO - Executing <Task(PostgresToGCSOperator): upload_to_gcs_department> on 2023-11-27 00:00:00+00:00
[2023-11-30T07:35:53.939+0000] {standard_task_runner.py:57} INFO - Started process 377 to run task
[2023-11-30T07:35:53.949+0000] {standard_task_runner.py:84} INFO - Running: ['airflow', 'tasks', 'run', 'ingest_to_postgres', 'upload_to_gcs_department', 'scheduled__2023-11-27T00:00:00+00:00', '--job-id', '176', '--raw', '--subdir', 'DAGS_FOLDER/postgres_to_gcs_staging.py', '--cfg-path', '/tmp/tmphfdc_hl5']
[2023-11-30T07:35:53.955+0000] {standard_task_runner.py:85} INFO - Job 176: Subtask upload_to_gcs_department
[2023-11-30T07:35:54.093+0000] {task_command.py:416} INFO - Running <TaskInstance: ingest_to_postgres.upload_to_gcs_department scheduled__2023-11-27T00:00:00+00:00 [running]> on host e27015ac188f
[2023-11-30T07:35:54.234+0000] {logging_mixin.py:151} WARNING - /home/airflow/.local/lib/python3.8/site-packages/airflow/utils/context.py:206 AirflowContextDeprecationWarning: Accessing 'execution_date' from the template is deprecated and will be removed in a future version. Please use 'data_interval_start' or 'logical_date' instead.
[2023-11-30T07:35:54.323+0000] {taskinstance.py:1662} INFO - Exporting env vars: AIRFLOW_CTX_DAG_EMAIL='franklinmutwiri41@gmail.com' AIRFLOW_CTX_DAG_OWNER='airflow' AIRFLOW_CTX_DAG_ID='ingest_to_postgres' AIRFLOW_CTX_TASK_ID='upload_to_gcs_department' AIRFLOW_CTX_EXECUTION_DATE='2023-11-27T00:00:00+00:00' AIRFLOW_CTX_TRY_NUMBER='3' AIRFLOW_CTX_DAG_RUN_ID='scheduled__2023-11-27T00:00:00+00:00'
[2023-11-30T07:35:54.325+0000] {sql_to_gcs.py:161} INFO - Executing query
[2023-11-30T07:35:54.347+0000] {base.py:73} INFO - Using connection ID 'postgres_docker' for task execution.
[2023-11-30T07:35:54.361+0000] {taskinstance.py:1937} ERROR - Task failed with exception
Traceback (most recent call last):
  File "/home/airflow/.local/lib/python3.8/site-packages/airflow/providers/google/cloud/transfers/sql_to_gcs.py", line 162, in execute
    cursor = self.query()
  File "/home/airflow/.local/lib/python3.8/site-packages/airflow/providers/google/cloud/transfers/postgres_to_gcs.py", line 120, in query
    conn = hook.get_conn()
  File "/home/airflow/.local/lib/python3.8/site-packages/airflow/providers/postgres/hooks/postgres.py", line 155, in get_conn
    self.conn = psycopg2.connect(**conn_args)
  File "/home/airflow/.local/lib/python3.8/site-packages/psycopg2/__init__.py", line 122, in connect
    conn = _connect(dsn, connection_factory=connection_factory, **kwasync)
psycopg2.OperationalError: connection to server at "postgres" (172.23.0.3), port 5432 failed: FATAL:  database "public" does not exist

[2023-11-30T07:35:54.391+0000] {taskinstance.py:1400} INFO - Marking task as FAILED. dag_id=ingest_to_postgres, task_id=upload_to_gcs_department, execution_date=20231127T000000, start_date=20231130T073553, end_date=20231130T073554
[2023-11-30T07:35:54.418+0000] {logging_mixin.py:151} WARNING - /home/***/.local/lib/python3.8/site-packages/***/utils/email.py:154 RemovedInAirflow3Warning: Fetching SMTP credentials from configuration variables will be deprecated in a future release. Please set credentials using a connection instead.
[2023-11-30T07:35:54.425+0000] {configuration.py:1068} WARNING - section/key [smtp/smtp_user] not found in config
[2023-11-30T07:35:54.427+0000] {email.py:270} INFO - Email alerting: attempt 1
[2023-11-30T07:35:54.446+0000] {configuration.py:1068} WARNING - section/key [smtp/smtp_user] not found in config
[2023-11-30T07:35:54.446+0000] {email.py:270} INFO - Email alerting: attempt 1
[2023-11-30T07:35:54.447+0000] {taskinstance.py:2007} ERROR - Failed to send email to: ['franklinmutwiri41@gmail.com']
Traceback (most recent call last):
  File "/home/airflow/.local/lib/python3.8/site-packages/airflow/models/taskinstance.py", line 1518, in _run_raw_task
    self._execute_task_with_callbacks(context, test_mode, session=session)
  File "/home/airflow/.local/lib/python3.8/site-packages/airflow/models/taskinstance.py", line 1681, in _execute_task_with_callbacks
    result = self._execute_task(context, task_orig)
  File "/home/airflow/.local/lib/python3.8/site-packages/airflow/models/taskinstance.py", line 1744, in _execute_task
    result = execute_callable(context=context, **execute_callable_kwargs)
  File "/home/airflow/.local/lib/python3.8/site-packages/airflow/providers/google/cloud/transfers/sql_to_gcs.py", line 162, in execute
    cursor = self.query()
  File "/home/airflow/.local/lib/python3.8/site-packages/airflow/providers/google/cloud/transfers/postgres_to_gcs.py", line 120, in query
    conn = hook.get_conn()
  File "/home/airflow/.local/lib/python3.8/site-packages/airflow/providers/postgres/hooks/postgres.py", line 155, in get_conn
    self.conn = psycopg2.connect(**conn_args)
  File "/home/airflow/.local/lib/python3.8/site-packages/psycopg2/__init__.py", line 122, in connect
    conn = _connect(dsn, connection_factory=connection_factory, **kwasync)
psycopg2.OperationalError: connection to server at "postgres" (172.23.0.3), port 5432 failed: FATAL:  database "public" does not exist


During handling of the above exception, another exception occurred:

Traceback (most recent call last):
  File "/home/airflow/.local/lib/python3.8/site-packages/airflow/models/taskinstance.py", line 2420, in email_alert
    send_email(task.email, subject, html_content)
  File "/home/airflow/.local/lib/python3.8/site-packages/airflow/utils/email.py", line 80, in send_email
    return backend(
  File "/home/airflow/.local/lib/python3.8/site-packages/airflow/utils/email.py", line 154, in send_email_smtp
    send_mime_email(e_from=mail_from, e_to=recipients, mime_msg=msg, conn_id=conn_id, dryrun=dryrun)
  File "/home/airflow/.local/lib/python3.8/site-packages/airflow/utils/email.py", line 272, in send_mime_email
    smtp_conn = _get_smtp_connection(smtp_host, smtp_port, smtp_timeout, smtp_ssl)
  File "/home/airflow/.local/lib/python3.8/site-packages/airflow/utils/email.py", line 316, in _get_smtp_connection
    return smtplib.SMTP(host=host, port=port, timeout=timeout)
  File "/usr/local/lib/python3.8/smtplib.py", line 255, in __init__
    (code, msg) = self.connect(host, port)
  File "/usr/local/lib/python3.8/smtplib.py", line 339, in connect
    self.sock = self._get_socket(host, port, self.timeout)
  File "/usr/local/lib/python3.8/smtplib.py", line 310, in _get_socket
    return socket.create_connection((host, port), timeout,
  File "/usr/local/lib/python3.8/socket.py", line 808, in create_connection
    raise err
  File "/usr/local/lib/python3.8/socket.py", line 796, in create_connection
    sock.connect(sa)
OSError: [Errno 99] Cannot assign requested address

During handling of the above exception, another exception occurred:

Traceback (most recent call last):
  File "/home/airflow/.local/lib/python3.8/site-packages/airflow/models/taskinstance.py", line 2005, in handle_failure
    self.email_alert(error, task)
  File "/home/airflow/.local/lib/python3.8/site-packages/airflow/models/taskinstance.py", line 2422, in email_alert
    send_email(task.email, subject, html_content_err)
  File "/home/airflow/.local/lib/python3.8/site-packages/airflow/utils/email.py", line 80, in send_email
    return backend(
  File "/home/airflow/.local/lib/python3.8/site-packages/airflow/utils/email.py", line 154, in send_email_smtp
    send_mime_email(e_from=mail_from, e_to=recipients, mime_msg=msg, conn_id=conn_id, dryrun=dryrun)
  File "/home/airflow/.local/lib/python3.8/site-packages/airflow/utils/email.py", line 272, in send_mime_email
    smtp_conn = _get_smtp_connection(smtp_host, smtp_port, smtp_timeout, smtp_ssl)
  File "/home/airflow/.local/lib/python3.8/site-packages/airflow/utils/email.py", line 316, in _get_smtp_connection
    return smtplib.SMTP(host=host, port=port, timeout=timeout)
  File "/usr/local/lib/python3.8/smtplib.py", line 255, in __init__
    (code, msg) = self.connect(host, port)
  File "/usr/local/lib/python3.8/smtplib.py", line 339, in connect
    self.sock = self._get_socket(host, port, self.timeout)
  File "/usr/local/lib/python3.8/smtplib.py", line 310, in _get_socket
    return socket.create_connection((host, port), timeout,
  File "/usr/local/lib/python3.8/socket.py", line 808, in create_connection
    raise err
  File "/usr/local/lib/python3.8/socket.py", line 796, in create_connection
    sock.connect(sa)
OSError: [Errno 99] Cannot assign requested address
[2023-11-30T07:35:54.492+0000] {standard_task_runner.py:104} ERROR - Failed to execute job 176 for task upload_to_gcs_department (connection to server at "postgres" (172.23.0.3), port 5432 failed: FATAL:  database "public" does not exist
; 377)
[2023-11-30T07:35:54.520+0000] {local_task_job_runner.py:228} INFO - Task exited with return code 1
[2023-11-30T07:35:54.602+0000] {taskinstance.py:2778} INFO - 0 downstream tasks scheduled from follow-on schedule check
